Workbook

Sheet Ampol Retail
B2: Ampol Retail — TDD Cost Calculator
B3: Cost build-up: Squad → Platform → Portfolio, split into TDD-funded and Other. Compared against the TDD lights-on budget to reveal the funding gap.
B4: All figures $m per annum • FY2026 • Cells shaded yellow with blue text are your selections
B6: HOW TO USE — For each squad choose: ①Squad Type ②Size (XS/S/M/L) ③On/Off (Onshore or Offshore) ④Support %. Total Squad Cost is looked up from the Squads sheet; Cost TDD = Total × Support %; Cost Other = Total × (1 − Support %). Platforms add a $0.165m overhead; the Portfolio adds a $0.6945m overhead. Support-% options are 0 / 20% / 100%.
B8: ① PORTFOLIO SUMMARY — Ampol Retail
B9: Cost component | G9: Total ($m) | H9: TDD ($m) | I9: Other ($m)
B10: Total Portfolio Overhead | G10: =H10+I10 -> 0.6945 | H10: ='Data Config'!$K$11 -> 0.6945 | I10: 0
B11: Total Platform Overhead | G11: =H11+I11 -> 0.825 | H11: =H35+H42+H49+H56+H63 -> 0.825 | I11: 0
B12: Total Support Costs | G12: =H12+I12 -> 13.4 | H12: =H36+H43+H50+H57+H64 -> 2.68 | I12: =I36+I43+I50+I57+I64 -> 10.72
B13: TOTAL COST | G13: =H13+I13 -> 14.9195 | H13: =SUM(H10:H12) -> 4.1995 | I13: =SUM(I10:I12) -> 10.72
B15: ② BUDGET & VARIANCE — TDD Lights-On
B16: TDD Lights-On Budget (Ampol Retail — Data Config) | H16: ='Data Config'!$E$12 -> 2.5
B17: TDD Cost implied by squad selections (Total TDD above) | H17: =H13 -> 4.1995
B18: VARIANCE (Budget − TDD Cost) → surplus / (shortfall to fund) | H18: =H16-H17 -> -1.6995
B19: =IF(H18>=0,"✔ Surplus of $"&TEXT(H18,"0.00")&"m within the TDD lights-on allocation.","✘ Shortfall of $"&TEXT(-H18,"0.00")&"m — additional funding required beyond the $"&TEXT(H16,"0.0")&"m TDD lights-on budget.") -> ✘ Shortfall of $1.70m — additional funding required beyond the $2.5m TDD lights-on budget.
B21: ③ FY2026 RETAIL BUDGET (envelope from the presentation pack)
B22: Lights On | D22: Initiatives (Project OpEx) | E22: Depreciation | F22: Significant Items | G22: CapEx | I22: Total FY26
B23: ='FY26 Budget'!C6 -> 13.925855 | D23: ='FY26 Budget'!D6 -> 1.31 | E23: ='FY26 Budget'!E6 -> 0 | F23: ='FY26 Budget'!F6 -> 6.845 | G23: ='FY26 Budget'!G6 -> 11.8 | I23: ='FY26 Budget'!H6 -> 33.880855
B24: Note: The TDD Lights-On budget used for the variance above ($2.5m) is the TDD-funded lights-on allocation for Ampol Retail from Data Config; the table above is the full FY26 Retail technology envelope for context.
B27: ④ PLATFORM DETAIL — select squad type, size, shore & support for every squad
B29: Platform 1 — Store Operations
B30: Squad | C30: Squad Type | D30: Size | E30: On/Off | F30: Support % | G30: Total Squad Cost ($m) | H30: Cost TDD ($m) | I30: Cost Other ($m)
B31: POS | C31: Configuration / Integration | D31: M | E31: Onshore | F31: 0.2 | G31: =IFERROR(IF($E31="Offshore",INDEX(Squads!$H$6:$H$24,MATCH($C31&"|"&$D31,Squads!$J$6:$J$24,0)),INDEX(Squads!$F$6:$F$24,MATCH($C31&"|"&$D31,Squads!$J$6:$J$24,0))),0) -> 1.4 | H31: =G31*F31 -> 0.28 | I31: =G31*(1-F31) -> 1.12
B32: Payments | C32: Configuration / Integration | D32: S | E32: Onshore | F32: 0.2 | G32: =IFERROR(IF($E32="Offshore",INDEX(Squads!$H$6:$H$24,MATCH($C32&"|"&$D32,Squads!$J$6:$J$24,0)),INDEX(Squads!$F$6:$F$24,MATCH($C32&"|"&$D32,Squads!$J$6:$J$24,0))),0) -> 0.4 | H32: =G32*F32 -> 0.08 | I32: =G32*(1-F32) -> 0.32
B33: Retail Operations | C33: Operations | D33: M | E33: Onshore | F33: 0.2 | G33: =IFERROR(IF($E33="Offshore",INDEX(Squads!$H$6:$H$24,MATCH($C33&"|"&$D33,Squads!$J$6:$J$24,0)),INDEX(Squads!$F$6:$F$24,MATCH($C33&"|"&$D33,Squads!$J$6:$J$24,0))),0) -> 1.4 | H33: =G33*F33 -> 0.28 | I33: =G33*(1-F33) -> 1.12
B34: Deployment | C34: Build and Run | D34: S | E34: Onshore | F34: 0.2 | G34: =IFERROR(IF($E34="Offshore",INDEX(Squads!$H$6:$H$24,MATCH($C34&"|"&$D34,Squads!$J$6:$J$24,0)),INDEX(Squads!$F$6:$F$24,MATCH($C34&"|"&$D34,Squads!$J$6:$J$24,0))),0) -> 0.9 | H34: =G34*F34 -> 0.18 | I34: =G34*(1-F34) -> 0.72
B35: Platform Overhead (TDD-funded) | G35: =H35+I35 -> 0.165 | H35: ='Data Config'!$K$16 -> 0.165 | I35: 0
B36: Support Cost (Σ squads) | G36: =H36+I36 -> 4.1 | H36: =SUM(H31:H34) -> 0.82 | I36: =SUM(I31:I34) -> 3.28
B37: PLATFORM TOTAL — Store Operations | G37: =H37+I37 -> 4.265 | H37: =H35+H36 -> 0.985 | I37: =I35+I36 -> 3.28
B39: Platform 2 — Merchandising / Supply Chain
B40: Squad | C40: Squad Type | D40: Size | E40: On/Off | F40: Support % | G40: Total Squad Cost ($m) | H40: Cost TDD ($m) | I40: Cost Other ($m)
B41: Merchandising & Supply Chain | C41: Engineering | D41: M | E41: Onshore | F41: 0.2 | G41: =IFERROR(IF($E41="Offshore",INDEX(Squads!$H$6:$H$24,MATCH($C41&"|"&$D41,Squads!$J$6:$J$24,0)),INDEX(Squads!$F$6:$F$24,MATCH($C41&"|"&$D41,Squads!$J$6:$J$24,0))),0) -> 2 | H41: =G41*F41 -> 0.4 | I41: =G41*(1-F41) -> 1.6
B42: Platform Overhead (TDD-funded) | G42: =H42+I42 -> 0.165 | H42: ='Data Config'!$K$16 -> 0.165 | I42: 0
B43: Support Cost (Σ squads) | G43: =H43+I43 -> 2 | H43: =SUM(H41:H41) -> 0.4 | I43: =SUM(I41:I41) -> 1.6
B44: PLATFORM TOTAL — Merchandising / Supply Chain | G44: =H44+I44 -> 2.165 | H44: =H42+H43 -> 0.565 | I44: =I42+I43 -> 1.6
B46: Platform 3 — Pricing & WFM
B47: Squad | C47: Squad Type | D47: Size | E47: On/Off | F47: Support % | G47: Total Squad Cost ($m) | H47: Cost TDD ($m) | I47: Cost Other ($m)
B48: Pricing & WFM | C48: Product | D48: M | E48: Onshore | F48: 0.2 | G48: =IFERROR(IF($E48="Offshore",INDEX(Squads!$H$6:$H$24,MATCH($C48&"|"&$D48,Squads!$J$6:$J$24,0)),INDEX(Squads!$F$6:$F$24,MATCH($C48&"|"&$D48,Squads!$J$6:$J$24,0))),0) -> 1.9 | H48: =G48*F48 -> 0.38 | I48: =G48*(1-F48) -> 1.52
B49: Platform Overhead (TDD-funded) | G49: =H49+I49 -> 0.165 | H49: ='Data Config'!$K$16 -> 0.165 | I49: 0
B50: Support Cost (Σ squads) | G50: =H50+I50 -> 1.9 | H50: =SUM(H48:H48) -> 0.38 | I50: =SUM(I48:I48) -> 1.52
...

Sheet Squads
B2: Squad Reference — Cost Library
B3: Standard squad archetypes and onshore/offshore cost per squad, per annum ($m). Offshore cost = onshore × offshore efficiency (0.4). The calculator looks up cost by Squad Type + Size.
B5: Squad Type | C5: Size | D5: Archetype | E5: # of roles | F5: Cost onshore ($m) | G5: Offshore efficiency | H5: Cost offshore ($m) | I5: Default support % | J5: Key
B6: Engineering | C6: S | D6: Lean build squad | E6: 4.5 | F6: 0.8 | G6: 0.4 | H6: =F6*G6 -> 0.32 | I6: 0.2 | J6: =B6&"|"&C6 -> Engineering|S
B7: Engineering | C7: M | D7: Standard Engineering Squad | E7: 9 | F7: 2 | G7: 0.4 | H7: =F7*G7 -> 0.8 | I7: 0.2 | J7: =B7&"|"&C7 -> Engineering|M
B8: Engineering | C8: L | D8: High-scale squad | E8: 12 | F8: 2.7 | G8: 0.4 | H8: =F8*G8 -> 1.08 | I8: 0.2 | J8: =B8&"|"&C8 -> Engineering|L
B9: Configuration / Integration | C9: XS | D9: MS Squad | E9: 1 | F9: 3.2 | G9: 0.4 | H9: =F9*G9 -> 1.28 | I9: 0.2 | J9: =B9&"|"&C9 -> Configuration / Integration|XS
B10: Configuration / Integration | C10: S | D10: Simple Configuration Squad | E10: 6 | F10: 0.4 | G10: 0.4 | H10: =F10*G10 -> 0.16 | I10: 0.2 | J10: =B10&"|"&C10 -> Configuration / Integration|S
B11: Configuration / Integration | C11: M | D11: Standard Configuration Squad | E11: 9 | F11: 1.4 | G11: 0.4 | H11: =F11*G11 -> 0.56 | I11: 0.2 | J11: =B11&"|"&C11 -> Configuration / Integration|M
B12: Configuration / Integration | C12: L | D12: Complex Integration Squad | E12: 14 | F12: 2.1 | G12: 0.4 | H12: =F12*G12 -> 0.84 | I12: 0.2 | J12: =B12&"|"&C12 -> Configuration / Integration|L
B13: Product | C13: S | D13: Lean Product Squad | E13: 5.5 | F13: 1.3 | G13: 0.4 | H13: =F13*G13 -> 0.52 | I13: 0.2 | J13: =B13&"|"&C13 -> Product|S
B14: Product | C14: M | D14: Balanced Product Squad | E14: 8.5 | F14: 1.9 | G14: 0.4 | H14: =F14*G14 -> 0.76 | I14: 0.2 | J14: =B14&"|"&C14 -> Product|M
B15: Product | C15: L | D15: Scaled Product Squad | E15: 12 | F15: 2.8 | G15: 0.4 | H15: =F15*G15 -> 1.12 | I15: 0.2 | J15: =B15&"|"&C15 -> Product|L
B16: Operations | C16: S | D16: Lean operations squad | E16: 4 | F16: 0.8 | G16: 0.4 | H16: =F16*G16 -> 0.32 | I16: 0.2 | J16: =B16&"|"&C16 -> Operations|S
B17: Operations | C17: M | D17: Balanced operations squad | E17: 6 | F17: 1.4 | G17: 0.4 | H17: =F17*G17 -> 0.56 | I17: 0.2 | J17: =B17&"|"&C17 -> Operations|M
... B24: Build and Run | C24: L | D24: Scaled build and run squad | E24: 13 | F24: 2.8 | G24: 0.4 | H24: =F24*G24 -> 1.12 | I24: 0.2 | J24: =B24&"|"&C24 -> Build and Run|L

Sheet Data Config
B2: Data Config — Budget Allocation & Overheads
B3: TDD budget allocation by area ($m) and the role-based build-up of portfolio & platform overheads. The calculator pulls Ampol Retail budget and the overhead subtotals from here.
B5: TDD Budget Allocation ($m) | H5: Overhead Build-up — TDD funded ($m)
B6: Area | C6: AU | D6: NZ | E6: Total | H6: Portfolio role | I6: Cost ($m) | J6: Alloc % | K6: Portfolio cost ($m)
B7: COE - Strat Arch | C7: 1.5 | D7: 0.5 | E7: =SUM(C7:D7) -> 2 | H7: Head of Tech | I7: 0.275 | J7: 0.3 | K7: =I7*J7 -> 0.0825
B8: COE - Cyber | C8: 1.5 | D8: 0.5 | E8: =SUM(C8:D8) -> 2 | H8: Business Partner | I8: 0.43 | J8: 0.4 | K8: =I8*J8 -> 0.172
B9: COE - Trans | C9: 1.5 | D9: 0.5 | E9: =SUM(C9:D9) -> 2 | H9: Domain Architect | I9: 0.28 | J9: 0.5 | K9: =I9*J9 -> 0.14
B10: COE - BP | C10: 1.5 | D10: 0.5 | E10: =SUM(C10:D10) -> 2 | H10: Leadership Overhead | I10: 1 | J10: 0.3 | K10: =I10*J10 -> 0.3
B11: COE - Data | C11: 1.5 | D11: 0.5 | E11: =SUM(C11:D11) -> 2 | H11: Portfolio overhead subtotal | K11: =SUM(K7:K10) -> 0.6945
B12: Ampol Retail | C12: 2.5 | E12: =SUM(C12:D12) -> 2.5
B13: Z Retail | D13: 2.5 | E13: =SUM(C13:D13) -> 2.5 | H13: Platform role | I13: Cost ($m) | J13: Alloc % | K13: Platform cost ($m)
B14: Ampol Customer | C14: 2.5 | E14: =SUM(C14:D14) -> 2.5 | H14: Delivery Manager | I14: 0.28 | J14: 0.3 | K14: =I14*J14 -> 0.084
B15: Z Customer | C15: 0 | D15: 2.5 | E15: =SUM(C15:D15) -> 2.5 | H15: Tech Manager | I15: 0.27 | J15: 0.3 | K15: =I15*J15 -> 0.081
B16: CF | C16: 2.5 | E16: =SUM(C16:D16) -> 2.5 | H16: Platform overhead subtotal | K16: =SUM(K14:K15) -> 0.165
B17: ES & B2B | C17: 2.5 | E17: =SUM(C17:D17) -> 2.5 | H17: Portfolio + platform overhead, TDD | K17: =K11+K16 -> 0.8595
B18: Infra | C18: 2.5 | E18: =SUM(C18:D18) -> 2.5
B19: P&C | C19: 1 | D19: 1 | E19: =SUM(C19:D19) -> 2
B20: Finance | C20: 1 | D20: 1 | E20: =SUM(C20:D20) -> 2
B21: Legal | C21: 0 | E21: =SUM(C21:D21) -> 0
B22: TDD | C22: 4.5 | D22: 1 | E22: =SUM(C22:D22) -> 5.5
B23: TDD Data | C23: 2.5 | D23: 1 | E23: =SUM(C23:D23) -> 3.5
B24: TDD Cyber | C24: 1 | D24: 0.5 | E24: =SUM(C24:D24) -> 1.5
B25: EG | C25: 0 | E25: =SUM(C25:D25) -> 0
B26: EGI | C26: 0 | E26: =SUM(C26:D26) -> 0
B27: Total Cost | C27: =SUM(C7:C26) -> 30 | D27: =SUM(D7:D26) -> 12 | E27: =SUM(E7:E26) -> 42

Sheet FY26 Budget
B2: FY2026 Technology Budget — by Business Segment
B3: FY2026 budget ($m) pulled from the TDD presentation pack. Total = Lights On + Initiatives (Project OpEx) + Depreciation + Significant Items + CapEx.
B5: Business Segment | C5: Lights On | D5: Initiatives (Project OpEx) | E5: Depreciation | F5: Significant Items | G5: CapEx | H5: Total FY26
B6: Retail | C6: 13.925855 | D6: 1.31 | E6: 0 | F6: 6.845 | G6: 11.8 | H6: =SUM(C6:G6) -> 33.880855
B7: Z-Energy | C7: 52.22526 | D7: 1.44624 | E7: 11.306521 | F7: 0 | G7: 11.725494 | H7: =SUM(C7:G7) -> 76.703515
B8: Commercial Fuels | C8: 13.655581 | D8: 5.861721 | E8: 0 | F8: 14.219208 | G8: 6.797713 | H8: =SUM(C8:G8) -> 40.534223
B9: Energy Solutions | C9: 4.041939 | D9: 0.97 | E9: 0 | F9: 0 | G9: 2.997585 | H9: =SUM(C9:G9) -> 8.009524
B10: Infrastructure | C10: 3.594596 | D10: 0.763362 | E10: 0 | F10: 0 | G10: 4.891418 | H10: =SUM(C10:G10) -> 9.249376
B11: Finance & Other Corp | C11: 2.945287 | D11: 0.935487 | E11: 0 | F11: 0 | G11: 0 | H11: =SUM(C11:G11) -> 3.880774
B12: People & Culture | C12: 2.148038 | D12: 1.975 | E12: 0 | F12: 1.36 | G12: 0.33 | H12: =SUM(C12:G12) -> 5.813038
B13: Customer | C13: 1.691533 | D13: 0 | E13: 0 | F13: 5 | G13: 5 | H13: =SUM(C13:G13) -> 11.691533
B14: Total Technology | C14: =SUM(C6:C13) -> 94.228089 | D14: =SUM(D6:D13) -> 13.26181 | E14: =SUM(E6:E13) -> 11.306521 | F14: =SUM(F6:F13) -> 27.424208 | G14: =SUM(G6:G13) -> 43.54221 | H14: =SUM(C14:G14) -> 189.76284
B16: Source: TDD presentation pack, 'For Presentation Pack' — FY2026 Budget by segment. Depreciation shown where separately reported in the pack.
