Workbook

Sheet Exec Summary
B2: TDD operating model - executive summary
B4: The organisation today
B5: Roles in the ledger | C5: ='3.1 Cost Bridge'!$H$41 -> 525
B6: Filled | C6: ='3.1 Cost Bridge'!$I$41 -> 390
B7: Vacant | C7: ='3.1 Cost Bridge'!$J$41 -> 135
B8: Cost of the 525 roles in the ledger ($m) | C8: ='3.1 Cost Bridge'!$E$41 -> 115.283
B9: Of which filled roles ($m) | C9: =SUMIFS('REVIEW - Complete Role Mapping'!$AA$2:$AA$528,'REVIEW - Complete Role Mapping'!$AK$2:$AK$528,"Filled")/1000000 -> 86.74851
B10: Of which vacancies not yet filled ($m) | C10: =SUMIFS('REVIEW - Complete Role Mapping'!$AA$2:$AA$528,'REVIEW - Complete Role Mapping'!$AK$2:$AK$528,"Vacant")/1000000 -> 28.534492
B11: The 8 GMs, outside the ledger ($m) | C11: =N(Lists!$AG$12) -> 5.1
B12: Cost today including the GM layer ($m) | C12: ='3.1 Cost Bridge'!$E$43 -> 120.383
B14: Against the archetype
B15: Squads priced by an archetype - archetype cost ($m) | C15: ='3.1 Cost Bridge'!$D$17 -> 64.2
B16: Squads priced by an archetype - actual ($m) | C16: ='3.1 Cost Bridge'!$E$17 -> 63.980998
B17: Squads priced by an archetype - over/(under) ($m) | C17: ='3.1 Cost Bridge'!$F$17 -> -0.219002
B18: Directly funded programmes - over/(under) funded ($m) | C18: ='3.1 Cost Bridge'!$F$27 -> -0.165942
B19: COEs and EGI - over/(under) their 1.x planned spend ($m) | C19: ='3.1 Cost Bridge'!$F$34 -> -
B20: Overhead roles - not covered by the allowance ($m) | C20: ='3.1 Cost Bridge'!$F$35 -> 5.32923
B21: The 8 GMs - over/(under) their allowance ($m) | C21: ='3.1 Cost Bridge'!$F$42 -> 2.1
B22: Total over/(under) archetype, everything comparable ($m) | C22: ='3.1 Cost Bridge'!$F$36+'3.1 Cost Bridge'!$F$42 -> 7.044285
B23: Groups with no archetype and no funded figure ($m) | C23: ='3.1 Cost Bridge'!$E$40 -> 1.3049171
B25: The vacancy decision
B26: Vacant roles | C26: ='3.1 Cost Bridge'!$J$41 -> 135
B27: Vacancies set to hire | C27: =N('2.1 Ampol Retail'!$I$29)+N('2.2 Customer'!$I$27)+N('2.3 Enterprise Data'!$I$22)+N('2.4 TDD Group Functions'!$I$24)+N('2.5 P&C'!$I$22)+N('2.6 Finance'!$I$20)+N('2.7 Infrastructure'!$I$24)+N('2.8 Energy Solutions & B2B'!$I$23)+N('2.9 Commercial Fuels'!$I$23)+N('2.10 Z Retail'!$I$24)+N('2.11 COE Cyber'!$I$23)+N('2.12 COE BP&T'!$I$21)+N('2.13 COE SA&D'!$I$23)+N('2.14 EGI'!$I$19) -> 135
B28: Roles set to offshore | C28: =N('2.1 Ampol Retail'!$J$29)+N('2.2 Customer'!$J$27)+N('2.3 Enterprise Data'!$J$22)+N('2.4 TDD Group Functions'!$J$24)+N('2.5 P&C'!$J$22)+N('2.6 Finance'!$J$20)+N('2.7 Infrastructure'!$J$24)+N('2.8 Energy Solutions & B2B'!$J$23)+N('2.9 Commercial Fuels'!$J$23)+N('2.10 Z Retail'!$J$24)+N('2.11 COE Cyber'!$J$23)+N('2.12 COE BP&T'!$J$21)+N('2.13 COE SA&D'!$J$23)+N('2.14 EGI'!$J$19) -> 0
B29: Roles put on hold | C29: =N('2.1 Ampol Retail'!$K$29)+N('2.2 Customer'!$K$27)+N('2.3 Enterprise Data'!$K$22)+N('2.4 TDD Group Functions'!$K$24)+N('2.5 P&C'!$K$22)+N('2.6 Finance'!$K$20)+N('2.7 Infrastructure'!$K$24)+N('2.8 Energy Solutions & B2B'!$K$23)+N('2.9 Commercial Fuels'!$K$23)+N('2.10 Z Retail'!$K$24)+N('2.11 COE Cyber'!$K$23)+N('2.12 COE BP&T'!$K$21)+N('2.13 COE SA&D'!$K$23)+N('2.14 EGI'!$K$19) -> 0
B30: Roles after the decisions set today | C30: ='3.1 Cost Bridge'!$K$41 -> 525
B31: Cost after the decisions set today ($m) | C31: ='3.1 Cost Bridge'!$G$41 -> 115.283
B32: Impact of those decisions ($m) | C32: ='3.1 Cost Bridge'!$G$41-'3.1 Cost Bridge'!$E$41 -> 0
B34: Portfolio drill-down
B35: Pick a portfolio | C35: Ampol Retail
B36: Roles | C36: =ROUND(SUMIFS('3.3 Squad Detail'!$H$6:$H$109,'3.3 Squad Detail'!$B$6:$B$109,$C$35),6) -> 70
B37: Filled | C37: =ROUND(SUMIFS('3.3 Squad Detail'!$I$6:$I$109,'3.3 Squad Detail'!$B$6:$B$109,$C$35),6) -> 48
B38: Vacant | C38: =ROUND(SUMIFS('3.3 Squad Detail'!$J$6:$J$109,'3.3 Squad Detail'!$B$6:$B$109,$C$35),6) -> 22
B39: Roles after decisions | C39: =ROUND(SUMIFS('3.3 Squad Detail'!$K$6:$K$109,'3.3 Squad Detail'!$B$6:$B$109,$C$35),6) -> 70
B40: Actual cost ($m) | C40: =ROUND(SUMIFS('3.3 Squad Detail'!$M$6:$M$109,'3.3 Squad Detail'!$B$6:$B$109,$C$35),6) -> 14.005227
B41: Of which overhead roles ($m) | C41: =ROUND(SUMIFS('3.3 Squad Detail'!$M$6:$M$109,'3.3 Squad Detail'!$B$6:$B$109,$C$35,'3.3 Squad Detail'!$C$6:$C$109,"Overhead"),6) -> 1.255616
B42: Squads priced by an archetype - over/(under) archetype ($m) | C42: =ROUND(SUMIFS('3.3 Squad Detail'!$N$6:$N$109,'3.3 Squad Detail'!$B$6:$B$109,$C$35,'3.3 Squad Detail'!$C$6:$C$109,"Archetype"),6) -> -0.766475
B43: Directly funded programmes - over/(under) funded ($m) | C43: =ROUND(SUMIFS('3.3 Squad Detail'!$N$6:$N$109,'3.3 Squad Detail'!$B$6:$B$109,$C$35,'3.3 Squad Detail'!$C$6:$C$109,"Directly funded"),6) -> 0.412299
B44: Cost after vacancy decisions ($m) | C44: =ROUND(SUMIFS('3.3 Squad Detail'!$O$6:$O$109,'3.3 Squad Detail'!$B$6:$B$109,$C$35),6) -> 14.005227

Sheet - INPUTS -
B2: INPUTS >>>

Sheet 0.1 Budget Table (Fin)
B3: BUSINESS | C3: EGM Sponsor | D3: GM Sponsor | E3: Domain Architect | F3: HO Technology | G3: Lights-on | M3: Depreciation | N3: Initiatives | O3: Sig Items | P3: Capex | Q3: Total Budget | S3: Existing | T3: Aligned Delivery | U3: Aligned COE's | V3: Total Budget
B4: SEGMENT | G4: People | H4: HW | I4: SW | J4: Network | K4: Vendor | L4: Sub-Total | Q4: FY2026 | V4: FY2026
B5: TDD Corporate (1) | C5: Brad Blyth | G5: 35.2 | H5: 2.9 | I5: 25.6 | J5: 2.1 | K5: 13.1 | L5: =SUM(G5:K5) -> 78.9 | M5: 5.8 | N5: 3 | O5: 20.2 | P5: 4.9 | Q5: =SUM(L5:P5) -> 112.8 | U5: =SUM(W25:W29) -> 91.6 | V5: =SUM(S5:U5) -> 91.6
B6: Z-Energy (2) | C6: Lindis Jones | D6: Vance Anderson | G6: 17.6 | H6: 19.8 | I6: 11.6 | J6: 0.6 | K6: 2.6 | L6: =SUM(G6:K6) -> 52.2 | M6: 11.3 | N6: 1.4 | O6: - | P6: 11.7 | Q6: =SUM(L6:P6) -> 76.6 | S6: =Q6 -> 76.6 | V6: =SUM(S6:U6) -> 76.6
B7: EnergySolutions | C7: Brent Merrick | D7: Roanne Steele | G7: 1 | H7: 1.5 | I7: 1.4 | L7: =SUM(G7:K7) -> 3.9 | N7: 1 | P7: 2.3 | Q7: =SUM(L7:P7) -> 7.2 | S7: =Q7 -> 7.2 | V7: =SUM(S7:U7) -> 7.2 | Y7: =SUM(L9,N9,O9,P9) -> 33.8
B8: Commercial Fuels | C8: Brent Merrick | D8: Roanne Steele | H8: 2.5 | I8: 9.4 | J8: 1.5 | L8: =SUM(G8:K8) -> 13.4 | N8: 6.1 | O8: 14.2 | P8: 6.8 | Q8: =SUM(L8:P8) -> 40.5 | S8: =Q8 -> 40.5 | T8: =S19 -> 1.2 | V8: =SUM(S8:U8) -> 41.7
B9: Retail | C9: Kate Thomson | D9: Roanne Steele | H9: 5.3 | I9: 6.4 | J9: 2.2 | L9: =SUM(G9:K9) -> 13.9 | N9: 1.3 | O9: 6.8 | P9: 11.8 | Q9: =SUM(L9:P9) -> 33.8 | S9: =Q9 -> 33.8 | T9: =S20 -> 5.2 | V9: =SUM(S9:U9) -> 39
B10: Infrastructure | C10: Michelle Bardy | D10: Roanne Steele | H10: 1.9 | I10: 2 | L10: =SUM(G10:K10) -> 3.9 | N10: 0.4 | P10: 5 | Q10: =SUM(L10:P10) -> 9.3 | S10: =Q10 -> 9.3 | T10: =S21 -> 2.2 | V10: =SUM(S10:U10) -> 11.5
B11: Corporate Finance | C11: Greg Barnes | D11: Emily Mogic | H11: 0.5 | I11: 2.1 | L11: =SUM(G11:K11) -> 2.6 | N11: 0.9 | Q11: =SUM(L11:P11) -> 3.5 | S11: =Q11 -> 3.5 | T11: =S22 -> 9 | V11: =SUM(S11:U11) -> 12.5
B12: P&C | C12: Meaghan Davis | D12: Emily Mogic | H12: 0.3 | I12: 1.8 | L12: =SUM(G12:K12) -> 2.1 | N12: 2 | O12: 1.4 | P12: 0.3 | Q12: =SUM(L12:P12) -> 5.8 | S12: =Q12 -> 5.8 | T12: =S23 -> 0 | V12: =SUM(S12:U12) -> 5.8
B13: Customer | C13: Kate Thomson | D13: Vance Anderson | H13: 0.1 | I13: 1.6 | L13: =SUM(G13:K13) -> 1.7 | O13: 5 | P13: 5 | Q13: =SUM(L13:P13) -> 11.7 | S13: =Q13 -> 11.7 | T13: =S24 -> 3.7 | V13: =SUM(S13:U13) -> 15.4
B14: Total Technology | G14: =SUM(G5:G13) -> 53.8 | H14: =SUM(H5:H13) -> 34.8 | I14: =SUM(I5:I13) -> 61.9 | J14: =SUM(J5:J13) -> 6.4 | K14: =SUM(K5:K13) -> 15.7 | L14: =SUM(L5:L13) -> 172.6 | M14: =SUM(M5:M13) -> 17.1 | N14: =SUM(N5:N13) -> 16.1 | ... Q14: =SUM(Q5:Q13) -> 301.2 | S14: =SUM(S6:S13) -> 188.4 | T14: =SUM(T8:T13) -> 21.3 | U14: =U5 -> 91.6 | V14: =SUM(V5:V13) -> 301.3
B17: BUSINESS SEGMENT | E17: EGM Sponsor | F17: GM Sponsor | G17: Domain Architect | H17: HO Technology | I17: Lights-on | O17: Depreciation | P17: Initiatives | Q17: Sig Items | R17: Capex | S17: Total Budget | U17: Existing | V17: Aligned Delivery | W17: Aligned | X17: Total Budget
I18: People | J18: HW | K18: SW | L18: Network | M18: Vendor | N18: Sub-Total | S18: FY2026 | W18: COE's | X18: FY2026
D19: Commercial Fuels | I19: 1.2 | J19: 0 | K19: 0 | L19: - | M19: - | N19: =SUM(I19:M19) -> 1.2 | O19: - | S19: =SUM(N19:R19) -> 1.2 | X19: -
D20: Retail | I20: 3.4 | J20: 0.2 | K20: 0.9 | L20: - | M20: 0.7 | N20: =SUM(I20:M20) -> 5.2 | O20: - | S20: =SUM(N20:R20) -> 5.2 | X20: -
D21: Infrastructure | I21: 2 | J21: - | K21: 0.2 | L21: - | M21: - | N21: =SUM(I21:M21) -> 2.2 | O21: - | S21: =SUM(N21:R21) -> 2.2 | X21: -
D22: Corporate Finance | I22: 1.3 | J22: - | K22: 4.2 | L22: - | M22: 3.5 | N22: =SUM(I22:M22) -> 9 | O22: - | S22: =SUM(N22:R22) -> 9 | X22: -
D23: P&C | I23: 0 | J23: - | K23: - | L23: - | M23: - | N23: =SUM(I23:M23) -> 0 | O23: - | S23: =SUM(N23:R23) -> 0 | X23: -
D24: Customer | I24: 1.2 | J24: - | K24: 0.6 | L24: 0 | M24: 1 | N24: =SUM(I24:M24) -> 2.8 | O24: 0.9 | S24: =SUM(N24:R24) -> 3.7 | X24: -
D25: TDD | F25: Emily Mogic | I25: 4.5 | J25: 2.5 | K25: 14.5 | L25: 0 | M25: 0.8 | N25: =SUM(I25:M25) -> 22.3 | O25: 4.9 | S25: =SUM(N25:R25) -> 27.2 | W25: =S25 -> 27.2 | X25: =W25 -> 27.2
D26: TDDEGM | F26: Brad Blyth | I26: 6.5 | J26: - | K26: - | L26: - | M26: 3.6 | N26: =SUM(I26:M26) -> 10.1 | O26: - | P26: 3 | Q26: 20.2 | R26: 4.9 | S26: =SUM(N26:R26) -> 38.2 | W26: =S26 -> 38.2 | X26: =W26 -> 38.2
D27: Strategy, Architecture and Data | F27: Matt Ashley | I27: 5.3 | J27: - | K27: 1 | L27: - | M27: 0.6 | N27: =SUM(I27:M27) -> 6.9 | O27: - | S27: =SUM(N27:R27) -> 6.9 | W27: =S27 -> 6.9 | X27: =W27 -> 6.9
D28: Cyber Risk and Operations | F28: Frances Bouzo | I28: 7.6 | J28: 0.2 | K28: 4.3 | L28: 2 | M28: 2.9 | N28: =SUM(I28:M28) -> 17 | O28: - | S28: =SUM(N28:R28) -> 17 | W28: =S28 -> 17 | X28: =W28 -> 17
D29: Business Partnering and Governance | F29: Michael Schofield | I29: 2.3 | J29: - | K29: - | L29: - | M29: - | N29: =SUM(I29:M29) -> 2.3 | O29: - | S29: =SUM(N29:R29) -> 2.3 | W29: =S29 -> 2.3 | X29: =W29 -> 2.3
B30: TDD Corporate (1) | E30: Brad Blyth | I30: =G5 -> 35.2 | J30: =H5 -> 2.9 | K30: =I5 -> 25.6 | L30: =J5 -> 2.1 | M30: =K5 -> 13.1 | N30: =L5 -> 78.9 | O30: =M5 -> 5.8 | P30: =N5 -> 3 | ... S30: =Q5 -> 112.8 | W30: =U5 -> 91.6 | X30: =W30 -> 91.6
C31: Z-Energy (Direct TDD) | I31: 17.6 | J31: 12.1 | K31: 6.3 | L31: 0.6 | M31: 2.6 | N31: 39.3 | O31: 11.3 | P31: 1.4 | R31: 11.7 | S31: 63.7 | X31: -
C32: Z-Energy (Other IT Spend for Supplies, Customer) | J32: 7.6 | K32: 5.3 | N32: 13 | S32: 13 | X32: -
B33: Z-Energy (2) | E33: Lindis Jones | F33: Vance Anderson | I33: =G6 -> 17.6 | J33: =H6 -> 19.8 | K33: =I6 -> 11.6 | L33: =J6 -> 0.6 | M33: =K6 -> 2.6 | N33: =L6 -> 52.2 | O33: =M6 -> 11.3 | P33: =N6 -> 1.4 | ... S33: =Q6 -> 76.6 | U33: =S6 -> 76.6 | X33: =U33 -> 76.6

Sheet 0.2 Data Config
B2: Data Config
B4: TDD Budget Allocation ($m) | I4: Portfolio Overhead (roles, $m)
B5: Portfolio | C5: AU | D5: NZ | E5: Total | F5: Actual cost ($m) | G5: Over/(under) budget ($m) | I5: Role | J5: Cost ($m) | K5: Allocation % | L5: Portfolio cost ($m)
B6: COE - Strategy Architecture | C6: 1.5 | D6: 0.5 | E6: =C6+D6 -> 2 | F6: =SUMIFS('REVIEW - Complete Role Mapping'!$AA$2:$AA$528,'REVIEW - Complete Role Mapping'!$AJ$2:$AJ$528,"COE SA&D")/1000000 -> 6.5294941 | G6: =$F6-$E6 -> 4.5294941 | I6: Head of Tech | J6: 0.275 | K6: 0.5 | L6: =J6*K6 -> 0.1375
B7: COE - Cyber, Risk & Service Ops (see 1.13 Cyber Roles) | C7: 0 | D7: 0 | E7: =C7+D7 -> 0 | F7: 0 | G7: =$F7-$E7 -> 0 | I7: Business Partner | J7: 0.44 | K7: 0.5 | L7: =J7*K7 -> 0.22
B8: COE - Transformation | C8: 1.5 | D8: 0.5 | E8: =C8+D8 -> 2 | F8: =SUMIFS('REVIEW - Complete Role Mapping'!$AA$2:$AA$528,'REVIEW - Complete Role Mapping'!$AJ$2:$AJ$528,"COE BP&T")/1000000 -> 6.4005618 | G8: =$F8-$E8 -> 4.4005618 | I8: Domain Architect | J8: 0.28 | K8: 0.5 | L8: =J8*K8 -> 0.14
B9: COE - Business Partnering | C9: 1.5 | D9: 0.5 | E9: =C9+D9 -> 2 | F9: 0 | G9: =$F9-$E9 -> -2 | I9: Leadership Overhead | J9: 1 | K9: 0.3 | L9: =J9*K9 -> 0.3
B10: COE - Data | C10: 1.5 | D10: 0.5 | E10: =C10+D10 -> 2 | F10: 0 | G10: =$F10-$E10 -> -2 | I10: Portfolio overhead subtotal | L10: =SUM(L6:L9) -> 0.7975
B11: Ampol Retail | C11: 5.5 | D11: 0 | E11: =C11+D11 -> 5.5 | F11: =SUMIFS('REVIEW - Complete Role Mapping'!$AA$2:$AA$528,'REVIEW - Complete Role Mapping'!$AJ$2:$AJ$528,"Ampol Retail")/1000000 -> 14.005227 | G11: =$F11-$E11 -> 8.5052275
B12: Z Retail | C12: 0 | D12: 6.5 | E12: =C12+D12 -> 6.5 | F12: =SUMIFS('REVIEW - Complete Role Mapping'!$AA$2:$AA$528,'REVIEW - Complete Role Mapping'!$AJ$2:$AJ$528,"Z Retail")/1000000 -> 7.3372944 | G12: =$F12-$E12 -> 0.83729435 | I12: Platform Overhead (roles, $m)
B13: Ampol Customer | C13: 2.5 | D13: 0 | E13: =C13+D13 -> 2.5 | F13: =SUMIFS('REVIEW - Complete Role Mapping'!$AA$2:$AA$528,'REVIEW - Complete Role Mapping'!$AJ$2:$AJ$528,"Customer")/1000000 -> 17.126867 | G13: =$F13-$E13 -> 14.626867 | I13: Role | J13: Cost ($m) | K13: Alloc % | L13: Platform cost ($m)
B14: Z Customer | C14: 0 | D14: 4 | E14: =C14+D14 -> 4 | F14: 0 | I14: Delivery Manager | J14: 0.28 | K14: 0.3 | L14: =J14*K14 -> 0.084
B15: Commercial Fuels | C15: 2.5 | D15: 0 | E15: =C15+D15 -> 2.5 | F15: =SUMIFS('REVIEW - Complete Role Mapping'!$AA$2:$AA$528,'REVIEW - Complete Role Mapping'!$AJ$2:$AJ$528,"Commercial Fuels")/1000000 -> 10.19767 | G15: =$F15-$E15 -> 7.6976697 | I15: Tech Manager | J15: 0.27 | K15: 0.3 | L15: =J15*K15 -> 0.081
B16: Energy Solutions & B2B | C16: 2.5 | D16: 0 | E16: =C16+D16 -> 2.5 | F16: =SUMIFS('REVIEW - Complete Role Mapping'!$AA$2:$AA$528,'REVIEW - Complete Role Mapping'!$AJ$2:$AJ$528,"Energy Solutions & B2B")/1000000 -> 6.4478163 | G16: =$F16-$E16 -> 3.9478163 | I16: Platform overhead subtotal (per platform) | L16: =SUM(L14:L15) -> 0.165
B17: Infrastructure | C17: 2.5 | D17: 0 | E17: =C17+D17 -> 2.5 | F17: =SUMIFS('REVIEW - Complete Role Mapping'!$AA$2:$AA$528,'REVIEW - Complete Role Mapping'!$AJ$2:$AJ$528,"Infrastructure")/1000000 -> 7.7483635 | G17: =$F17-$E17 -> 5.2483635
B18: P&C | C18: 1 | D18: 1 | E18: =C18+D18 -> 2 | F18: =SUMIFS('REVIEW - Complete Role Mapping'!$AA$2:$AA$528,'REVIEW - Complete Role Mapping'!$AJ$2:$AJ$528,"P&C")/1000000 -> 4.1844409 | G18: =$F18-$E18 -> 2.1844409
B19: Finance | C19: 1 | D19: 1 | E19: =C19+D19 -> 2 | F19: =SUMIFS('REVIEW - Complete Role Mapping'!$AA$2:$AA$528,'REVIEW - Complete Role Mapping'!$AJ$2:$AJ$528,"Finance")/1000000 -> 3.8446161 | G19: =$F19-$E19 -> 1.8446161
B20: Legal | C20: 0 | D20: 0 | E20: =C20+D20 -> 0 | F20: 0 | G20: =$F20-$E20 -> 0
B21: TDD | C21: 4.5 | D21: 1 | E21: =C21+D21 -> 5.5 | F21: =SUMIFS('REVIEW - Complete Role Mapping'!$AA$2:$AA$528,'REVIEW - Complete Role Mapping'!$AJ$2:$AJ$528,"TDD Group Functions")/1000000 -> 10.200969 | G21: =$F21-$E21 -> 4.7009695
B22: TDD Data | C22: 2.5 | D22: 1 | E22: =C22+D22 -> 3.5 | F22: =SUMIFS('REVIEW - Complete Role Mapping'!$AA$2:$AA$528,'REVIEW - Complete Role Mapping'!$AJ$2:$AJ$528,"Enterprise Data")/1000000 -> 6.4184038 | G22: =$F22-$E22 -> 2.9184038
B23: TDD Cyber | C23: 2.5 | D23: 1 | E23: =C23+D23 -> 3.5 | F23: =SUMIFS('REVIEW - Complete Role Mapping'!$AA$2:$AA$528,'REVIEW - Complete Role Mapping'!$AJ$2:$AJ$528,"COE Cyber")/1000000 -> 9.8978583 | G23: =$F23-$E23 -> 6.3978583
B25: EGI | C25: 0 | D25: 0 | E25: =C25+D25 -> 0 | F25: =SUMIFS('REVIEW - Complete Role Mapping'!$AA$2:$AA$528,'REVIEW - Complete Role Mapping'!$AJ$2:$AJ$528,"EGI")/1000000 -> 4.9434194 | G25: =$F25-$E25 -> 4.9434194
B26: Total | C26: =SUM(C6:C25) -> 33 | D26: =SUM(D6:D25) -> 17.5 | E26: =SUM(E6:E25) -> 50.5 | F26: =SUM(F6:F25) -> 115.283 | G26: =$F26-$E26 -> 64.783002
B27: Budget | C27: ='0.1 Budget Table (Fin)'!G5+'0.1 Budget Table (Fin)'!G7 -> 36.2 | D27: ='0.1 Budget Table (Fin)'!G6 -> 17.6 | E27: ='0.1 Budget Table (Fin)'!G14 -> 53.8
B28: Variance | C28: =C27-C26 -> 3.2 | D28: =D27-D26 -> 0.1 | E28: =E27-E26 -> 3.3

Sheet 0.3 Squad Archetypes
B2: Squad Archetypes - the cost library | C2: Squad Cost Lookup
A4: Key | C4: Squad Type | D4: Size | E4: Archetype | F4: # of roles | G4: Onshore Cost ($m) | H4: Offshore Cost ($m) | I4: Use When | K4: Offshore rate
A5: =$C5&"|"&$D5 -> Engineering|S | C5: Engineering | D5: S | E5: Lean build squad | F5: 4.5 | G5: 0.8 | H5: =G5*$K$5 -> 0.32 | I5: Simple platforms, incremental changes | K5: 0.4
A6: =$C6&"|"&$D6 -> Engineering|M | C6: Engineering | D6: M | E6: Standard Engineering Squad | F6: 9 | G6: 2 | H6: =G6*$K$5 -> 0.8 | I6: Medium complexity platforms
A7: =$C7&"|"&$D7 -> Engineering|L | C7: Engineering | D7: L | E7: High-scale squad | F7: 12 | G7: 2.7 | H7: =G7*$K$5 -> 1.08 | I7: Scalable platforms, high volume output
A8: =$C8&"|"&$D8 -> Configuration / Integration|XS | C8: Configuration / Integration | D8: XS | E8: MS Squad | F8: 1 | G8: 0.4 | H8: =G8*$K$5 -> 0.16 | I8: Work managed by a vendor
A9: =$C9&"|"&$D9 -> Configuration / Integration|S | C9: Configuration / Integration | D9: S | E9: Simple Configuration Squad | F9: 6 | G9: 1.4 | H9: =G9*$K$5 -> 0.56 | I9: Simple configuration, limited integration
A10: =$C10&"|"&$D10 -> Configuration / Integration|M | C10: Configuration / Integration | D10: M | E10: Standard Configuration Squad | F10: 9 | G10: 2.1 | H10: =G10*$K$5 -> 0.84 | I10: Standard configuration, medium complexity
A11: =$C11&"|"&$D11 -> Configuration / Integration|L | C11: Configuration / Integration | D11: L | E11: Complex Integration Squad | F11: 14 | G11: 3.2 | H11: =G11*$K$5 -> 1.28 | I11: Complex config or custom build, high integration
A12: =$C12&"|"&$D12 -> Product|S | C12: Product | D12: S | E12: Lean Product Squad | F12: 5.5 | G12: 1.3 | H12: =G12*$K$5 -> 0.52 | I12: Early stage product testing or low complexity
A13: =$C13&"|"&$D13 -> Product|M | C13: Product | D13: M | E13: Balanced Product Squad | F13: 8.5 | G13: 1.9 | H13: =G13*$K$5 -> 0.76 | I13: Ongoing product development, moderate complexity
A14: =$C14&"|"&$D14 -> Product|L | C14: Product | D14: L | E14: Scaled Product Squad | F14: 12 | G14: 2.8 | H14: =G14*$K$5 -> 1.12 | I14: Mature product
A15: =$C15&"|"&$D15 -> Operations|S | C15: Operations | D15: S | E15: Lean operations squad | F15: 4 | G15: 0.8 | H15: =G15*$K$5 -> 0.32 | I15: Low change, stable platforms
A16: =$C16&"|"&$D16 -> Operations|M | C16: Operations | D16: M | E16: Balanced operations squad | F16: 6 | G16: 1.4 | H16: =G16*$K$5 -> 0.56 | I16: Moderate support plus improvements
A17: =$C17&"|"&$D17 -> Operations|L | C17: Operations | D17: L | E17: High demand operations squad | F17: 10 | G17: 2.3 | H17: =G17*$K$5 -> 0.92 | I17: High ticket volume, critical systems
... A23: =$C23&"|"&$D23 -> Build and Run|L | C23: Build and Run | D23: L | E23: Scaled build and run squad | F23: 13 | G23: 2.8 | H23: =G23*$K$5 -> 1.12 | I23: High traffic or business critical, 24/7
C24: Exceptions (will need to incl. rules) | E24: TBC | I24: TBC
C27: Exception for ES EVCI - 6 FTE vs 4.5 FTE
C29: Exception for TDD DevOps - no BA, DL 6 FTE vs 4.5 FTE

Sheet 0.4 Presentation Pack
B3: BUSINESS SEGMENTS | C3: TDD GM | D3: TOTAL YTD (Jun-2026) | I3: OPEX: LIGHTS ON + INITIATIVES (YTD) | N3: OPEX: LIGHTS ON (YTD) | S3: OPEX: INITIATIVES (YTD) | X3: OPEX: DEPRECIATION (YTD) | AC3: SIGNIFICANT ITEMS (YTD) | AH3: CAPEX (YTD) | AN3: FY2026
D4: A | E4: B | F4: V | G4: V % | H4: Trend | I4: A | J4: B | K4: V | L4: V % | M4: Trend | N4: A | O4: B | P4: V | R4: Trend | S4: A | T4: B | U4: V | V4: V % | W4: Trend | X4: A | Y4: B | Z4: V | AA4: V % | AB4: Trend | AC4: A | AD4: B | AE4: V | AF4: V % | AG4: Trend | AH4: A | AI4: B | AJ4: V | AK4: V % | AL4: Trend | AN4: F | AO4: B | AP4: V | AR4: Trend
A5: TDD (Corporate)1 | B5: TDD (Corporate)1 | C5: Brad Blyth Greg Cassis | D5: =I5+AC5+AH5+X5 -> 53.575006 | E5: =J5+AD5+AI5+Y5 -> 56.158125 | F5: =E5-D5 -> 2.5831189 | G5: =IFERROR(F5/E5,"-") -> 0.045997243 | H5: G | I5: 41.773797 | J5: 41.933694 | K5: =J5-I5 -> 0.15989672 | L5: =IFERROR(K5/J5,"-") -> 0.0038130846 | M5: G | N5: =I5-S5 -> 40.972956 | O5: =J5-T5 -> 40.433694 | P5: =O5-N5 -> -0.53926205 | Q5: =IFERROR(P5/O5,"-") -> -0.013336947 | R5: A | S5: 0.80084123 | T5: 1.5 | U5: =T5-S5 -> 0.69915877 | V5: =IFERROR(U5/T5,"-") -> 0.46610585 | W5: G | X5: 2.7852211 | Y5: 2.9338979 | Z5: =Y5-X5 -> 0.14867679 | AA5: =IFERROR(Z5/Y5,"-") -> 0.050675516 | AB5: G | AC5: 8.8400082 | AD5: 9.2622 | AE5: =AD5-AC5 -> 0.4221918 | AF5: =IFERROR(AE5/AD5,"-") -> 0.045582237 | AG5: G | AH5: 0.17597979 | AI5: 2.0283334 | AJ5: =AI5-AH5 -> 1.8523536 | AK5: =IFERROR(AJ5/AI5,"-") -> 0.91323922 | AL5: G | AN5: =I21+AC21+AH21+X21 -> 117.95714 | AO5: =J21+AD21+AI21+Y21 -> 112.75951 | AP5: =AO5-AN5 -> -5.1976273 | AQ5: =IFERROR(AP5/AO5,"-") -> -0.046094801 | AR5: A
A6: Z-Energy | B6: Z- Energy | C6: Vance Anderson Harley Giles | D6: =I6+AC6+AH6+X6 -> 35.257858 | E6: =J6+AD6+AI6+Y6 -> 38.25416 | F6: =E6-D6 -> 2.9963016 | G6: =IFERROR(F6/E6,"-") -> 0.078326164 | H6: G | I6: 26.455513 | J6: 26.80099 | K6: =J6-I6 -> 0.34547723 | L6: =IFERROR(K6/J6,"-") -> 0.012890465 | M6: G | N6: =I6-S6 -> 26.455513 | O6: =J6-T6 -> 26.07787 | P6: =O6-N6 -> -0.37764277 | Q6: =IFERROR(P6/O6,"-") -> -0.01448135 | R6: A | S6: 0 | T6: 0.72312 | U6: =T6-S6 -> 0.72312 | V6: =IFERROR(U6/T6,"-") -> 1 | W6: G | X6: 4.8357552 | Y6: 5.1436863 | Z6: =Y6-X6 -> 0.30793102 | AA6: =IFERROR(Z6/Y6,"-") -> 0.059865825 | AB6: G | AC6: 0 | AD6: 0 | AE6: =AD6-AC6 -> 0 | AF6: =IFERROR(AE6/AD6,"-") -> - | AH6: 3.9665899 | AI6: 6.3094833 | AJ6: =AI6-AH6 -> 2.3428933 | AK6: =IFERROR(AJ6/AI6,"-") -> 0.37132888 | AL6: G | AN6: =I22+AC22+AH22+X22 -> 73.108391 | AO6: =J22+AD22+AI22+Y22 -> 76.703514 | AP6: =AO6-AN6 -> 3.5951226 | AQ6: =IFERROR(AP6/AO6,"-") -> 0.046870376 | AR6: G
A7: Commercial Fuels | B7: Commercial Fuels | C7: Roanne Steele | D7: =I7+AC7+AH7+X7 -> 12.401562 | E7: =J7+AD7+AI7+Y7 -> 18.777378 | F7: =E7-D7 -> 6.3758153 | G7: =IFERROR(F7/E7,"-") -> 0.3395477 | H7: G | I7: 7.1072414 | J7: 8.2847223 | K7: =J7-I7 -> 1.1774809 | L7: =IFERROR(K7/J7,"-") -> 0.14212678 | M7: G | N7: =I7-S7 -> 5.0186846 | O7: =J7-T7 -> 5.3538618 | P7: =O7-N7 -> 0.33517727 | Q7: =IFERROR(P7/O7,"-") -> 0.062604767 | R7: G | S7: 2.0885568 | T7: 2.9308605 | U7: =T7-S7 -> 0.84230361 | V7: =IFERROR(U7/T7,"-") -> 0.28739124 | W7: G | Z7: =Y7-X7 -> 0 | AA7: =IFERROR(Z7/Y7,"-") -> - | AC7: 4.7285415 | AD7: 7.109604 | AE7: =AD7-AC7 -> 2.3810625 | AF7: =IFERROR(AE7/AD7,"-") -> 0.3349079 | AG7: G | AH7: 0.56577941 | AI7: 3.3830513 | AJ7: =AI7-AH7 -> 2.8172719 | AK7: =IFERROR(AJ7/AI7,"-") -> 0.83276062 | AL7: G | AN7: =I23+AC23+AH23+X23 -> 32.768998 | AO7: =J23+AD23+AI23+Y23 -> 40.534223 | AP7: =AO7-AN7 -> 7.7652255 | AQ7: =IFERROR(AP7/AO7,"-") -> 0.19157208 | AR7: G
A8: Retail | B8: Retail | C8: Vance Anderson | D8: =I8+AC8+AH8+X8 -> 14.290549 | E8: =J8+AD8+AI8+Y8 -> 18.065295 | F8: =E8-D8 -> 3.7747465 | G8: =IFERROR(F8/E8,"-") -> 0.20895017 | H8: G | I8: 6.854453 | J8: 7.0852951 | K8: =J8-I8 -> 0.23084214 | L8: =IFERROR(K8/J8,"-") -> 0.032580455 | M8: G | N8: =I8-S8 -> 6.4596074 | O8: =J8-T8 -> 6.4302951 | P8: =O8-N8 -> -0.02931227 | Q8: =IFERROR(P8/O8,"-") -> -0.0045584642 | R8: G | S8: 0.39484559 | T8: 0.655 | U8: =T8-S8 -> 0.26015441 | V8: =IFERROR(U8/T8,"-") -> 0.39718231 | W8: G | Z8: =Y8-X8 -> 0 | AA8: =IFERROR(Z8/Y8,"-") -> - | AC8: 3.3546059 | AD8: 5.08 | AE8: =AD8-AC8 -> 1.7253941 | AF8: =IFERROR(AE8/AD8,"-") -> 0.33964451 | AG8: G | AH8: 4.0814897 | AI8: 5.9 | AJ8: =AI8-AH8 -> 1.8185103 | AK8: =IFERROR(AJ8/AI8,"-") -> 0.30822208 | AL8: G | AN8: =I24+AC24+AH24+X24 -> 35.260356 | AO8: =J24+AD24+AI24+Y24 -> 33.880855 | AP8: =AO8-AN8 -> -1.3795012 | AQ8: =IFERROR(AP8/AO8,"-") -> -0.040716245 | AR8: R
A9: Energy Solutions | B9: Energy Solutions | C9: Roanne Steele | D9: =I9+AC9+AH9+X9 -> 4.138504 | E9: =J9+AD9+AI9+Y9 -> 3.8066795 | F9: =E9-D9 -> -0.33182446 | G9: =IFERROR(F9/E9,"-") -> -0.087169002 | H9: R | I9: 2.8789003 | J9: 2.5160191 | K9: =J9-I9 -> -0.36288119 | L9: =IFERROR(K9/J9,"-") -> -0.14422831 | M9: R | N9: =I9-S9 -> 2.5452916 | O9: =J9-T9 -> 2.0310192 | P9: =O9-N9 -> -0.51427247 | Q9: =IFERROR(P9/O9,"-") -> -0.25320907 | R9: R | S9: 0.33360872 | T9: 0.485 | U9: =T9-S9 -> 0.15139128 | V9: =IFERROR(U9/T9,"-") -> 0.31214697 | W9: G | Z9: =Y9-X9 -> 0 | AA9: =IFERROR(Z9/Y9,"-") -> - | AE9: =AD9-AC9 -> 0 | AF9: =IFERROR(AE9/AD9,"-") -> - | AH9: 1.2596037 | AI9: 1.2906604 | AJ9: =AI9-AH9 -> 0.031056732 | AK9: =IFERROR(AJ9/AI9,"-") -> 0.024062667 | AL9: G | AN9: =I25+AC25+AH25+X25 -> 7.830666 | AO9: =J25+AD25+AI25+Y25 -> 8.0095244 | AP9: =AO9-AN9 -> 0.17885836 | AQ9: =IFERROR(AP9/AO9,"-") -> 0.022330709 | AR9: R
A10: Infrastructure | B10: Infrastructure | C10: Roanne Steele | D10: =I10+AC10+AH10+X10 -> 2.6905766 | E10: =J10+AD10+AI10+Y10 -> 4.277083 | F10: =E10-D10 -> 1.5865064 | G10: =IFERROR(F10/E10,"-") -> 0.37093187 | H10: G | I10: 1.7562082 | J10: 1.831374 | K10: =J10-I10 -> 0.07516578 | L10: =IFERROR(K10/J10,"-") -> 0.041043381 | M10: G | N10: =I10-S10 -> 1.4404499 | O10: =J10-T10 -> 1.449693 | P10: =O10-N10 -> 0.00924308 | Q10: =IFERROR(P10/O10,"-") -> 0.0063758879 | R10: G | S10: 0.3157583 | T10: 0.381681 | U10: =T10-S10 -> 0.0659227 | V10: =IFERROR(U10/T10,"-") -> 0.17271675 | W10: G | Z10: =Y10-X10 -> 0 | AA10: =IFERROR(Z10/Y10,"-") -> - | AE10: =AD10-AC10 -> 0 | AF10: =IFERROR(AE10/AD10,"-") -> - | AH10: 0.93436839 | AI10: 2.445709 | AJ10: =AI10-AH10 -> 1.5113406 | AK10: =IFERROR(AJ10/AI10,"-") -> 0.61795602 | AL10: G | AN10: =I26+AC26+AH26+X26 -> 8.4185471 | AO10: =J26+AD26+AI26+Y26 -> 9.249376 | AP10: =AO10-AN10 -> 0.83082882 | AQ10: =IFERROR(AP10/AO10,"-") -> 0.089825392 | AR10: G
A11: Finance & Other Corp | B11: Finance & Other Corp | C11: Emily Mogic | D11: =I11+AC11+AH11+X11 -> 2.8468529 | E11: =J11+AD11+AI11+Y11 -> 2.1223538 | F11: =E11-D11 -> -0.72449911 | G11: =IFERROR(F11/E11,"-") -> -0.34136585 | H11: R | I11: 2.8468529 | J11: 2.1223538 | K11: =J11-I11 -> -0.72449911 | L11: =IFERROR(K11/J11,"-") -> -0.34136585 | M11: R | N11: =I11-S11 -> 2.0786006 | O11: =J11-T11 -> 1.6546105 | P11: =O11-N11 -> -0.42399014 | Q11: =IFERROR(P11/O11,"-") -> -0.25624771 | R11: R | S11: 0.76825227 | T11: 0.4677433 | U11: =T11-S11 -> -0.30050897 | V11: =IFERROR(U11/T11,"-") -> -0.64246556 | W11: R | Z11: =Y11-X11 -> 0 | AA11: =IFERROR(Z11/Y11,"-") -> - | AE11: =AD11-AC11 -> 0 | AF11: =IFERROR(AE11/AD11,"-") -> - | AH11: 0 | AI11: 0 | AJ11: =AI11-AH11 -> 0 | AK11: =IFERROR(AJ11/AI11,"-") -> - | AN11: =I27+AC27+AH27+X27 -> 5.2721119 | AO11: =J27+AD27+AI27+Y27 -> 3.8807737 | AP11: =AO11-AN11 -> -1.3913382 | AQ11: =IFERROR(AP11/AO11,"-") -> -0.35852084 | AR11: G
A12: People & Culture | B12: P&C | C12: Emily Mogic | D12: =I12+AC12+AH12+X12 -> 1.9651397 | E12: =J12+AD12+AI12+Y12 -> 2.460508 | F12: =E12-D12 -> 0.49536834 | G12: =IFERROR(F12/E12,"-") -> 0.20132767 | H12: G | I12: 1.6178184 | J12: 1.860608 | K12: =J12-I12 -> 0.2427896 | L12: =IFERROR(K12/J12,"-") -> 0.13048939 | M12: G | N12: =I12-S12 -> 0.70035539 | O12: =J12-T12 -> 0.87310804 | P12: =O12-N12 -> 0.17275265 | Q12: =IFERROR(P12/O12,"-") -> 0.19785942 | R12: G | S12: 0.91746305 | T12: 0.9875 | U12: =T12-S12 -> 0.07003695 | V12: =IFERROR(U12/T12,"-") -> 0.070923494 | W12: G | Z12: =Y12-X12 -> 0 | AA12: =IFERROR(Z12/Y12,"-") -> - | AC12: 0.34732126 | AD12: 0.4624 | AE12: =AD12-AC12 -> 0.11507874 | AF12: =IFERROR(AE12/AD12,"-") -> 0.24887271 | AG12: G | AH12: 0 | AI12: 0.1375 | AJ12: =AI12-AH12 -> 0.1375 | AK12: =IFERROR(AJ12/AI12,"-") -> 1 | AL12: G | AN12: =I28+AC28+AH28+X28 -> 5.4932256 | AO12: =J28+AD28+AI28+Y28 -> 5.813038 | AP12: =AO12-AN12 -> 0.31981243 | AQ12: =IFERROR(AP12/AO12,"-") -> 0.055016401 | AR12: G
A13: Customer | B13: Customer | C13: Harley Giles | D13: =I13+AC13+AH13+X13 -> 2.4105283 | E13: =J13+AD13+AI13+Y13 -> 5.4047457 | F13: =E13-D13 -> 2.9942174 | G13: =IFERROR(F13/E13,"-") -> 0.55399783 | H13: G | I13: 0.98861064 | J13: 0.82141236 | K13: =J13-I13 -> -0.16719828 | L13: =IFERROR(K13/J13,"-") -> -0.20354975 | M13: R | N13: =I13-S13 -> 0.98861064 | O13: =J13-T13 -> 0.82141236 | P13: =O13-N13 -> -0.16719828 | Q13: =IFERROR(P13/O13,"-") -> -0.20354975 | R13: R | S13: 0 | T13: 0 | U13: =T13-S13 -> 0 | V13: =IFERROR(U13/T13,"-") -> - | Z13: =Y13-X13 -> 0 | AA13: =IFERROR(Z13/Y13,"-") -> - | AC13: 0 | AD13: 2.5 | AE13: =AD13-AC13 -> 2.5 | AF13: =IFERROR(AE13/AD13,"-") -> 1 | AG13: G | AH13: 1.4219177 | AI13: 2.0833333 | AJ13: =AI13-AH13 -> 0.66141564 | AK13: =IFERROR(AJ13/AI13,"-") -> 0.31747951 | AL13: G | AN13: =I29+AC29+AH29+X29 -> 10.983783 | AO13: =J29+AD29+AI29+Y29 -> 11.691533 | AP13: =AO13-AN13 -> 0.70775018 | AQ13: =IFERROR(AP13/AO13,"-") -> 0.060535277 | AR13: G
B14: Total Technology | D14: =SUM(D5:D13) -> 129.57658 | E14: =SUM(E5:E13) -> 149.32633 | F14: =SUM(F5:F13) -> 19.749751 | G14: =F14/E14 -> 0.132259 | H14: G | I14: =SUM(I5:I13) -> 92.279395 | J14: =SUM(J5:J13) -> 93.256469 | K14: =SUM(K5:K13) -> 0.97707378 | L14: =K14/J14 -> 0.010477276 | M14: G | N14: =SUM(N5:N13) -> 86.660069 | O14: =SUM(O5:O13) -> 85.125564 | P14: =SUM(P5:P13) -> -1.534505 | Q14: =P14/O14 -> -0.018026371 | R14: A | S14: =SUM(S5:S13) -> 5.619326 | T14: =SUM(T5:T13) -> 8.1309048 | U14: =SUM(U5:U13) -> 2.5115788 | V14: =U14/T14 -> 0.3088929 | W14: G | X14: =SUM(X5:X13) -> 7.6209764 | Y14: =SUM(Y5:Y13) -> 8.0775842 | Z14: =SUM(Z5:Z13) -> 0.45660781 | AA14: =Z14/Y14 -> 0.056527769 | AB14: G | AC14: =SUM(AC5:AC13) -> 17.270477 | AD14: =SUM(AD5:AD13) -> 24.414204 | AE14: =SUM(AE5:AE13) -> 7.1437272 | AF14: =AE14/AD14 -> 0.29260537 | AG14: G | AH14: =SUM(AH5:AH13) -> 12.405729 | AI14: =SUM(AI5:AI13) -> 23.578071 | AJ14: =SUM(AJ5:AJ13) -> 11.172342 | AK14: =AJ14/AI14 -> 0.47384463 | AL14: G | AN14: =SUM(AN5:AN13) -> 297.09322 | AO14: =SUM(AO5:AO13) -> 302.52235 | AP14: =SUM(AP5:AP13) -> 5.4291311 | AQ14: =AP14/AO14 -> 0.017946215 | AR14: G
F15: =F14/E14 -> 0.132259 | I15: =I14/$D14 -> 0.71216108 | J15: ` | K15: =K14/J14 -> 0.010477276 | N15: =N14/$D14 -> 0.66879425 | P15: =P14/O14 -> -0.018026371 | S15: =S14/$D14 -> 0.043366835 | U15: =U14/T14 -> 0.3088929 | X15: =X14/$D14 -> 0.05881446 | Z15: =Z14/Y14 -> 0.056527769 | AC15: =AC14/$D14 -> 0.13328394 | AE15: =AE14/AD14 -> 0.29260537 | AH15: =AH14/$D14 -> 0.095740518 | AJ15: =AJ14/AI14 -> 0.47384463
B19: BUSINESS SEGMENTS | C19: TDD GM | D19: FY2026 - TOTAL | I19: OPEX: LIGHTS ON + INITIATIVES | N19: OPEX:LIGHTS ON | S19: OPEX: INITIATIVES | X19: OPEX: DEPRECIATION | AC19: OPEX: SIGNIFICANT ITEMS | AH19: CAPEX
D20: F | E20: B | F20: V | G20: V % | H20: Trend | I20: F | J20: B | K20: V | L20: V % | M20: Trend | N20: F | O20: B | P20: V | Q20: V % | R20: Trend | S20: F | T20: B | U20: V | V20: V % | W20: Trend | X20: F | Y20: B | Z20: V | AA20: V % | AB20: Trend | AC20: F | AD20: B | AE20: V | AF20: V % | AG20: Trend | AH20: F | AI20: B | AJ20: V | AK20: V % | AL20: Trend
A21: TDD (Corporate)1 | B21: TDD (Corporate)1 | C21: Brad Blyth Greg Cassis | D21: =I21+AC21+AH21+X21 -> 117.95714 | E21: =J21+AD21+AI21+Y21 -> 112.75951 | F21: =E21-D21 -> -5.1976273 | G21: =IFERROR(F21/E21,"-") -> -0.046094801 | H21: R | I21: 82.087877 | J21: 81.894863 | K21: =J21-I21 -> -0.19301366 | L21: =IFERROR(K21/J21,"-") -> -0.002356847 | M21: G | N21: =I21-S21 -> 79.310436 | O21: =J21-T21 -> 78.894863 | P21: =O21-N21 -> -0.41557243 | Q21: =IFERROR(P21/O21,"-") -> -0.0052674206 | R21: A | S21: 2.7774412 | T21: 3 | U21: =T21-S21 -> 0.22255877 | V21: =IFERROR(U21/T21,"-") -> 0.074186257 | W21: G | X21: 5.6865111 | Y21: 5.8000499 | Z21: =Y21-X21 -> 0.11353882 | AA21: =IFERROR(Z21/Y21,"-") -> 0.01957549 | AB21: G | AC21: 25.395773 | AD21: 20.1966 | AE21: =AD21-AC21 -> -5.1991726 | AF21: =IFERROR(AE21/AD21,"-") -> -0.25742811 | AG21: R | AH21: 4.7869798 | AI21: 4.868 | AJ21: =AI21-AH21 -> 0.08102017 | AK21: =IFERROR(AJ21/AI21,"-") -> 0.01664342 | AL21: G | AM21: =I21+X21 -> 87.774388 | AN21: input retail SI number manually
A22: Z-Energy | B22: Z- Energy | C22: Vance Anderson Harley Giles | D22: =I22+AC22+AH22+X22 -> 73.108391 | E22: =J22+AD22+AI22+Y22 -> 76.703514 | F22: =E22-D22 -> 3.5951226 | G22: =IFERROR(F22/E22,"-") -> 0.046870376 | H22: G | I22: 53.465434 | J22: 53.6715 | K22: =J22-I22 -> 0.20606573 | L22: =IFERROR(K22/J22,"-") -> 0.0038393884 | M22: G | N22: =I22-S22 -> 53.465434 | O22: =J22-T22 -> 52.22526 | P22: =O22-N22 -> -1.2401743 | Q22: =IFERROR(P22/O22,"-") -> -0.023746637 | R22: A | S22: 0 | T22: 1.44624 | U22: =T22-S22 -> 1.44624 | V22: =IFERROR(U22/T22,"-") -> 1 | W22: G | X22: 10.161498 | Y22: 11.306521 | Z22: =Y22-X22 -> 1.1450224 | AA22: =IFERROR(Z22/Y22,"-") -> 0.10127098 | AB22: G | AC22: 0 | AD22: 0 | AE22: =AD22-AC22 -> 0 | AF22: =IFERROR(AE22/AD22,"-") -> - | AH22: 9.4814594 | AI22: 11.725494 | AJ22: =AI22-AH22 -> 2.2440344 | AK22: =IFERROR(AJ22/AI22,"-") -> 0.1913808 | AL22: G | AM22: =I22+X22 -> 63.626932
A23: Commercial Fuels | B23: Commercial Fuels | C23: Roanne Steele | D23: =I23+AC23+AH23+X23 -> 32.768998 | E23: =J23+AD23+AI23+Y23 -> 40.534223 | F23: =E23-D23 -> 7.7652255 | G23: =IFERROR(F23/E23,"-") -> 0.19157208 | H23: G | I23: 18.07582 | J23: 19.517302 | K23: =J23-I23 -> 1.4414818 | L23: =IFERROR(K23/J23,"-") -> 0.073856612 | M23: G | N23: =I23-S23 -> 12.122014 | O23: =J23-T23 -> 13.655581 | P23: =O23-N23 -> 1.533567 | Q23: =IFERROR(P23/O23,"-") -> 0.11230331 | R23: G | S23: 5.9538061 | T23: 5.8617209 | U23: =T23-S23 -> -0.092085221 | V23: =IFERROR(U23/T23,"-") -> -0.015709588 | W23: A | Z23: =Y23-X23 -> 0 | AA23: =IFERROR(Z23/Y23,"-") -> - | AC23: 8.927316 | AD23: 14.219208 | AE23: =AD23-AC23 -> 5.291892 | AF23: =IFERROR(AE23/AD23,"-") -> 0.37216503 | AG23: G | AH23: 5.7658612 | AI23: 6.7977128 | AJ23: =AI23-AH23 -> 1.0318517 | AK23: =IFERROR(AJ23/AI23,"-") -> 0.15179395 | AL23: G
A24: Retail | B24: Retail | C24: Vance Anderson | D24: =I24+AC24+AH24+X24 -> 35.260356 | E24: =J24+AD24+AI24+Y24 -> 33.880855 | F24: =E24-D24 -> -1.3795012 | G24: =IFERROR(F24/E24,"-") -> -0.040716245 | H24: A | I24: 15.230723 | J24: 15.235855 | K24: =J24-I24 -> 0.0051319 | L24: =IFERROR(K24/J24,"-") -> 0.00033683047 | M24: G | N24: =I24-S24 -> 14.481085 | O24: =J24-T24 -> 13.925855 | P24: =O24-N24 -> -0.55523051 | Q24: =IFERROR(P24/O24,"-") -> -0.03987048 | R24: A | S24: 0.74963759 | T24: 1.31 | U24: =T24-S24 -> 0.56036241 | V24: =IFERROR(U24/T24,"-") -> 0.42775756 | W24: G | Z24: =Y24-X24 -> 0 | AA24: =IFERROR(Z24/Y24,"-") -> - | AC24: 8.64 | AD24: 6.845 | AE24: =AD24-AC24 -> -1.795 | AF24: =IFERROR(AE24/AD24,"-") -> -0.26223521 | AG24: R | AH24: 11.389633 | AI24: 11.8 | AJ24: =AI24-AH24 -> 0.41036692 | AK24: =IFERROR(AJ24/AI24,"-") -> 0.034776858 | AL24: G
A25: Energy Solutions | B25: Energy Solutions | C25: Roanne Steele | D25: =I25+AC25+AH25+X25 -> 7.830666 | E25: =J25+AD25+AI25+Y25 -> 8.0095244 | F25: =E25-D25 -> 0.17885836 | G25: =IFERROR(F25/E25,"-") -> 0.022330709 | H25: G | I25: 5.0440983 | J25: 5.0119394 | K25: =J25-I25 -> -0.0321589 | L25: =IFERROR(K25/J25,"-") -> -0.0064164582 | M25: A | N25: =I25-S25 -> 4.5362156 | O25: =J25-T25 -> 4.0419395 | P25: =O25-N25 -> -0.49427618 | Q25: =IFERROR(P25/O25,"-") -> -0.12228688 | R25: R | S25: 0.50788272 | T25: 0.97 | U25: =T25-S25 -> 0.46211728 | V25: =IFERROR(U25/T25,"-") -> 0.47640957 | W25: G | Z25: =Y25-X25 -> 0 | AA25: =IFERROR(Z25/Y25,"-") -> - | AE25: =AD25-AC25 -> 0 | AF25: =IFERROR(AE25/AD25,"-") -> - | AH25: 2.7865677 | AI25: 2.9975849 | AJ25: =AI25-AH25 -> 0.21101726 | AK25: =IFERROR(AJ25/AI25,"-") -> 0.070395758 | AL25: G
A26: Infrastructure | B26: Infrastructure | C26: Roanne Steele | D26: =I26+AC26+AH26+X26 -> 8.4185471 | E26: =J26+AD26+AI26+Y26 -> 9.249376 | F26: =E26-D26 -> 0.83082882 | G26: =IFERROR(F26/E26,"-") -> 0.089825392 | H26: G | I26: 4.2749786 | J26: 4.357958 | K26: =J26-I26 -> 0.08297936 | L26: =IFERROR(K26/J26,"-") -> 0.019040881 | M26: G | N26: =I26-S26 -> 3.3010253 | O26: =J26-T26 -> 3.594596 | P26: =O26-N26 -> 0.29357066 | Q26: =IFERROR(P26/O26,"-") -> 0.081670001 | R26: G | S26: 0.9739533 | T26: 0.763362 | U26: =T26-S26 -> -0.2105913 | V26: =IFERROR(U26/T26,"-") -> -0.27587344 | W26: R | Z26: =Y26-X26 -> 0 | AA26: =IFERROR(Z26/Y26,"-") -> - | AE26: =AD26-AC26 -> 0 | AF26: =IFERROR(AE26/AD26,"-") -> - | AH26: 4.1435685 | AI26: 4.891418 | AJ26: =AI26-AH26 -> 0.74784946 | AK26: =IFERROR(AJ26/AI26,"-") -> 0.15289012 | AL26: G
A27: Finance & Other Corp | B27: Finance & Other Corp | C27: Emily Mogic | D27: =I27+AC27+AH27+X27 -> 5.2721119 | E27: =J27+AD27+AI27+Y27 -> 3.8807737 | F27: =E27-D27 -> -1.3913382 | G27: =IFERROR(F27/E27,"-") -> -0.35852084 | H27: R | I27: 5.2721119 | J27: 3.8807737 | K27: =J27-I27 -> -1.3913382 | L27: =IFERROR(K27/J27,"-") -> -0.35852084 | M27: R | N27: =I27-S27 -> 4.3588956 | O27: =J27-T27 -> 2.9452871 | P27: =O27-N27 -> -1.4136086 | Q27: =IFERROR(P27/O27,"-") -> -0.47995613 | R27: R | S27: 0.91321627 | T27: 0.93548661 | U27: =T27-S27 -> 0.02227034 | V27: =IFERROR(U27/T27,"-") -> 0.023806156 | W27: G | Z27: =Y27-X27 -> 0 | AA27: =IFERROR(Z27/Y27,"-") -> - | AE27: =AD27-AC27 -> 0 | AF27: =IFERROR(AE27/AD27,"-") -> - | AH27: 0 | AI27: 0 | AJ27: =AI27-AH27 -> 0 | AK27: =IFERROR(AJ27/AI27,"-") -> - | AL27: G
A28: People & Culture | B28: P&C | C28: Emily Mogic | D28: =I28+AC28+AH28+X28 -> 5.4932256 | E28: =J28+AD28+AI28+Y28 -> 5.813038 | F28: =E28-D28 -> 0.31981243 | G28: =IFERROR(F28/E28,"-") -> 0.055016401 | H28: G | I28: 3.8516861 | J28: 4.123038 | K28: =J28-I28 -> 0.27135188 | L28: =IFERROR(K28/J28,"-") -> 0.065813577 | M28: G | N28: =I28-S28 -> 1.9121353 | O28: =J28-T28 -> 2.148038 | P28: =O28-N28 -> 0.23590273 | Q28: =IFERROR(P28/O28,"-") -> 0.10982242 | R28: G | S28: 1.9395508 | T28: 1.975 | U28: =T28-S28 -> 0.035449154 | V28: =IFERROR(U28/T28,"-") -> 0.017948939 | W28: G | Z28: =Y28-X28 -> 0 | AA28: =IFERROR(Z28/Y28,"-") -> - | AC28: 1.3115394 | AD28: 1.36 | AE28: =AD28-AC28 -> 0.04846055 | AF28: =IFERROR(AE28/AD28,"-") -> 0.035632757 | AG28: G | AH28: 0.33 | AI28: 0.33 | AJ28: =AI28-AH28 -> 0 | AK28: =IFERROR(AJ28/AI28,"-") -> 0 | AL28: G
A29: Customer | B29: Customer | C29: Harley Giles | D29: =I29+AC29+AH29+X29 -> 10.983783 | E29: =J29+AD29+AI29+Y29 -> 11.691533 | F29: =E29-D29 -> 0.70775018 | G29: =IFERROR(F29/E29,"-") -> 0.060535277 | H29: G | I29: 2.74505 | J29: 1.6915328 | K29: =J29-I29 -> -1.0535172 | L29: =IFERROR(K29/J29,"-") -> -0.62281806 | M29: R | N29: =I29-S29 -> 2.74505 | O29: =J29-T29 -> 1.6915328 | P29: =O29-N29 -> -1.0535172 | Q29: =IFERROR(P29/O29,"-") -> -0.62281806 | R29: R | S29: 0 | T29: 0 | U29: =T29-S29 -> 0 | V29: =IFERROR(U29/T29,"-") -> - | Z29: =Y29-X29 -> 0 | AA29: =IFERROR(Z29/Y29,"-") -> - | AC29: 3.832387 | AD29: 5 | AE29: =AD29-AC29 -> 1.1676131 | AF29: =IFERROR(AE29/AD29,"-") -> 0.23352261 | AG29: G | AH29: 4.4063457 | AI29: 5 | AJ29: =AI29-AH29 -> 0.59365431 | AK29: =IFERROR(AJ29/AI29,"-") -> 0.11873086 | AL29: G
B30: Total Technology | D30: =SUM(D21:D29) -> 297.09322 | E30: =SUM(E21:E29) -> 302.52235 | F30: =SUM(F21:F29) -> 5.4291311 | G30: =F30/E30 -> 0.017946215 | H30: G | I30: =SUM(I21:I29) -> 190.04778 | J30: =SUM(J21:J29) -> 189.38476 | K30: =SUM(K21:K29) -> -0.66301729 | L30: =K30/J30 -> -0.0035009009 | M30: A | N30: =SUM(N21:N29) -> 176.23229 | O30: =SUM(O21:O29) -> 173.12295 | P30: =SUM(P21:P29) -> -3.1093387 | Q30: =P30/O30 -> -0.017960292 | R30: A | S30: =SUM(S21:S29) -> 13.815488 | T30: =SUM(T21:T29) -> 16.26181 | U30: =SUM(U21:U29) -> 2.4463214 | V30: =U30/T30 -> 0.15043353 | W30: G | X30: =SUM(X21:X29) -> 15.848009 | Y30: =SUM(Y21:Y29) -> 17.10657 | Z30: =SUM(Z21:Z29) -> 1.2585612 | AA30: =Z30/Y30 -> 0.073571802 | AB30: G | AC30: =SUM(AC21:AC29) -> 48.107015 | AD30: =SUM(AD21:AD29) -> 47.620808 | AE30: =SUM(AE21:AE29) -> -0.48620701 | AF30: =AE30/AD30 -> -0.01020997 | AG30: A | AH30: =SUM(AH21:AH29) -> 43.090415 | AI30: =SUM(AI21:AI29) -> 48.41021 | AJ30: =SUM(AJ21:AJ29) -> 5.3197942 | AK30: =AJ30/AI30 -> 0.10988992 | AL30: G
I31: =I30/$D30 -> 0.63969073 | N31: =N30/$D30 -> 0.59318853 | S31: =S30/$D30 -> 0.046502199 | X31: =X30/$D30 -> 0.053343558 | AC31: =AC30/$D30 -> 0.16192566 | AH31: =AH30/$D30 -> 0.14504005
AO32: =E30-297 -> 5.5223497
D35: =D3 -> TOTAL YTD (Jun-2026) | I35: TOTAL TECHNOLOGY Full Year 2026
B36: Spend Type | D36: A | E36: B | F36: V | G36: V % | H36: Trend | I36: F | J36: B | K36: V | L36: V % | M36: Trend
B37: Lights on | D37: =N14 -> 86.660069 | E37: =O14 -> 85.125564 | F37: =E37-D37 -> -1.534505 | G37: =IFERROR(F37/E37,"-") -> -0.018026371 | H37: A | I37: =N30 -> 176.23229 | J37: =O30 -> 173.12295 | K37: =J37-I37 -> -3.1093387 | L37: =IFERROR(K37/J37,"-") -> -0.017960292 | M37: A
B38: Depreciation | D38: =X14 -> 7.6209764 | E38: =Y14 -> 8.0775842 | F38: =E38-D38 -> 0.45660781 | G38: =IFERROR(F38/E38,"-") -> 0.056527769 | H38: G | I38: =X30 -> 15.848009 | J38: =Y30 -> 17.10657 | K38: =J38-I38 -> 1.2585612 | L38: =IFERROR(K38/J38,"-") -> 0.073571802 | M38: G
B39: Lights on + Depreciation | D39: =SUM(D37:D38) -> 94.281045 | E39: =SUM(E37:E38) -> 93.203148 | F39: =SUM(F37:F38) -> -1.0778972 | G39: =IFERROR(F39/E39,"-") -> -0.01156503 | H39: A | I39: =SUM(I37:I38) -> 192.0803 | J39: =SUM(J37:J38) -> 190.22952 | K39: =SUM(K37:K38) -> -1.8507775 | L39: =IFERROR(K39/J39,"-") -> -0.0097291812 | M39: A
B40: Opex Initiatives | D40: =S14 -> 5.619326 | E40: =T14 -> 8.1309048 | F40: =E40-D40 -> 2.5115788 | G40: =IFERROR(F40/E40,"-") -> 0.3088929 | H40: G | I40: =S30 -> 13.815488 | J40: =T30 -> 16.26181 | K40: =J40-I40 -> 2.4463214 | L40: =IFERROR(K40/J40,"-") -> 0.15043353 | M40: G
B41: Capex | D41: =AH14 -> 12.405729 | E41: =AI14 -> 23.578071 | F41: =E41-D41 -> 11.172342 | G41: =IFERROR(F41/E41,"-") -> 0.47384463 | H41: G | I41: =AH30 -> 43.090415 | J41: =AI30 -> 48.41021 | K41: =J41-I41 -> 5.3197942 | L41: =IFERROR(K41/J41,"-") -> 0.10988992 | M41: G
B42: Significant Items | D42: =AC14 -> 17.270477 | E42: =AD14 -> 24.414204 | F42: =E42-D42 -> 7.1437272 | G42: =IFERROR(F42/E42,"-") -> 0.29260537 | H42: G | I42: =AC30 -> 48.107015 | J42: =AD30 -> 47.620808 | K42: =J42-I42 -> -0.48620701 | L42: =IFERROR(K42/J42,"-") -> -0.01020997 | M42: A
B43: Projects | D43: =SUM(D40:D42) -> 35.295531 | E43: =SUM(E40:E42) -> 56.123179 | F43: =SUM(F40:F42) -> 20.827648 | G43: =IFERROR(F43/E43,"-") -> 0.37110599 | H43: G | I43: =SUM(I40:I42) -> 105.01292 | J43: =SUM(J40:J42) -> 112.29283 | K43: =SUM(K40:K42) -> 7.2799086 | L43: =IFERROR(K43/J43,"-") -> 0.064829685 | M43: G
B44: Total Technology | D44: =SUM(D43,D39) -> 129.57658 | E44: =SUM(E43,E39) -> 149.32633 | F44: =SUM(F43,F39) -> 19.749751 | G44: =IFERROR(F44/E44,"-") -> 0.132259 | H44: G | I44: =SUM(I43,I39) -> 297.09322 | J44: =SUM(J43,J39) -> 302.52235 | K44: =SUM(K43,K39) -> 5.4291311 | L44: =IFERROR(K44/J44,"-") -> 0.017946215 | M44: G
B47: SPEND CATEGORY | D47: =D3 -> TOTAL YTD (Jun-2026) | I47: TOTAL TECHNOLOGY YTD (May-2026)
D48: A | E48: B | F48: V | G48: V % | H48: Trend | I48: A | J48: B | K48: V | L48: V % | M48: Trend
B49: Opex | D49: =I14+X14 -> 99.900371 | E49: =J14+Y14 -> 101.33405 | F49: =E49-D49 -> 1.4336816 | G49: =IFERROR(F49/E49,"-") -> 0.014148073 | H49: G | I49: =I30+X30 -> 205.89579 | J49: =J30+Y30 -> 206.49133 | K49: =J49-I49 -> 0.59554393 | L49: =IFERROR(K49/J49,"-") -> 0.002884111 | M49: G
...

Sheet REVIEW - Complete Role Mapping
A1: EE Number | B1: Name | C1: Position Title | D1: Reports to name | E1: Reports to Position | F1: Division (GM) | G1: Department (GM-1) | H1: Team (GM-2) | I1: Portfolio | J1: Platform | K1: Squad | L1: CC | M1: Country | N1: Job Level | O1: FTE | Q1: Type | R1: Unit | S1: day rate | T1: FTE Base Local | U1: FTE Base AUD | V1: STI | W1: Payroll | X1: Pensions | Y1: medical | Z1: CPI | AA1: Full Cost AUD | AB1: MyHR ee no | AJ1: MTab | AK1: MStatus | AL1: MAUNZ | AM1: MRank | AN1: MKey | AP1: Squad (canonical, from col K) | AQ1: Leadership | AR1: Overhead line | AS1: Squad name on the 1.x tab | AT1: Squad or overhead line | AU1: Agreed cost override (AUD)
A2: 99999101533 | B2: Adrian Alcance | C2: Senior Engineer - DevOps | D2: Vacant | E2: Technology Manager, Engineering | F2: Ampol Retail & Z | G2: Z & Group Retail | H2: Z & Group Retail, Engineering | I2: Z | J2: Z Customer | K2: Z Retail Backend | M2: NZ | N2: CIA | O2: 1 | Q2: Permanent - Full Time | T2: 123710 | U2: 113813.2 | V2: 0.15 | X2: 0.05 | Y2: 2910 | Z2: 0.03 | AA2: =IF(TRIM($B2)="","",IF(N($AU2)>0,$AU2,IF(N($S2)>0,$S2*Lists!$AG$15*(1+N($Z2)),N($U2)*(1+N($V2)+N($W2)+N($X2)+N($Z2))+N($Y2)))) -> 142900.24 | AJ2: =IF(TRIM($B2)="","",IF(IFERROR(INDEX(Lists!$AO$2:$AO$11,MATCH(ROW(),Lists!$AN$2:$AN$11,0)),"")<>"",IFERROR(INDEX(Lists!$AO$2:$AO$11,MATCH(ROW(),Lists!$AN$2:$AN$11,0)),""),IFERROR(INDEX(Lists!$U:$U,MATCH(TRIM($I2),Lists!$T:$T,0)),TRIM($I2)))) -> Z Retail | AK2: =IF(ISNUMBER(SEARCH("vacant",$B2)),"Vacant","Filled") -> Filled | AL2: =IF($M2="NZ","NZ","AU") -> NZ | AM2: =COUNTIF($AJ$2:$AJ2,$AJ2) -> 1 | AN2: =$AJ2&"|"&$AM2 -> Z Retail|1 | AP2: =IF(TRIM($B2)="","",IF($AQ2=1,"Leadership",IFERROR(INDEX(Lists!$X:$X,MATCH(TRIM($K2),Lists!$W:$W,0)),IF(OR(TRIM($K2)="",LOWER(TRIM($K2))="na"),IF(TRIM($G2)="","Unassigned",TRIM($G2)),TRIM($K2))))) -> Z Retail Backend | AQ2: =IF(TRIM($B2)="","",--OR(TRIM($K2)="Leadership",TRIM($J2)="Leadership")) -> FALSE | AR2: =IF(TRIM($B2)="","",IF(IFERROR(INDEX(Lists!$AQ$2:$AQ$11,MATCH(ROW(),Lists!$AN$2:$AN$11,0)),"")<>"",IFERROR(INDEX(Lists!$AQ$2:$AQ$11,MATCH(ROW(),Lists!$AN$2:$AN$11,0)),""),IF(ISNUMBER(SEARCH("head of ",$C2)),"Head of Technology",IF(ISNUMBER(SEARCH("TDD BP",$C2)),"Business Partner",IF(OR(ISNUMBER(SEARCH("domain architect",$C2)),ISNUMBER(SEARCH("enterprise architect",$C2))),"Domain Architect",IF(ISNUMBER(SEARCH("delivery man",$C2)),"Delivery Manager",IF(OR(ISNUMBER(SEARCH("technology manager",$C2)),ISNUMBER(SEARCH("technology manger",$C2)),ISNUMBER(SEARCH("tech manager",$C2))),"Technology Manager","Squad"))))))) -> Squad | AS2: =IF(TRIM($B2)="","",IFERROR(INDEX(Lists!$AA:$AA,MATCH($AP2,Lists!$Z:$Z,0)),$AP2)) -> Z Retail Backend | AT2: =IF(TRIM($B2)="","",IF(IFERROR(INDEX(Lists!$AP$2:$AP$11,MATCH(ROW(),Lists!$AN$2:$AN$11,0)),"")<>"",IFERROR(INDEX(Lists!$AP$2:$AP$11,MATCH(ROW(),Lists!$AN$2:$AN$11,0)),""),IF(OR(LEFT($AJ2,3)="COE",$AJ2="EGI"),$AP2,IF($AR2<>"Squad",$AR2,$AP2)))) -> Z Retail Backend
A3: 110388 | B3: Adrian Lueng | C3: Quality Assurance | D3: Vedran Jukic | E3: Technology Manager, Retail | F3: Ampol Retail & Z | G3: Ampol Retail | H3: Ampol Retail, Technology | I3: Retail | J3: Network/QSR | K3: Network & QSR | M3: Australia | N3: CIA | O3: 1 | Q3: Permanent - Full Time | T3: 120030 | U3: 120030 | V3: 0.1 | W3: 0.055 | X3: 0.12 | Z3: 0.04 | AA3: =IF(TRIM($B3)="","",IF(N($AU3)>0,$AU3,IF(N($S3)>0,$S3*Lists!$AG$15*(1+N($Z3)),N($U3)*(1+N($V3)+N($W3)+N($X3)+N($Z3))+N($Y3)))) -> 157839.45 | AH3: 374 | AJ3: =IF(TRIM($B3)="","",IF(IFERROR(INDEX(Lists!$AO$2:$AO$11,MATCH(ROW(),Lists!$AN$2:$AN$11,0)),"")<>"",IFERROR(INDEX(Lists!$AO$2:$AO$11,MATCH(ROW(),Lists!$AN$2:$AN$11,0)),""),IFERROR(INDEX(Lists!$U:$U,MATCH(TRIM($I3),Lists!$T:$T,0)),TRIM($I3)))) -> Ampol Retail | AK3: =IF(ISNUMBER(SEARCH("vacant",$B3)),"Vacant","Filled") -> Filled | AL3: =IF($M3="NZ","NZ","AU") -> AU | AM3: =COUNTIF($AJ$2:$AJ3,$AJ3) -> 1 | AN3: =$AJ3&"|"&$AM3 -> Ampol Retail|1 | AP3: =IF(TRIM($B3)="","",IF($AQ3=1,"Leadership",IFERROR(INDEX(Lists!$X:$X,MATCH(TRIM($K3),Lists!$W:$W,0)),IF(OR(TRIM($K3)="",LOWER(TRIM($K3))="na"),IF(TRIM($G3)="","Unassigned",TRIM($G3)),TRIM($K3))))) -> Network & QSR | AQ3: =IF(TRIM($B3)="","",--OR(TRIM($K3)="Leadership",TRIM($J3)="Leadership")) -> FALSE | AR3: =IF(TRIM($B3)="","",IF(IFERROR(INDEX(Lists!$AQ$2:$AQ$11,MATCH(ROW(),Lists!$AN$2:$AN$11,0)),"")<>"",IFERROR(INDEX(Lists!$AQ$2:$AQ$11,MATCH(ROW(),Lists!$AN$2:$AN$11,0)),""),IF(ISNUMBER(SEARCH("head of ",$C3)),"Head of Technology",IF(ISNUMBER(SEARCH("TDD BP",$C3)),"Business Partner",IF(OR(ISNUMBER(SEARCH("domain architect",$C3)),ISNUMBER(SEARCH("enterprise architect",$C3))),"Domain Architect",IF(ISNUMBER(SEARCH("delivery man",$C3)),"Delivery Manager",IF(OR(ISNUMBER(SEARCH("technology manager",$C3)),ISNUMBER(SEARCH("technology manger",$C3)),ISNUMBER(SEARCH("tech manager",$C3))),"Technology Manager","Squad"))))))) -> Squad | AS3: =IF(TRIM($B3)="","",IFERROR(INDEX(Lists!$AA:$AA,MATCH($AP3,Lists!$Z:$Z,0)),$AP3)) -> Network & QSR | AT3: =IF(TRIM($B3)="","",IF(IFERROR(INDEX(Lists!$AP$2:$AP$11,MATCH(ROW(),Lists!$AN$2:$AN$11,0)),"")<>"",IFERROR(INDEX(Lists!$AP$2:$AP$11,MATCH(ROW(),Lists!$AN$2:$AN$11,0)),""),IF(OR(LEFT($AJ3,3)="COE",$AJ3="EGI"),$AP3,IF($AR3<>"Squad",$AR3,$AP3)))) -> Network & QSR
A4: C | B4: Alex Prakhiy | C4: Business Analyst | D4: Vanessa Allen | E4: Delivery Manager, Ampol Retail | F4: Ampol Retail & Z | G4: Ampol Retail | H4: Ampol Retail, Delivery | I4: Ampol Retail | J4: EGI | K4: EGI Retail | M4: Australia | N4: NA | O4: 1 | Q4: cxc | R4: Daily | S4: 1000 | T4: 0 | AA4: =IF(TRIM($B4)="","",IF(N($AU4)>0,$AU4,IF(N($S4)>0,$S4*Lists!$AG$15*(1+N($Z4)),N($U4)*(1+N($V4)+N($W4)+N($X4)+N($Z4))+N($Y4)))) -> 222000 | AH4: 374 | AJ4: =IF(TRIM($B4)="","",IF(IFERROR(INDEX(Lists!$AO$2:$AO$11,MATCH(ROW(),Lists!$AN$2:$AN$11,0)),"")<>"",IFERROR(INDEX(Lists!$AO$2:$AO$11,MATCH(ROW(),Lists!$AN$2:$AN$11,0)),""),IFERROR(INDEX(Lists!$U:$U,MATCH(TRIM($I4),Lists!$T:$T,0)),TRIM($I4)))) -> Ampol Retail | AK4: =IF(ISNUMBER(SEARCH("vacant",$B4)),"Vacant","Filled") -> Filled | AL4: =IF($M4="NZ","NZ","AU") -> AU | AM4: =COUNTIF($AJ$2:$AJ4,$AJ4) -> 2 | AN4: =$AJ4&"|"&$AM4 -> Ampol Retail|2 | AP4: =IF(TRIM($B4)="","",IF($AQ4=1,"Leadership",IFERROR(INDEX(Lists!$X:$X,MATCH(TRIM($K4),Lists!$W:$W,0)),IF(OR(TRIM($K4)="",LOWER(TRIM($K4))="na"),IF(TRIM($G4)="","Unassigned",TRIM($G4)),TRIM($K4))))) -> EGI Retail | AQ4: =IF(TRIM($B4)="","",--OR(TRIM($K4)="Leadership",TRIM($J4)="Leadership")) -> FALSE | AR4: =IF(TRIM($B4)="","",IF(IFERROR(INDEX(Lists!$AQ$2:$AQ$11,MATCH(ROW(),Lists!$AN$2:$AN$11,0)),"")<>"",IFERROR(INDEX(Lists!$AQ$2:$AQ$11,MATCH(ROW(),Lists!$AN$2:$AN$11,0)),""),IF(ISNUMBER(SEARCH("head of ",$C4)),"Head of Technology",IF(ISNUMBER(SEARCH("TDD BP",$C4)),"Business Partner",IF(OR(ISNUMBER(SEARCH("domain architect",$C4)),ISNUMBER(SEARCH("enterprise architect",$C4))),"Domain Architect",IF(ISNUMBER(SEARCH("delivery man",$C4)),"Delivery Manager",IF(OR(ISNUMBER(SEARCH("technology manager",$C4)),ISNUMBER(SEARCH("technology manger",$C4)),ISNUMBER(SEARCH("tech manager",$C4))),"Technology Manager","Squad"))))))) -> Squad | AS4: =IF(TRIM($B4)="","",IFERROR(INDEX(Lists!$AA:$AA,MATCH($AP4,Lists!$Z:$Z,0)),$AP4)) -> EGI Retail | AT4: =IF(TRIM($B4)="","",IF(IFERROR(INDEX(Lists!$AP$2:$AP$11,MATCH(ROW(),Lists!$AN$2:$AN$11,0)),"")<>"",IFERROR(INDEX(Lists!$AP$2:$AP$11,MATCH(ROW(),Lists!$AN$2:$AN$11,0)),""),IF(OR(LEFT($AJ4,3)="COE",$AJ4="EGI"),$AP4,IF($AR4<>"Squad",$AR4,$AP4)))) -> EGI Retail
A5: 99999101643 | B5: Alex Sutherland | C5: Site Systems Analyst | D5: Callan McLaughlin | E5: Technology Manager, Site Systems | F5: Ampol Retail & Z | G5: Z & Group Retail | H5: Z & Group Retail, Site Systems | I5: Z | J5: Z Customer | K5: Site Systems | M5: NZ | N5: CDB | O5: 1 | Q5: Permanent - Full Time | T5: 86540 | U5: 79616.8 | V5: 0.1 | X5: 0.05 | Y5: 2910 | Z5: 0.03 | AA5: =IF(TRIM($B5)="","",IF(N($AU5)>0,$AU5,IF(N($S5)>0,$S5*Lists!$AG$15*(1+N($Z5)),N($U5)*(1+N($V5)+N($W5)+N($X5)+N($Z5))+N($Y5)))) -> 96857.824 | AJ5: =IF(TRIM($B5)="","",IF(IFERROR(INDEX(Lists!$AO$2:$AO$11,MATCH(ROW(),Lists!$AN$2:$AN$11,0)),"")<>"",IFERROR(INDEX(Lists!$AO$2:$AO$11,MATCH(ROW(),Lists!$AN$2:$AN$11,0)),""),IFERROR(INDEX(Lists!$U:$U,MATCH(TRIM($I5),Lists!$T:$T,0)),TRIM($I5)))) -> Z Retail | AK5: =IF(ISNUMBER(SEARCH("vacant",$B5)),"Vacant","Filled") -> Filled | AL5: =IF($M5="NZ","NZ","AU") -> NZ | AM5: =COUNTIF($AJ$2:$AJ5,$AJ5) -> 2 | AN5: =$AJ5&"|"&$AM5 -> Z Retail|2 | AP5: =IF(TRIM($B5)="","",IF($AQ5=1,"Leadership",IFERROR(INDEX(Lists!$X:$X,MATCH(TRIM($K5),Lists!$W:$W,0)),IF(OR(TRIM($K5)="",LOWER(TRIM($K5))="na"),IF(TRIM($G5)="","Unassigned",TRIM($G5)),TRIM($K5))))) -> Site Systems | AQ5: =IF(TRIM($B5)="","",--OR(TRIM($K5)="Leadership",TRIM($J5)="Leadership")) -> FALSE | AR5: =IF(TRIM($B5)="","",IF(IFERROR(INDEX(Lists!$AQ$2:$AQ$11,MATCH(ROW(),Lists!$AN$2:$AN$11,0)),"")<>"",IFERROR(INDEX(Lists!$AQ$2:$AQ$11,MATCH(ROW(),Lists!$AN$2:$AN$11,0)),""),IF(ISNUMBER(SEARCH("head of ",$C5)),"Head of Technology",IF(ISNUMBER(SEARCH("TDD BP",$C5)),"Business Partner",IF(OR(ISNUMBER(SEARCH("domain architect",$C5)),ISNUMBER(SEARCH("enterprise architect",$C5))),"Domain Architect",IF(ISNUMBER(SEARCH("delivery man",$C5)),"Delivery Manager",IF(OR(ISNUMBER(SEARCH("technology manager",$C5)),ISNUMBER(SEARCH("technology manger",$C5)),ISNUMBER(SEARCH("tech manager",$C5))),"Technology Manager","Squad"))))))) -> Squad | AS5: =IF(TRIM($B5)="","",IFERROR(INDEX(Lists!$AA:$AA,MATCH($AP5,Lists!$Z:$Z,0)),$AP5)) -> Site Systems | AT5: =IF(TRIM($B5)="","",IF(IFERROR(INDEX(Lists!$AP$2:$AP$11,MATCH(ROW(),Lists!$AN$2:$AN$11,0)),"")<>"",IFERROR(INDEX(Lists!$AP$2:$AP$11,MATCH(ROW(),Lists!$AN$2:$AN$11,0)),""),IF(OR(LEFT($AJ5,3)="COE",$AJ5="EGI"),$AP5,IF($AR5<>"Squad",$AR5,$AP5)))) -> Site Systems
A6: 99999101548 | B6: Allana Arbuckle | C6: Business Analyst | D6: Vacant | E6: Delivery Manager, Z and Retail Data | F6: Ampol Retail & Z | G6: Z & Group Retail | H6: Z & Group Retail, Delivery | I6: Z | J6: Z Customer | K6: Z Retail Backend | M6: NZ | N6: CDB | O6: 1 | Q6: Permanent - Full Time | T6: 100900 | U6: 92828 | V6: 0.1 | X6: 0.05 | Y6: 2910 | Z6: 0.03 | AA6: =IF(TRIM($B6)="","",IF(N($AU6)>0,$AU6,IF(N($S6)>0,$S6*Lists!$AG$15*(1+N($Z6)),N($U6)*(1+N($V6)+N($W6)+N($X6)+N($Z6))+N($Y6)))) -> 112447.04 | AJ6: =IF(TRIM($B6)="","",IF(IFERROR(INDEX(Lists!$AO$2:$AO$11,MATCH(ROW(),Lists!$AN$2:$AN$11,0)),"")<>"",IFERROR(INDEX(Lists!$AO$2:$AO$11,MATCH(ROW(),Lists!$AN$2:$AN$11,0)),""),IFERROR(INDEX(Lists!$U:$U,MATCH(TRIM($I6),Lists!$T:$T,0)),TRIM($I6)))) -> Z Retail | AK6: =IF(ISNUMBER(SEARCH("vacant",$B6)),"Vacant","Filled") -> Filled | AL6: =IF($M6="NZ","NZ","AU") -> NZ | AM6: =COUNTIF($AJ$2:$AJ6,$AJ6) -> 3 | AN6: =$AJ6&"|"&$AM6 -> Z Retail|3 | AP6: =IF(TRIM($B6)="","",IF($AQ6=1,"Leadership",IFERROR(INDEX(Lists!$X:$X,MATCH(TRIM($K6),Lists!$W:$W,0)),IF(OR(TRIM($K6)="",LOWER(TRIM($K6))="na"),IF(TRIM($G6)="","Unassigned",TRIM($G6)),TRIM($K6))))) -> Z Retail Backend | AQ6: =IF(TRIM($B6)="","",--OR(TRIM($K6)="Leadership",TRIM($J6)="Leadership")) -> FALSE | AR6: =IF(TRIM($B6)="","",IF(IFERROR(INDEX(Lists!$AQ$2:$AQ$11,MATCH(ROW(),Lists!$AN$2:$AN$11,0)),"")<>"",IFERROR(INDEX(Lists!$AQ$2:$AQ$11,MATCH(ROW(),Lists!$AN$2:$AN$11,0)),""),IF(ISNUMBER(SEARCH("head of ",$C6)),"Head of Technology",IF(ISNUMBER(SEARCH("TDD BP",$C6)),"Business Partner",IF(OR(ISNUMBER(SEARCH("domain architect",$C6)),ISNUMBER(SEARCH("enterprise architect",$C6))),"Domain Architect",IF(ISNUMBER(SEARCH("delivery man",$C6)),"Delivery Manager",IF(OR(ISNUMBER(SEARCH("technology manager",$C6)),ISNUMBER(SEARCH("technology manger",$C6)),ISNUMBER(SEARCH("tech manager",$C6))),"Technology Manager","Squad"))))))) -> Squad | AS6: =IF(TRIM($B6)="","",IFERROR(INDEX(Lists!$AA:$AA,MATCH($AP6,Lists!$Z:$Z,0)),$AP6)) -> Z Retail Backend | AT6: =IF(TRIM($B6)="","",IF(IFERROR(INDEX(Lists!$AP$2:$AP$11,MATCH(ROW(),Lists!$AN$2:$AN$11,0)),"")<>"",IFERROR(INDEX(Lists!$AP$2:$AP$11,MATCH(ROW(),Lists!$AN$2:$AN$11,0)),""),IF(OR(LEFT($AJ6,3)="COE",$AJ6="EGI"),$AP6,IF($AR6<>"Squad",$AR6,$AP6)))) -> Z Retail Backend
A7: 4534 | B7: Andrew Whitford | C7: Field Systems Operations Lead - WA | D7: Ephriam Adan | E7: Manager, AU Retail Operations | F7: Ampol Retail & Z | G7: Ampol Retail | H7: Ampol Retail, Technology | I7: Retail | J7: Store Operations | K7: Store Operations | M7: Australia | N7: CIA | O7: 1 | Q7: Permanent - Full Time | T7: 124740 | U7: 124740 | V7: 0.1 | W7: 0.055 | X7: 0.12 | Z7: 0.04 | AA7: =IF(TRIM($B7)="","",IF(N($AU7)>0,$AU7,IF(N($S7)>0,$S7*Lists!$AG$15*(1+N($Z7)),N($U7)*(1+N($V7)+N($W7)+N($X7)+N($Z7))+N($Y7)))) -> 164033.1 | AJ7: =IF(TRIM($B7)="","",IF(IFERROR(INDEX(Lists!$AO$2:$AO$11,MATCH(ROW(),Lists!$AN$2:$AN$11,0)),"")<>"",IFERROR(INDEX(Lists!$AO$2:$AO$11,MATCH(ROW(),Lists!$AN$2:$AN$11,0)),""),IFERROR(INDEX(Lists!$U:$U,MATCH(TRIM($I7),Lists!$T:$T,0)),TRIM($I7)))) -> Ampol Retail | AK7: =IF(ISNUMBER(SEARCH("vacant",$B7)),"Vacant","Filled") -> Filled | AL7: =IF($M7="NZ","NZ","AU") -> AU | AM7: =COUNTIF($AJ$2:$AJ7,$AJ7) -> 3 | AN7: =$AJ7&"|"&$AM7 -> Ampol Retail|3 | AP7: =IF(TRIM($B7)="","",IF($AQ7=1,"Leadership",IFERROR(INDEX(Lists!$X:$X,MATCH(TRIM($K7),Lists!$W:$W,0)),IF(OR(TRIM($K7)="",LOWER(TRIM($K7))="na"),IF(TRIM($G7)="","Unassigned",TRIM($G7)),TRIM($K7))))) -> Store Operations | AQ7: =IF(TRIM($B7)="","",--OR(TRIM($K7)="Leadership",TRIM($J7)="Leadership")) -> FALSE | AR7: =IF(TRIM($B7)="","",IF(IFERROR(INDEX(Lists!$AQ$2:$AQ$11,MATCH(ROW(),Lists!$AN$2:$AN$11,0)),"")<>"",IFERROR(INDEX(Lists!$AQ$2:$AQ$11,MATCH(ROW(),Lists!$AN$2:$AN$11,0)),""),IF(ISNUMBER(SEARCH("head of ",$C7)),"Head of Technology",IF(ISNUMBER(SEARCH("TDD BP",$C7)),"Business Partner",IF(OR(ISNUMBER(SEARCH("domain architect",$C7)),ISNUMBER(SEARCH("enterprise architect",$C7))),"Domain Architect",IF(ISNUMBER(SEARCH("delivery man",$C7)),"Delivery Manager",IF(OR(ISNUMBER(SEARCH("technology manager",$C7)),ISNUMBER(SEARCH("technology manger",$C7)),ISNUMBER(SEARCH("tech manager",$C7))),"Technology Manager","Squad"))))))) -> Squad | AS7: =IF(TRIM($B7)="","",IFERROR(INDEX(Lists!$AA:$AA,MATCH($AP7,Lists!$Z:$Z,0)),$AP7)) -> Store Operations | AT7: =IF(TRIM($B7)="","",IF(IFERROR(INDEX(Lists!$AP$2:$AP$11,MATCH(ROW(),Lists!$AN$2:$AN$11,0)),"")<>"",IFERROR(INDEX(Lists!$AP$2:$AP$11,MATCH(ROW(),Lists!$AN$2:$AN$11,0)),""),IF(OR(LEFT($AJ7,3)="COE",$AJ7="EGI"),$AP7,IF($AR7<>"Squad",$AR7,$AP7)))) -> Store Operations
A8: 111451 | B8: Aniket Banerji | C8: Deployment Lead | D8: Matthew Patane | E8: Release & Deployment Manager | F8: Ampol Retail & Z | G8: Ampol Retail | H8: Ampol Retail, Technology | I8: Retail | J8: Store Operations | K8: Deployment | M8: Australia | N8: CIB | O8: 1 | Q8: Temporary - Full Time | T8: 150000 | U8: 150000 | V8: 0.12 | W8: 0.055 | X8: 0.12 | Z8: 0.04 | AA8: =IF(TRIM($B8)="","",IF(N($AU8)>0,$AU8,IF(N($S8)>0,$S8*Lists!$AG$15*(1+N($Z8)),N($U8)*(1+N($V8)+N($W8)+N($X8)+N($Z8))+N($Y8)))) -> 200250 | AJ8: =IF(TRIM($B8)="","",IF(IFERROR(INDEX(Lists!$AO$2:$AO$11,MATCH(ROW(),Lists!$AN$2:$AN$11,0)),"")<>"",IFERROR(INDEX(Lists!$AO$2:$AO$11,MATCH(ROW(),Lists!$AN$2:$AN$11,0)),""),IFERROR(INDEX(Lists!$U:$U,MATCH(TRIM($I8),Lists!$T:$T,0)),TRIM($I8)))) -> Ampol Retail | AK8: =IF(ISNUMBER(SEARCH("vacant",$B8)),"Vacant","Filled") -> Filled | AL8: =IF($M8="NZ","NZ","AU") -> AU | AM8: =COUNTIF($AJ$2:$AJ8,$AJ8) -> 4 | AN8: =$AJ8&"|"&$AM8 -> Ampol Retail|4 | AP8: =IF(TRIM($B8)="","",IF($AQ8=1,"Leadership",IFERROR(INDEX(Lists!$X:$X,MATCH(TRIM($K8),Lists!$W:$W,0)),IF(OR(TRIM($K8)="",LOWER(TRIM($K8))="na"),IF(TRIM($G8)="","Unassigned",TRIM($G8)),TRIM($K8))))) -> Deployment | AQ8: =IF(TRIM($B8)="","",--OR(TRIM($K8)="Leadership",TRIM($J8)="Leadership")) -> FALSE | AR8: =IF(TRIM($B8)="","",IF(IFERROR(INDEX(Lists!$AQ$2:$AQ$11,MATCH(ROW(),Lists!$AN$2:$AN$11,0)),"")<>"",IFERROR(INDEX(Lists!$AQ$2:$AQ$11,MATCH(ROW(),Lists!$AN$2:$AN$11,0)),""),IF(ISNUMBER(SEARCH("head of ",$C8)),"Head of Technology",IF(ISNUMBER(SEARCH("TDD BP",$C8)),"Business Partner",IF(OR(ISNUMBER(SEARCH("domain architect",$C8)),ISNUMBER(SEARCH("enterprise architect",$C8))),"Domain Architect",IF(ISNUMBER(SEARCH("delivery man",$C8)),"Delivery Manager",IF(OR(ISNUMBER(SEARCH("technology manager",$C8)),ISNUMBER(SEARCH("technology manger",$C8)),ISNUMBER(SEARCH("tech manager",$C8))),"Technology Manager","Squad"))))))) -> Squad | AS8: =IF(TRIM($B8)="","",IFERROR(INDEX(Lists!$AA:$AA,MATCH($AP8,Lists!$Z:$Z,0)),$AP8)) -> Deployment | AT8: =IF(TRIM($B8)="","",IF(IFERROR(INDEX(Lists!$AP$2:$AP$11,MATCH(ROW(),Lists!$AN$2:$AN$11,0)),"")<>"",IFERROR(INDEX(Lists!$AP$2:$AP$11,MATCH(ROW(),Lists!$AN$2:$AN$11,0)),""),IF(OR(LEFT($AJ8,3)="COE",$AJ8="EGI"),$AP8,IF($AR8<>"Squad",$AR8,$AP8)))) -> Deployment
