Workbook
Name BPTCat: Lists!$E$2:$E$4
Name CYBCat: Lists!$G$2:$G$4
Name OnOff: Lists!$C$2:$C$3
Name SADCat: Lists!$F$2:$F$4
Name SquadSizes: Lists!$B$2:$B$5
Name SquadTypes: Lists!$A$2:$A$8
Name SupportPct: Lists!$D$2:$D$10

Sheet Exec Summary
B2: TDD Operating Model - Executive Summary
B4: Why this workbook exists
B5: Purpose: each GM designed a new operating model against set squad archetypes (type x size = people and cost). This workbook prices the archetypes and checks the actual design against them.
B6: The test: can each portfolio fund its archetype cost (TDD + business)? If yes, live within it. If not, start with the vacancies (4.x GM tabs), then archetype size (1.x dropdowns).
B7: Each portfolio tab (1.x) shows the squads, sizes, support %, budget draw-downs and what is left to fund.
B8: Next step: agree funding for what is left to fund, and decide which vacancies to hire or hold.
B10: How the model is built - key decisions
B11: Squads are priced from the archetype library on 0.3 Squad Archetypes (type x size). Offshore is priced at the offshore rate set on 0.3 Squad Archetypes.
B12: Each portfolio pays one overhead: Head of Tech, Business Partner and Domain Architect shares, and leadership - rates on 0.2 Data Config.
B13: Strategic programs (AmPOS, CTRM, EGI) are priced at their entered cost. EGI is funded from Significant Items, not overheads.
B14: TDD Cyber is priced from its actual roles on 2.3 Cyber Roles, not archetypes.
B15: Business Partner & Domain Architect money sits inside the portfolio overheads, so it is taken out of the COE total - never counted twice.
... B18: The TDD budget
B19: Total TDD people budget ($m) | C19: ='0.2 Data Config'!$E$27 -> 53.8
B20: Allocated to portfolios + COEs ($m) | C20: ='2.5 Group Summary'!$C$30 -> 43.5
B21: Not yet allocated ($m) | C21: ='0.2 Data Config'!$E$27-'2.5 Group Summary'!$C$30 -> 10.3
B22: What the archetype model costs
B23: TDD Cost - funded by TDD ($m) | C23: ='2.5 Group Summary'!$D$24 -> 62.417348
B24: Funded outside TDD ($m) | C24: ='2.5 Group Summary'!$G$24 -> 30.672
B25: Less: BP & Domain Architect already funded in portfolio overheads ($m) | C25: ='2.6 Total Cost'!$C$23 -> -3.432
B26: Total archetype model cost ($m) | C26: ='2.6 Total Cost'!$C$24 -> 89.657348
B27: of which TDD pays - after the double-count ($m) | C27: ='2.5 Group Summary'!$D$24+'2.6 Total Cost'!$C$23 -> 58.985348
B28: Left to fund - portfolios + COEs ($m) | C28: ='2.5 Group Summary'!$I$24 -> 21.113297
B29: What the org actually costs today
B30: All roles today - filled + vacant ($m) | C30: ='2.6 Total Cost'!$I$24 -> 118.19871
B31: of which filled ($m) | C31: ='2.6 Total Cost'!$E$24 -> 84.832646
B32: of which vacant ($m) | C32: ='2.6 Total Cost'!$G$24 -> 33.36606
B33: Difference vs archetype model ($m) | C33: ='2.6 Total Cost'!$K$24 -> 28.541358
B35: The people - archetypes vs the org
B36: Roles the archetypes allow - squads at their set sizes | C36: ='2.7 Squad Detail'!$G$4 -> 328.5
B37: Roles actually raised in those squads - filled + vacant | C37: ='2.7 Squad Detail'!$G$95+'2.7 Squad Detail'!$K$95 -> 328
B38: Roles raised beyond the archetypes | C38: ='2.7 Squad Detail'!$H$4 -> -0.5
B39: Roles in squads priced outside archetypes (AmPOS, EGI, cyber) | C39: ='2.7 Squad Detail'!$J$95-'2.7 Squad Detail'!$G$95-'2.7 Squad Detail'!$K$95 -> 94
B40: All org roles (squads + leadership + COEs + unmapped) | C40: ='2.7 Squad Detail'!$C$4 -> 536
B41: Filled - people in roles today | C41: ='2.7 Squad Detail'!$D$4 -> 370
B42: Vacant - raised, not yet hired | C42: ='2.7 Squad Detail'!$E$4 -> 166
B43: of which squad roles - the GM hire or hold lever | C43: =COUNTIFS(Squads!$Q:$Q,"Squad",Squads!$R:$R,"Vacant")+COUNTIFS(Squads!$Q:$Q,"Strategic Program",Squads!$R:$R,"Vacant") -> 124
B44: of which leadership, COE and unmapped roles | C44: ='2.7 Squad Detail'!$E$4-COUNTIFS(Squads!$Q:$Q,"Squad",Squads!$R:$R,"Vacant")-COUNTIFS(Squads!$Q:$Q,"Strategic Program",Squads!$R:$R,"Vacant") -> 42
B45: Vacancy rate | C45: ='2.7 Squad Detail'!$F$4 -> 0.30970149
B46: Vacant = open roles in the raw data. Sheet2 status updates (Paused, ring-fenced) show on 2.1 to 2.3 and 5.0.
...

Sheet - INPUTS -
B2: INPUTS >>>

Sheet 0.0 Guide
B2: How this workbook flows
B4: The flow - two streams that meet in the middle
B5: STREAM 1, THE DESIGN: 0.1 Budget Table (the money Finance gave) feeds 0.2 Data Config (how it is allocated per portfolio, AU and NZ, plus overhead rates and the four $2m COE allocations). 0.3 Squad Archetypes prices the contract (type x size). Each GM's design sits on 1.1 to 1.11, priced from 0.3 and funded per 0.2.
B6: STREAM 2, THE ORG: the Squads tab holds every role actually raised (536, filled and vacant) and its model mapping. Sheet2 holds the updated rosters for BP&T, SA&D, Cyber and EGI. Added data holds what each person actually costs.
B7: THE ROLL-UP: the COE rosters (2.1 BP&T, 2.2 SA&D, 2.3 Cyber Roles) and their funding roll into 2.4 COE Summary. 2.5 Group Summary answers: can the budgets fund the design (with AU and NZ variance). 2.6 Total Cost is the test: the design vs what the org actually costs. 2.7 Squad Detail is the same test squad by squad.
B8: THE DECISIONS: tabs 4.1 to 4.14 - every role in the organisation appears on exactly one of them. GMs mark Hire or Hold on every vacancy. The Exec Summary tells the result. 5.0 Data QA is the evidence behind every number.
B9: What you can edit (yellow cells are inputs)
B10: 0.2 Data Config: budgets, rates, allocations. | 0.3 Squad Archetypes: prices and the offshore rate. | 1.x: squad type, size, On/Off, support %, Fund (AU or NZ). | 4.x: the Hire or Hold Call cells. | Squads / Sheet2 / Added data: your source data.
B11: If you change X, Y updates
B12: A squad's type, size, On/Off, support % or Fund toggle on 1.x updates 2.5, 2.6, 2.7 and the Exec Summary.
B13: A status or mapping in the Squads tab updates every role count: 2.6, 2.7 and the 4.x tabs.
B14: A person or cost in Sheet2 updates 2.1, 2.2, 2.3, the EGI roster, 2.4, the COE lines of 2.5 and 2.6, and tabs 4.12 to 4.14.
... B22: Every row labelled Check must read 0. All reconciliations, the Sheet2 update log, the mapping change log and the raw data audit live on 5.0 Data QA. Every role has exactly one 4.x home - if one were missed, the checks would not foot.

Sheet 0.1 Budget Table (Fin)
B3: BUSINESS | C3: EGM Sponsor | D3: GM Sponsor | E3: Domain Architect | F3: HO Technology | G3: Lights-on | M3: Depreciation | N3: Initiatives | O3: Sig Items | P3: Capex | Q3: Total Budget | S3: Existing | T3: Aligned Delivery | U3: Aligned COE's | V3: Total Budget
B4: SEGMENT | G4: People | H4: HW | I4: SW | J4: Network | K4: Vendor | L4: Sub-Total | Q4: FY2026 | V4: FY2026
B5: TDD Corporate (1) | C5: Brad Blyth | G5: 35.2 | H5: 2.9 | I5: 25.6 | J5: 2.1 | K5: 13.1 | L5: =SUM(G5:K5) -> 78.9 | M5: 5.8 | N5: 3 | O5: 20.2 | P5: 4.9 | Q5: =SUM(L5:P5) -> 112.8 | U5: =SUM(W25:W29) -> 91.6 | V5: =SUM(S5:U5) -> 91.6
B6: Z-Energy (2) | C6: Lindis Jones | D6: Vance Anderson | G6: 17.6 | H6: 19.8 | I6: 11.6 | J6: 0.6 | K6: 2.6 | L6: =SUM(G6:K6) -> 52.2 | M6: 11.3 | N6: 1.4 | O6: - | P6: 11.7 | Q6: =SUM(L6:P6) -> 76.6 | S6: =Q6 -> 76.6 | V6: =SUM(S6:U6) -> 76.6
B7: EnergySolutions | C7: Brent Merrick | D7: Roanne Steele | G7: 1 | H7: 1.5 | I7: 1.4 | L7: =SUM(G7:K7) -> 3.9 | N7: 1 | P7: 2.3 | Q7: =SUM(L7:P7) -> 7.2 | S7: =Q7 -> 7.2 | V7: =SUM(S7:U7) -> 7.2 | Y7: =SUM(L9,N9,O9,P9) -> 33.8
B8: Commercial Fuels | C8: Brent Merrick | D8: Roanne Steele | H8: 2.5 | I8: 9.4 | J8: 1.5 | L8: =SUM(G8:K8) -> 13.4 | N8: 6.1 | O8: 14.2 | P8: 6.8 | Q8: =SUM(L8:P8) -> 40.5 | S8: =Q8 -> 40.5 | T8: =S19 -> 1.2 | V8: =SUM(S8:U8) -> 41.7
B9: Retail | C9: Kate Thomson | D9: Roanne Steele | H9: 5.3 | I9: 6.4 | J9: 2.2 | L9: =SUM(G9:K9) -> 13.9 | N9: 1.3 | O9: 6.8 | P9: 11.8 | Q9: =SUM(L9:P9) -> 33.8 | S9: =Q9 -> 33.8 | T9: =S20 -> 5.2 | V9: =SUM(S9:U9) -> 39
B10: Infrastructure | C10: Michelle Bardy | D10: Roanne Steele | H10: 1.9 | I10: 2 | L10: =SUM(G10:K10) -> 3.9 | N10: 0.4 | P10: 5 | Q10: =SUM(L10:P10) -> 9.3 | S10: =Q10 -> 9.3 | T10: =S21 -> 2.2 | V10: =SUM(S10:U10) -> 11.5
B11: Corporate Finance | C11: Greg Barnes | D11: Emily Mogic | H11: 0.5 | I11: 2.1 | L11: =SUM(G11:K11) -> 2.6 | N11: 0.9 | Q11: =SUM(L11:P11) -> 3.5 | S11: =Q11 -> 3.5 | T11: =S22 -> 9 | V11: =SUM(S11:U11) -> 12.5
B12: P&C | C12: Meaghan Davis | D12: Emily Mogic | H12: 0.3 | I12: 1.8 | L12: =SUM(G12:K12) -> 2.1 | N12: 2 | O12: 1.4 | P12: 0.3 | Q12: =SUM(L12:P12) -> 5.8 | S12: =Q12 -> 5.8 | T12: =S23 -> 0 | V12: =SUM(S12:U12) -> 5.8
B13: Customer | C13: Kate Thomson | D13: Vance Anderson | H13: 0.1 | I13: 1.6 | L13: =SUM(G13:K13) -> 1.7 | O13: 5 | P13: 5 | Q13: =SUM(L13:P13) -> 11.7 | S13: =Q13 -> 11.7 | T13: =S24 -> 3.7 | V13: =SUM(S13:U13) -> 15.4
B14: Total Technology | G14: =SUM(G5:G13) -> 53.8 | H14: =SUM(H5:H13) -> 34.8 | I14: =SUM(I5:I13) -> 61.9 | J14: =SUM(J5:J13) -> 6.4 | K14: =SUM(K5:K13) -> 15.7 | L14: =SUM(L5:L13) -> 172.6 | M14: =SUM(M5:M13) -> 17.1 | N14: =SUM(N5:N13) -> 16.1 | ... Q14: =SUM(Q5:Q13) -> 301.2 | S14: =SUM(S6:S13) -> 188.4 | T14: =SUM(T8:T13) -> 21.3 | U14: =U5 -> 91.6 | V14: =SUM(V5:V13) -> 301.3
B17: BUSINESS SEGMENT | E17: EGM Sponsor | F17: GM Sponsor | G17: Domain Architect | H17: HO Technology | I17: Lights-on | O17: Depreciation | P17: Initiatives | Q17: Sig Items | R17: Capex | S17: Total Budget | U17: Existing | V17: Aligned Delivery | W17: Aligned | X17: Total Budget
I18: People | J18: HW | K18: SW | L18: Network | M18: Vendor | N18: Sub-Total | S18: FY2026 | W18: COE's | X18: FY2026
D19: Commercial Fuels | I19: 1.2 | J19: 0 | K19: 0 | L19: - | M19: - | N19: =SUM(I19:M19) -> 1.2 | O19: - | S19: =SUM(N19:R19) -> 1.2 | X19: -
D20: Retail | I20: 3.4 | J20: 0.2 | K20: 0.9 | L20: - | M20: 0.7 | N20: =SUM(I20:M20) -> 5.2 | O20: - | S20: =SUM(N20:R20) -> 5.2 | X20: -
D21: Infrastructure | I21: 2 | J21: - | K21: 0.2 | L21: - | M21: - | N21: =SUM(I21:M21) -> 2.2 | O21: - | S21: =SUM(N21:R21) -> 2.2 | X21: -
D22: Corporate Finance | I22: 1.3 | J22: - | K22: 4.2 | L22: - | M22: 3.5 | N22: =SUM(I22:M22) -> 9 | O22: - | S22: =SUM(N22:R22) -> 9 | X22: -
D23: P&C | I23: 0 | J23: - | K23: - | L23: - | M23: - | N23: =SUM(I23:M23) -> 0 | O23: - | S23: =SUM(N23:R23) -> 0 | X23: -
D24: Customer | I24: 1.2 | J24: - | K24: 0.6 | L24: 0 | M24: 1 | N24: =SUM(I24:M24) -> 2.8 | O24: 0.9 | S24: =SUM(N24:R24) -> 3.7 | X24: -
D25: TDD | F25: Emily Mogic | I25: 4.5 | J25: 2.5 | K25: 14.5 | L25: 0 | M25: 0.8 | N25: =SUM(I25:M25) -> 22.3 | O25: 4.9 | S25: =SUM(N25:R25) -> 27.2 | W25: =S25 -> 27.2 | X25: =W25 -> 27.2
D26: TDDEGM | F26: Brad Blyth | I26: 6.5 | J26: - | K26: - | L26: - | M26: 3.6 | N26: =SUM(I26:M26) -> 10.1 | O26: - | P26: 3 | Q26: 20.2 | R26: 4.9 | S26: =SUM(N26:R26) -> 38.2 | W26: =S26 -> 38.2 | X26: =W26 -> 38.2
D27: Strategy, Architecture and Data | F27: Matt Ashley | I27: 5.3 | J27: - | K27: 1 | L27: - | M27: 0.6 | N27: =SUM(I27:M27) -> 6.9 | O27: - | S27: =SUM(N27:R27) -> 6.9 | W27: =S27 -> 6.9 | X27: =W27 -> 6.9
D28: Cyber Risk and Operations | F28: Frances Bouzo | I28: 7.6 | J28: 0.2 | K28: 4.3 | L28: 2 | M28: 2.9 | N28: =SUM(I28:M28) -> 17 | O28: - | S28: =SUM(N28:R28) -> 17 | W28: =S28 -> 17 | X28: =W28 -> 17
D29: Business Partnering and Governance | F29: Michael Schofield | I29: 2.3 | J29: - | K29: - | L29: - | M29: - | N29: =SUM(I29:M29) -> 2.3 | O29: - | S29: =SUM(N29:R29) -> 2.3 | W29: =S29 -> 2.3 | X29: =W29 -> 2.3
B30: TDD Corporate (1) | E30: Brad Blyth | I30: =G5 -> 35.2 | J30: =H5 -> 2.9 | K30: =I5 -> 25.6 | L30: =J5 -> 2.1 | M30: =K5 -> 13.1 | N30: =L5 -> 78.9 | O30: =M5 -> 5.8 | P30: =N5 -> 3 | ... S30: =Q5 -> 112.8 | W30: =U5 -> 91.6 | X30: =W30 -> 91.6
C31: Z-Energy (Direct TDD) | I31: 17.6 | J31: 12.1 | K31: 6.3 | L31: 0.6 | M31: 2.6 | N31: 39.3 | O31: 11.3 | P31: 1.4 | R31: 11.7 | S31: 63.7 | X31: -
C32: Z-Energy (Other IT Spend for Supplies, Customer) | J32: 7.6 | K32: 5.3 | N32: 13 | S32: 13 | X32: -
B33: Z-Energy (2) | E33: Lindis Jones | F33: Vance Anderson | I33: =G6 -> 17.6 | J33: =H6 -> 19.8 | K33: =I6 -> 11.6 | L33: =J6 -> 0.6 | M33: =K6 -> 2.6 | N33: =L6 -> 52.2 | O33: =M6 -> 11.3 | P33: =N6 -> 1.4 | ... S33: =Q6 -> 76.6 | U33: =S6 -> 76.6 | X33: =U33 -> 76.6

Sheet 0.2 Data Config
B2: Data Config
B4: TDD Budget Allocation ($m) | I4: Portfolio Overhead (roles, $m)
B5: Portfolio | C5: AU | D5: NZ | E5: Total | F5: Spend | G5: Variance | I5: Role | J5: Cost ($m) | K5: Allocation % | L5: Portfolio cost ($m)
B6: COE - Strategy Architecture | C6: 1.5 | D6: 0.5 | E6: =C6+D6 -> 2 | F6: ='2.4 COE Summary'!$D$8 -> 4.320561 | G6: =SUM(E6-F6) -> -2.320561 | I6: Head of Tech | J6: 0.275 | K6: 0.5 | L6: =J6*K6 -> 0.1375
B7: COE - Cyber, Risk & Service Ops (rolled into 1.11 TDD Cyber) | C7: 0 | D7: 0 | E7: =C7+D7 -> 0 | F7: ='2.4 COE Summary'!$D$9 -> 0 | G7: =SUM(E7-F7) -> 0 | I7: Business Partner | J7: 0.43 | K7: 0.4 | L7: =J7*K7 -> 0.172
B8: COE - Transformation | C8: 1.5 | D8: 0.5 | E8: =C8+D8 -> 2 | F8: ='2.4 COE Summary'!$D$10 -> 3.1079992 | G8: =SUM(E8-F8) -> -1.1079992 | I8: Domain Architect | J8: 0.28 | K8: 0.5 | L8: =J8*K8 -> 0.14
B9: COE - Business Partnering | C9: 1.5 | D9: 0.5 | E9: =C9+D9 -> 2 | F9: ='2.4 COE Summary'!$D$11 -> 3.2925626 | G9: =SUM(E9-F9) -> -1.2925626 | I9: Leadership Overhead | J9: 1 | K9: 0.3 | L9: =J9*K9 -> 0.3
B10: COE - Data | C10: 1.5 | D10: 0.5 | E10: =C10+D10 -> 2 | F10: ='2.4 COE Summary'!$D$12 -> 2.2327366 | G10: =SUM(E10-F10) -> -0.23273662 | I10: Portfolio overhead subtotal | L10: =SUM(L6:L9) -> 0.7495
B11: Ampol Retail | C11: 2.5 | D11: 0 | E11: =C11+D11 -> 2.5 | F11: ='1.1 Ampol Retail'!$C$9 -> 5.6265 | G11: =SUM(E11-F11) -> -3.1265
B12: Z Retail | C12: 0 | D12: 2.5 | E12: =C12+D12 -> 2.5 | F12: ='1.10 Z Retail'!$C$9 -> 5.3995 | G12: =SUM(E12-F12) -> -2.8995 | I12: Platform Overhead (roles, $m)
B13: Ampol Customer | C13: 2.5 | D13: 0 | E13: =C13+D13 -> 2.5 | F13: ='1.2 Customer'!$C$9 -> 9.0245 | G13: =SUM(E13:E14)-F13 -> -2.5245 | I13: Role | J13: Cost ($m) | K13: Alloc % | L13: Platform cost ($m)
B14: Z Customer | C14: 0 | D14: 4 | E14: =C14+D14 -> 4 | I14: Delivery Manager | J14: 0.28 | K14: 0.3 | L14: =J14*K14 -> 0.084
B15: Commercial Fuels | C15: 2.5 | D15: 0 | E15: =C15+D15 -> 2.5 | F15: ='1.9 Commercial Fuels'!C9 -> 2.0845 | G15: =SUM(E15-F15) -> 0.4155 | I15: Tech Manager | J15: 0.27 | K15: 0.3 | L15: =J15*K15 -> 0.081
B16: Energy Solutions & B2B | C16: 2.5 | D16: 0 | E16: =C16+D16 -> 2.5 | F16: ='1.8 Energy Solutions & B2B'!$C$9 -> 2.5095 | G16: =SUM(E16-F16) -> -0.0095 | I16: Platform overhead subtotal (per platform) | L16: =SUM(L14:L15) -> 0.165
B17: Infrastructure | C17: 2.5 | D17: 0 | E17: =C17+D17 -> 2.5 | F17: ='1.7 Infrastructure'!$C$10 -> 2.5245 | G17: =SUM(E17-F17) -> -0.0245
B18: P&C | C18: 1 | D18: 1 | E18: =C18+D18 -> 2 | F18: ='1.5 P&C'!$C$9 -> 1.2745 | G18: =SUM(E18-F18) -> 0.7255
B19: Finance | C19: 1 | D19: 1 | E19: =C19+D19 -> 2 | F19: ='1.6 Finance'!$C$9 -> 1.4145 | G19: =SUM(E19-F19) -> 0.5855
B20: Legal | C20: 0 | D20: 0 | E20: =C20+D20 -> 0
B21: TDD | C21: 4.5 | D21: 1 | E21: =C21+D21 -> 5.5 | F21: ='1.4 TDD Group Functions'!$C$9 -> 3.6645 | G21: =SUM(E21-F21) -> 1.8355
B22: TDD Data | C22: 2.5 | D22: 1 | E22: =C22+D22 -> 3.5 | F22: ='1.3 Enterprise Data'!$C$9 -> 4.1105 | G22: =SUM(E22-F22) -> -0.6105
B23: TDD Cyber | C23: 2.5 | D23: 1 | E23: =C23+D23 -> 3.5 | F23: ='1.11 TDD Cyber'!$C$9 -> 11.830489 | G23: =SUM(E23-F23) -> -8.330489
B24: EG | C24: 0 | D24: 0 | E24: =C24+D24 -> 0
B25: EGI | C25: 0 | D25: 0 | E25: =C25+D25 -> 0
B26: Total | C26: =SUM(C6:C25) -> 30 | D26: =SUM(D6:D25) -> 13.5 | E26: =SUM(E6:E25) -> 43.5 | F26: =SUM(F6:F25) -> 62.417348 | G26: =SUM(G6:G25) -> -18.917348
B27: Budget | C27: ='0.1 Budget Table (Fin)'!G5 +1 -> 36.2 | D27: ='0.1 Budget Table (Fin)'!G6 -> 17.6 | E27: ='0.1 Budget Table (Fin)'!G14 -> 53.8
B28: Variance | C28: =C27-C26 -> 6.2 | D28: =D27-D26 -> 4.1 | E28: =E27-E26 -> 10.3

Sheet 0.3 Squad Archetypes
C2: Squad Cost Lookup
A4: Key | C4: Squad Type | D4: Size | E4: Archetype | F4: # of roles | G4: Onshore Cost ($m) | H4: Offshore Cost ($m) | I4: Use When | K4: Offshore rate
A5: Engineering|S | C5: Engineering | D5: S | E5: Lean build squad | F5: 4.5 | G5: 0.8 | H5: =G5*$K$5 -> 0.32 | I5: Simple platforms, incremental changes | K5: 0.4
A6: Engineering|M | C6: Engineering | D6: M | E6: Standard Engineering Squad | F6: 9 | G6: 2 | H6: =G6*$K$5 -> 0.8 | I6: Medium complexity platforms
A7: Engineering|L | C7: Engineering | D7: L | E7: High-scale squad | F7: 12 | G7: 2.7 | H7: =G7*$K$5 -> 1.08 | I7: Scalable platforms, high volume output
A8: Configuration / Integration|XS | C8: Configuration / Integration | D8: XS | E8: MS Squad | F8: 1 | G8: 3.2 | H8: =G8*$K$5 -> 1.28 | I8: Work managed by a vendor
A9: Configuration / Integration|S | C9: Configuration / Integration | D9: S | E9: Simple Configuration Squad | F9: 6 | G9: 0.4 | H9: =G9*$K$5 -> 0.16 | I9: Simple configuration, limited integration
A10: Configuration / Integration|M | C10: Configuration / Integration | D10: M | E10: Standard Configuration Squad | F10: 9 | G10: 1.4 | H10: =G10*$K$5 -> 0.56 | I10: Standard configuration, medium complexity
A11: Configuration / Integration|L | C11: Configuration / Integration | D11: L | E11: Complex Integration Squad | F11: 14 | G11: 2.1 | H11: =G11*$K$5 -> 0.84 | I11: Complex config or custom build, high integration
A12: Product|S | C12: Product | D12: S | E12: Lean Product Squad | F12: 5.5 | G12: 1.3 | H12: =G12*$K$5 -> 0.52 | I12: Early stage product testing or low complexity
A13: Product|M | C13: Product | D13: M | E13: Balanced Product Squad | F13: 8.5 | G13: 1.9 | H13: =G13*$K$5 -> 0.76 | I13: Ongoing product development, moderate complexity
A14: Product|L | C14: Product | D14: L | E14: Scaled Product Squad | F14: 12 | G14: 2.8 | H14: =G14*$K$5 -> 1.12 | I14: Mature product
A15: Operations|S | C15: Operations | D15: S | E15: Lean operations squad | F15: 4 | G15: 0.8 | H15: =G15*$K$5 -> 0.32 | I15: Low change, stable platforms
A16: Operations|M | C16: Operations | D16: M | E16: Balanced operations squad | F16: 6 | G16: 1.4 | H16: =G16*$K$5 -> 0.56 | I16: Moderate support plus improvements
A17: Operations|L | C17: Operations | D17: L | E17: High demand operations squad | F17: 10 | G17: 2.3 | H17: =G17*$K$5 -> 0.92 | I17: High ticket volume, critical systems
... A23: Build and Run|L | C23: Build and Run | D23: L | E23: Scaled build and run squad | F23: 13 | G23: 2.8 | H23: =G23*$K$5 -> 1.12 | I23: High traffic or business critical, 24/7
C24: Exceptions (will need to incl. rules) | E24: TBC | I24: TBC
C27: Exception for ES EVCI - 6 FTE vs 4.5 FTE

Sheet 0.4 Presentation Pack
B3: BUSINESS SEGMENTS | C3: TDD GM | D3: TOTAL YTD (Jun-2026) | I3: OPEX: LIGHTS ON + INITIATIVES (YTD) | N3: OPEX: LIGHTS ON (YTD) | S3: OPEX: INITIATIVES (YTD) | X3: OPEX: DEPRECIATION (YTD) | AC3: SIGNIFICANT ITEMS (YTD) | AH3: CAPEX (YTD) | AN3: FY2026
D4: A | E4: B | F4: V | G4: V % | H4: Trend | I4: A | J4: B | K4: V | L4: V % | M4: Trend | N4: A | O4: B | P4: V | R4: Trend | S4: A | T4: B | U4: V | V4: V % | W4: Trend | X4: A | Y4: B | Z4: V | AA4: V % | AB4: Trend | AC4: A | AD4: B | AE4: V | AF4: V % | AG4: Trend | AH4: A | AI4: B | AJ4: V | AK4: V % | AL4: Trend | AN4: F | AO4: B | AP4: V | AR4: Trend
A5: TDD (Corporate)1 | B5: TDD (Corporate)1 | C5: Brad Blyth Greg Cassis | D5: =I5+AC5+AH5+X5 -> 53.575006 | E5: =J5+AD5+AI5+Y5 -> 56.158125 | F5: =E5-D5 -> 2.5831189 | G5: =IFERROR(F5/E5,"-") -> 0.045997243 | H5: G | I5: 41.773797 | J5: 41.933694 | K5: =J5-I5 -> 0.15989672 | L5: =IFERROR(K5/J5,"-") -> 0.0038130846 | M5: G | N5: =I5-S5 -> 40.972956 | O5: =J5-T5 -> 40.433694 | P5: =O5-N5 -> -0.53926205 | Q5: =IFERROR(P5/O5,"-") -> -0.013336947 | R5: A | S5: 0.80084123 | T5: 1.5 | U5: =T5-S5 -> 0.69915877 | V5: =IFERROR(U5/T5,"-") -> 0.46610585 | W5: G | X5: 2.7852211 | Y5: 2.9338979 | Z5: =Y5-X5 -> 0.14867679 | AA5: =IFERROR(Z5/Y5,"-") -> 0.050675516 | AB5: G | AC5: 8.8400082 | AD5: 9.2622 | AE5: =AD5-AC5 -> 0.4221918 | AF5: =IFERROR(AE5/AD5,"-") -> 0.045582237 | AG5: G | AH5: 0.17597979 | AI5: 2.0283334 | AJ5: =AI5-AH5 -> 1.8523536 | AK5: =IFERROR(AJ5/AI5,"-") -> 0.91323922 | AL5: G | AN5: =I21+AC21+AH21+X21 -> 117.95714 | AO5: =J21+AD21+AI21+Y21 -> 112.75951 | AP5: =AO5-AN5 -> -5.1976273 | AQ5: =IFERROR(AP5/AO5,"-") -> -0.046094801 | AR5: A
A6: Z-Energy | B6: Z- Energy | C6: Vance Anderson Harley Giles | D6: =I6+AC6+AH6+X6 -> 35.257858 | E6: =J6+AD6+AI6+Y6 -> 38.25416 | F6: =E6-D6 -> 2.9963016 | G6: =IFERROR(F6/E6,"-") -> 0.078326164 | H6: G | I6: 26.455513 | J6: 26.80099 | K6: =J6-I6 -> 0.34547723 | L6: =IFERROR(K6/J6,"-") -> 0.012890465 | M6: G | N6: =I6-S6 -> 26.455513 | O6: =J6-T6 -> 26.07787 | P6: =O6-N6 -> -0.37764277 | Q6: =IFERROR(P6/O6,"-") -> -0.01448135 | R6: A | S6: 0 | T6: 0.72312 | U6: =T6-S6 -> 0.72312 | V6: =IFERROR(U6/T6,"-") -> 1 | W6: G | X6: 4.8357552 | Y6: 5.1436863 | Z6: =Y6-X6 -> 0.30793102 | AA6: =IFERROR(Z6/Y6,"-") -> 0.059865825 | AB6: G | AC6: 0 | AD6: 0 | AE6: =AD6-AC6 -> 0 | AF6: =IFERROR(AE6/AD6,"-") -> - | AH6: 3.9665899 | AI6: 6.3094833 | AJ6: =AI6-AH6 -> 2.3428933 | AK6: =IFERROR(AJ6/AI6,"-") -> 0.37132888 | AL6: G | AN6: =I22+AC22+AH22+X22 -> 73.108391 | AO6: =J22+AD22+AI22+Y22 -> 76.703514 | AP6: =AO6-AN6 -> 3.5951226 | AQ6: =IFERROR(AP6/AO6,"-") -> 0.046870376 | AR6: G
A7: Commercial Fuels | B7: Commercial Fuels | C7: Roanne Steele | D7: =I7+AC7+AH7+X7 -> 12.401562 | E7: =J7+AD7+AI7+Y7 -> 18.777378 | F7: =E7-D7 -> 6.3758153 | G7: =IFERROR(F7/E7,"-") -> 0.3395477 | H7: G | I7: 7.1072414 | J7: 8.2847223 | K7: =J7-I7 -> 1.1774809 | L7: =IFERROR(K7/J7,"-") -> 0.14212678 | M7: G | N7: =I7-S7 -> 5.0186846 | O7: =J7-T7 -> 5.3538618 | P7: =O7-N7 -> 0.33517727 | Q7: =IFERROR(P7/O7,"-") -> 0.062604767 | R7: G | S7: 2.0885568 | T7: 2.9308605 | U7: =T7-S7 -> 0.84230361 | V7: =IFERROR(U7/T7,"-") -> 0.28739124 | W7: G | Z7: =Y7-X7 -> 0 | AA7: =IFERROR(Z7/Y7,"-") -> - | AC7: 4.7285415 | AD7: 7.109604 | AE7: =AD7-AC7 -> 2.3810625 | AF7: =IFERROR(AE7/AD7,"-") -> 0.3349079 | AG7: G | AH7: 0.56577941 | AI7: 3.3830513 | AJ7: =AI7-AH7 -> 2.8172719 | AK7: =IFERROR(AJ7/AI7,"-") -> 0.83276062 | AL7: G | AN7: =I23+AC23+AH23+X23 -> 32.768998 | AO7: =J23+AD23+AI23+Y23 -> 40.534223 | AP7: =AO7-AN7 -> 7.7652255 | AQ7: =IFERROR(AP7/AO7,"-") -> 0.19157208 | AR7: G
A8: Retail | B8: Retail | C8: Vance Anderson | D8: =I8+AC8+AH8+X8 -> 14.290549 | E8: =J8+AD8+AI8+Y8 -> 18.065295 | F8: =E8-D8 -> 3.7747465 | G8: =IFERROR(F8/E8,"-") -> 0.20895017 | H8: G | I8: 6.854453 | J8: 7.0852951 | K8: =J8-I8 -> 0.23084214 | L8: =IFERROR(K8/J8,"-") -> 0.032580455 | M8: G | N8: =I8-S8 -> 6.4596074 | O8: =J8-T8 -> 6.4302951 | P8: =O8-N8 -> -0.02931227 | Q8: =IFERROR(P8/O8,"-") -> -0.0045584642 | R8: G | S8: 0.39484559 | T8: 0.655 | U8: =T8-S8 -> 0.26015441 | V8: =IFERROR(U8/T8,"-") -> 0.39718231 | W8: G | Z8: =Y8-X8 -> 0 | AA8: =IFERROR(Z8/Y8,"-") -> - | AC8: 3.3546059 | AD8: 5.08 | AE8: =AD8-AC8 -> 1.7253941 | AF8: =IFERROR(AE8/AD8,"-") -> 0.33964451 | AG8: G | AH8: 4.0814897 | AI8: 5.9 | AJ8: =AI8-AH8 -> 1.8185103 | AK8: =IFERROR(AJ8/AI8,"-") -> 0.30822208 | AL8: G | AN8: =I24+AC24+AH24+X24 -> 35.260356 | AO8: =J24+AD24+AI24+Y24 -> 33.880855 | AP8: =AO8-AN8 -> -1.3795012 | AQ8: =IFERROR(AP8/AO8,"-") -> -0.040716245 | AR8: R
A9: Energy Solutions | B9: Energy Solutions | C9: Roanne Steele | D9: =I9+AC9+AH9+X9 -> 4.138504 | E9: =J9+AD9+AI9+Y9 -> 3.8066795 | F9: =E9-D9 -> -0.33182446 | G9: =IFERROR(F9/E9,"-") -> -0.087169002 | H9: R | I9: 2.8789003 | J9: 2.5160191 | K9: =J9-I9 -> -0.36288119 | L9: =IFERROR(K9/J9,"-") -> -0.14422831 | M9: R | N9: =I9-S9 -> 2.5452916 | O9: =J9-T9 -> 2.0310192 | P9: =O9-N9 -> -0.51427247 | Q9: =IFERROR(P9/O9,"-") -> -0.25320907 | R9: R | S9: 0.33360872 | T9: 0.485 | U9: =T9-S9 -> 0.15139128 | V9: =IFERROR(U9/T9,"-") -> 0.31214697 | W9: G | Z9: =Y9-X9 -> 0 | AA9: =IFERROR(Z9/Y9,"-") -> - | AE9: =AD9-AC9 -> 0 | AF9: =IFERROR(AE9/AD9,"-") -> - | AH9: 1.2596037 | AI9: 1.2906604 | AJ9: =AI9-AH9 -> 0.031056732 | AK9: =IFERROR(AJ9/AI9,"-") -> 0.024062667 | AL9: G | AN9: =I25+AC25+AH25+X25 -> 7.830666 | AO9: =J25+AD25+AI25+Y25 -> 8.0095244 | AP9: =AO9-AN9 -> 0.17885836 | AQ9: =IFERROR(AP9/AO9,"-") -> 0.022330709 | AR9: R
A10: Infrastructure | B10: Infrastructure | C10: Roanne Steele | D10: =I10+AC10+AH10+X10 -> 2.6905766 | E10: =J10+AD10+AI10+Y10 -> 4.277083 | F10: =E10-D10 -> 1.5865064 | G10: =IFERROR(F10/E10,"-") -> 0.37093187 | H10: G | I10: 1.7562082 | J10: 1.831374 | K10: =J10-I10 -> 0.07516578 | L10: =IFERROR(K10/J10,"-") -> 0.041043381 | M10: G | N10: =I10-S10 -> 1.4404499 | O10: =J10-T10 -> 1.449693 | P10: =O10-N10 -> 0.00924308 | Q10: =IFERROR(P10/O10,"-") -> 0.0063758879 | R10: G | S10: 0.3157583 | T10: 0.381681 | U10: =T10-S10 -> 0.0659227 | V10: =IFERROR(U10/T10,"-") -> 0.17271675 | W10: G | Z10: =Y10-X10 -> 0 | AA10: =IFERROR(Z10/Y10,"-") -> - | AE10: =AD10-AC10 -> 0 | AF10: =IFERROR(AE10/AD10,"-") -> - | AH10: 0.93436839 | AI10: 2.445709 | AJ10: =AI10-AH10 -> 1.5113406 | AK10: =IFERROR(AJ10/AI10,"-") -> 0.61795602 | AL10: G | AN10: =I26+AC26+AH26+X26 -> 8.4185471 | AO10: =J26+AD26+AI26+Y26 -> 9.249376 | AP10: =AO10-AN10 -> 0.83082882 | AQ10: =IFERROR(AP10/AO10,"-") -> 0.089825392 | AR10: G
A11: Finance & Other Corp | B11: Finance & Other Corp | C11: Emily Mogic | D11: =I11+AC11+AH11+X11 -> 2.8468529 | E11: =J11+AD11+AI11+Y11 -> 2.1223538 | F11: =E11-D11 -> -0.72449911 | G11: =IFERROR(F11/E11,"-") -> -0.34136585 | H11: R | I11: 2.8468529 | J11: 2.1223538 | K11: =J11-I11 -> -0.72449911 | L11: =IFERROR(K11/J11,"-") -> -0.34136585 | M11: R | N11: =I11-S11 -> 2.0786006 | O11: =J11-T11 -> 1.6546105 | P11: =O11-N11 -> -0.42399014 | Q11: =IFERROR(P11/O11,"-") -> -0.25624771 | R11: R | S11: 0.76825227 | T11: 0.4677433 | U11: =T11-S11 -> -0.30050896 | V11: =IFERROR(U11/T11,"-") -> -0.64246556 | W11: R | Z11: =Y11-X11 -> 0 | AA11: =IFERROR(Z11/Y11,"-") -> - | AE11: =AD11-AC11 -> 0 | AF11: =IFERROR(AE11/AD11,"-") -> - | AH11: 0 | AI11: 0 | AJ11: =AI11-AH11 -> 0 | AK11: =IFERROR(AJ11/AI11,"-") -> - | AN11: =I27+AC27+AH27+X27 -> 5.2721119 | AO11: =J27+AD27+AI27+Y27 -> 3.8807737 | AP11: =AO11-AN11 -> -1.3913382 | AQ11: =IFERROR(AP11/AO11,"-") -> -0.35852084 | AR11: G
A12: People & Culture | B12: P&C | C12: Emily Mogic | D12: =I12+AC12+AH12+X12 -> 1.9651397 | E12: =J12+AD12+AI12+Y12 -> 2.460508 | F12: =E12-D12 -> 0.49536834 | G12: =IFERROR(F12/E12,"-") -> 0.20132767 | H12: G | I12: 1.6178184 | J12: 1.860608 | K12: =J12-I12 -> 0.2427896 | L12: =IFERROR(K12/J12,"-") -> 0.13048939 | M12: G | N12: =I12-S12 -> 0.70035539 | O12: =J12-T12 -> 0.87310804 | P12: =O12-N12 -> 0.17275265 | Q12: =IFERROR(P12/O12,"-") -> 0.19785942 | R12: G | S12: 0.91746305 | T12: 0.9875 | U12: =T12-S12 -> 0.07003695 | V12: =IFERROR(U12/T12,"-") -> 0.070923494 | W12: G | Z12: =Y12-X12 -> 0 | AA12: =IFERROR(Z12/Y12,"-") -> - | AC12: 0.34732126 | AD12: 0.4624 | AE12: =AD12-AC12 -> 0.11507874 | AF12: =IFERROR(AE12/AD12,"-") -> 0.24887271 | AG12: G | AH12: 0 | AI12: 0.1375 | AJ12: =AI12-AH12 -> 0.1375 | AK12: =IFERROR(AJ12/AI12,"-") -> 1 | AL12: G | AN12: =I28+AC28+AH28+X28 -> 5.4932256 | AO12: =J28+AD28+AI28+Y28 -> 5.813038 | AP12: =AO12-AN12 -> 0.31981243 | AQ12: =IFERROR(AP12/AO12,"-") -> 0.055016401 | AR12: G
A13: Customer | B13: Customer | C13: Harley Giles | D13: =I13+AC13+AH13+X13 -> 2.4105283 | E13: =J13+AD13+AI13+Y13 -> 5.4047457 | F13: =E13-D13 -> 2.9942174 | G13: =IFERROR(F13/E13,"-") -> 0.55399783 | H13: G | I13: 0.98861064 | J13: 0.82141236 | K13: =J13-I13 -> -0.16719828 | L13: =IFERROR(K13/J13,"-") -> -0.20354975 | M13: R | N13: =I13-S13 -> 0.98861064 | O13: =J13-T13 -> 0.82141236 | P13: =O13-N13 -> -0.16719828 | Q13: =IFERROR(P13/O13,"-") -> -0.20354975 | R13: R | S13: 0 | T13: 0 | U13: =T13-S13 -> 0 | V13: =IFERROR(U13/T13,"-") -> - | Z13: =Y13-X13 -> 0 | AA13: =IFERROR(Z13/Y13,"-") -> - | AC13: 0 | AD13: 2.5 | AE13: =AD13-AC13 -> 2.5 | AF13: =IFERROR(AE13/AD13,"-") -> 1 | AG13: G | AH13: 1.4219177 | AI13: 2.0833333 | AJ13: =AI13-AH13 -> 0.66141564 | AK13: =IFERROR(AJ13/AI13,"-") -> 0.31747951 | AL13: G | AN13: =I29+AC29+AH29+X29 -> 10.983783 | AO13: =J29+AD29+AI29+Y29 -> 11.691533 | AP13: =AO13-AN13 -> 0.70775018 | AQ13: =IFERROR(AP13/AO13,"-") -> 0.060535277 | AR13: G
B14: Total Technology | D14: =SUM(D5:D13) -> 129.57658 | E14: =SUM(E5:E13) -> 149.32633 | F14: =SUM(F5:F13) -> 19.749751 | G14: =F14/E14 -> 0.132259 | H14: G | I14: =SUM(I5:I13) -> 92.279395 | J14: =SUM(J5:J13) -> 93.256469 | K14: =SUM(K5:K13) -> 0.97707378 | L14: =K14/J14 -> 0.010477276 | M14: G | N14: =SUM(N5:N13) -> 86.660069 | O14: =SUM(O5:O13) -> 85.125564 | P14: =SUM(P5:P13) -> -1.534505 | Q14: =P14/O14 -> -0.018026371 | R14: A | S14: =SUM(S5:S13) -> 5.619326 | T14: =SUM(T5:T13) -> 8.1309048 | U14: =SUM(U5:U13) -> 2.5115788 | V14: =U14/T14 -> 0.3088929 | W14: G | X14: =SUM(X5:X13) -> 7.6209764 | Y14: =SUM(Y5:Y13) -> 8.0775842 | Z14: =SUM(Z5:Z13) -> 0.45660781 | AA14: =Z14/Y14 -> 0.056527769 | AB14: G | AC14: =SUM(AC5:AC13) -> 17.270477 | AD14: =SUM(AD5:AD13) -> 24.414204 | AE14: =SUM(AE5:AE13) -> 7.1437272 | AF14: =AE14/AD14 -> 0.29260537 | AG14: G | AH14: =SUM(AH5:AH13) -> 12.405729 | AI14: =SUM(AI5:AI13) -> 23.578071 | AJ14: =SUM(AJ5:AJ13) -> 11.172342 | AK14: =AJ14/AI14 -> 0.47384463 | AL14: G | AN14: =SUM(AN5:AN13) -> 297.09322 | AO14: =SUM(AO5:AO13) -> 302.52235 | AP14: =SUM(AP5:AP13) -> 5.4291311 | AQ14: =AP14/AO14 -> 0.017946215 | AR14: G
F15: =F14/E14 -> 0.132259 | I15: =I14/$D14 -> 0.71216108 | J15: ` | K15: =K14/J14 -> 0.010477276 | N15: =N14/$D14 -> 0.66879425 | P15: =P14/O14 -> -0.018026371 | S15: =S14/$D14 -> 0.043366835 | U15: =U14/T14 -> 0.3088929 | X15: =X14/$D14 -> 0.05881446 | Z15: =Z14/Y14 -> 0.056527769 | AC15: =AC14/$D14 -> 0.13328394 | AE15: =AE14/AD14 -> 0.29260537 | AH15: =AH14/$D14 -> 0.095740518 | AJ15: =AJ14/AI14 -> 0.47384463
B19: BUSINESS SEGMENTS | C19: TDD GM | D19: FY2026 - TOTAL | I19: OPEX: LIGHTS ON + INITIATIVES | N19: OPEX:LIGHTS ON | S19: OPEX: INITIATIVES | X19: OPEX: DEPRECIATION | AC19: OPEX: SIGNIFICANT ITEMS | AH19: CAPEX
D20: F | E20: B | F20: V | G20: V % | H20: Trend | I20: F | J20: B | K20: V | L20: V % | M20: Trend | N20: F | O20: B | P20: V | Q20: V % | R20: Trend | S20: F | T20: B | U20: V | V20: V % | W20: Trend | X20: F | Y20: B | Z20: V | AA20: V % | AB20: Trend | AC20: F | AD20: B | AE20: V | AF20: V % | AG20: Trend | AH20: F | AI20: B | AJ20: V | AK20: V % | AL20: Trend
A21: TDD (Corporate)1 | B21: TDD (Corporate)1 | C21: Brad Blyth Greg Cassis | D21: =I21+AC21+AH21+X21 -> 117.95714 | E21: =J21+AD21+AI21+Y21 -> 112.75951 | F21: =E21-D21 -> -5.1976273 | G21: =IFERROR(F21/E21,"-") -> -0.046094801 | H21: R | I21: 82.087877 | J21: 81.894863 | K21: =J21-I21 -> -0.19301366 | L21: =IFERROR(K21/J21,"-") -> -0.002356847 | M21: G | N21: =I21-S21 -> 79.310436 | O21: =J21-T21 -> 78.894863 | P21: =O21-N21 -> -0.41557243 | Q21: =IFERROR(P21/O21,"-") -> -0.0052674206 | R21: A | S21: 2.7774412 | T21: 3 | U21: =T21-S21 -> 0.22255877 | V21: =IFERROR(U21/T21,"-") -> 0.074186257 | W21: G | X21: 5.6865111 | Y21: 5.8000499 | Z21: =Y21-X21 -> 0.11353882 | AA21: =IFERROR(Z21/Y21,"-") -> 0.01957549 | AB21: G | AC21: 25.395773 | AD21: 20.1966 | AE21: =AD21-AC21 -> -5.1991726 | AF21: =IFERROR(AE21/AD21,"-") -> -0.25742811 | AG21: R | AH21: 4.7869798 | AI21: 4.868 | AJ21: =AI21-AH21 -> 0.08102017 | AK21: =IFERROR(AJ21/AI21,"-") -> 0.01664342 | AL21: G | AM21: =I21+X21 -> 87.774388 | AN21: input retail SI number manually
A22: Z-Energy | B22: Z- Energy | C22: Vance Anderson Harley Giles | D22: =I22+AC22+AH22+X22 -> 73.108391 | E22: =J22+AD22+AI22+Y22 -> 76.703514 | F22: =E22-D22 -> 3.5951226 | G22: =IFERROR(F22/E22,"-") -> 0.046870376 | H22: G | I22: 53.465434 | J22: 53.6715 | K22: =J22-I22 -> 0.20606573 | L22: =IFERROR(K22/J22,"-") -> 0.0038393884 | M22: G | N22: =I22-S22 -> 53.465434 | O22: =J22-T22 -> 52.22526 | P22: =O22-N22 -> -1.2401743 | Q22: =IFERROR(P22/O22,"-") -> -0.023746637 | R22: A | S22: 0 | T22: 1.44624 | U22: =T22-S22 -> 1.44624 | V22: =IFERROR(U22/T22,"-") -> 1 | W22: G | X22: 10.161498 | Y22: 11.306521 | Z22: =Y22-X22 -> 1.1450224 | AA22: =IFERROR(Z22/Y22,"-") -> 0.10127098 | AB22: G | AC22: 0 | AD22: 0 | AE22: =AD22-AC22 -> 0 | AF22: =IFERROR(AE22/AD22,"-") -> - | AH22: 9.4814594 | AI22: 11.725494 | AJ22: =AI22-AH22 -> 2.2440344 | AK22: =IFERROR(AJ22/AI22,"-") -> 0.1913808 | AL22: G | AM22: =I22+X22 -> 63.626932
A23: Commercial Fuels | B23: Commercial Fuels | C23: Roanne Steele | D23: =I23+AC23+AH23+X23 -> 32.768998 | E23: =J23+AD23+AI23+Y23 -> 40.534223 | F23: =E23-D23 -> 7.7652255 | G23: =IFERROR(F23/E23,"-") -> 0.19157208 | H23: G | I23: 18.07582 | J23: 19.517302 | K23: =J23-I23 -> 1.4414818 | L23: =IFERROR(K23/J23,"-") -> 0.073856612 | M23: G | N23: =I23-S23 -> 12.122014 | O23: =J23-T23 -> 13.655581 | P23: =O23-N23 -> 1.533567 | Q23: =IFERROR(P23/O23,"-") -> 0.11230331 | R23: G | S23: 5.9538061 | T23: 5.8617209 | U23: =T23-S23 -> -0.092085221 | V23: =IFERROR(U23/T23,"-") -> -0.015709588 | W23: A | Z23: =Y23-X23 -> 0 | AA23: =IFERROR(Z23/Y23,"-") -> - | AC23: 8.927316 | AD23: 14.219208 | AE23: =AD23-AC23 -> 5.291892 | AF23: =IFERROR(AE23/AD23,"-") -> 0.37216503 | AG23: G | AH23: 5.7658612 | AI23: 6.7977128 | AJ23: =AI23-AH23 -> 1.0318517 | AK23: =IFERROR(AJ23/AI23,"-") -> 0.15179395 | AL23: G
A24: Retail | B24: Retail | C24: Vance Anderson | D24: =I24+AC24+AH24+X24 -> 35.260356 | E24: =J24+AD24+AI24+Y24 -> 33.880855 | F24: =E24-D24 -> -1.3795012 | G24: =IFERROR(F24/E24,"-") -> -0.040716245 | H24: A | I24: 15.230723 | J24: 15.235855 | K24: =J24-I24 -> 0.0051319 | L24: =IFERROR(K24/J24,"-") -> 0.00033683047 | M24: G | N24: =I24-S24 -> 14.481085 | O24: =J24-T24 -> 13.925855 | P24: =O24-N24 -> -0.55523051 | Q24: =IFERROR(P24/O24,"-") -> -0.03987048 | R24: A | S24: 0.74963759 | T24: 1.31 | U24: =T24-S24 -> 0.56036241 | V24: =IFERROR(U24/T24,"-") -> 0.42775756 | W24: G | Z24: =Y24-X24 -> 0 | AA24: =IFERROR(Z24/Y24,"-") -> - | AC24: 8.64 | AD24: 6.845 | AE24: =AD24-AC24 -> -1.795 | AF24: =IFERROR(AE24/AD24,"-") -> -0.26223521 | AG24: R | AH24: 11.389633 | AI24: 11.8 | AJ24: =AI24-AH24 -> 0.41036692 | AK24: =IFERROR(AJ24/AI24,"-") -> 0.034776858 | AL24: G
A25: Energy Solutions | B25: Energy Solutions | C25: Roanne Steele | D25: =I25+AC25+AH25+X25 -> 7.830666 | E25: =J25+AD25+AI25+Y25 -> 8.0095244 | F25: =E25-D25 -> 0.17885836 | G25: =IFERROR(F25/E25,"-") -> 0.022330709 | H25: G | I25: 5.0440983 | J25: 5.0119394 | K25: =J25-I25 -> -0.0321589 | L25: =IFERROR(K25/J25,"-") -> -0.0064164582 | M25: A | N25: =I25-S25 -> 4.5362156 | O25: =J25-T25 -> 4.0419395 | P25: =O25-N25 -> -0.49427618 | Q25: =IFERROR(P25/O25,"-") -> -0.12228688 | R25: R | S25: 0.50788272 | T25: 0.97 | U25: =T25-S25 -> 0.46211728 | V25: =IFERROR(U25/T25,"-") -> 0.47640957 | W25: G | Z25: =Y25-X25 -> 0 | AA25: =IFERROR(Z25/Y25,"-") -> - | AE25: =AD25-AC25 -> 0 | AF25: =IFERROR(AE25/AD25,"-") -> - | AH25: 2.7865677 | AI25: 2.9975849 | AJ25: =AI25-AH25 -> 0.21101726 | AK25: =IFERROR(AJ25/AI25,"-") -> 0.070395758 | AL25: G
A26: Infrastructure | B26: Infrastructure | C26: Roanne Steele | D26: =I26+AC26+AH26+X26 -> 8.4185471 | E26: =J26+AD26+AI26+Y26 -> 9.249376 | F26: =E26-D26 -> 0.83082882 | G26: =IFERROR(F26/E26,"-") -> 0.089825392 | H26: G | I26: 4.2749786 | J26: 4.357958 | K26: =J26-I26 -> 0.08297936 | L26: =IFERROR(K26/J26,"-") -> 0.019040881 | M26: G | N26: =I26-S26 -> 3.3010253 | O26: =J26-T26 -> 3.594596 | P26: =O26-N26 -> 0.29357066 | Q26: =IFERROR(P26/O26,"-") -> 0.081670001 | R26: G | S26: 0.9739533 | T26: 0.763362 | U26: =T26-S26 -> -0.2105913 | V26: =IFERROR(U26/T26,"-") -> -0.27587344 | W26: R | Z26: =Y26-X26 -> 0 | AA26: =IFERROR(Z26/Y26,"-") -> - | AE26: =AD26-AC26 -> 0 | AF26: =IFERROR(AE26/AD26,"-") -> - | AH26: 4.1435685 | AI26: 4.891418 | AJ26: =AI26-AH26 -> 0.74784946 | AK26: =IFERROR(AJ26/AI26,"-") -> 0.15289012 | AL26: G
A27: Finance & Other Corp | B27: Finance & Other Corp | C27: Emily Mogic | D27: =I27+AC27+AH27+X27 -> 5.2721119 | E27: =J27+AD27+AI27+Y27 -> 3.8807737 | F27: =E27-D27 -> -1.3913382 | G27: =IFERROR(F27/E27,"-") -> -0.35852084 | H27: R | I27: 5.2721119 | J27: 3.8807737 | K27: =J27-I27 -> -1.3913382 | L27: =IFERROR(K27/J27,"-") -> -0.35852084 | M27: R | N27: =I27-S27 -> 4.3588956 | O27: =J27-T27 -> 2.9452871 | P27: =O27-N27 -> -1.4136086 | Q27: =IFERROR(P27/O27,"-") -> -0.47995613 | R27: R | S27: 0.91321627 | T27: 0.93548661 | U27: =T27-S27 -> 0.02227034 | V27: =IFERROR(U27/T27,"-") -> 0.023806156 | W27: G | Z27: =Y27-X27 -> 0 | AA27: =IFERROR(Z27/Y27,"-") -> - | AE27: =AD27-AC27 -> 0 | AF27: =IFERROR(AE27/AD27,"-") -> - | AH27: 0 | AI27: 0 | AJ27: =AI27-AH27 -> 0 | AK27: =IFERROR(AJ27/AI27,"-") -> - | AL27: G
A28: People & Culture | B28: P&C | C28: Emily Mogic | D28: =I28+AC28+AH28+X28 -> 5.4932256 | E28: =J28+AD28+AI28+Y28 -> 5.813038 | F28: =E28-D28 -> 0.31981243 | G28: =IFERROR(F28/E28,"-") -> 0.055016401 | H28: G | I28: 3.8516861 | J28: 4.123038 | K28: =J28-I28 -> 0.27135188 | L28: =IFERROR(K28/J28,"-") -> 0.065813577 | M28: G | N28: =I28-S28 -> 1.9121353 | O28: =J28-T28 -> 2.148038 | P28: =O28-N28 -> 0.23590273 | Q28: =IFERROR(P28/O28,"-") -> 0.10982242 | R28: G | S28: 1.9395508 | T28: 1.975 | U28: =T28-S28 -> 0.035449154 | V28: =IFERROR(U28/T28,"-") -> 0.017948939 | W28: G | Z28: =Y28-X28 -> 0 | AA28: =IFERROR(Z28/Y28,"-") -> - | AC28: 1.3115394 | AD28: 1.36 | AE28: =AD28-AC28 -> 0.04846055 | AF28: =IFERROR(AE28/AD28,"-") -> 0.035632757 | AG28: G | AH28: 0.33 | AI28: 0.33 | AJ28: =AI28-AH28 -> 0 | AK28: =IFERROR(AJ28/AI28,"-") -> 0 | AL28: G
A29: Customer | B29: Customer | C29: Harley Giles | D29: =I29+AC29+AH29+X29 -> 10.983783 | E29: =J29+AD29+AI29+Y29 -> 11.691533 | F29: =E29-D29 -> 0.70775018 | G29: =IFERROR(F29/E29,"-") -> 0.060535277 | H29: G | I29: 2.74505 | J29: 1.6915328 | K29: =J29-I29 -> -1.0535172 | L29: =IFERROR(K29/J29,"-") -> -0.62281806 | M29: R | N29: =I29-S29 -> 2.74505 | O29: =J29-T29 -> 1.6915328 | P29: =O29-N29 -> -1.0535172 | Q29: =IFERROR(P29/O29,"-") -> -0.62281806 | R29: R | S29: 0 | T29: 0 | U29: =T29-S29 -> 0 | V29: =IFERROR(U29/T29,"-") -> - | Z29: =Y29-X29 -> 0 | AA29: =IFERROR(Z29/Y29,"-") -> - | AC29: 3.832387 | AD29: 5 | AE29: =AD29-AC29 -> 1.1676131 | AF29: =IFERROR(AE29/AD29,"-") -> 0.23352261 | AG29: G | AH29: 4.4063457 | AI29: 5 | AJ29: =AI29-AH29 -> 0.59365431 | AK29: =IFERROR(AJ29/AI29,"-") -> 0.11873086 | AL29: G
B30: Total Technology | D30: =SUM(D21:D29) -> 297.09322 | E30: =SUM(E21:E29) -> 302.52235 | F30: =SUM(F21:F29) -> 5.4291311 | G30: =F30/E30 -> 0.017946215 | H30: G | I30: =SUM(I21:I29) -> 190.04778 | J30: =SUM(J21:J29) -> 189.38476 | K30: =SUM(K21:K29) -> -0.66301729 | L30: =K30/J30 -> -0.0035009009 | M30: A | N30: =SUM(N21:N29) -> 176.23229 | O30: =SUM(O21:O29) -> 173.12295 | P30: =SUM(P21:P29) -> -3.1093387 | Q30: =P30/O30 -> -0.017960292 | R30: A | S30: =SUM(S21:S29) -> 13.815488 | T30: =SUM(T21:T29) -> 16.26181 | U30: =SUM(U21:U29) -> 2.4463214 | V30: =U30/T30 -> 0.15043353 | W30: G | X30: =SUM(X21:X29) -> 15.848009 | Y30: =SUM(Y21:Y29) -> 17.10657 | Z30: =SUM(Z21:Z29) -> 1.2585612 | AA30: =Z30/Y30 -> 0.073571802 | AB30: G | AC30: =SUM(AC21:AC29) -> 48.107015 | AD30: =SUM(AD21:AD29) -> 47.620808 | AE30: =SUM(AE21:AE29) -> -0.48620701 | AF30: =AE30/AD30 -> -0.01020997 | AG30: A | AH30: =SUM(AH21:AH29) -> 43.090415 | AI30: =SUM(AI21:AI29) -> 48.41021 | AJ30: =SUM(AJ21:AJ29) -> 5.3197942 | AK30: =AJ30/AI30 -> 0.10988992 | AL30: G
I31: =I30/$D30 -> 0.63969073 | N31: =N30/$D30 -> 0.59318853 | S31: =S30/$D30 -> 0.046502199 | X31: =X30/$D30 -> 0.053343558 | AC31: =AC30/$D30 -> 0.16192566 | AH31: =AH30/$D30 -> 0.14504005
AO32: =E30-297 -> 5.5223497
D35: =D3 -> TOTAL YTD (Jun-2026) | I35: TOTAL TECHNOLOGY Full Year 2026
B36: Spend Type | D36: A | E36: B | F36: V | G36: V % | H36: Trend | I36: F | J36: B | K36: V | L36: V % | M36: Trend
B37: Lights on | D37: =N14 -> 86.660069 | E37: =O14 -> 85.125564 | F37: =E37-D37 -> -1.534505 | G37: =IFERROR(F37/E37,"-") -> -0.018026371 | H37: A | I37: =N30 -> 176.23229 | J37: =O30 -> 173.12295 | K37: =J37-I37 -> -3.1093387 | L37: =IFERROR(K37/J37,"-") -> -0.017960292 | M37: A
B38: Depreciation | D38: =X14 -> 7.6209764 | E38: =Y14 -> 8.0775842 | F38: =E38-D38 -> 0.45660781 | G38: =IFERROR(F38/E38,"-") -> 0.056527769 | H38: G | I38: =X30 -> 15.848009 | J38: =Y30 -> 17.10657 | K38: =J38-I38 -> 1.2585612 | L38: =IFERROR(K38/J38,"-") -> 0.073571802 | M38: G
B39: Lights on + Depreciation | D39: =SUM(D37:D38) -> 94.281045 | E39: =SUM(E37:E38) -> 93.203148 | F39: =SUM(F37:F38) -> -1.0778972 | G39: =IFERROR(F39/E39,"-") -> -0.01156503 | H39: A | I39: =SUM(I37:I38) -> 192.0803 | J39: =SUM(J37:J38) -> 190.22952 | K39: =SUM(K37:K38) -> -1.8507775 | L39: =IFERROR(K39/J39,"-") -> -0.0097291812 | M39: A
B40: Opex Initiatives | D40: =S14 -> 5.619326 | E40: =T14 -> 8.1309048 | F40: =E40-D40 -> 2.5115788 | G40: =IFERROR(F40/E40,"-") -> 0.3088929 | H40: G | I40: =S30 -> 13.815488 | J40: =T30 -> 16.26181 | K40: =J40-I40 -> 2.4463214 | L40: =IFERROR(K40/J40,"-") -> 0.15043353 | M40: G
B41: Capex | D41: =AH14 -> 12.405729 | E41: =AI14 -> 23.578071 | F41: =E41-D41 -> 11.172342 | G41: =IFERROR(F41/E41,"-") -> 0.47384463 | H41: G | I41: =AH30 -> 43.090415 | J41: =AI30 -> 48.41021 | K41: =J41-I41 -> 5.3197942 | L41: =IFERROR(K41/J41,"-") -> 0.10988992 | M41: G
B42: Significant Items | D42: =AC14 -> 17.270477 | E42: =AD14 -> 24.414204 | F42: =E42-D42 -> 7.1437272 | G42: =IFERROR(F42/E42,"-") -> 0.29260537 | H42: G | I42: =AC30 -> 48.107015 | J42: =AD30 -> 47.620808 | K42: =J42-I42 -> -0.48620701 | L42: =IFERROR(K42/J42,"-") -> -0.01020997 | M42: A
B43: Projects | D43: =SUM(D40:D42) -> 35.295531 | E43: =SUM(E40:E42) -> 56.123179 | F43: =SUM(F40:F42) -> 20.827648 | G43: =IFERROR(F43/E43,"-") -> 0.37110599 | H43: G | I43: =SUM(I40:I42) -> 105.01292 | J43: =SUM(J40:J42) -> 112.29283 | K43: =SUM(K40:K42) -> 7.2799086 | L43: =IFERROR(K43/J43,"-") -> 0.064829685 | M43: G
B44: Total Technology | D44: =SUM(D43,D39) -> 129.57658 | E44: =SUM(E43,E39) -> 149.32633 | F44: =SUM(F43,F39) -> 19.749751 | G44: =IFERROR(F44/E44,"-") -> 0.132259 | H44: G | I44: =SUM(I43,I39) -> 297.09322 | J44: =SUM(J43,J39) -> 302.52235 | K44: =SUM(K43,K39) -> 5.4291311 | L44: =IFERROR(K44/J44,"-") -> 0.017946215 | M44: G
B47: SPEND CATEGORY | D47: =D3 -> TOTAL YTD (Jun-2026) | I47: TOTAL TECHNOLOGY YTD (May-2026)
D48: A | E48: B | F48: V | G48: V % | H48: Trend | I48: A | J48: B | K48: V | L48: V % | M48: Trend
B49: Opex | D49: =I14+X14 -> 99.900371 | E49: =J14+Y14 -> 101.33405 | F49: =E49-D49 -> 1.4336816 | G49: =IFERROR(F49/E49,"-") -> 0.014148073 | H49: G | I49: =I30+X30 -> 205.89579 | J49: =J30+Y30 -> 206.49133 | K49: =J49-I49 -> 0.59554393 | L49: =IFERROR(K49/J49,"-") -> 0.002884111 | M49: G
...

Sheet - DESIGNS -
B2: DESIGNS >>>

Sheet 1.1 Ampol Retail
B2: Ampol Retail
B4: Portfolio Summary | G4: Budget vs TDD Cost
B5: Cost | C5: TDD ($m) | D5: Other ($m) | E5: Total Retail Cost ($m) | G5: TDD Lights On Budget (people - 0.2 Data Config) | H5: ='0.2 Data Config'!$E$11 -> 2.5
B6: Portfolio Overhead (see 0.2 Data Config) | C6: ='0.2 Data Config'!$L$10 -> 0.7495 | E6: =C6 -> 0.7495 | G6: Overheads & Support (this model) | H6: =C9 -> 5.6265
B7: Platform Overheads | C7: =SUM(H27,H34,H47,H53,H59) -> 0.825 | E7: =C7 -> 0.825 | G7: Variance (budget less cost) | H7: =H5-H6 -> -3.1265
B8: Squad Support Costs | C8: =SUM(H23,H24,H25,H26,H32,H33,H46,H52,H58,H64) -> 4.052 | D8: =SUM(I23,I24,I25,I26,I32,I33,I46,I52,I58,I64) -> 4.728 | E8: =C8+D8 -> 8.78
B9: Total Cost | C9: =SUM(C6:C8) -> 5.6265 | D9: =SUM(D6:D8) -> 4.728 | E9: =C9+D9 -> 10.3545
G10: Other funding
B11: Total Retail budget | E11: =SUM(H12:H16) -> 33.8 | G11: Budget line | H11: Budget ($m) | I11: Amount that can be allocated to people | J11: Remaining for non-people ($m)
B12: Reconciled to Finance | E12: ='0.1 Budget Table (Fin)'!Q9 -> 33.8 | G12: Retail Lights On | H12: ='0.1 Budget Table (Fin)'!L9 -> 13.9 | I12: ='0.1 Budget Table (Fin)'!G9 -> 0 | J12: =IFERROR(H12-I12,0) -> 13.9
G13: OpEx Initiatives | H13: ='0.1 Budget Table (Fin)'!N9 -> 1.3 | I13: 0 | J13: =IFERROR(H13-I13,0) -> 1.3
B14: Total to fund | G14: Retail CapEx | H14: ='0.1 Budget Table (Fin)'!P9 -> 11.8 | J14: =IFERROR(H14-I14,0) -> 11.8
B15: TDD Variance | C15: =MAX(0,-H7) -> 3.1265 | G15: Significant Items | H15: ='0.1 Budget Table (Fin)'!O9 -> 6.8 | I15: =I46 -> 0 | J15: =IFERROR(H15-I15,0) -> 6.8
B16: Other Variance | C16: =MAX(0,I19) -> 4.728 | G16: Significant Items EGI | I16: =I64 -> 0
B17: Total | C17: =C15+C16 -> 7.8545 | G17: Total applied | I17: =SUM(I12:I16) -> 0
G18: Other cost (this model) | I18: =D9 -> 4.728
G19: Left to fund | I19: =I18-I17 -> 4.728
B21: Platform: Store Operations
B22: Squad | C22: Squad Type | D22: Size | E22: On/Off | F22: Support % | G22: Total Squad Cost ($m) | H22: TDD Cost ($m) | I22: Funded outside TDD ($m) | K22: Fund
B23: POS | C23: Configuration / Integration | D23: M | E23: Onshore | F23: 0.7 | G23: =IFERROR(IF($E23="Onshore",INDEX('0.3 Squad Archetypes'!$G$5:$G$23,MATCH($C23&"|"&$D23,'0.3 Squad Archetypes'!$A$5:$A$23,0)),INDEX('0.3 Squad Archetypes'!$H$5:$H$23,MATCH($C23&"|"&$D23,'0.3 Squad Archetypes'!$A$5:$A$23,0))),"check size") -> 1.4 | H23: =IFERROR($G23*$F23,"") -> 0.98 | I23: =IFERROR($G23*(1-$F23),"") -> 0.42 | K23: AU
B24: Payments | C24: Configuration / Integration | D24: S | E24: Onshore | F24: 0.2 | G24: =IFERROR(IF($E24="Onshore",INDEX('0.3 Squad Archetypes'!$G$5:$G$23,MATCH($C24&"|"&$D24,'0.3 Squad Archetypes'!$A$5:$A$23,0)),INDEX('0.3 Squad Archetypes'!$H$5:$H$23,MATCH($C24&"|"&$D24,'0.3 Squad Archetypes'!$A$5:$A$23,0))),"check size") -> 0.4 | H24: =IFERROR($G24*$F24,"") -> 0.08 | I24: =IFERROR($G24*(1-$F24),"") -> 0.32 | K24: AU
B25: Store Operations | C25: Operations | D25: M | E25: Onshore | F25: 1 | G25: =IFERROR(IF($E25="Onshore",INDEX('0.3 Squad Archetypes'!$G$5:$G$23,MATCH($C25&"|"&$D25,'0.3 Squad Archetypes'!$A$5:$A$23,0)),INDEX('0.3 Squad Archetypes'!$H$5:$H$23,MATCH($C25&"|"&$D25,'0.3 Squad Archetypes'!$A$5:$A$23,0))),"check size") -> 1.4 | H25: =IFERROR($G25*$F25,"") -> 1.4 | I25: =IFERROR($G25*(1-$F25),"") -> 0 | K25: AU
B26: Deployment | C26: Configuration / Integration | D26: M | E26: Onshore | F26: 0.2 | G26: =IFERROR(IF($E26="Onshore",INDEX('0.3 Squad Archetypes'!$G$5:$G$23,MATCH($C26&"|"&$D26,'0.3 Squad Archetypes'!$A$5:$A$23,0)),INDEX('0.3 Squad Archetypes'!$H$5:$H$23,MATCH($C26&"|"&$D26,'0.3 Squad Archetypes'!$A$5:$A$23,0))),"check size") -> 1.4 | H26: =IFERROR($G26*$F26,"") -> 0.28 | I26: =IFERROR($G26*(1-$F26),"") -> 1.12 | K26: AU
B27: Platform Overhead | H27: ='0.2 Data Config'!$L$16 -> 0.165
B28: Store Operations Total | G28: =SUM(G23:G26) -> 4.6 | H28: =SUM(H23:H27) -> 2.905 | I28: =SUM(I23:I26) -> 1.86
B30: Platform: Above Store
B31: Squad | C31: Squad Type | D31: Size | E31: On/Off | F31: Support % | G31: Total Squad Cost ($m) | H31: TDD Cost ($m) | I31: Funded outside TDD ($m) | K31: Fund
B32: Above Store | C32: Configuration / Integration | D32: L | E32: Onshore | F32: 0.2 | G32: =IFERROR(IF($E32="Onshore",INDEX('0.3 Squad Archetypes'!$G$5:$G$23,MATCH($C32&"|"&$D32,'0.3 Squad Archetypes'!$A$5:$A$23,0)),INDEX('0.3 Squad Archetypes'!$H$5:$H$23,MATCH($C32&"|"&$D32,'0.3 Squad Archetypes'!$A$5:$A$23,0))),"check size") -> 2.1 | H32: =IFERROR($G32*$F32,"") -> 0.42 | I32: =IFERROR($G32*(1-$F32),"") -> 1.68 | K32: AU
J33: Will combine - takes out 4 roles. New platform Above Store & new squad Above Store
B34: Platform Overhead | H34: ='0.2 Data Config'!$L$16 -> 0.165
B35: Above Store Total | G35: =SUM(G32:G33) -> 2.1 | H35: =SUM(H32:H34) -> 0.585 | I35: =SUM(I32:I33) -> 1.68
B37: Platform: Pricing & WFM - combined into Above Store
B38: Squad | C38: Squad Type | D38: Size | E38: On/Off | F38: Support % | G38: Total Squad Cost ($m) | H38: TDD Cost ($m) | I38: Funded outside TDD ($m)
B41: Platform Overhead
B42: (combined into Above Store)
B44: Platform: AmPOS
B45: Squad | C45: Squad Type | D45: Size | E45: On/Off | F45: Support % | G45: Total Squad Cost ($m) | H45: TDD Cost ($m) | I45: Funded outside TDD ($m) | K45: Fund
B46: AmPOS | C46: Strategic Programs | E46: Onshore | F46: 0 | G46: 0 | H46: =IFERROR($G46*$F46,"") -> 0 | I46: =IFERROR($G46*(1-$F46),"") -> 0 | J46: Change this to strat projects; impact on price | K46: AU | L46: 7 FTE in AmPOS
B47: Platform Overhead | H47: ='0.2 Data Config'!$L$16 -> 0.165 | J47: Take some roles from POS and put into Pos
B48: AmPOS Total | G48: =SUM(G46:G46) -> 0 | H48: =SUM(H46:H47) -> 0.165 | I48: =SUM(I46:I46) -> 0
...

Sheet 1.2 Customer
B2: Customer
B4: Portfolio Summary | G4: Budget vs TDD Cost
B5: Cost | C5: TDD ($m) | D5: Other ($m) | E5: Total Customer Cost ($m) | G5: TDD Lights On Budget (people - 0.2 Data Config) | H5: ='0.2 Data Config'!$E$13+'0.2 Data Config'!$E$14 -> 6.5
B6: Portfolio Overhead (see 0.2 Data Config) | C6: ='0.2 Data Config'!$L$10 -> 0.7495 | E6: =C6 -> 0.7495 | G6: Overheads & Support (this model) | H6: =C9 -> 9.0245
B7: Platform Overheads | C7: =SUM(H32,H40,H47) -> 0.495 | E7: =C7 -> 0.495 | G7: Variance (budget less cost) | H7: =H5-H6 -> -2.5245
B8: Squad Support Costs | C8: =SUM(H29,H30,H31,H37,H38,H39,H45,H46,H52) -> 7.78 | D8: =SUM(I29,I30,I31,I37,I38,I39,I45,I46,I52) -> 5.92 | E8: =C8+D8 -> 13.7
B9: Total Cost | C9: =SUM(C6:C8) -> 9.0245 | D9: =SUM(D6:D8) -> 5.92 | E9: =C9+D9 -> 14.9445
G10: Other funding
B11: Total Customer budget | E11: =SUM(H12:H21) -> 11.7 | G11: Budget line | H11: Budget ($m) | I11: Amount that can be allocated to people | J11: Remaining for non-people ($m)
B12: Reconciled to Finance | E12: ='0.1 Budget Table (Fin)'!Q13 -> 11.7 | G12: Customer Lights On | H12: ='0.1 Budget Table (Fin)'!L13 -> 1.7 | I12: ='0.1 Budget Table (Fin)'!G13 -> 0 | J12: =IFERROR(H12-I12,0) -> 1.7
G13: OpEx Initiatives | H13: ='0.1 Budget Table (Fin)'!N13 -> 0 | I13: 0 | J13: =IFERROR(H13-I13,0) -> 0
B14: Total to fund | G14: CapEx | H14: ='0.1 Budget Table (Fin)'!P13 -> 5 | I14: 2 | J14: =IFERROR(H14-I14,0) -> 3
B15: TDD Variance | C15: =MAX(0,-H7) -> 2.5245 | G15: Significant Items EGI | I15: =I52 -> 0
B16: Other Variance | C16: =MAX(0,I24) -> 1.92 | G16: Significant Items | H16: ='0.1 Budget Table (Fin)'!O13 -> 5 | I16: 2 | J16: =IFERROR(H16-I16,0) -> 3
B17: Total | C17: =C15+C16 -> 4.4445 | G17: Sig Items EG
G18: Z OpEx Initiatives
G19: Z CapEx
G20: Z Sig items
G21: Depreciation | H21: ='0.1 Budget Table (Fin)'!M13 -> 0 | I21: 0 | J21: =IFERROR(H21-I21,0) -> 0
G22: Total applied | I22: =SUM(I12:I21) -> 4
G23: Other cost (this model) | I23: =D9 -> 5.92
G24: Left to fund | I24: =I23-I22 -> 1.92
B27: Platform: Ampol Digital
B28: Squad | C28: Squad Type | D28: Size | E28: On/Off | F28: Support % | G28: Total Squad Cost ($m) | H28: TDD Cost ($m) | I28: Funded outside TDD ($m) | J28: FTE | L28: Fund
B29: Ampol App | C29: Product | D29: L | E29: Onshore | F29: 0.2 | G29: =IFERROR(IF($E29="Onshore",INDEX('0.3 Squad Archetypes'!$G$5:$G$23,MATCH($C29&"|"&$D29,'0.3 Squad Archetypes'!$A$5:$A$23,0)),INDEX('0.3 Squad Archetypes'!$H$5:$H$23,MATCH($C29&"|"&$D29,'0.3 Squad Archetypes'!$A$5:$A$23,0))),"check size") -> 2.8 | H29: =IFERROR($G29*$F29,"") -> 0.56 | I29: =IFERROR($G29*(1-$F29),"") -> 2.24 | J29: 15 | L29: AU
B30: Ampol Web | C30: Product | D30: M | E30: Onshore | F30: 0.2 | G30: =IFERROR(IF($E30="Onshore",INDEX('0.3 Squad Archetypes'!$G$5:$G$23,MATCH($C30&"|"&$D30,'0.3 Squad Archetypes'!$A$5:$A$23,0)),INDEX('0.3 Squad Archetypes'!$H$5:$H$23,MATCH($C30&"|"&$D30,'0.3 Squad Archetypes'!$A$5:$A$23,0))),"check size") -> 1.9 | H30: =IFERROR($G30*$F30,"") -> 0.38 | I30: =IFERROR($G30*(1-$F30),"") -> 1.52 | J30: 9 | L30: AU
B31: Digital Operations | C31: Operations | D31: M | E31: Onshore | F31: 1 | G31: =IFERROR(IF($E31="Onshore",INDEX('0.3 Squad Archetypes'!$G$5:$G$23,MATCH($C31&"|"&$D31,'0.3 Squad Archetypes'!$A$5:$A$23,0)),INDEX('0.3 Squad Archetypes'!$H$5:$H$23,MATCH($C31&"|"&$D31,'0.3 Squad Archetypes'!$A$5:$A$23,0))),"check size") -> 1.4 | H31: =IFERROR($G31*$F31,"") -> 1.4 | I31: =IFERROR($G31*(1-$F31),"") -> 0 | J31: 6 | L31: AU
B32: Platform Overhead | H32: ='0.2 Data Config'!$L$16 -> 0.165
B33: Ampol Digital Total | G33: =SUM(G29:G31) -> 6.1 | H33: =SUM(H29:H32) -> 2.505 | I33: =SUM(I29:I31) -> 3.76
B35: Platform: Customer Z
B36: Squad | C36: Squad Type | D36: Size | E36: On/Off | F36: Support % | G36: Total Squad Cost ($m) | H36: TDD Cost ($m) | I36: Funded outside TDD ($m) | L36: Fund
B37: Z Energy Apps | C37: Product | D37: S | E37: Onshore | F37: 1 | G37: =IFERROR(IF($E37="Onshore",INDEX('0.3 Squad Archetypes'!$G$5:$G$23,MATCH($C37&"|"&$D37,'0.3 Squad Archetypes'!$A$5:$A$23,0)),INDEX('0.3 Squad Archetypes'!$H$5:$H$23,MATCH($C37&"|"&$D37,'0.3 Squad Archetypes'!$A$5:$A$23,0))),"check size") -> 1.3 | H37: =IFERROR($G37*$F37,"") -> 1.3 | I37: =IFERROR($G37*(1-$F37),"") -> 0 | J37: Z funded incl. in the lights on budget. Needs to be under group customer platforms | K37: 5 | L37: NZ
B38: Z Energy Martech | C38: Product | D38: L | E38: Onshore | F38: 1 | G38: =IFERROR(IF($E38="Onshore",INDEX('0.3 Squad Archetypes'!$G$5:$G$23,MATCH($C38&"|"&$D38,'0.3 Squad Archetypes'!$A$5:$A$23,0)),INDEX('0.3 Squad Archetypes'!$H$5:$H$23,MATCH($C38&"|"&$D38,'0.3 Squad Archetypes'!$A$5:$A$23,0))),"check size") -> 2.8 | H38: =IFERROR($G38*$F38,"") -> 2.8 | I38: =IFERROR($G38*(1-$F38),"") -> 0 | J38: Z funded incl. in the lights on budget. Needs to be under group customer platforms | K38: 16 | L38: NZ
A39: Net New | B39: Digital Support NZ | C39: Operations | D39: S | E39: Onshore | F39: 1 | G39: =IFERROR(IF($E39="Onshore",INDEX('0.3 Squad Archetypes'!$G$5:$G$23,MATCH($C39&"|"&$D39,'0.3 Squad Archetypes'!$A$5:$A$23,0)),INDEX('0.3 Squad Archetypes'!$H$5:$H$23,MATCH($C39&"|"&$D39,'0.3 Squad Archetypes'!$A$5:$A$23,0))),"check size") -> 0.8 | H39: =IFERROR($G39*$F39,"") -> 0.8 | I39: =IFERROR($G39*(1-$F39),"") -> 0 | J39: Z funded incl. in the lights on budget. Needs to be under group customer platforms | L39: NZ
B40: Platform Overhead | H40: ='0.2 Data Config'!$L$16 -> 0.165
B41: Customer Z Total | G41: =SUM(G37:G39) -> 4.9 | H41: =SUM(H37:H40) -> 5.065 | I41: =SUM(I37:I39) -> 0
M42: 2 B2B Vacant FTEs
B43: Platform: Group Customer Platforms
B44: Squad | C44: Squad Type | D44: Size | E44: On/Off | F44: Support % | G44: Total Squad Cost ($m) | H44: TDD Cost ($m) | I44: Funded outside TDD ($m) | L44: Fund
B45: AU CRM & Martech | C45: Product | D45: M | E45: Onshore | F45: 0.2 | G45: =IFERROR(IF($E45="Onshore",INDEX('0.3 Squad Archetypes'!$G$5:$G$23,MATCH($C45&"|"&$D45,'0.3 Squad Archetypes'!$A$5:$A$23,0)),INDEX('0.3 Squad Archetypes'!$H$5:$H$23,MATCH($C45&"|"&$D45,'0.3 Squad Archetypes'!$A$5:$A$23,0))),"check size") -> 1.9 | H45: =IFERROR($G45*$F45,"") -> 0.38 | I45: =IFERROR($G45*(1-$F45),"") -> 1.52 | J45: 7 | L45: AU
...

Sheet 1.3 Enterprise Data
B2: Enterprise Data
B4: Portfolio Summary | G4: Budget vs TDD Cost
B5: Cost | C5: TDD ($m) | D5: Other ($m) | E5: Total Enterprise Data Cost ($m) | G5: TDD Lights On Budget (people - 0.2 Data Config) | H5: ='0.2 Data Config'!$E$22 -> 3.5
B6: Portfolio Overhead (see 0.2 Data Config) | C6: ='0.2 Data Config'!$L$10 -> 0.7495 | E6: =C6 -> 0.7495 | G6: Overheads & Support (this model) | H6: =C9 -> 4.1105
B7: Platform Overheads | C7: =SUM(H29) -> 0.165 | E7: =C7 -> 0.165 | G7: Variance (budget less cost) | H7: =H5-H6 -> -0.6105
B8: Squad Support Costs | C8: =SUM(H24,H25,H26,H27,H28) -> 3.196 | D8: =SUM(I24,I25,I26,I27,I28) -> 1.904 | E8: =C8+D8 -> 5.1
B9: Total Cost | C9: =SUM(C6:C8) -> 4.1105 | D9: =SUM(D6:D8) -> 1.904 | E9: =C9+D9 -> 6.0145
G10: Other funding
G11: Funding position
G12: Other cost (this model) | I12: =D9 -> 1.904
B13: Total to fund | G13: Funded from TDD Corporate pool (2.4 COE Summary) | I13: 0
B14: TDD Variance | C14: =MAX(0,-H7) -> 0.6105 | G14: Left to fund | I14: =I12-I13 -> 1.904
B15: Other Variance | C15: =MAX(0,I14) -> 1.904
B16: Total | C16: =C14+C15 -> 2.5145
B22: Platform: Group Data
B23: Squad | C23: Squad Type | D23: Size | E23: On/Off | F23: Support % | G23: Total Squad Cost ($m) | H23: TDD Cost ($m) | I23: Funded outside TDD ($m) | K23: Fund
B24: Data Science | C24: Enterprise Data and Insights | D24: M | E24: Onshore | F24: 0.2 | G24: =IFERROR(IF($E24="Onshore",INDEX('0.3 Squad Archetypes'!$G$5:$G$23,MATCH($C24&"|"&$D24,'0.3 Squad Archetypes'!$A$5:$A$23,0)),INDEX('0.3 Squad Archetypes'!$H$5:$H$23,MATCH($C24&"|"&$D24,'0.3 Squad Archetypes'!$A$5:$A$23,0))),"check size") -> 1.7 | H24: =IFERROR($G24*$F24,"") -> 0.34 | I24: =IFERROR($G24*(1-$F24),"") -> 1.36 | K24: AU
B25: Operations | C25: Operations | D25: L | E25: Offshore | F25: 1 | G25: =IFERROR(IF($E25="Onshore",INDEX('0.3 Squad Archetypes'!$G$5:$G$23,MATCH($C25&"|"&$D25,'0.3 Squad Archetypes'!$A$5:$A$23,0)),INDEX('0.3 Squad Archetypes'!$H$5:$H$23,MATCH($C25&"|"&$D25,'0.3 Squad Archetypes'!$A$5:$A$23,0))),"check size") -> 0.92 | H25: =IFERROR($G25*$F25,"") -> 0.92 | I25: =IFERROR($G25*(1-$F25),"") -> 0 | J25: 2 Large to 1 big ops squad offshore and 2 small data squads onshore | K25: AU
B26: Reporting & Analytics | C26: Enterprise Data and Insights | D26: S | E26: Onshore | F26: 1 | G26: =IFERROR(IF($E26="Onshore",INDEX('0.3 Squad Archetypes'!$G$5:$G$23,MATCH($C26&"|"&$D26,'0.3 Squad Archetypes'!$A$5:$A$23,0)),INDEX('0.3 Squad Archetypes'!$H$5:$H$23,MATCH($C26&"|"&$D26,'0.3 Squad Archetypes'!$A$5:$A$23,0))),"check size") -> 0.9 | H26: =IFERROR($G26*$F26,"") -> 0.9 | I26: =IFERROR($G26*(1-$F26),"") -> 0 | K26: AU
B27: Data Platforms | C27: Enterprise Data and Insights | D27: S | E27: Onshore | F27: 1 | G27: =IFERROR(IF($E27="Onshore",INDEX('0.3 Squad Archetypes'!$G$5:$G$23,MATCH($C27&"|"&$D27,'0.3 Squad Archetypes'!$A$5:$A$23,0)),INDEX('0.3 Squad Archetypes'!$H$5:$H$23,MATCH($C27&"|"&$D27,'0.3 Squad Archetypes'!$A$5:$A$23,0))),"check size") -> 0.9 | H27: =IFERROR($G27*$F27,"") -> 0.9 | I27: =IFERROR($G27*(1-$F27),"") -> 0 | K27: AU
B28: Enterprise Data Delivery | C28: Enterprise Data and Insights | D28: M | E28: Offshore | F28: 0.2 | G28: =IFERROR(IF($E28="Onshore",INDEX('0.3 Squad Archetypes'!$G$5:$G$23,MATCH($C28&"|"&$D28,'0.3 Squad Archetypes'!$A$5:$A$23,0)),INDEX('0.3 Squad Archetypes'!$H$5:$H$23,MATCH($C28&"|"&$D28,'0.3 Squad Archetypes'!$A$5:$A$23,0))),"check size") -> 0.68 | H28: =IFERROR($G28*$F28,"") -> 0.136 | I28: =IFERROR($G28*(1-$F28),"") -> 0.544 | K28: AU
B29: Platform Overhead | H29: ='0.2 Data Config'!$L$16 -> 0.165
B30: Group Data Total | G30: =SUM(G24:G28) -> 5.1 | H30: =SUM(H24:H29) -> 3.361 | I30: =SUM(I24:I28) -> 1.904
B32: TDD squad cost - AU funded (Fund toggles) ($m) | C32: =SUMIF(K24:K28,"AU",H24:H28) -> 3.196
B33: TDD squad cost - NZ funded (Fund toggles) ($m) | C33: =SUMIF(K24:K28,"NZ",H24:H28) -> 0

Sheet 1.4 TDD Group Functions
B2: TDD Group Functions
B4: Portfolio Summary | G4: Budget vs TDD Cost
B5: Cost | C5: TDD ($m) | D5: Other ($m) | E5: Total TDD Group Functions Cost ($m) | G5: TDD Lights On Budget (people - 0.2 Data Config) | H5: ='0.2 Data Config'!$E$21 -> 5.5
B6: Portfolio Overhead (see 0.2 Data Config) | C6: ='0.2 Data Config'!$L$10 -> 0.7495 | E6: =C6 -> 0.7495 | G6: Overheads & Support (this model) | H6: =C9 -> 3.6645
B7: Platform Overheads | C7: =SUM(H28) -> 0.165 | E7: =C7 -> 0.165 | G7: Variance (budget less cost) | H7: =H5-H6 -> 1.8355
B8: Squad Support Costs | C8: =SUM(H24,H25,H26,H27,H33) -> 2.75 | D8: =SUM(I24,I25,I26,I27,I33) -> 1.15 | E8: =C8+D8 -> 3.9
B9: Total Cost | C9: =SUM(C6:C8) -> 3.6645 | D9: =SUM(D6:D8) -> 1.15 | E9: =C9+D9 -> 4.8145
G10: Other funding
B11: Lights On funded from the TDD allocation above (Data Config). Shared TDD Corporate pool sits on 2.4 COE Summary. | G11: Funding position
G12: Other cost (this model) | I12: =D9 -> 1.15
B13: Total to fund | G13: Funded from TDD Corporate pool (2.4 COE Summary) | I13: =I33 -> 0
B14: TDD Variance | C14: =MAX(0,-H7) -> 0 | G14: Left to fund | I14: =I12-I13 -> 1.15
B15: Other Variance | C15: =MAX(0,I14) -> 1.15
B16: Total | C16: =C14+C15 -> 1.15
B22: Platform: TDD Group Functions
B23: Squad | C23: Squad Type | D23: Size | E23: On/Off | F23: Support % | G23: Total Squad Cost ($m) | H23: TDD Cost ($m) | I23: Funded outside TDD ($m) | K23: Fund
