Workbook

Sheet 1 Scenarios
B2: Offshore scenario model
B3: Edit only the blue cells: the three scenario names below, and the Offshore? and Start month columns on the 2 Roles tab. Everything else is locked (password with Lee).
B4: Scenario A name | C4: Example scenario | G4: Scenario A is loaded as a worked example with four roles offshored. Overwrite the toggles and the name with your own.
B5: Scenario B name | C5: Scenario B
B6: Scenario C name | C6: Scenario C
B8: Measure | C8: =C4 -> Example scenario | D8: =C5 -> Scenario B | E8: =C6 -> Scenario C
B9: Roles toggled on | C9: =COUNTIF('2 Roles'!K6:K545,"Yes") -> 4 | D9: =COUNTIF('2 Roles'!P6:P545,"Yes") -> 0 | E9: =COUNTIF('2 Roles'!U6:U545,"Yes") -> 0
B10: FTE of those roles | C10: =SUMIF('2 Roles'!K6:K545,"Yes",'2 Roles'!$H$6:$H$545) -> 4 | D10: =SUMIF('2 Roles'!P6:P545,"Yes",'2 Roles'!$H$6:$H$545) -> 0 | E10: =SUMIF('2 Roles'!U6:U545,"Yes",'2 Roles'!$H$6:$H$545) -> 0
B11: Cost of those roles today ($m) | C11: =SUMIF('2 Roles'!K6:K545,"Yes",'2 Roles'!$J$6:$J$545) -> 0.7607 | D11: =SUMIF('2 Roles'!P6:P545,"Yes",'2 Roles'!$J$6:$J$545) -> 0 | E11: =SUMIF('2 Roles'!U6:U545,"Yes",'2 Roles'!$J$6:$J$545) -> 0
B12: Cost of those roles at the rate ($m) | C12: =C11-C13 -> 0.37104 | D12: =D11-D13 -> 0 | E12: =E11-E13 -> 0
B13: Reduction of cost, full year ($m) | C13: =SUM('2 Roles'!M6:M545) -> 0.38966 | D13: =SUM('2 Roles'!R6:R545) -> 0 | E13: =SUM('2 Roles'!W6:W545) -> 0
B14: Impact in FY26 ($m) | C14: =SUM('2 Roles'!N6:N545) -> 0.07118 | D14: =SUM('2 Roles'!S6:S545) -> 0 | E14: =SUM('2 Roles'!X6:X545) -> 0
B15: Impact in FY27 ($m) | C15: =SUM('2 Roles'!O6:O545) -> 0.38966 | D15: =SUM('2 Roles'!T6:T545) -> 0 | E15: =SUM('2 Roles'!Y6:Y545) -> 0
B18: Reduction of cost by portfolio, full year ($m) | C18: =C4 -> Example scenario | D18: =C5 -> Scenario B | E18: =C6 -> Scenario C
B19: Ampol Customer | C19: =SUMIFS('2 Roles'!$M$6:$M$545,'2 Roles'!$D$6:$D$545,$B19) -> 0.16376 | D19: =SUMIFS('2 Roles'!$R$6:$R$545,'2 Roles'!$D$6:$D$545,$B19) -> 0 | E19: =SUMIFS('2 Roles'!$W$6:$W$545,'2 Roles'!$D$6:$D$545,$B19) -> 0
B20: B2B & Energy Solutions | C20: =SUMIFS('2 Roles'!$M$6:$M$545,'2 Roles'!$D$6:$D$545,$B20) -> 0 | D20: =SUMIFS('2 Roles'!$R$6:$R$545,'2 Roles'!$D$6:$D$545,$B20) -> 0 | E20: =SUMIFS('2 Roles'!$W$6:$W$545,'2 Roles'!$D$6:$D$545,$B20) -> 0
B21: Commercial Fuels | C21: =SUMIFS('2 Roles'!$M$6:$M$545,'2 Roles'!$D$6:$D$545,$B21) -> 0 | D21: =SUMIFS('2 Roles'!$R$6:$R$545,'2 Roles'!$D$6:$D$545,$B21) -> 0 | E21: =SUMIFS('2 Roles'!$W$6:$W$545,'2 Roles'!$D$6:$D$545,$B21) -> 0
B22: EGI | C22: =SUMIFS('2 Roles'!$M$6:$M$545,'2 Roles'!$D$6:$D$545,$B22) -> 0 | D22: =SUMIFS('2 Roles'!$R$6:$R$545,'2 Roles'!$D$6:$D$545,$B22) -> 0 | E22: =SUMIFS('2 Roles'!$W$6:$W$545,'2 Roles'!$D$6:$D$545,$B22) -> 0
B23: EGI Integration | C23: =SUMIFS('2 Roles'!$M$6:$M$545,'2 Roles'!$D$6:$D$545,$B23) -> 0 | D23: =SUMIFS('2 Roles'!$R$6:$R$545,'2 Roles'!$D$6:$D$545,$B23) -> 0 | E23: =SUMIFS('2 Roles'!$W$6:$W$545,'2 Roles'!$D$6:$D$545,$B23) -> 0
B24: Enterprise Data | C24: =SUMIFS('2 Roles'!$M$6:$M$545,'2 Roles'!$D$6:$D$545,$B24) -> 0 | D24: =SUMIFS('2 Roles'!$R$6:$R$545,'2 Roles'!$D$6:$D$545,$B24) -> 0 | E24: =SUMIFS('2 Roles'!$W$6:$W$545,'2 Roles'!$D$6:$D$545,$B24) -> 0
B25: Finance | C25: =SUMIFS('2 Roles'!$M$6:$M$545,'2 Roles'!$D$6:$D$545,$B25) -> 0.10494 | D25: =SUMIFS('2 Roles'!$R$6:$R$545,'2 Roles'!$D$6:$D$545,$B25) -> 0 | E25: =SUMIFS('2 Roles'!$W$6:$W$545,'2 Roles'!$D$6:$D$545,$B25) -> 0
B26: Infrastructure | C26: =SUMIFS('2 Roles'!$M$6:$M$545,'2 Roles'!$D$6:$D$545,$B26) -> 0 | D26: =SUMIFS('2 Roles'!$R$6:$R$545,'2 Roles'!$D$6:$D$545,$B26) -> 0 | E26: =SUMIFS('2 Roles'!$W$6:$W$545,'2 Roles'!$D$6:$D$545,$B26) -> 0
B27: NA | C27: =SUMIFS('2 Roles'!$M$6:$M$545,'2 Roles'!$D$6:$D$545,$B27) -> 0 | D27: =SUMIFS('2 Roles'!$R$6:$R$545,'2 Roles'!$D$6:$D$545,$B27) -> 0 | E27: =SUMIFS('2 Roles'!$W$6:$W$545,'2 Roles'!$D$6:$D$545,$B27) -> 0
B28: P&C | C28: =SUMIFS('2 Roles'!$M$6:$M$545,'2 Roles'!$D$6:$D$545,$B28) -> 0 | D28: =SUMIFS('2 Roles'!$R$6:$R$545,'2 Roles'!$D$6:$D$545,$B28) -> 0 | E28: =SUMIFS('2 Roles'!$W$6:$W$545,'2 Roles'!$D$6:$D$545,$B28) -> 0
B29: P&C, Finance & Legal | C29: =SUMIFS('2 Roles'!$M$6:$M$545,'2 Roles'!$D$6:$D$545,$B29) -> 0 | D29: =SUMIFS('2 Roles'!$R$6:$R$545,'2 Roles'!$D$6:$D$545,$B29) -> 0 | E29: =SUMIFS('2 Roles'!$W$6:$W$545,'2 Roles'!$D$6:$D$545,$B29) -> 0
B30: Retail | C30: =SUMIFS('2 Roles'!$M$6:$M$545,'2 Roles'!$D$6:$D$545,$B30) -> 0.12096 | D30: =SUMIFS('2 Roles'!$R$6:$R$545,'2 Roles'!$D$6:$D$545,$B30) -> 0 | E30: =SUMIFS('2 Roles'!$W$6:$W$545,'2 Roles'!$D$6:$D$545,$B30) -> 0
... B33: Z ENERGY (DIGITAL) | C33: =SUMIFS('2 Roles'!$M$6:$M$545,'2 Roles'!$D$6:$D$545,$B33) -> 0 | D33: =SUMIFS('2 Roles'!$R$6:$R$545,'2 Roles'!$D$6:$D$545,$B33) -> 0 | E33: =SUMIFS('2 Roles'!$W$6:$W$545,'2 Roles'!$D$6:$D$545,$B33) -> 0
B34: Not mapped to a portfolio | C34: =SUMIFS('2 Roles'!$M$6:$M$545,'2 Roles'!$D$6:$D$545,"=") -> 0 | D34: =SUMIFS('2 Roles'!$R$6:$R$545,'2 Roles'!$D$6:$D$545,"=") -> 0 | E34: =SUMIFS('2 Roles'!$W$6:$W$545,'2 Roles'!$D$6:$D$545,"=") -> 0
B35: Total | C35: =SUM(C19:C34) -> 0.38966 | D35: =SUM(D19:D34) -> 0 | E35: =SUM(E19:E34) -> 0
B36: Check against the full year row above (should be zero) | C36: =C35-C13 -> 0 | D36: =D35-D13 -> 0 | E36: =E35-E13 -> 0
B37: Built from the role mapping in TDD_FY27_Cost_Calc_0608 (11 August 2026), copied in full on the REVIEW tab. Cost in the book today: filled roles at mapped cost, planned hires at planned spend, held roles at zero, roles already at the offshore rate at 0.4, WiPro at vendor day rates.
B42: Chart data | C42: =C4 -> Example scenario | D42: =C5 -> Scenario B | E42: =C6 -> Scenario C
B43: Impact in FY26 ($m) | C43: =C14 -> 0.07118 | D43: =D14 -> 0 | E43: =E14 -> 0
B44: Impact in FY27 ($m) | C44: =C15 -> 0.38966 | D44: =D15 -> 0 | E44: =E15 -> 0
B45: Reduction of cost, full year ($m) | C45: =C16 -> 0 | D45: =D16 -> 0 | E45: =E16 -> 0

Sheet 2 Roles
B2: Roles and toggles
B3: Toggle Offshore? to Yes and pick a start month. Only the toggle and month cells can be edited. A role already at the offshore rate or on vendor day rates contributes nothing extra. A held role costs nothing today, so offshoring it shows as added cost.
K4: =CONCATENATE("Scenario ",'1 Scenarios'!C4) -> Scenario Example scenario | P4: =CONCATENATE("Scenario ",'1 Scenarios'!C5) -> Scenario Scenario B | U4: =CONCATENATE("Scenario ",'1 Scenarios'!C6) -> Scenario Scenario C
B5: Role ID | C5: Role | D5: Portfolio | E5: Squad or line | F5: Country | G5: Status in the model | H5: FTE | I5: Full onshore cost ($m) | J5: Cost in the book today ($m) | K5: Offshore? | L5: Start month | M5: Reduction a year ($m) | N5: Impact FY26 ($m) | O5: Impact FY27 ($m) | P5: Offshore? | Q5: Start month | R5: Reduction a year ($m) | S5: Impact FY26 ($m) | T5: Impact FY27 ($m) | U5: Offshore? | V5: Start month | W5: Reduction a year ($m) | X5: Impact FY26 ($m) | Y5: Impact FY27 ($m)
B6: R0001 | C6: Delivery Lead | D6: EGI Integration | E6: EGI Customer | F6: AU | G6: Filled | H6: 1 | I6: 0.2642 | J6: 0.2642 | K6: No | M6: =IF(AND($K6="Yes",$G6<>"Vendor day rates"),$J6-0.4*$I6,0) -> 0 | N6: =IF(OR($K6<>"Yes",$L6=""),0,$M6*MAX(0,7-MATCH($L6,MonthList,0))/12) -> 0 | O6: =IF(OR($K6<>"Yes",$L6=""),0,$M6*IF(MATCH($L6,MonthList,0)<=7,12,19-MATCH($L6,MonthList,0))/12) -> 0 | P6: No | R6: =IF(AND($P6="Yes",$G6<>"Vendor day rates"),$J6-0.4*$I6,0) -> 0 | S6: =IF(OR($P6<>"Yes",$Q6=""),0,$R6*MAX(0,7-MATCH($Q6,MonthList,0))/12) -> 0 | T6: =IF(OR($P6<>"Yes",$Q6=""),0,$R6*IF(MATCH($Q6,MonthList,0)<=7,12,19-MATCH($Q6,MonthList,0))/12) -> 0 | U6: No | W6: =IF(AND($U6="Yes",$G6<>"Vendor day rates"),$J6-0.4*$I6,0) -> 0 | X6: =IF(OR($U6<>"Yes",$V6=""),0,$W6*MAX(0,7-MATCH($V6,MonthList,0))/12) -> 0 | Y6: =IF(OR($U6<>"Yes",$V6=""),0,$W6*IF(MATCH($V6,MonthList,0)<=7,12,19-MATCH($V6,MonthList,0))/12) -> 0
B7: R0002 | C7: Snr Business Analyst | D7: Ampol Customer | E7: Ampol Web | F7: AU | G7: Filled | H7: 1 | I7: 0.2729 | J7: 0.2729 | K7: Yes | L7: Oct-2026 | M7: =IF(AND($K7="Yes",$G7<>"Vendor day rates"),$J7-0.4*$I7,0) -> 0.16374 | N7: =IF(OR($K7<>"Yes",$L7=""),0,$M7*MAX(0,7-MATCH($L7,MonthList,0))/12) -> 0.040935 | O7: =IF(OR($K7<>"Yes",$L7=""),0,$M7*IF(MATCH($L7,MonthList,0)<=7,12,19-MATCH($L7,MonthList,0))/12) -> 0.16374 | P7: No | R7: =IF(AND($P7="Yes",$G7<>"Vendor day rates"),$J7-0.4*$I7,0) -> 0 | S7: =IF(OR($P7<>"Yes",$Q7=""),0,$R7*MAX(0,7-MATCH($Q7,MonthList,0))/12) -> 0 | T7: =IF(OR($P7<>"Yes",$Q7=""),0,$R7*IF(MATCH($Q7,MonthList,0)<=7,12,19-MATCH($Q7,MonthList,0))/12) -> 0 | U7: No | W7: =IF(AND($U7="Yes",$G7<>"Vendor day rates"),$J7-0.4*$I7,0) -> 0 | X7: =IF(OR($U7<>"Yes",$V7=""),0,$W7*MAX(0,7-MATCH($V7,MonthList,0))/12) -> 0 | Y7: =IF(OR($U7<>"Yes",$V7=""),0,$W7*IF(MATCH($V7,MonthList,0)<=7,12,19-MATCH($V7,MonthList,0))/12) -> 0
B8: R0003 | C8: Snr Business Analyst | D8: Ampol Customer | E8: Ampol App | F8: AU | G8: Filled | H8: 1 | I8: 0.2591 | J8: 0.2591 | K8: No | M8: =IF(AND($K8="Yes",$G8<>"Vendor day rates"),$J8-0.4*$I8,0) -> 0 | N8: =IF(OR($K8<>"Yes",$L8=""),0,$M8*MAX(0,7-MATCH($L8,MonthList,0))/12) -> 0 | O8: =IF(OR($K8<>"Yes",$L8=""),0,$M8*IF(MATCH($L8,MonthList,0)<=7,12,19-MATCH($L8,MonthList,0))/12) -> 0 | P8: No | R8: =IF(AND($P8="Yes",$G8<>"Vendor day rates"),$J8-0.4*$I8,0) -> 0 | S8: =IF(OR($P8<>"Yes",$Q8=""),0,$R8*MAX(0,7-MATCH($Q8,MonthList,0))/12) -> 0 | T8: =IF(OR($P8<>"Yes",$Q8=""),0,$R8*IF(MATCH($Q8,MonthList,0)<=7,12,19-MATCH($Q8,MonthList,0))/12) -> 0 | U8: No | W8: =IF(AND($U8="Yes",$G8<>"Vendor day rates"),$J8-0.4*$I8,0) -> 0 | X8: =IF(OR($U8<>"Yes",$V8=""),0,$W8*MAX(0,7-MATCH($V8,MonthList,0))/12) -> 0 | Y8: =IF(OR($U8<>"Yes",$V8=""),0,$W8*IF(MATCH($V8,MonthList,0)<=7,12,19-MATCH($V8,MonthList,0))/12) -> 0
B9: R0004 | C9: Business Analyst (SAP Payroll) | D9: EGI | E9: EGI | F9: AU | G9: Filled | H9: 1 | I9: 0.2442 | J9: 0.2442 | K9: No | M9: =IF(AND($K9="Yes",$G9<>"Vendor day rates"),$J9-0.4*$I9,0) -> 0 | N9: =IF(OR($K9<>"Yes",$L9=""),0,$M9*MAX(0,7-MATCH($L9,MonthList,0))/12) -> 0 | O9: =IF(OR($K9<>"Yes",$L9=""),0,$M9*IF(MATCH($L9,MonthList,0)<=7,12,19-MATCH($L9,MonthList,0))/12) -> 0 | P9: No | R9: =IF(AND($P9="Yes",$G9<>"Vendor day rates"),$J9-0.4*$I9,0) -> 0 | S9: =IF(OR($P9<>"Yes",$Q9=""),0,$R9*MAX(0,7-MATCH($Q9,MonthList,0))/12) -> 0 | T9: =IF(OR($P9<>"Yes",$Q9=""),0,$R9*IF(MATCH($Q9,MonthList,0)<=7,12,19-MATCH($Q9,MonthList,0))/12) -> 0 | U9: No | W9: =IF(AND($U9="Yes",$G9<>"Vendor day rates"),$J9-0.4*$I9,0) -> 0 | X9: =IF(OR($U9<>"Yes",$V9=""),0,$W9*MAX(0,7-MATCH($V9,MonthList,0))/12) -> 0 | Y9: =IF(OR($U9<>"Yes",$V9=""),0,$W9*IF(MATCH($V9,MonthList,0)<=7,12,19-MATCH($V9,MonthList,0))/12) -> 0
B10: R0005 | C10: Project Manager (PEP13-EGI-UKG) | D10: EGI | E10: EGI | F10: AU | G10: Filled | H10: 1 | I10: 0.2442 | J10: 0.2442 | K10: No | M10: =IF(AND($K10="Yes",$G10<>"Vendor day rates"),$J10-0.4*$I10,0) -> 0 | N10: =IF(OR($K10<>"Yes",$L10=""),0,$M10*MAX(0,7-MATCH($L10,MonthList,0))/12) -> 0 | O10: =IF(OR($K10<>"Yes",$L10=""),0,$M10*IF(MATCH($L10,MonthList,0)<=7,12,19-MATCH($L10,MonthList,0))/12) -> 0 | P10: No | R10: =IF(AND($P10="Yes",$G10<>"Vendor day rates"),$J10-0.4*$I10,0) -> 0 | S10: =IF(OR($P10<>"Yes",$Q10=""),0,$R10*MAX(0,7-MATCH($Q10,MonthList,0))/12) -> 0 | T10: =IF(OR($P10<>"Yes",$Q10=""),0,$R10*IF(MATCH($Q10,MonthList,0)<=7,12,19-MATCH($Q10,MonthList,0))/12) -> 0 | U10: No | W10: =IF(AND($U10="Yes",$G10<>"Vendor day rates"),$J10-0.4*$I10,0) -> 0 | X10: =IF(OR($U10<>"Yes",$V10=""),0,$W10*MAX(0,7-MATCH($V10,MonthList,0))/12) -> 0 | Y10: =IF(OR($U10<>"Yes",$V10=""),0,$W10*IF(MATCH($V10,MonthList,0)<=7,12,19-MATCH($V10,MonthList,0))/12) -> 0
B11: R0006 | C11: Program Architect | D11: EGI | E11: EGI | F11: AU | G11: Filled | H11: 1 | I11: 0.3108 | J11: 0.3108 | K11: No | M11: =IF(AND($K11="Yes",$G11<>"Vendor day rates"),$J11-0.4*$I11,0) -> 0 | N11: =IF(OR($K11<>"Yes",$L11=""),0,$M11*MAX(0,7-MATCH($L11,MonthList,0))/12) -> 0 | O11: =IF(OR($K11<>"Yes",$L11=""),0,$M11*IF(MATCH($L11,MonthList,0)<=7,12,19-MATCH($L11,MonthList,0))/12) -> 0 | P11: No | R11: =IF(AND($P11="Yes",$G11<>"Vendor day rates"),$J11-0.4*$I11,0) -> 0 | S11: =IF(OR($P11<>"Yes",$Q11=""),0,$R11*MAX(0,7-MATCH($Q11,MonthList,0))/12) -> 0 | T11: =IF(OR($P11<>"Yes",$Q11=""),0,$R11*IF(MATCH($Q11,MonthList,0)<=7,12,19-MATCH($Q11,MonthList,0))/12) -> 0 | U11: No | W11: =IF(AND($U11="Yes",$G11<>"Vendor day rates"),$J11-0.4*$I11,0) -> 0 | X11: =IF(OR($U11<>"Yes",$V11=""),0,$W11*MAX(0,7-MATCH($V11,MonthList,0))/12) -> 0 | Y11: =IF(OR($U11<>"Yes",$V11=""),0,$W11*IF(MATCH($V11,MonthList,0)<=7,12,19-MATCH($V11,MonthList,0))/12) -> 0
B12: R0007 | C12: TDD Strategic Delivery | D12: EGI | E12: EGI | F12: AU | G12: Filled | H12: 1 | I12: 0.2775 | J12: 0.2775 | K12: No | M12: =IF(AND($K12="Yes",$G12<>"Vendor day rates"),$J12-0.4*$I12,0) -> 0 | N12: =IF(OR($K12<>"Yes",$L12=""),0,$M12*MAX(0,7-MATCH($L12,MonthList,0))/12) -> 0 | O12: =IF(OR($K12<>"Yes",$L12=""),0,$M12*IF(MATCH($L12,MonthList,0)<=7,12,19-MATCH($L12,MonthList,0))/12) -> 0 | P12: No | R12: =IF(AND($P12="Yes",$G12<>"Vendor day rates"),$J12-0.4*$I12,0) -> 0 | S12: =IF(OR($P12<>"Yes",$Q12=""),0,$R12*MAX(0,7-MATCH($Q12,MonthList,0))/12) -> 0 | T12: =IF(OR($P12<>"Yes",$Q12=""),0,$R12*IF(MATCH($Q12,MonthList,0)<=7,12,19-MATCH($Q12,MonthList,0))/12) -> 0 | U12: No | W12: =IF(AND($U12="Yes",$G12<>"Vendor day rates"),$J12-0.4*$I12,0) -> 0 | X12: =IF(OR($U12<>"Yes",$V12=""),0,$W12*MAX(0,7-MATCH($V12,MonthList,0))/12) -> 0 | Y12: =IF(OR($U12<>"Yes",$V12=""),0,$W12*IF(MATCH($V12,MonthList,0)<=7,12,19-MATCH($V12,MonthList,0))/12) -> 0
B13: R0008 | C13: Strategic Delivery Consultant | D13: EGI | E13: EGI | F13: AU | G13: Filled | H13: 1 | I13: 0.3013 | J13: 0.3013 | K13: No | M13: =IF(AND($K13="Yes",$G13<>"Vendor day rates"),$J13-0.4*$I13,0) -> 0 | N13: =IF(OR($K13<>"Yes",$L13=""),0,$M13*MAX(0,7-MATCH($L13,MonthList,0))/12) -> 0 | O13: =IF(OR($K13<>"Yes",$L13=""),0,$M13*IF(MATCH($L13,MonthList,0)<=7,12,19-MATCH($L13,MonthList,0))/12) -> 0 | P13: No | R13: =IF(AND($P13="Yes",$G13<>"Vendor day rates"),$J13-0.4*$I13,0) -> 0 | S13: =IF(OR($P13<>"Yes",$Q13=""),0,$R13*MAX(0,7-MATCH($Q13,MonthList,0))/12) -> 0 | T13: =IF(OR($P13<>"Yes",$Q13=""),0,$R13*IF(MATCH($Q13,MonthList,0)<=7,12,19-MATCH($Q13,MonthList,0))/12) -> 0 | U13: No | W13: =IF(AND($U13="Yes",$G13<>"Vendor day rates"),$J13-0.4*$I13,0) -> 0 | X13: =IF(OR($U13<>"Yes",$V13=""),0,$W13*MAX(0,7-MATCH($V13,MonthList,0))/12) -> 0 | Y13: =IF(OR($U13<>"Yes",$V13=""),0,$W13*IF(MATCH($V13,MonthList,0)<=7,12,19-MATCH($V13,MonthList,0))/12) -> 0
B14: R0009 | C14: Program Manager (PEP13-EGI-UKG) | D14: EGI | E14: EGI | F14: AU | G14: Filled | H14: 1 | I14: 0.3432 | J14: 0.3432 | K14: No | M14: =IF(AND($K14="Yes",$G14<>"Vendor day rates"),$J14-0.4*$I14,0) -> 0 | N14: =IF(OR($K14<>"Yes",$L14=""),0,$M14*MAX(0,7-MATCH($L14,MonthList,0))/12) -> 0 | O14: =IF(OR($K14<>"Yes",$L14=""),0,$M14*IF(MATCH($L14,MonthList,0)<=7,12,19-MATCH($L14,MonthList,0))/12) -> 0 | P14: No | R14: =IF(AND($P14="Yes",$G14<>"Vendor day rates"),$J14-0.4*$I14,0) -> 0 | S14: =IF(OR($P14<>"Yes",$Q14=""),0,$R14*MAX(0,7-MATCH($Q14,MonthList,0))/12) -> 0 | T14: =IF(OR($P14<>"Yes",$Q14=""),0,$R14*IF(MATCH($Q14,MonthList,0)<=7,12,19-MATCH($Q14,MonthList,0))/12) -> 0 | U14: No | W14: =IF(AND($U14="Yes",$G14<>"Vendor day rates"),$J14-0.4*$I14,0) -> 0 | X14: =IF(OR($U14<>"Yes",$V14=""),0,$W14*MAX(0,7-MATCH($V14,MonthList,0))/12) -> 0 | Y14: =IF(OR($U14<>"Yes",$V14=""),0,$W14*IF(MATCH($V14,MonthList,0)<=7,12,19-MATCH($V14,MonthList,0))/12) -> 0
B15: R0010 | C15: Program Manager Tech & P&C | D15: EGI | E15: EGI | F15: AU | G15: Filled | H15: 1 | I15: 0.2664 | J15: 0.2664 | K15: No | M15: =IF(AND($K15="Yes",$G15<>"Vendor day rates"),$J15-0.4*$I15,0) -> 0 | N15: =IF(OR($K15<>"Yes",$L15=""),0,$M15*MAX(0,7-MATCH($L15,MonthList,0))/12) -> 0 | O15: =IF(OR($K15<>"Yes",$L15=""),0,$M15*IF(MATCH($L15,MonthList,0)<=7,12,19-MATCH($L15,MonthList,0))/12) -> 0 | P15: No | R15: =IF(AND($P15="Yes",$G15<>"Vendor day rates"),$J15-0.4*$I15,0) -> 0 | S15: =IF(OR($P15<>"Yes",$Q15=""),0,$R15*MAX(0,7-MATCH($Q15,MonthList,0))/12) -> 0 | T15: =IF(OR($P15<>"Yes",$Q15=""),0,$R15*IF(MATCH($Q15,MonthList,0)<=7,12,19-MATCH($Q15,MonthList,0))/12) -> 0 | U15: No | W15: =IF(AND($U15="Yes",$G15<>"Vendor day rates"),$J15-0.4*$I15,0) -> 0 | X15: =IF(OR($U15<>"Yes",$V15=""),0,$W15*MAX(0,7-MATCH($V15,MonthList,0))/12) -> 0 | Y15: =IF(OR($U15<>"Yes",$V15=""),0,$W15*IF(MATCH($V15,MonthList,0)<=7,12,19-MATCH($V15,MonthList,0))/12) -> 0
B16: R0011 | C16: Project Manager Retail | D16: EGI | E16: EGI | F16: AU | G16: Filled | H16: 1 | I16: 0.4884 | J16: 0.4884 | K16: No | M16: =IF(AND($K16="Yes",$G16<>"Vendor day rates"),$J16-0.4*$I16,0) -> 0 | N16: =IF(OR($K16<>"Yes",$L16=""),0,$M16*MAX(0,7-MATCH($L16,MonthList,0))/12) -> 0 | O16: =IF(OR($K16<>"Yes",$L16=""),0,$M16*IF(MATCH($L16,MonthList,0)<=7,12,19-MATCH($L16,MonthList,0))/12) -> 0 | P16: No | R16: =IF(AND($P16="Yes",$G16<>"Vendor day rates"),$J16-0.4*$I16,0) -> 0 | S16: =IF(OR($P16<>"Yes",$Q16=""),0,$R16*MAX(0,7-MATCH($Q16,MonthList,0))/12) -> 0 | T16: =IF(OR($P16<>"Yes",$Q16=""),0,$R16*IF(MATCH($Q16,MonthList,0)<=7,12,19-MATCH($Q16,MonthList,0))/12) -> 0 | U16: No | W16: =IF(AND($U16="Yes",$G16<>"Vendor day rates"),$J16-0.4*$I16,0) -> 0 | X16: =IF(OR($U16<>"Yes",$V16=""),0,$W16*MAX(0,7-MATCH($V16,MonthList,0))/12) -> 0 | Y16: =IF(OR($U16<>"Yes",$V16=""),0,$W16*IF(MATCH($V16,MonthList,0)<=7,12,19-MATCH($V16,MonthList,0))/12) -> 0
B17: R0012 | C17: Strategic Delivery Consultant | D17: EGI | E17: EGI | F17: AU | G17: Filled | H17: 1 | I17: 0.2997 | J17: 0.2997 | K17: No | M17: =IF(AND($K17="Yes",$G17<>"Vendor day rates"),$J17-0.4*$I17,0) -> 0 | N17: =IF(OR($K17<>"Yes",$L17=""),0,$M17*MAX(0,7-MATCH($L17,MonthList,0))/12) -> 0 | O17: =IF(OR($K17<>"Yes",$L17=""),0,$M17*IF(MATCH($L17,MonthList,0)<=7,12,19-MATCH($L17,MonthList,0))/12) -> 0 | P17: No | R17: =IF(AND($P17="Yes",$G17<>"Vendor day rates"),$J17-0.4*$I17,0) -> 0 | S17: =IF(OR($P17<>"Yes",$Q17=""),0,$R17*MAX(0,7-MATCH($Q17,MonthList,0))/12) -> 0 | T17: =IF(OR($P17<>"Yes",$Q17=""),0,$R17*IF(MATCH($Q17,MonthList,0)<=7,12,19-MATCH($Q17,MonthList,0))/12) -> 0 | U17: No | W17: =IF(AND($U17="Yes",$G17<>"Vendor day rates"),$J17-0.4*$I17,0) -> 0 | X17: =IF(OR($U17<>"Yes",$V17=""),0,$W17*MAX(0,7-MATCH($V17,MonthList,0))/12) -> 0 | Y17: =IF(OR($U17<>"Yes",$V17=""),0,$W17*IF(MATCH($V17,MonthList,0)<=7,12,19-MATCH($V17,MonthList,0))/12) -> 0
B18: R0013 | C18: Strategic Delivery Consultant | D18: EGI | E18: EGI | F18: AU | G18: Filled | H18: 1 | I18: 0.2304 | J18: 0.2304 | K18: No | M18: =IF(AND($K18="Yes",$G18<>"Vendor day rates"),$J18-0.4*$I18,0) -> 0 | N18: =IF(OR($K18<>"Yes",$L18=""),0,$M18*MAX(0,7-MATCH($L18,MonthList,0))/12) -> 0 | O18: =IF(OR($K18<>"Yes",$L18=""),0,$M18*IF(MATCH($L18,MonthList,0)<=7,12,19-MATCH($L18,MonthList,0))/12) -> 0 | P18: No | R18: =IF(AND($P18="Yes",$G18<>"Vendor day rates"),$J18-0.4*$I18,0) -> 0 | S18: =IF(OR($P18<>"Yes",$Q18=""),0,$R18*MAX(0,7-MATCH($Q18,MonthList,0))/12) -> 0 | T18: =IF(OR($P18<>"Yes",$Q18=""),0,$R18*IF(MATCH($Q18,MonthList,0)<=7,12,19-MATCH($Q18,MonthList,0))/12) -> 0 | U18: No | W18: =IF(AND($U18="Yes",$G18<>"Vendor day rates"),$J18-0.4*$I18,0) -> 0 | X18: =IF(OR($U18<>"Yes",$V18=""),0,$W18*MAX(0,7-MATCH($V18,MonthList,0))/12) -> 0 | Y18: =IF(OR($U18<>"Yes",$V18=""),0,$W18*IF(MATCH($V18,MonthList,0)<=7,12,19-MATCH($V18,MonthList,0))/12) -> 0
B19: R0014 | C19: Project Manager Deployment | E19: EGI | F19: AU | G19: Filled | H19: 1 | I19: 0.2664 | J19: 0.2664 | K19: No | M19: =IF(AND($K19="Yes",$G19<>"Vendor day rates"),$J19-0.4*$I19,0) -> 0 | N19: =IF(OR($K19<>"Yes",$L19=""),0,$M19*MAX(0,7-MATCH($L19,MonthList,0))/12) -> 0 | O19: =IF(OR($K19<>"Yes",$L19=""),0,$M19*IF(MATCH($L19,MonthList,0)<=7,12,19-MATCH($L19,MonthList,0))/12) -> 0 | P19: No | R19: =IF(AND($P19="Yes",$G19<>"Vendor day rates"),$J19-0.4*$I19,0) -> 0 | S19: =IF(OR($P19<>"Yes",$Q19=""),0,$R19*MAX(0,7-MATCH($Q19,MonthList,0))/12) -> 0 | T19: =IF(OR($P19<>"Yes",$Q19=""),0,$R19*IF(MATCH($Q19,MonthList,0)<=7,12,19-MATCH($Q19,MonthList,0))/12) -> 0 | U19: No | W19: =IF(AND($U19="Yes",$G19<>"Vendor day rates"),$J19-0.4*$I19,0) -> 0 | X19: =IF(OR($U19<>"Yes",$V19=""),0,$W19*MAX(0,7-MATCH($V19,MonthList,0))/12) -> 0 | Y19: =IF(OR($U19<>"Yes",$V19=""),0,$W19*IF(MATCH($V19,MonthList,0)<=7,12,19-MATCH($V19,MonthList,0))/12) -> 0
B20: R0015 | C20: Reporting Analyst | D20: Infrastructure | E20: Data & Insights | F20: AU | G20: Filled | H20: 1 | I20: 0.1976 | J20: 0.1976 | K20: No | M20: =IF(AND($K20="Yes",$G20<>"Vendor day rates"),$J20-0.4*$I20,0) -> 0 | N20: =IF(OR($K20<>"Yes",$L20=""),0,$M20*MAX(0,7-MATCH($L20,MonthList,0))/12) -> 0 | O20: =IF(OR($K20<>"Yes",$L20=""),0,$M20*IF(MATCH($L20,MonthList,0)<=7,12,19-MATCH($L20,MonthList,0))/12) -> 0 | P20: No | R20: =IF(AND($P20="Yes",$G20<>"Vendor day rates"),$J20-0.4*$I20,0) -> 0 | S20: =IF(OR($P20<>"Yes",$Q20=""),0,$R20*MAX(0,7-MATCH($Q20,MonthList,0))/12) -> 0 | T20: =IF(OR($P20<>"Yes",$Q20=""),0,$R20*IF(MATCH($Q20,MonthList,0)<=7,12,19-MATCH($Q20,MonthList,0))/12) -> 0 | U20: No | W20: =IF(AND($U20="Yes",$G20<>"Vendor day rates"),$J20-0.4*$I20,0) -> 0 | X20: =IF(OR($U20<>"Yes",$V20=""),0,$W20*MAX(0,7-MATCH($V20,MonthList,0))/12) -> 0 | Y20: =IF(OR($U20<>"Yes",$V20=""),0,$W20*IF(MATCH($V20,MonthList,0)<=7,12,19-MATCH($V20,MonthList,0))/12) -> 0
B21: R0016 | C21: QA / Tester / Mid | D21: Ampol Customer | E21: Ampol Loyalty & Martech | F21: AU | G21: Vendor day rates | H21: 1 | I21: 0.0733 | J21: 0.0733 | K21: No | M21: =IF(AND($K21="Yes",$G21<>"Vendor day rates"),$J21-0.4*$I21,0) -> 0 | N21: =IF(OR($K21<>"Yes",$L21=""),0,$M21*MAX(0,7-MATCH($L21,MonthList,0))/12) -> 0 | O21: =IF(OR($K21<>"Yes",$L21=""),0,$M21*IF(MATCH($L21,MonthList,0)<=7,12,19-MATCH($L21,MonthList,0))/12) -> 0 | P21: No | R21: =IF(AND($P21="Yes",$G21<>"Vendor day rates"),$J21-0.4*$I21,0) -> 0 | S21: =IF(OR($P21<>"Yes",$Q21=""),0,$R21*MAX(0,7-MATCH($Q21,MonthList,0))/12) -> 0 | T21: =IF(OR($P21<>"Yes",$Q21=""),0,$R21*IF(MATCH($Q21,MonthList,0)<=7,12,19-MATCH($Q21,MonthList,0))/12) -> 0 | U21: No | W21: =IF(AND($U21="Yes",$G21<>"Vendor day rates"),$J21-0.4*$I21,0) -> 0 | X21: =IF(OR($U21<>"Yes",$V21=""),0,$W21*MAX(0,7-MATCH($V21,MonthList,0))/12) -> 0 | Y21: =IF(OR($U21<>"Yes",$V21=""),0,$W21*IF(MATCH($V21,MonthList,0)<=7,12,19-MATCH($V21,MonthList,0))/12) -> 0
B22: R0017 | C22: Systems Analyst / Mid | D22: Ampol Customer | E22: Ampol Loyalty & Martech | F22: AU | G22: Vendor day rates | H22: 1 | I22: 0.0733 | J22: 0.0733 | K22: No | M22: =IF(AND($K22="Yes",$G22<>"Vendor day rates"),$J22-0.4*$I22,0) -> 0 | N22: =IF(OR($K22<>"Yes",$L22=""),0,$M22*MAX(0,7-MATCH($L22,MonthList,0))/12) -> 0 | O22: =IF(OR($K22<>"Yes",$L22=""),0,$M22*IF(MATCH($L22,MonthList,0)<=7,12,19-MATCH($L22,MonthList,0))/12) -> 0 | P22: No | R22: =IF(AND($P22="Yes",$G22<>"Vendor day rates"),$J22-0.4*$I22,0) -> 0 | S22: =IF(OR($P22<>"Yes",$Q22=""),0,$R22*MAX(0,7-MATCH($Q22,MonthList,0))/12) -> 0 | T22: =IF(OR($P22<>"Yes",$Q22=""),0,$R22*IF(MATCH($Q22,MonthList,0)<=7,12,19-MATCH($Q22,MonthList,0))/12) -> 0 | U22: No | W22: =IF(AND($U22="Yes",$G22<>"Vendor day rates"),$J22-0.4*$I22,0) -> 0 | X22: =IF(OR($U22<>"Yes",$V22=""),0,$W22*MAX(0,7-MATCH($V22,MonthList,0))/12) -> 0 | Y22: =IF(OR($U22<>"Yes",$V22=""),0,$W22*IF(MATCH($V22,MonthList,0)<=7,12,19-MATCH($V22,MonthList,0))/12) -> 0
B23: R0018 | C23: Data Migration Lead | D23: EGI Integration | E23: EGI TDD | F23: AU | G23: Filled | H23: 1 | I23: 0.2997 | J23: 0.2997 | K23: No | M23: =IF(AND($K23="Yes",$G23<>"Vendor day rates"),$J23-0.4*$I23,0) -> 0 | N23: =IF(OR($K23<>"Yes",$L23=""),0,$M23*MAX(0,7-MATCH($L23,MonthList,0))/12) -> 0 | O23: =IF(OR($K23<>"Yes",$L23=""),0,$M23*IF(MATCH($L23,MonthList,0)<=7,12,19-MATCH($L23,MonthList,0))/12) -> 0 | P23: No | R23: =IF(AND($P23="Yes",$G23<>"Vendor day rates"),$J23-0.4*$I23,0) -> 0 | S23: =IF(OR($P23<>"Yes",$Q23=""),0,$R23*MAX(0,7-MATCH($Q23,MonthList,0))/12) -> 0 | T23: =IF(OR($P23<>"Yes",$Q23=""),0,$R23*IF(MATCH($Q23,MonthList,0)<=7,12,19-MATCH($Q23,MonthList,0))/12) -> 0 | U23: No | W23: =IF(AND($U23="Yes",$G23<>"Vendor day rates"),$J23-0.4*$I23,0) -> 0 | X23: =IF(OR($U23<>"Yes",$V23=""),0,$W23*MAX(0,7-MATCH($V23,MonthList,0))/12) -> 0 | Y23: =IF(OR($U23<>"Yes",$V23=""),0,$W23*IF(MATCH($V23,MonthList,0)<=7,12,19-MATCH($V23,MonthList,0))/12) -> 0
B24: R0019 | C24: .NET Back End Developer / Mid | D24: Ampol Customer | E24: Digital Operations | F24: AU | G24: Vendor day rates | H24: 1 | I24: 0.0733 | J24: 0.0733 | K24: No | M24: =IF(AND($K24="Yes",$G24<>"Vendor day rates"),$J24-0.4*$I24,0) -> 0 | N24: =IF(OR($K24<>"Yes",$L24=""),0,$M24*MAX(0,7-MATCH($L24,MonthList,0))/12) -> 0 | O24: =IF(OR($K24<>"Yes",$L24=""),0,$M24*IF(MATCH($L24,MonthList,0)<=7,12,19-MATCH($L24,MonthList,0))/12) -> 0 | P24: No | R24: =IF(AND($P24="Yes",$G24<>"Vendor day rates"),$J24-0.4*$I24,0) -> 0 | S24: =IF(OR($P24<>"Yes",$Q24=""),0,$R24*MAX(0,7-MATCH($Q24,MonthList,0))/12) -> 0 | T24: =IF(OR($P24<>"Yes",$Q24=""),0,$R24*IF(MATCH($Q24,MonthList,0)<=7,12,19-MATCH($Q24,MonthList,0))/12) -> 0 | U24: No | W24: =IF(AND($U24="Yes",$G24<>"Vendor day rates"),$J24-0.4*$I24,0) -> 0 | X24: =IF(OR($U24<>"Yes",$V24=""),0,$W24*MAX(0,7-MATCH($V24,MonthList,0))/12) -> 0 | Y24: =IF(OR($U24<>"Yes",$V24=""),0,$W24*IF(MATCH($V24,MonthList,0)<=7,12,19-MATCH($V24,MonthList,0))/12) -> 0
B25: R0020 | C25: .NET Back End Developer / Mid | D25: Ampol Customer | E25: Digital Operations | F25: AU | G25: Vendor day rates | H25: 1 | I25: 0.0733 | J25: 0.0733 | K25: No | M25: =IF(AND($K25="Yes",$G25<>"Vendor day rates"),$J25-0.4*$I25,0) -> 0 | N25: =IF(OR($K25<>"Yes",$L25=""),0,$M25*MAX(0,7-MATCH($L25,MonthList,0))/12) -> 0 | O25: =IF(OR($K25<>"Yes",$L25=""),0,$M25*IF(MATCH($L25,MonthList,0)<=7,12,19-MATCH($L25,MonthList,0))/12) -> 0 | P25: No | R25: =IF(AND($P25="Yes",$G25<>"Vendor day rates"),$J25-0.4*$I25,0) -> 0 | S25: =IF(OR($P25<>"Yes",$Q25=""),0,$R25*MAX(0,7-MATCH($Q25,MonthList,0))/12) -> 0 | T25: =IF(OR($P25<>"Yes",$Q25=""),0,$R25*IF(MATCH($Q25,MonthList,0)<=7,12,19-MATCH($Q25,MonthList,0))/12) -> 0 | U25: No | W25: =IF(AND($U25="Yes",$G25<>"Vendor day rates"),$J25-0.4*$I25,0) -> 0 | X25: =IF(OR($U25<>"Yes",$V25=""),0,$W25*MAX(0,7-MATCH($V25,MonthList,0))/12) -> 0 | Y25: =IF(OR($U25<>"Yes",$V25=""),0,$W25*IF(MATCH($V25,MonthList,0)<=7,12,19-MATCH($V25,MonthList,0))/12) -> 0
B26: R0021 | C26: .NET Back End Developer / Mid | D26: Ampol Customer | E26: Digital Operations | F26: AU | G26: Vendor day rates | H26: 1 | I26: 0.0733 | J26: 0.0733 | K26: No | M26: =IF(AND($K26="Yes",$G26<>"Vendor day rates"),$J26-0.4*$I26,0) -> 0 | N26: =IF(OR($K26<>"Yes",$L26=""),0,$M26*MAX(0,7-MATCH($L26,MonthList,0))/12) -> 0 | O26: =IF(OR($K26<>"Yes",$L26=""),0,$M26*IF(MATCH($L26,MonthList,0)<=7,12,19-MATCH($L26,MonthList,0))/12) -> 0 | P26: No | R26: =IF(AND($P26="Yes",$G26<>"Vendor day rates"),$J26-0.4*$I26,0) -> 0 | S26: =IF(OR($P26<>"Yes",$Q26=""),0,$R26*MAX(0,7-MATCH($Q26,MonthList,0))/12) -> 0 | T26: =IF(OR($P26<>"Yes",$Q26=""),0,$R26*IF(MATCH($Q26,MonthList,0)<=7,12,19-MATCH($Q26,MonthList,0))/12) -> 0 | U26: No | W26: =IF(AND($U26="Yes",$G26<>"Vendor day rates"),$J26-0.4*$I26,0) -> 0 | X26: =IF(OR($U26<>"Yes",$V26=""),0,$W26*MAX(0,7-MATCH($V26,MonthList,0))/12) -> 0 | Y26: =IF(OR($U26<>"Yes",$V26=""),0,$W26*IF(MATCH($V26,MonthList,0)<=7,12,19-MATCH($V26,MonthList,0))/12) -> 0
B27: R0022 | C27: QA / Tester / Mid | D27: Ampol Customer | E27: Digital Operations | F27: AU | G27: Vendor day rates | H27: 1 | I27: 0.0733 | J27: 0.0733 | K27: No | M27: =IF(AND($K27="Yes",$G27<>"Vendor day rates"),$J27-0.4*$I27,0) -> 0 | N27: =IF(OR($K27<>"Yes",$L27=""),0,$M27*MAX(0,7-MATCH($L27,MonthList,0))/12) -> 0 | O27: =IF(OR($K27<>"Yes",$L27=""),0,$M27*IF(MATCH($L27,MonthList,0)<=7,12,19-MATCH($L27,MonthList,0))/12) -> 0 | P27: No | R27: =IF(AND($P27="Yes",$G27<>"Vendor day rates"),$J27-0.4*$I27,0) -> 0 | S27: =IF(OR($P27<>"Yes",$Q27=""),0,$R27*MAX(0,7-MATCH($Q27,MonthList,0))/12) -> 0 | T27: =IF(OR($P27<>"Yes",$Q27=""),0,$R27*IF(MATCH($Q27,MonthList,0)<=7,12,19-MATCH($Q27,MonthList,0))/12) -> 0 | U27: No | W27: =IF(AND($U27="Yes",$G27<>"Vendor day rates"),$J27-0.4*$I27,0) -> 0 | X27: =IF(OR($U27<>"Yes",$V27=""),0,$W27*MAX(0,7-MATCH($V27,MonthList,0))/12) -> 0 | Y27: =IF(OR($U27<>"Yes",$V27=""),0,$W27*IF(MATCH($V27,MonthList,0)<=7,12,19-MATCH($V27,MonthList,0))/12) -> 0
B28: R0023 | C28: Integration Architect (C) - Boomi | D28: EGI | E28: EGI TDD | F28: AU | G28: Filled | H28: 1 | I28: 0.3481 | J28: 0.3481 | K28: No | M28: =IF(AND($K28="Yes",$G28<>"Vendor day rates"),$J28-0.4*$I28,0) -> 0 | N28: =IF(OR($K28<>"Yes",$L28=""),0,$M28*MAX(0,7-MATCH($L28,MonthList,0))/12) -> 0 | O28: =IF(OR($K28<>"Yes",$L28=""),0,$M28*IF(MATCH($L28,MonthList,0)<=7,12,19-MATCH($L28,MonthList,0))/12) -> 0 | P28: No | R28: =IF(AND($P28="Yes",$G28<>"Vendor day rates"),$J28-0.4*$I28,0) -> 0 | S28: =IF(OR($P28<>"Yes",$Q28=""),0,$R28*MAX(0,7-MATCH($Q28,MonthList,0))/12) -> 0 | T28: =IF(OR($P28<>"Yes",$Q28=""),0,$R28*IF(MATCH($Q28,MonthList,0)<=7,12,19-MATCH($Q28,MonthList,0))/12) -> 0 | U28: No | W28: =IF(AND($U28="Yes",$G28<>"Vendor day rates"),$J28-0.4*$I28,0) -> 0 | X28: =IF(OR($U28<>"Yes",$V28=""),0,$W28*MAX(0,7-MATCH($V28,MonthList,0))/12) -> 0 | Y28: =IF(OR($U28<>"Yes",$V28=""),0,$W28*IF(MATCH($V28,MonthList,0)<=7,12,19-MATCH($V28,MonthList,0))/12) -> 0
B29: R0024 | C29: Integration Architect (C) | D29: EGI | E29: EGI TDD | F29: NZ | G29: Filled | H29: 1 | I29: 0.2664 | J29: 0.2664 | K29: No | M29: =IF(AND($K29="Yes",$G29<>"Vendor day rates"),$J29-0.4*$I29,0) -> 0 | N29: =IF(OR($K29<>"Yes",$L29=""),0,$M29*MAX(0,7-MATCH($L29,MonthList,0))/12) -> 0 | O29: =IF(OR($K29<>"Yes",$L29=""),0,$M29*IF(MATCH($L29,MonthList,0)<=7,12,19-MATCH($L29,MonthList,0))/12) -> 0 | P29: No | R29: =IF(AND($P29="Yes",$G29<>"Vendor day rates"),$J29-0.4*$I29,0) -> 0 | S29: =IF(OR($P29<>"Yes",$Q29=""),0,$R29*MAX(0,7-MATCH($Q29,MonthList,0))/12) -> 0 | T29: =IF(OR($P29<>"Yes",$Q29=""),0,$R29*IF(MATCH($Q29,MonthList,0)<=7,12,19-MATCH($Q29,MonthList,0))/12) -> 0 | U29: No | W29: =IF(AND($U29="Yes",$G29<>"Vendor day rates"),$J29-0.4*$I29,0) -> 0 | X29: =IF(OR($U29<>"Yes",$V29=""),0,$W29*MAX(0,7-MATCH($V29,MonthList,0))/12) -> 0 | Y29: =IF(OR($U29<>"Yes",$V29=""),0,$W29*IF(MATCH($V29,MonthList,0)<=7,12,19-MATCH($V29,MonthList,0))/12) -> 0
B30: R0025 | C30: Engineer - Mobile | D30: Ampol Customer | E30: Ampol App | F30: AU | G30: Filled | H30: 1 | I30: 0.1909 | J30: 0.1909 | K30: No | M30: =IF(AND($K30="Yes",$G30<>"Vendor day rates"),$J30-0.4*$I30,0) -> 0 | N30: =IF(OR($K30<>"Yes",$L30=""),0,$M30*MAX(0,7-MATCH($L30,MonthList,0))/12) -> 0 | O30: =IF(OR($K30<>"Yes",$L30=""),0,$M30*IF(MATCH($L30,MonthList,0)<=7,12,19-MATCH($L30,MonthList,0))/12) -> 0 | P30: No | R30: =IF(AND($P30="Yes",$G30<>"Vendor day rates"),$J30-0.4*$I30,0) -> 0 | S30: =IF(OR($P30<>"Yes",$Q30=""),0,$R30*MAX(0,7-MATCH($Q30,MonthList,0))/12) -> 0 | T30: =IF(OR($P30<>"Yes",$Q30=""),0,$R30*IF(MATCH($Q30,MonthList,0)<=7,12,19-MATCH($Q30,MonthList,0))/12) -> 0 | U30: No | W30: =IF(AND($U30="Yes",$G30<>"Vendor day rates"),$J30-0.4*$I30,0) -> 0 | X30: =IF(OR($U30<>"Yes",$V30=""),0,$W30*MAX(0,7-MATCH($V30,MonthList,0))/12) -> 0 | Y30: =IF(OR($U30<>"Yes",$V30=""),0,$W30*IF(MATCH($V30,MonthList,0)<=7,12,19-MATCH($V30,MonthList,0))/12) -> 0
B31: R0026 | C31: Solution Architect | D31: Ampol Customer | E31: Ampol Web | F31: AU | G31: Filled | H31: 1 | I31: 0.3219 | J31: 0.3219 | K31: No | M31: =IF(AND($K31="Yes",$G31<>"Vendor day rates"),$J31-0.4*$I31,0) -> 0 | N31: =IF(OR($K31<>"Yes",$L31=""),0,$M31*MAX(0,7-MATCH($L31,MonthList,0))/12) -> 0 | O31: =IF(OR($K31<>"Yes",$L31=""),0,$M31*IF(MATCH($L31,MonthList,0)<=7,12,19-MATCH($L31,MonthList,0))/12) -> 0 | P31: No | R31: =IF(AND($P31="Yes",$G31<>"Vendor day rates"),$J31-0.4*$I31,0) -> 0 | S31: =IF(OR($P31<>"Yes",$Q31=""),0,$R31*MAX(0,7-MATCH($Q31,MonthList,0))/12) -> 0 | T31: =IF(OR($P31<>"Yes",$Q31=""),0,$R31*IF(MATCH($Q31,MonthList,0)<=7,12,19-MATCH($Q31,MonthList,0))/12) -> 0 | U31: No | W31: =IF(AND($U31="Yes",$G31<>"Vendor day rates"),$J31-0.4*$I31,0) -> 0 | X31: =IF(OR($U31<>"Yes",$V31=""),0,$W31*MAX(0,7-MATCH($V31,MonthList,0))/12) -> 0 | Y31: =IF(OR($U31<>"Yes",$V31=""),0,$W31*IF(MATCH($V31,MonthList,0)<=7,12,19-MATCH($V31,MonthList,0))/12) -> 0
... B33: R0028 | C33: Quality Assurance | D33: Ampol Customer | E33: Ampol App | F33: AU | G33: Already at the offshore rate | H33: 1 | I33: 0.1792 | J33: 0.0717 | K33: No | M33: =IF(AND($K33="Yes",$G33<>"Vendor day rates"),$J33-0.4*$I33,0) -> 0 | N33: =IF(OR($K33<>"Yes",$L33=""),0,$M33*MAX(0,7-MATCH($L33,MonthList,0))/12) -> 0 | O33: =IF(OR($K33<>"Yes",$L33=""),0,$M33*IF(MATCH($L33,MonthList,0)<=7,12,19-MATCH($L33,MonthList,0))/12) -> 0 | P33: No | R33: =IF(AND($P33="Yes",$G33<>"Vendor day rates"),$J33-0.4*$I33,0) -> 0 | S33: =IF(OR($P33<>"Yes",$Q33=""),0,$R33*MAX(0,7-MATCH($Q33,MonthList,0))/12) -> 0 | T33: =IF(OR($P33<>"Yes",$Q33=""),0,$R33*IF(MATCH($Q33,MonthList,0)<=7,12,19-MATCH($Q33,MonthList,0))/12) -> 0 | U33: No | W33: =IF(AND($U33="Yes",$G33<>"Vendor day rates"),$J33-0.4*$I33,0) -> 0 | X33: =IF(OR($U33<>"Yes",$V33=""),0,$W33*MAX(0,7-MATCH($V33,MonthList,0))/12) -> 0 | Y33: =IF(OR($U33<>"Yes",$V33=""),0,$W33*IF(MATCH($V33,MonthList,0)<=7,12,19-MATCH($V33,MonthList,0))/12) -> 0
B34: R0029 | C34: Lead Engineer - Mobile | D34: Ampol Customer | E34: Ampol App | F34: AU | G34: Already at the offshore rate | H34: 1 | I34: 0.2782 | J34: 0.1113 | K34: Yes | L34: Oct-2026 | M34: =IF(AND($K34="Yes",$G34<>"Vendor day rates"),$J34-0.4*$I34,0) -> 2e-05 | N34: =IF(OR($K34<>"Yes",$L34=""),0,$M34*MAX(0,7-MATCH($L34,MonthList,0))/12) -> 5e-06 | O34: =IF(OR($K34<>"Yes",$L34=""),0,$M34*IF(MATCH($L34,MonthList,0)<=7,12,19-MATCH($L34,MonthList,0))/12) -> 2e-05 | P34: No | R34: =IF(AND($P34="Yes",$G34<>"Vendor day rates"),$J34-0.4*$I34,0) -> 0 | S34: =IF(OR($P34<>"Yes",$Q34=""),0,$R34*MAX(0,7-MATCH($Q34,MonthList,0))/12) -> 0 | T34: =IF(OR($P34<>"Yes",$Q34=""),0,$R34*IF(MATCH($Q34,MonthList,0)<=7,12,19-MATCH($Q34,MonthList,0))/12) -> 0 | U34: No | W34: =IF(AND($U34="Yes",$G34<>"Vendor day rates"),$J34-0.4*$I34,0) -> 0 | X34: =IF(OR($U34<>"Yes",$V34=""),0,$W34*MAX(0,7-MATCH($V34,MonthList,0))/12) -> 0 | Y34: =IF(OR($U34<>"Yes",$V34=""),0,$W34*IF(MATCH($V34,MonthList,0)<=7,12,19-MATCH($V34,MonthList,0))/12) -> 0
B35: R0030 | C35: Solution Architect | D35: Ampol Customer | E35: Ampol Web | F35: AU | G35: Filled | H35: 1 | I35: 0.2431 | J35: 0.2431 | K35: No | M35: =IF(AND($K35="Yes",$G35<>"Vendor day rates"),$J35-0.4*$I35,0) -> 0 | N35: =IF(OR($K35<>"Yes",$L35=""),0,$M35*MAX(0,7-MATCH($L35,MonthList,0))/12) -> 0 | O35: =IF(OR($K35<>"Yes",$L35=""),0,$M35*IF(MATCH($L35,MonthList,0)<=7,12,19-MATCH($L35,MonthList,0))/12) -> 0 | P35: No | R35: =IF(AND($P35="Yes",$G35<>"Vendor day rates"),$J35-0.4*$I35,0) -> 0 | S35: =IF(OR($P35<>"Yes",$Q35=""),0,$R35*MAX(0,7-MATCH($Q35,MonthList,0))/12) -> 0 | T35: =IF(OR($P35<>"Yes",$Q35=""),0,$R35*IF(MATCH($Q35,MonthList,0)<=7,12,19-MATCH($Q35,MonthList,0))/12) -> 0 | U35: No | W35: =IF(AND($U35="Yes",$G35<>"Vendor day rates"),$J35-0.4*$I35,0) -> 0 | X35: =IF(OR($U35<>"Yes",$V35=""),0,$W35*MAX(0,7-MATCH($V35,MonthList,0))/12) -> 0 | Y35: =IF(OR($U35<>"Yes",$V35=""),0,$W35*IF(MATCH($V35,MonthList,0)<=7,12,19-MATCH($V35,MonthList,0))/12) -> 0
B36: R0031 | C36: Quality Assurance | D36: EGI Integration | E36: EGI Customer | F36: AU | G36: Filled | H36: 1 | I36: 0.2697 | J36: 0.2697 | K36: No | M36: =IF(AND($K36="Yes",$G36<>"Vendor day rates"),$J36-0.4*$I36,0) -> 0 | N36: =IF(OR($K36<>"Yes",$L36=""),0,$M36*MAX(0,7-MATCH($L36,MonthList,0))/12) -> 0 | O36: =IF(OR($K36<>"Yes",$L36=""),0,$M36*IF(MATCH($L36,MonthList,0)<=7,12,19-MATCH($L36,MonthList,0))/12) -> 0 | P36: No | R36: =IF(AND($P36="Yes",$G36<>"Vendor day rates"),$J36-0.4*$I36,0) -> 0 | S36: =IF(OR($P36<>"Yes",$Q36=""),0,$R36*MAX(0,7-MATCH($Q36,MonthList,0))/12) -> 0 | T36: =IF(OR($P36<>"Yes",$Q36=""),0,$R36*IF(MATCH($Q36,MonthList,0)<=7,12,19-MATCH($Q36,MonthList,0))/12) -> 0 | U36: No | W36: =IF(AND($U36="Yes",$G36<>"Vendor day rates"),$J36-0.4*$I36,0) -> 0 | X36: =IF(OR($U36<>"Yes",$V36=""),0,$W36*MAX(0,7-MATCH($V36,MonthList,0))/12) -> 0 | Y36: =IF(OR($U36<>"Yes",$V36=""),0,$W36*IF(MATCH($V36,MonthList,0)<=7,12,19-MATCH($V36,MonthList,0))/12) -> 0
B37: R0032 | C37: Delivery Lead - Integration | D37: EGI | E37: EGI | F37: AU | G37: Filled | H37: 1 | I37: 0.2735 | J37: 0.2735 | K37: No | M37: =IF(AND($K37="Yes",$G37<>"Vendor day rates"),$J37-0.4*$I37,0) -> 0 | N37: =IF(OR($K37<>"Yes",$L37=""),0,$M37*MAX(0,7-MATCH($L37,MonthList,0))/12) -> 0 | O37: =IF(OR($K37<>"Yes",$L37=""),0,$M37*IF(MATCH($L37,MonthList,0)<=7,12,19-MATCH($L37,MonthList,0))/12) -> 0 | P37: No | R37: =IF(AND($P37="Yes",$G37<>"Vendor day rates"),$J37-0.4*$I37,0) -> 0 | S37: =IF(OR($P37<>"Yes",$Q37=""),0,$R37*MAX(0,7-MATCH($Q37,MonthList,0))/12) -> 0 | T37: =IF(OR($P37<>"Yes",$Q37=""),0,$R37*IF(MATCH($Q37,MonthList,0)<=7,12,19-MATCH($Q37,MonthList,0))/12) -> 0 | U37: No | W37: =IF(AND($U37="Yes",$G37<>"Vendor day rates"),$J37-0.4*$I37,0) -> 0 | X37: =IF(OR($U37<>"Yes",$V37=""),0,$W37*MAX(0,7-MATCH($V37,MonthList,0))/12) -> 0 | Y37: =IF(OR($U37<>"Yes",$V37=""),0,$W37*IF(MATCH($V37,MonthList,0)<=7,12,19-MATCH($V37,MonthList,0))/12) -> 0
B38: R0033 | C38: SAP Solution Architect | E38: SAP ERP | F38: AU | G38: Filled | H38: 1 | I38: 0.3552 | J38: 0.3552 | K38: No | M38: =IF(AND($K38="Yes",$G38<>"Vendor day rates"),$J38-0.4*$I38,0) -> 0 | N38: =IF(OR($K38<>"Yes",$L38=""),0,$M38*MAX(0,7-MATCH($L38,MonthList,0))/12) -> 0 | O38: =IF(OR($K38<>"Yes",$L38=""),0,$M38*IF(MATCH($L38,MonthList,0)<=7,12,19-MATCH($L38,MonthList,0))/12) -> 0 | P38: No | R38: =IF(AND($P38="Yes",$G38<>"Vendor day rates"),$J38-0.4*$I38,0) -> 0 | S38: =IF(OR($P38<>"Yes",$Q38=""),0,$R38*MAX(0,7-MATCH($Q38,MonthList,0))/12) -> 0 | T38: =IF(OR($P38<>"Yes",$Q38=""),0,$R38*IF(MATCH($Q38,MonthList,0)<=7,12,19-MATCH($Q38,MonthList,0))/12) -> 0 | U38: No | W38: =IF(AND($U38="Yes",$G38<>"Vendor day rates"),$J38-0.4*$I38,0) -> 0 | X38: =IF(OR($U38<>"Yes",$V38=""),0,$W38*MAX(0,7-MATCH($V38,MonthList,0))/12) -> 0 | Y38: =IF(OR($U38<>"Yes",$V38=""),0,$W38*IF(MATCH($V38,MonthList,0)<=7,12,19-MATCH($V38,MonthList,0))/12) -> 0
B39: R0034 | C39: Project Manger | D39: EGI | E39: EGI | F39: AU | G39: Filled | H39: 1 | I39: 0.222 | J39: 0.222 | K39: No | M39: =IF(AND($K39="Yes",$G39<>"Vendor day rates"),$J39-0.4*$I39,0) -> 0 | N39: =IF(OR($K39<>"Yes",$L39=""),0,$M39*MAX(0,7-MATCH($L39,MonthList,0))/12) -> 0 | O39: =IF(OR($K39<>"Yes",$L39=""),0,$M39*IF(MATCH($L39,MonthList,0)<=7,12,19-MATCH($L39,MonthList,0))/12) -> 0 | P39: No | R39: =IF(AND($P39="Yes",$G39<>"Vendor day rates"),$J39-0.4*$I39,0) -> 0 | S39: =IF(OR($P39<>"Yes",$Q39=""),0,$R39*MAX(0,7-MATCH($Q39,MonthList,0))/12) -> 0 | T39: =IF(OR($P39<>"Yes",$Q39=""),0,$R39*IF(MATCH($Q39,MonthList,0)<=7,12,19-MATCH($Q39,MonthList,0))/12) -> 0 | U39: No | W39: =IF(AND($U39="Yes",$G39<>"Vendor day rates"),$J39-0.4*$I39,0) -> 0 | X39: =IF(OR($U39<>"Yes",$V39=""),0,$W39*MAX(0,7-MATCH($V39,MonthList,0))/12) -> 0 | Y39: =IF(OR($U39<>"Yes",$V39=""),0,$W39*IF(MATCH($V39,MonthList,0)<=7,12,19-MATCH($V39,MonthList,0))/12) -> 0
B40: R0035 | C40: strategic program architect | D40: EGI | E40: EGI | F40: AU | G40: Filled | H40: 1 | I40: 0.333 | J40: 0.333 | K40: No | M40: =IF(AND($K40="Yes",$G40<>"Vendor day rates"),$J40-0.4*$I40,0) -> 0 | N40: =IF(OR($K40<>"Yes",$L40=""),0,$M40*MAX(0,7-MATCH($L40,MonthList,0))/12) -> 0 | O40: =IF(OR($K40<>"Yes",$L40=""),0,$M40*IF(MATCH($L40,MonthList,0)<=7,12,19-MATCH($L40,MonthList,0))/12) -> 0 | P40: No | R40: =IF(AND($P40="Yes",$G40<>"Vendor day rates"),$J40-0.4*$I40,0) -> 0 | S40: =IF(OR($P40<>"Yes",$Q40=""),0,$R40*MAX(0,7-MATCH($Q40,MonthList,0))/12) -> 0 | T40: =IF(OR($P40<>"Yes",$Q40=""),0,$R40*IF(MATCH($Q40,MonthList,0)<=7,12,19-MATCH($Q40,MonthList,0))/12) -> 0 | U40: No | W40: =IF(AND($U40="Yes",$G40<>"Vendor day rates"),$J40-0.4*$I40,0) -> 0 | X40: =IF(OR($U40<>"Yes",$V40=""),0,$W40*MAX(0,7-MATCH($V40,MonthList,0))/12) -> 0 | Y40: =IF(OR($U40<>"Yes",$V40=""),0,$W40*IF(MATCH($V40,MonthList,0)<=7,12,19-MATCH($V40,MonthList,0))/12) -> 0
B41: R0036 | C41: Engineer - BE | D41: Ampol Customer | E41: Ampol Web | F41: AU | G41: Already at the offshore rate | H41: 1 | I41: 0.2775 | J41: 0.111 | K41: No | M41: =IF(AND($K41="Yes",$G41<>"Vendor day rates"),$J41-0.4*$I41,0) -> 0 | N41: =IF(OR($K41<>"Yes",$L41=""),0,$M41*MAX(0,7-MATCH($L41,MonthList,0))/12) -> 0 | O41: =IF(OR($K41<>"Yes",$L41=""),0,$M41*IF(MATCH($L41,MonthList,0)<=7,12,19-MATCH($L41,MonthList,0))/12) -> 0 | P41: No | R41: =IF(AND($P41="Yes",$G41<>"Vendor day rates"),$J41-0.4*$I41,0) -> 0 | S41: =IF(OR($P41<>"Yes",$Q41=""),0,$R41*MAX(0,7-MATCH($Q41,MonthList,0))/12) -> 0 | T41: =IF(OR($P41<>"Yes",$Q41=""),0,$R41*IF(MATCH($Q41,MonthList,0)<=7,12,19-MATCH($Q41,MonthList,0))/12) -> 0 | U41: No | W41: =IF(AND($U41="Yes",$G41<>"Vendor day rates"),$J41-0.4*$I41,0) -> 0 | X41: =IF(OR($U41<>"Yes",$V41=""),0,$W41*MAX(0,7-MATCH($V41,MonthList,0))/12) -> 0 | Y41: =IF(OR($U41<>"Yes",$V41=""),0,$W41*IF(MATCH($V41,MonthList,0)<=7,12,19-MATCH($V41,MonthList,0))/12) -> 0
B42: R0037 | C42: Engineer - BE | D42: Ampol Customer | E42: Ampol App | F42: AU | G42: Already at the offshore rate | H42: 1 | I42: 0.2705 | J42: 0.1082 | K42: No | M42: =IF(AND($K42="Yes",$G42<>"Vendor day rates"),$J42-0.4*$I42,0) -> 0 | N42: =IF(OR($K42<>"Yes",$L42=""),0,$M42*MAX(0,7-MATCH($L42,MonthList,0))/12) -> 0 | O42: =IF(OR($K42<>"Yes",$L42=""),0,$M42*IF(MATCH($L42,MonthList,0)<=7,12,19-MATCH($L42,MonthList,0))/12) -> 0 | P42: No | R42: =IF(AND($P42="Yes",$G42<>"Vendor day rates"),$J42-0.4*$I42,0) -> 0 | S42: =IF(OR($P42<>"Yes",$Q42=""),0,$R42*MAX(0,7-MATCH($Q42,MonthList,0))/12) -> 0 | T42: =IF(OR($P42<>"Yes",$Q42=""),0,$R42*IF(MATCH($Q42,MonthList,0)<=7,12,19-MATCH($Q42,MonthList,0))/12) -> 0 | U42: No | W42: =IF(AND($U42="Yes",$G42<>"Vendor day rates"),$J42-0.4*$I42,0) -> 0 | X42: =IF(OR($U42<>"Yes",$V42=""),0,$W42*MAX(0,7-MATCH($V42,MonthList,0))/12) -> 0 | Y42: =IF(OR($U42<>"Yes",$V42=""),0,$W42*IF(MATCH($V42,MonthList,0)<=7,12,19-MATCH($V42,MonthList,0))/12) -> 0
...

Sheet REVIEW - Complete Role Mapping
A1: EE Number | B1: Name | C1: EE Number | D1: Position Title | E1: Reports to name | F1: Reports to Position | G1: Division (GM) | H1: Department (GM-1) | I1: Team (GM-2) | J1: Portfolio | K1: Platform | L1: Squad | M1: CC | N1: Country | O1: Job Level | P1: FTE | Q1: Vacant Column | R1: Type | S1: Unit | T1: day rate | U1: FTE Base Local | V1: FTE Base AUD | W1: STI | X1: Payroll | Y1: Pensions | Z1: medical | AA1: CPI | AB1: Full Cost AUD | AC1: MyHR ee no | AE1: Effective cost (AUD) | AF1: MStatus | AG1: Ring fenced | AH1: MTab | AI1: Leadership | AJ1: Squad (canonical, from col L) | AK1: Overhead line | AL1: Squad or overhead line | AM1: EGI funded | AN1: Status (PCM) | AO1: Commentry (PCM) | AP1: End date (PCM) | AQ1: Role ID | AR1: Country side (AU or NZ)
A2: C | B2: Alan Peng | C2: C | D2: Delivery Lead | E2: Adriel Jeyanandhan | F2: Delivery Manager, Digital | G2: Customer | H2: Digital | I2: Digital, Delivery | J2: EGI Integration | K2: EGI | L2: EGI Customer | N2: Australia | O2: NA | P2: 1 | R2: Contractor | S2: Day | T2: 1190 | AB2: 264180 | AC2: End Date: 28/08/2026 | AE2: 264180 | AF2: Filled | AG2: 0 | AH2: Customer | AI2: 0 | AJ2: EGI Customer | AK2: Squad | AL2: EGI Customer | AM2: 1 | AN2: Filled | AO2: End Date: 28/08/2026 | AP2: 46262 | AQ2: R0001 | AR2: AU
A3: C | B3: Lily Fong | C3: C | D3: Snr Business Analyst | E3: Adriel Jeyanandhan | F3: Delivery Manager, Digital | G3: Customer | H3: Digital | I3: Digital, Delivery | J3: Ampol Customer | K3: Ampol Digital | L3: Ampol Web | N3: Australia | O3: NA | P3: 1 | R3: Contractor (CXC) | S3: Day | T3: 1229.2 | AB3: 272882.4 | AC3: End Date: 8/08/2026 | AE3: 272882.4 | AF3: Filled | AG3: 0 | AH3: Customer | AI3: 0 | AJ3: Ampol Web | AK3: Squad | AL3: Ampol Web | AM3: 0 | AN3: Filled | AO3: End Date: 8/08/2026 | AP3: 46242 | AQ3: R0002 | AR3: AU
A4: C | B4: Peter (Won) Lee | C4: C | D4: Snr Business Analyst | E4: Adriel Jeyanandhan | F4: Delivery Manager, Digital | G4: Customer | H4: Digital | I4: Digital, Delivery | J4: Ampol Customer | K4: Ampol Digital | L4: Ampol App | N4: Australia | O4: NA | P4: 1 | R4: Contractor | S4: Day | T4: 1167 | AB4: 259074 | AC4: End Date: 2/01/2027 | AE4: 259074 | AF4: Filled | AG4: 0 | AH4: Customer | AI4: 0 | AJ4: Ampol App | AK4: Squad | AL4: Ampol App | AM4: 0 | AN4: Filled | AO4: End Date: 2/01/2027 | AP4: 46389 | AQ4: R0003 | AR4: AU
A5: C | B5: Harish Dasari | C5: C | D5: Business Analyst (SAP Payroll) | E5: Areum Kim-Lee | F5: GM TDD, EGI | G5: EGI | H5: EGI | I5: EGI | J5: EGI | K5: EGI | L5: EGI | N5: Australia | O5: na | P5: 1 | R5: cxc | S5: daily | T5: 1100 | U5: 0 | AB5: 244200 | AE5: 244200 | AF5: Filled | AG5: 0 | AH5: EGI | AI5: 0 | AJ5: EGI | AK5: Squad | AL5: EGI | AM5: 1 | AQ5: R0004 | AR5: AU
A6: C | B6: Niall Greene | C6: C | D6: Project Manager (PEP13-EGI-UKG) | E6: Areum Kim-Lee | F6: GM TDD, EGI | G6: EGI | H6: EGI | I6: EGI | J6: EGI | K6: EGI | L6: EGI | N6: Australia | O6: NA | P6: 1 | R6: cxc | S6: Daily | T6: 1100 | U6: 0 | AB6: 244200 | AE6: 244200 | AF6: Filled | AG6: 0 | AH6: EGI | AI6: 0 | AJ6: EGI | AK6: Squad | AL6: EGI | AM6: 1 | AQ6: R0005 | AR6: AU
A7: c | B7: Paul Hassey | C7: c | D7: Program Architect | E7: Ed Tacey | G7: EGI | H7: EGI | I7: EGI | J7: EGI | K7: EGI | L7: EGI | N7: Australia | O7: na | P7: 1 | R7: cxc | S7: Daily | T7: 1400 | U7: 0 | AB7: 310800 | AE7: 310800 | AF7: Filled | AG7: 0 | AH7: EGI | AI7: 0 | AJ7: EGI | AK7: Squad | AL7: EGI | AM7: 1 | AQ7: R0006 | AR7: AU
A8: C | B8: Ahmed Yehya | C8: C | D8: TDD Strategic Delivery | E8: Greg Cassis | F8: GM TDD, EGI | G8: EGI | H8: EGI | I8: EGI | J8: EGI | K8: EGI | L8: EGI | N8: Australia | O8: na | P8: 1 | R8: cxc | S8: Daily | T8: 1250 | U8: 0 | AB8: 277500 | AE8: 277500 | AF8: Filled | AG8: 0 | AH8: EGI | AI8: 0 | AJ8: EGI | AK8: Squad | AL8: EGI | AM8: 1 | AQ8: R0007 | AR8: AU
A9: C | B9: Anthony Huynh | C9: C | D9: Strategic Delivery Consultant | E9: Greg Cassis | F9: GM TDD, EGI | G9: EGI | H9: EGI | I9: EGI | J9: EGI | K9: EGI | L9: EGI | N9: australia | O9: NA | P9: 1 | R9: cxc | S9: daily | T9: 1357 | U9: 0 | AB9: 301254 | AE9: 301254 | AF9: Filled | AG9: 0 | AH9: EGI | AI9: 0 | AJ9: EGI | AK9: Squad | AL9: EGI | AM9: 1 | AQ9: R0008 | AR9: AU
A10: C | B10: Areum Kim Lee | C10: C | D10: Program Manager (PEP13-EGI-UKG) | E10: Greg Cassis | F10: GM TDD, EGI | G10: EGI | H10: EGI | I10: EGI | J10: EGI | K10: EGI | L10: EGI | N10: Australia | O10: NA | P10: 1 | R10: cxc | S10: Daily | T10: 1545.76 | U10: 0 | AB10: 343158.72 | AE10: 343158.72 | AF10: Filled | AG10: 0 | AH10: EGI | AI10: 0 | AJ10: EGI | AK10: Squad | AL10: EGI | AM10: 1 | AQ10: R0009 | AR10: AU
A11: C | B11: James Munt | C11: C | D11: Program Manager Tech & P&C | E11: Greg Cassis | F11: GM TDD, EGI | G11: EGI | H11: EGI | I11: EGI | J11: EGI | K11: EGI | L11: EGI | N11: Australia | O11: na | P11: 1 | R11: cxc | S11: daily | T11: 1200 | U11: 0 | AB11: 266400 | AE11: 266400 | AF11: Filled | AG11: 0 | AH11: EGI | AI11: 0 | AJ11: EGI | AK11: Squad | AL11: EGI | AM11: 1 | AQ11: R0010 | AR11: AU
A12: c | B12: Jason McNamara | C12: c | D12: Project Manager Retail | E12: Greg Cassis | F12: GM TDD, EGI | G12: EGI | H12: EGI | I12: EGI | J12: EGI | K12: EGI | L12: EGI | N12: Australia | O12: na | P12: 1 | R12: cxc | S12: daily | T12: 2200 | U12: 0 | AB12: 488400 | AE12: 488400 | AF12: Filled | AG12: 0 | AH12: EGI | AI12: 0 | AJ12: EGI | AK12: Squad | AL12: EGI | AM12: 1 | AQ12: R0011 | AR12: AU
A13: c | B13: Karl Reyneke | C13: c | D13: Strategic Delivery Consultant | E13: Greg Cassis | F13: GM TDD, EGI | G13: EGI | H13: EGI | I13: EGI | J13: EGI | K13: EGI | L13: EGI | N13: australia | O13: na | P13: 1 | R13: cxc | S13: daily | T13: 1350 | U13: 0 | AB13: 299700 | AE13: 299700 | AF13: Filled | AG13: 0 | AH13: EGI | AI13: 0 | AJ13: EGI | AK13: Squad | AL13: EGI | AM13: 1 | AQ13: R0012 | AR13: AU
A14: c | B14: michelle Siegman | C14: c | D14: Strategic Delivery Consultant | E14: Greg Cassis | F14: GM TDD, EGI | G14: EGI | H14: EGI | I14: EGI | J14: EGI | K14: EGI | L14: EGI | N14: Australia | O14: na | P14: 1 | R14: cxc | S14: Daily | T14: 1038 | U14: 0 | AB14: 230436 | AE14: 230436 | AF14: Filled | AG14: 0 | AH14: EGI | AI14: 0 | AJ14: EGI | AK14: Squad | AL14: EGI | AM14: 1 | AQ14: R0013 | AR14: AU
A15: c | B15: vijay Solanki | C15: c | D15: Project Manager Deployment | E15: greg Cassis | G15: EGI | K15: EGI | L15: EGI | N15: Australia | O15: na | P15: 1 | R15: cxc | S15: Daily | T15: 1200 | U15: 0 | AB15: 266400 | AE15: 266400 | AF15: Filled | AG15: 0 | AH15: EGI | AI15: 0 | AJ15: EGI | AK15: Squad | AL15: EGI | AM15: 1 | AQ15: R0014 | AR15: AU
A16: C | B16: Simrat Singh | C16: C | D16: Reporting Analyst | E16: Jaya Ganasan | F16: Technology Manager, TDD Refinery | G16: TDD CFE&I | H16: Fuel Infrastructure | I16: Refinery Applications | J16: Infrastructure | K16: Data & Insights | L16: Data & Insights | N16: Australia | O16: NA | P16: 1 | R16: cxc | S16: Daily | T16: 890 | U16: 0 | AB16: 197580 | AE16: 197580 | AF16: Filled | AG16: 0 | AH16: Infrastructure | AI16: 0 | AJ16: Data & Insights | AK16: Squad | AL16: Data & Insights | AM16: 0 | AQ16: R0015 | AR16: AU
A17: W- Vacant | B17: Vacant | C17: W- Vacant | D17: QA / Tester / Mid | E17: Jill Martin | F17: Delivery Manager, Loyalty | G17: Customer | H17: Loyalty & Martech | I17: Loyalty, Delivery | J17: Ampol Customer | K17: Ampol Loyalty & Martech | L17: Ampol Loyalty & Martech | N17: WIPRO | O17: NA | P17: 1 | R17: WIPRO - vacant | S17: 222 | T17: 330 | AB17: 73260 | AE17: 73260 | AF17: Vacant | AG17: 0 | AH17: Customer | AI17: 0 | AJ17: Ampol Loyalty & Martech | AK17: Squad | AL17: Ampol Loyalty & Martech | AM17: 0 | AN17: Wipro | AQ17: R0016 | AR17: AU
A18: W- Vacant | B18: Vacant | C18: W- Vacant | D18: Systems Analyst / Mid | E18: Jill Martin | F18: Delivery Manager, Loyalty | G18: Customer | H18: Loyalty & Martech | I18: Loyalty, Delivery | J18: Ampol Customer | K18: Ampol Loyalty & Martech | L18: Ampol Loyalty & Martech | N18: WIPRO | O18: NA | P18: 1 | R18: WIPRO - vacant | S18: 222 | T18: 330 | AB18: 73260 | AE18: 73260 | AF18: Vacant | AG18: 0 | AH18: Customer | AI18: 0 | AJ18: Ampol Loyalty & Martech | AK18: Squad | AL18: Ampol Loyalty & Martech | AM18: 0 | AN18: Wipro | AQ18: R0017 | AR18: AU
A19: C | B19: Viren Khatri | C19: C | D19: Data Migration Lead | E19: Manjot Kaur | F19: Technology Manager, Data | G19: Ampol Retail & Z | H19: Z & Group Retail | I19: Z & Group Retail, Data | J19: EGI Integration | K19: EGI | L19: EGI TDD | N19: Australia | O19: NA | P19: 1 | R19: cxc | S19: Daily | T19: 1350 | U19: 0 | AB19: 299700 | AE19: 299700 | AF19: Filled | AG19: 0 | AH19: TDD Group Functions | AI19: 0 | AJ19: EGI TDD | AK19: Squad | AL19: EGI TDD | AM19: 1 | AQ19: R0018 | AR19: AU
A20: W-106200 | B20: Emile Violi - QA Wipro | C20: W-106200 | D20: .NET Back End Developer / Mid | E20: Mark Wilson | F20: Digital Support Manager(AU) | G20: Customer | H20: Digital | I20: Digital Support (AU) | J20: Ampol Customer | K20: Ampol Digital | L20: Digital Operations | N20: WIPRO | O20: NA | P20: 1 | R20: WIPRO - filled | S20: 222 | T20: 330 | AB20: 73260 | AE20: 73260 | AF20: Filled | AG20: 0 | AH20: Customer | AI20: 0 | AJ20: Digital Operations | AK20: Squad | AL20: Digital Operations | AM20: 0 | AN20: Filled | AQ20: R0019 | AR20: AU
A21: W- Vacant | B21: Vacant | C21: W- Vacant | D21: .NET Back End Developer / Mid | E21: Mark Wilson | F21: Digital Support Manager(AU) | G21: Customer | H21: Digital | I21: Digital Support (AU) | J21: Ampol Customer | K21: Ampol Digital | L21: Digital Operations | N21: WIPRO | O21: NA | P21: 1 | R21: WIPRO - vacant | S21: 222 | T21: 330 | AB21: 73260 | AE21: 73260 | AF21: Vacant | AG21: 0 | AH21: Customer | AI21: 0 | AJ21: Digital Operations | AK21: Squad | AL21: Digital Operations | AM21: 0 | AN21: Wipro | AQ21: R0020 | AR21: AU
A22: W- Vacant | B22: Vacant | C22: W- Vacant | D22: .NET Back End Developer / Mid | E22: Mark Wilson | F22: Digital Support Manager(AU) | G22: Customer | H22: Digital | I22: Digital Support (AU) | J22: Ampol Customer | K22: Ampol Digital | L22: Digital Operations | N22: WIPRO | O22: NA | P22: 1 | R22: WIPRO - vacant | S22: 222 | T22: 330 | AB22: 73260 | AE22: 73260 | AF22: Vacant | AG22: 0 | AH22: Customer | AI22: 0 | AJ22: Digital Operations | AK22: Squad | AL22: Digital Operations | AM22: 0 | AN22: Wipro | AQ22: R0021 | AR22: AU
A23: W- Vacant | B23: Vacant | C23: W- Vacant | D23: QA / Tester / Mid | E23: Mark Wilson | F23: Digital Support Manager(AU) | G23: Customer | H23: Digital | I23: Digital Support (AU) | J23: Ampol Customer | K23: Ampol Digital | L23: Digital Operations | N23: WIPRO | O23: NA | P23: 1 | R23: WIPRO - vacant | S23: 222 | T23: 330 | AB23: 73260 | AE23: 73260 | AF23: Vacant | AG23: 0 | AH23: Customer | AI23: 0 | AJ23: Digital Operations | AK23: Squad | AL23: Digital Operations | AM23: 0 | AN23: Wipro | AQ23: R0022 | AR23: AU
A24: C | B24: Arun Tahlan | C24: C | D24: Integration Architect (C) - Boomi | E24: Mike Seales | F24: Technology Manager Integration & Process Managemetn | G24: TDD Group Functions | H24: TDD & Engineering | I24: Integration & Process Management | J24: EGI | K24: EGI | L24: EGI TDD | N24: Australia | O24: NA | P24: 1 | R24: cxc | S24: Daily | T24: 1568 | U24: 0 | AB24: 348096 | AE24: 348096 | AF24: Filled | AG24: 0 | AH24: TDD Group Functions | AI24: 0 | AJ24: EGI TDD | AK24: Squad | AL24: EGI TDD | AM24: 1 | AQ24: R0023 | AR24: AU
A25: C | B25: Kris Thornley | C25: C | D25: Integration Architect (C) | E25: Mike Seales | F25: Technology Manager Integration & Process Managemetn | G25: TDD Group Functions | H25: TDD & Engineering | I25: Integration & Process Management | J25: EGI | K25: EGI | L25: EGI TDD | N25: NZ | O25: NA | P25: 1 | R25: Contractor | S25: cant find this person | T25: 1200 | U25: 0 | AB25: 266400 | AE25: 266400 | AF25: Filled | AG25: 0 | AH25: TDD Group Functions | AI25: 0 | AJ25: EGI TDD | AK25: Squad | AL25: EGI TDD | AM25: 1 | AQ25: R0024 | AR25: NZ
A26: C | B26: Annabel Phu | C26: C | D26: Engineer - Mobile | E26: Mitesh Shah | F26: Technology Manager, Digitial | G26: Customer | H26: Digital | I26: Digital, Tech | J26: Ampol Customer | K26: Ampol Digital | L26: Ampol App | N26: Australia | O26: NA | P26: 1 | R26: Contractor | S26: Day | T26: 860 | AB26: 190920 | AC26: Jac: Don’t know end Date | AE26: 190920 | AF26: Filled | AG26: 0 | AH26: Customer | AI26: 0 | AJ26: Ampol App | AK26: Squad | AL26: Ampol App | AM26: 0 | AN26: Filled | AO26: Jac: Don’t know end Date | AQ26: R0025 | AR26: AU
A27: C | B27: Jordan Askwith | C27: C | D27: Solution Architect | E27: Mitesh Shah | F27: Technology Manager, Digitial | G27: Customer | H27: Digital | I27: Digital, Tech | J27: Ampol Customer | K27: Ampol Digital | L27: Ampol Web | N27: Australia | O27: NA | P27: 1 | R27: Contractor (Digizoo) | S27: Day | T27: 1450 | AB27: 321900 | AC27: Jac: Don’t know end date | AE27: 321900 | AF27: Filled | AG27: 0 | AH27: Customer | AI27: 0 | AJ27: Ampol Web | AK27: Squad | AL27: Ampol Web | AM27: 0 | AN27: Filled | AO27: Jac: Don’t know end date | AQ27: R0026 | AR27: AU
A28: c | B28: Kanika Narula | C28: c | D28: Business Analyst Digital | E28: Mitesh Shah | F28: Technology Manager, Digitial | G28: EGI | H28: EGI | I28: EGI | J28: EGI | K28: EGI | L28: EGI | N28: Australia | O28: na | P28: 1 | R28: cxc | S28: daily | T28: 1078.84 | U28: 0 | AB28: 239502.48 | AE28: 239502.48 | AF28: Filled | AG28: 0 | AH28: EGI | AI28: 0 | AJ28: EGI | AK28: Squad | AL28: EGI | AM28: 1 | AQ28: R0027 | AR28: AU
A29: C | B29: Phillip Kewley | C29: C | D29: Quality Assurance | E29: Mitesh Shah | F29: Technology Manager, Digitial | G29: Customer | H29: Digital | I29: Digital, Tech | J29: Ampol Customer | K29: Ampol Digital | L29: Ampol App | N29: Australia | O29: NA | P29: 1 | R29: Contractor | S29: Day | T29: 807.2 | AB29: 179198.4 | AC29: End Date: 30/10/26 | AE29: 179198.4 | AF29: Filled | AG29: 0 | AH29: Customer | AI29: 0 | AJ29: Ampol App | AK29: Squad | AL29: Ampol App | AM29: 0 | AN29: Filled | AO29: End Date: 30/10/26 | AP29: 46326 | AQ29: R0028 | AR29: AU
A30: C | B30: Sheetal Karkera | C30: C | D30: Lead Engineer - Mobile | E30: Mitesh Shah | F30: Technology Manager, Digitial | G30: Customer | H30: Digital | I30: Digital, Tech | J30: Ampol Customer | K30: Ampol Digital | L30: Ampol App | N30: Australia | O30: NA | P30: 1 | R30: Contractor | S30: Day | T30: 1253 | AB30: 278166 | AC30: End Date: 21/08/2026 | AE30: 278166 | AF30: Filled | AG30: 0 | AH30: Customer | AI30: 0 | AJ30: Ampol App | AK30: Squad | AL30: Ampol App | AM30: 0 | AN30: Filled | AO30: End Date: 21/08/2026 | AP30: 46255 | AQ30: R0029 | AR30: AU
A31: =#N/A -> #N/A | B31: Shreema Das | C31: =#N/A -> #N/A | D31: Solution Architect | E31: Mitesh Shah | F31: Technology Manager, Digitial | G31: Customer | H31: Digital | I31: Digital, Tech | J31: Ampol Customer | K31: Ampol Digital | L31: Ampol Web | N31: Australia | O31: NA | P31: 1 | R31: Permanent - Part Time | U31: 190000 | V31: 190000 | W31: 0.12 | X31: 0.055 | Y31: 0.12 | AA31: 0.04 | AB31: 243090.15 | AC31: Joins Perm in August | AE31: 243090.15 | AF31: Filled | AG31: 0 | AH31: Customer | AI31: 0 | AJ31: Ampol Web | AK31: Squad | AL31: Ampol Web | AM31: 0 | AN31: Filled | AO31: Joins Perm in August NOTE: Shreema Das is in the Ampol Web Squad | AQ31: R0030 | AR31: AU
A32: C | B32: Waheed Malek | C32: C | D32: Quality Assurance | E32: Mitesh Shah | F32: Technology Manager, Digitial | G32: Customer | H32: Digital | I32: Digital, Tech | J32: EGI Integration | K32: EGI | L32: EGI Customer | N32: Australia | O32: NA | P32: 1 | R32: Contractor | S32: Daily | T32: 1215 | AB32: 269730 | AC32: End Date: 21/09/2026 | AE32: 269730 | AF32: Filled | AG32: 0 | AH32: Customer | AI32: 0 | AJ32: EGI Customer | AK32: Squad | AL32: EGI Customer | AM32: 1 | AN32: Filled | AO32: End Date: 21/09/2026 | AP32: 46286 | AQ32: R0031 | AR32: AU
A33: C | B33: Winnie Fernandes | C33: C | D33: Delivery Lead - Integration | E33: Moitri Pal | F33: Program Manager - EGI | G33: EGI | H33: EGI | I33: EGI | J33: EGI | K33: EGI | L33: EGI | N33: Australia | O33: NA | P33: 1 | R33: cxc | S33: Daily | T33: 1232 | U33: 0 | AB33: 273504 | AE33: 273504 | AF33: Filled | AG33: 0 | AH33: EGI | AI33: 0 | AJ33: EGI | AK33: Squad | AL33: EGI | AM33: 1 | AQ33: R0032 | AR33: AU
A34: c | B34: Jens Tom | C34: c | D34: SAP Solution Architect | E34: Shane Ker | F34: Solution Architect SAP | G34: TDD Group Functions | O34: na | P34: 1 | R34: cxc | S34: daily | T34: 1600 | U34: 0 | AB34: 355200 | AE34: 355200 | AF34: Filled | AG34: 0 | AH34: TDD Group Functions | AI34: 0 | AJ34: SAP ERP | AK34: Squad | AL34: SAP ERP | AM34: 0 | AO34: NOT IN MY ORG CHART | AQ34: R0033 | AR34: AU
A35: C | B35: Ernesto Pereira | C35: C | D35: Project Manger | E35: Trena Foote | F35: Project Manger | G35: EGI | H35: EGI | I35: EGI | J35: EGI | K35: EGI | L35: EGI | N35: Australia | O35: na | P35: 1 | R35: cxc | S35: daily | T35: 1000 | U35: 0 | AB35: 222000 | AE35: 222000 | AF35: Filled | AG35: 0 | AH35: EGI | AI35: 0 | AJ35: EGI | AK35: Squad | AL35: EGI | AM35: 1 | AQ35: R0034 | AR35: AU
A36: c | B36: Jason Sipkovic | C36: c | D36: strategic program architect | E36: Trena Foote | F36: Project Manger | G36: EGI | H36: EGI | I36: EGI | J36: EGI | K36: EGI | L36: EGI | N36: Australia | O36: na | P36: 1 | R36: cxc | S36: daily | T36: 1500 | U36: 0 | AB36: 333000 | AE36: 333000 | AF36: Filled | AG36: 0 | AH36: EGI | AI36: 0 | AJ36: EGI | AK36: Squad | AL36: EGI | AM36: 1 | AQ36: R0035 | AR36: AU
