Workbook

Sheet 1 Start here
B2: Offshore scenario builder
B4: Pick which roles move offshore and when. Compare up to three lists side by side and see the cost come out, month by month.
B8: Example | E8: List B | H8: List C
B10: ='3 Compare'!C9 -> 0.38966 | E10: ='3 Compare'!D9 -> 0 | H10: ='3 Compare'!E9 -> 0
B11: =TEXT('3 Compare'!C5,"0")&" roles · "&TEXT('3 Compare'!C6,"0.0")&" FTE · 2026 $"&TEXT('3 Compare'!C10,"0.00")&"m" -> 4 roles · 4.0 FTE · 2026 $0.07m | E11: =TEXT('3 Compare'!D5,"0")&" roles · "&TEXT('3 Compare'!D6,"0.0")&" FTE · 2026 $"&TEXT('3 Compare'!D10,"0.00")&"m" -> 0 roles · 0.0 FTE · 2026 $0.00m | H11: =TEXT('3 Compare'!E5,"0")&" roles · "&TEXT('3 Compare'!E6,"0.0")&" FTE · 2026 $"&TEXT('3 Compare'!E10,"0.00")&"m" -> 0 roles · 0.0 FTE · 2026 $0.00m
B12: =TEXT(IFERROR('3 Compare'!C9/'3 Compare'!C7,0),"0%")&" of what these roles cost today" -> 51% of what these roles cost today | E12: =TEXT(IFERROR('3 Compare'!D9/'3 Compare'!D7,0),"0%")&" of what these roles cost today" -> 0% of what these roles cost today | H12: =TEXT(IFERROR('3 Compare'!E9/'3 Compare'!E7,0),"0%")&" of what these roles cost today" -> 0% of what these roles cost today
B13: Type over a yellow title to rename that list. The Example list holds a worked example - clear it on the Pick roles tab and make your own.
B15: Ten biggest roles you've picked ($m a year)
B16: Role | E16: Portfolio | G16: Lists | H16: $m / yr
B17: =IF($N17<0.00001,"",INDEX('2 Pick roles'!$C$5:$C$544,$O17)) -> Snr Business Analyst | E17: =IF($N17<0.00001,"",INDEX('2 Pick roles'!$D$5:$D$544,$O17)) -> Ampol Customer | G17: =IF($N17<0.00001,"",INDEX('2 Pick roles'!$AF$5:$AF$544,$O17)) -> A | H17: =IF($N17<0.00001,"",INDEX('2 Pick roles'!$AD$5:$AD$544,$O17)) -> 0.16374 | N17: =IFERROR(LARGE('2 Pick roles'!$AE$5:$AE$544,1),0) -> 0.16374001 | O17: =IFERROR(MATCH($N17,'2 Pick roles'!$AE$5:$AE$544,0),0) -> 2
B18: =IF($N18<0.00001,"",INDEX('2 Pick roles'!$C$5:$C$544,$O18)) -> Systems Analyst | E18: =IF($N18<0.00001,"",INDEX('2 Pick roles'!$D$5:$D$544,$O18)) -> Retail | G18: =IF($N18<0.00001,"",INDEX('2 Pick roles'!$AF$5:$AF$544,$O18)) -> A | H18: =IF($N18<0.00001,"",INDEX('2 Pick roles'!$AD$5:$AD$544,$O18)) -> 0.12096 | N18: =IFERROR(LARGE('2 Pick roles'!$AE$5:$AE$544,2),0) -> 0.12096047 | O18: =IFERROR(MATCH($N18,'2 Pick roles'!$AE$5:$AE$544,0),0) -> 468
B19: =IF($N19<0.00001,"",INDEX('2 Pick roles'!$C$5:$C$544,$O19)) -> Integration Specialist (ASAPIO CTR | E19: =IF($N19<0.00001,"",INDEX('2 Pick roles'!$D$5:$D$544,$O19)) -> Finance | G19: =IF($N19<0.00001,"",INDEX('2 Pick roles'!$AF$5:$AF$544,$O19)) -> A | H19: =IF($N19<0.00001,"",INDEX('2 Pick roles'!$AD$5:$AD$544,$O19)) -> 0.10494 | N19: =IFERROR(LARGE('2 Pick roles'!$AE$5:$AE$544,3),0) -> 0.10494035 | O19: =IFERROR(MATCH($N19,'2 Pick roles'!$AE$5:$AE$544,0),0) -> 351
B20: =IF($N20<0.00001,"",INDEX('2 Pick roles'!$C$5:$C$544,$O20)) -> Lead Engineer - Mobile | E20: =IF($N20<0.00001,"",INDEX('2 Pick roles'!$D$5:$D$544,$O20)) -> Ampol Customer | G20: =IF($N20<0.00001,"",INDEX('2 Pick roles'!$AF$5:$AF$544,$O20)) -> A | H20: =IF($N20<0.00001,"",INDEX('2 Pick roles'!$AD$5:$AD$544,$O20)) -> 2e-05 | N20: =IFERROR(LARGE('2 Pick roles'!$AE$5:$AE$544,4),0) -> 2.0033e-05 | O20: =IFERROR(MATCH($N20,'2 Pick roles'!$AE$5:$AE$544,0),0) -> 29
B21: =IF($N21<0.00001,"",INDEX('2 Pick roles'!$C$5:$C$544,$O21)) | E21: =IF($N21<0.00001,"",INDEX('2 Pick roles'!$D$5:$D$544,$O21)) | G21: =IF($N21<0.00001,"",INDEX('2 Pick roles'!$AF$5:$AF$544,$O21)) | H21: =IF($N21<0.00001,"",INDEX('2 Pick roles'!$AD$5:$AD$544,$O21)) | N21: =IFERROR(LARGE('2 Pick roles'!$AE$5:$AE$544,5),0) -> 5.44e-07 | O21: =IFERROR(MATCH($N21,'2 Pick roles'!$AE$5:$AE$544,0),0) -> 540
B22: =IF($N22<0.00001,"",INDEX('2 Pick roles'!$C$5:$C$544,$O22)) | E22: =IF($N22<0.00001,"",INDEX('2 Pick roles'!$D$5:$D$544,$O22)) | G22: =IF($N22<0.00001,"",INDEX('2 Pick roles'!$AF$5:$AF$544,$O22)) | H22: =IF($N22<0.00001,"",INDEX('2 Pick roles'!$AD$5:$AD$544,$O22)) | N22: =IFERROR(LARGE('2 Pick roles'!$AE$5:$AE$544,6),0) -> 5.43e-07 | O22: =IFERROR(MATCH($N22,'2 Pick roles'!$AE$5:$AE$544,0),0) -> 539
B23: =IF($N23<0.00001,"",INDEX('2 Pick roles'!$C$5:$C$544,$O23)) | E23: =IF($N23<0.00001,"",INDEX('2 Pick roles'!$D$5:$D$544,$O23)) | G23: =IF($N23<0.00001,"",INDEX('2 Pick roles'!$AF$5:$AF$544,$O23)) | H23: =IF($N23<0.00001,"",INDEX('2 Pick roles'!$AD$5:$AD$544,$O23)) | N23: =IFERROR(LARGE('2 Pick roles'!$AE$5:$AE$544,7),0) -> 5.42e-07 | O23: =IFERROR(MATCH($N23,'2 Pick roles'!$AE$5:$AE$544,0),0) -> 538
B24: =IF($N24<0.00001,"",INDEX('2 Pick roles'!$C$5:$C$544,$O24)) | E24: =IF($N24<0.00001,"",INDEX('2 Pick roles'!$D$5:$D$544,$O24)) | G24: =IF($N24<0.00001,"",INDEX('2 Pick roles'!$AF$5:$AF$544,$O24)) | H24: =IF($N24<0.00001,"",INDEX('2 Pick roles'!$AD$5:$AD$544,$O24)) | N24: =IFERROR(LARGE('2 Pick roles'!$AE$5:$AE$544,8),0) -> 5.41e-07 | O24: =IFERROR(MATCH($N24,'2 Pick roles'!$AE$5:$AE$544,0),0) -> 537
B25: =IF($N25<0.00001,"",INDEX('2 Pick roles'!$C$5:$C$544,$O25)) | E25: =IF($N25<0.00001,"",INDEX('2 Pick roles'!$D$5:$D$544,$O25)) | G25: =IF($N25<0.00001,"",INDEX('2 Pick roles'!$AF$5:$AF$544,$O25)) | H25: =IF($N25<0.00001,"",INDEX('2 Pick roles'!$AD$5:$AD$544,$O25)) | N25: =IFERROR(LARGE('2 Pick roles'!$AE$5:$AE$544,9),0) -> 5.4e-07 | O25: =IFERROR(MATCH($N25,'2 Pick roles'!$AE$5:$AE$544,0),0) -> 536
B26: =IF($N26<0.00001,"",INDEX('2 Pick roles'!$C$5:$C$544,$O26)) | E26: =IF($N26<0.00001,"",INDEX('2 Pick roles'!$D$5:$D$544,$O26)) | G26: =IF($N26<0.00001,"",INDEX('2 Pick roles'!$AF$5:$AF$544,$O26)) | H26: =IF($N26<0.00001,"",INDEX('2 Pick roles'!$AD$5:$AD$544,$O26)) | N26: =IFERROR(LARGE('2 Pick roles'!$AE$5:$AE$544,10),0) -> 5.39e-07 | O26: =IFERROR(MATCH($N26,'2 Pick roles'!$AE$5:$AE$544,0),0) -> 535
B29: How to use it
B30: 1. Open the Pick roles tab and use the filter arrows to find the roles you want.
B31: 2. Set a role to Yes in List A, B or C, and choose the month it moves. It can sit in more than one list.
B32: 3. A role set to Yes turns green. If it has no month it flags red until you choose one.
B33: 4. This page and the Compare tab move as you go.
B35: How the money works
B36: A role that moves offshore costs 40% of its full onshore cost. What comes out is today's cost less that 40%.
B37: Roles on vendor day rates stay as they are. A held role costs nothing today, so moving it shows as added cost.
B38: The year is the calendar year (Ampol's December year-end). The horizon runs Jul-2026 to Dec-2027.
B39: Figures are A$ millions. NZ roles are converted at the planning rate.
B40: The tabs are locked so the sums can't break. Only the yellow cells take typing. Password to unlock: Tdd123.
B41: Built from the role mapping in TDD_FY27_Cost_Calc_0608 (11 August 2026), copied in full on the hidden data tab.

Sheet 2 Pick roles
B1: Pick roles
B2: Filter to find a role, set it to Yes in List A, B or C, and choose the month it moves. A role can sit in more than one list.
B4: Role ID | C4: Role | D4: Portfolio | E4: Squad or line | F4: AU / NZ | G4: Status | H4: FTE | I4: Cost today $m | J4: In A? | K4: A month | L4: In B? | M4: B month | N4: In C? | O4: C month | P4: Full onshore $m | Q4: Taken out A $m/yr | R4: pos A | S4: 2026 A $m | T4: 2027 A $m | U4: Taken out B $m/yr | V4: pos B | W4: 2026 B $m | X4: 2027 B $m | Y4: Taken out C $m/yr | Z4: pos C | AA4: 2026 C $m | AB4: 2027 C $m | AC4: In any list? | AD4: Best taken out $m/yr | AE4: rank | AF4: Lists
B5: R0001 | C5: Delivery Lead | D5: EGI Integration | E5: EGI Customer | F5: AU | G5: Filled | H5: 1 | I5: 0.2642 | J5: No | L5: No | N5: No | P5: 0.2642 | Q5: =IF(AND($J5="Yes",$G5<>"Vendor day rates"),$I5-0.4*$P5,0) -> 0 | R5: =IFERROR(MATCH($K5,MonthList,0),0) -> 0 | S5: =IF(OR($J5<>"Yes",$K5=""),0,$Q5*MAX(0,7-$R5)/12) -> 0 | T5: =IF(OR($J5<>"Yes",$K5=""),0,$Q5*IF($R5<=7,12,19-$R5)/12) -> 0 | U5: =IF(AND($L5="Yes",$G5<>"Vendor day rates"),$I5-0.4*$P5,0) -> 0 | V5: =IFERROR(MATCH($M5,MonthList,0),0) -> 0 | W5: =IF(OR($L5<>"Yes",$M5=""),0,$U5*MAX(0,7-$V5)/12) -> 0 | X5: =IF(OR($L5<>"Yes",$M5=""),0,$U5*IF($V5<=7,12,19-$V5)/12) -> 0 | Y5: =IF(AND($N5="Yes",$G5<>"Vendor day rates"),$I5-0.4*$P5,0) -> 0 | Z5: =IFERROR(MATCH($O5,MonthList,0),0) -> 0 | AA5: =IF(OR($N5<>"Yes",$O5=""),0,$Y5*MAX(0,7-$Z5)/12) -> 0 | AB5: =IF(OR($N5<>"Yes",$O5=""),0,$Y5*IF($Z5<=7,12,19-$Z5)/12) -> 0 | AC5: =IF(OR($J5="Yes",$L5="Yes",$N5="Yes"),"Yes","No") -> No | AD5: =MAX($Q5,$U5,$Y5) -> 0 | AE5: =$AD5+ROW()*0.000000001 -> 5e-09 | AF5: =IF($J5="Yes","A","")&IF($L5="Yes","B","")&IF($N5="Yes","C","")
B6: R0002 | C6: Snr Business Analyst | D6: Ampol Customer | E6: Ampol Web | F6: AU | G6: Filled | H6: 1 | I6: 0.2729 | J6: Yes | K6: Oct-2026 | L6: No | N6: No | P6: 0.2729 | Q6: =IF(AND($J6="Yes",$G6<>"Vendor day rates"),$I6-0.4*$P6,0) -> 0.16374 | R6: =IFERROR(MATCH($K6,MonthList,0),0) -> 4 | S6: =IF(OR($J6<>"Yes",$K6=""),0,$Q6*MAX(0,7-$R6)/12) -> 0.040935 | T6: =IF(OR($J6<>"Yes",$K6=""),0,$Q6*IF($R6<=7,12,19-$R6)/12) -> 0.16374 | U6: =IF(AND($L6="Yes",$G6<>"Vendor day rates"),$I6-0.4*$P6,0) -> 0 | V6: =IFERROR(MATCH($M6,MonthList,0),0) -> 0 | W6: =IF(OR($L6<>"Yes",$M6=""),0,$U6*MAX(0,7-$V6)/12) -> 0 | X6: =IF(OR($L6<>"Yes",$M6=""),0,$U6*IF($V6<=7,12,19-$V6)/12) -> 0 | Y6: =IF(AND($N6="Yes",$G6<>"Vendor day rates"),$I6-0.4*$P6,0) -> 0 | Z6: =IFERROR(MATCH($O6,MonthList,0),0) -> 0 | AA6: =IF(OR($N6<>"Yes",$O6=""),0,$Y6*MAX(0,7-$Z6)/12) -> 0 | AB6: =IF(OR($N6<>"Yes",$O6=""),0,$Y6*IF($Z6<=7,12,19-$Z6)/12) -> 0 | AC6: =IF(OR($J6="Yes",$L6="Yes",$N6="Yes"),"Yes","No") -> Yes | AD6: =MAX($Q6,$U6,$Y6) -> 0.16374 | AE6: =$AD6+ROW()*0.000000001 -> 0.16374001 | AF6: =IF($J6="Yes","A","")&IF($L6="Yes","B","")&IF($N6="Yes","C","") -> A
B7: R0003 | C7: Snr Business Analyst | D7: Ampol Customer | E7: Ampol App | F7: AU | G7: Filled | H7: 1 | I7: 0.2591 | J7: No | L7: No | N7: No | P7: 0.2591 | Q7: =IF(AND($J7="Yes",$G7<>"Vendor day rates"),$I7-0.4*$P7,0) -> 0 | R7: =IFERROR(MATCH($K7,MonthList,0),0) -> 0 | S7: =IF(OR($J7<>"Yes",$K7=""),0,$Q7*MAX(0,7-$R7)/12) -> 0 | T7: =IF(OR($J7<>"Yes",$K7=""),0,$Q7*IF($R7<=7,12,19-$R7)/12) -> 0 | U7: =IF(AND($L7="Yes",$G7<>"Vendor day rates"),$I7-0.4*$P7,0) -> 0 | V7: =IFERROR(MATCH($M7,MonthList,0),0) -> 0 | W7: =IF(OR($L7<>"Yes",$M7=""),0,$U7*MAX(0,7-$V7)/12) -> 0 | X7: =IF(OR($L7<>"Yes",$M7=""),0,$U7*IF($V7<=7,12,19-$V7)/12) -> 0 | Y7: =IF(AND($N7="Yes",$G7<>"Vendor day rates"),$I7-0.4*$P7,0) -> 0 | Z7: =IFERROR(MATCH($O7,MonthList,0),0) -> 0 | AA7: =IF(OR($N7<>"Yes",$O7=""),0,$Y7*MAX(0,7-$Z7)/12) -> 0 | AB7: =IF(OR($N7<>"Yes",$O7=""),0,$Y7*IF($Z7<=7,12,19-$Z7)/12) -> 0 | AC7: =IF(OR($J7="Yes",$L7="Yes",$N7="Yes"),"Yes","No") -> No | AD7: =MAX($Q7,$U7,$Y7) -> 0 | AE7: =$AD7+ROW()*0.000000001 -> 7e-09 | AF7: =IF($J7="Yes","A","")&IF($L7="Yes","B","")&IF($N7="Yes","C","")
B8: R0004 | C8: Business Analyst (SAP Payroll) | D8: EGI | E8: EGI | F8: AU | G8: Filled | H8: 1 | I8: 0.2442 | J8: No | L8: No | N8: No | P8: 0.2442 | Q8: =IF(AND($J8="Yes",$G8<>"Vendor day rates"),$I8-0.4*$P8,0) -> 0 | R8: =IFERROR(MATCH($K8,MonthList,0),0) -> 0 | S8: =IF(OR($J8<>"Yes",$K8=""),0,$Q8*MAX(0,7-$R8)/12) -> 0 | T8: =IF(OR($J8<>"Yes",$K8=""),0,$Q8*IF($R8<=7,12,19-$R8)/12) -> 0 | U8: =IF(AND($L8="Yes",$G8<>"Vendor day rates"),$I8-0.4*$P8,0) -> 0 | V8: =IFERROR(MATCH($M8,MonthList,0),0) -> 0 | W8: =IF(OR($L8<>"Yes",$M8=""),0,$U8*MAX(0,7-$V8)/12) -> 0 | X8: =IF(OR($L8<>"Yes",$M8=""),0,$U8*IF($V8<=7,12,19-$V8)/12) -> 0 | Y8: =IF(AND($N8="Yes",$G8<>"Vendor day rates"),$I8-0.4*$P8,0) -> 0 | Z8: =IFERROR(MATCH($O8,MonthList,0),0) -> 0 | AA8: =IF(OR($N8<>"Yes",$O8=""),0,$Y8*MAX(0,7-$Z8)/12) -> 0 | AB8: =IF(OR($N8<>"Yes",$O8=""),0,$Y8*IF($Z8<=7,12,19-$Z8)/12) -> 0 | AC8: =IF(OR($J8="Yes",$L8="Yes",$N8="Yes"),"Yes","No") -> No | AD8: =MAX($Q8,$U8,$Y8) -> 0 | AE8: =$AD8+ROW()*0.000000001 -> 8e-09 | AF8: =IF($J8="Yes","A","")&IF($L8="Yes","B","")&IF($N8="Yes","C","")
B9: R0005 | C9: Project Manager (PEP13-EGI-UKG) | D9: EGI | E9: EGI | F9: AU | G9: Filled | H9: 1 | I9: 0.2442 | J9: No | L9: No | N9: No | P9: 0.2442 | Q9: =IF(AND($J9="Yes",$G9<>"Vendor day rates"),$I9-0.4*$P9,0) -> 0 | R9: =IFERROR(MATCH($K9,MonthList,0),0) -> 0 | S9: =IF(OR($J9<>"Yes",$K9=""),0,$Q9*MAX(0,7-$R9)/12) -> 0 | T9: =IF(OR($J9<>"Yes",$K9=""),0,$Q9*IF($R9<=7,12,19-$R9)/12) -> 0 | U9: =IF(AND($L9="Yes",$G9<>"Vendor day rates"),$I9-0.4*$P9,0) -> 0 | V9: =IFERROR(MATCH($M9,MonthList,0),0) -> 0 | W9: =IF(OR($L9<>"Yes",$M9=""),0,$U9*MAX(0,7-$V9)/12) -> 0 | X9: =IF(OR($L9<>"Yes",$M9=""),0,$U9*IF($V9<=7,12,19-$V9)/12) -> 0 | Y9: =IF(AND($N9="Yes",$G9<>"Vendor day rates"),$I9-0.4*$P9,0) -> 0 | Z9: =IFERROR(MATCH($O9,MonthList,0),0) -> 0 | AA9: =IF(OR($N9<>"Yes",$O9=""),0,$Y9*MAX(0,7-$Z9)/12) -> 0 | AB9: =IF(OR($N9<>"Yes",$O9=""),0,$Y9*IF($Z9<=7,12,19-$Z9)/12) -> 0 | AC9: =IF(OR($J9="Yes",$L9="Yes",$N9="Yes"),"Yes","No") -> No | AD9: =MAX($Q9,$U9,$Y9) -> 0 | AE9: =$AD9+ROW()*0.000000001 -> 9e-09 | AF9: =IF($J9="Yes","A","")&IF($L9="Yes","B","")&IF($N9="Yes","C","")
B10: R0006 | C10: Program Architect | D10: EGI | E10: EGI | F10: AU | G10: Filled | H10: 1 | I10: 0.3108 | J10: No | L10: No | N10: No | P10: 0.3108 | Q10: =IF(AND($J10="Yes",$G10<>"Vendor day rates"),$I10-0.4*$P10,0) -> 0 | R10: =IFERROR(MATCH($K10,MonthList,0),0) -> 0 | S10: =IF(OR($J10<>"Yes",$K10=""),0,$Q10*MAX(0,7-$R10)/12) -> 0 | T10: =IF(OR($J10<>"Yes",$K10=""),0,$Q10*IF($R10<=7,12,19-$R10)/12) -> 0 | U10: =IF(AND($L10="Yes",$G10<>"Vendor day rates"),$I10-0.4*$P10,0) -> 0 | V10: =IFERROR(MATCH($M10,MonthList,0),0) -> 0 | W10: =IF(OR($L10<>"Yes",$M10=""),0,$U10*MAX(0,7-$V10)/12) -> 0 | X10: =IF(OR($L10<>"Yes",$M10=""),0,$U10*IF($V10<=7,12,19-$V10)/12) -> 0 | Y10: =IF(AND($N10="Yes",$G10<>"Vendor day rates"),$I10-0.4*$P10,0) -> 0 | Z10: =IFERROR(MATCH($O10,MonthList,0),0) -> 0 | AA10: =IF(OR($N10<>"Yes",$O10=""),0,$Y10*MAX(0,7-$Z10)/12) -> 0 | AB10: =IF(OR($N10<>"Yes",$O10=""),0,$Y10*IF($Z10<=7,12,19-$Z10)/12) -> 0 | AC10: =IF(OR($J10="Yes",$L10="Yes",$N10="Yes"),"Yes","No") -> No | AD10: =MAX($Q10,$U10,$Y10) -> 0 | AE10: =$AD10+ROW()*0.000000001 -> 1e-08 | AF10: =IF($J10="Yes","A","")&IF($L10="Yes","B","")&IF($N10="Yes","C","")
B11: R0007 | C11: TDD Strategic Delivery | D11: EGI | E11: EGI | F11: AU | G11: Filled | H11: 1 | I11: 0.2775 | J11: No | L11: No | N11: No | P11: 0.2775 | Q11: =IF(AND($J11="Yes",$G11<>"Vendor day rates"),$I11-0.4*$P11,0) -> 0 | R11: =IFERROR(MATCH($K11,MonthList,0),0) -> 0 | S11: =IF(OR($J11<>"Yes",$K11=""),0,$Q11*MAX(0,7-$R11)/12) -> 0 | T11: =IF(OR($J11<>"Yes",$K11=""),0,$Q11*IF($R11<=7,12,19-$R11)/12) -> 0 | U11: =IF(AND($L11="Yes",$G11<>"Vendor day rates"),$I11-0.4*$P11,0) -> 0 | V11: =IFERROR(MATCH($M11,MonthList,0),0) -> 0 | W11: =IF(OR($L11<>"Yes",$M11=""),0,$U11*MAX(0,7-$V11)/12) -> 0 | X11: =IF(OR($L11<>"Yes",$M11=""),0,$U11*IF($V11<=7,12,19-$V11)/12) -> 0 | Y11: =IF(AND($N11="Yes",$G11<>"Vendor day rates"),$I11-0.4*$P11,0) -> 0 | Z11: =IFERROR(MATCH($O11,MonthList,0),0) -> 0 | AA11: =IF(OR($N11<>"Yes",$O11=""),0,$Y11*MAX(0,7-$Z11)/12) -> 0 | AB11: =IF(OR($N11<>"Yes",$O11=""),0,$Y11*IF($Z11<=7,12,19-$Z11)/12) -> 0 | AC11: =IF(OR($J11="Yes",$L11="Yes",$N11="Yes"),"Yes","No") -> No | AD11: =MAX($Q11,$U11,$Y11) -> 0 | AE11: =$AD11+ROW()*0.000000001 -> 1.1e-08 | AF11: =IF($J11="Yes","A","")&IF($L11="Yes","B","")&IF($N11="Yes","C","")
B12: R0008 | C12: Strategic Delivery Consultant | D12: EGI | E12: EGI | F12: AU | G12: Filled | H12: 1 | I12: 0.3013 | J12: No | L12: No | N12: No | P12: 0.3013 | Q12: =IF(AND($J12="Yes",$G12<>"Vendor day rates"),$I12-0.4*$P12,0) -> 0 | R12: =IFERROR(MATCH($K12,MonthList,0),0) -> 0 | S12: =IF(OR($J12<>"Yes",$K12=""),0,$Q12*MAX(0,7-$R12)/12) -> 0 | T12: =IF(OR($J12<>"Yes",$K12=""),0,$Q12*IF($R12<=7,12,19-$R12)/12) -> 0 | U12: =IF(AND($L12="Yes",$G12<>"Vendor day rates"),$I12-0.4*$P12,0) -> 0 | V12: =IFERROR(MATCH($M12,MonthList,0),0) -> 0 | W12: =IF(OR($L12<>"Yes",$M12=""),0,$U12*MAX(0,7-$V12)/12) -> 0 | X12: =IF(OR($L12<>"Yes",$M12=""),0,$U12*IF($V12<=7,12,19-$V12)/12) -> 0 | Y12: =IF(AND($N12="Yes",$G12<>"Vendor day rates"),$I12-0.4*$P12,0) -> 0 | Z12: =IFERROR(MATCH($O12,MonthList,0),0) -> 0 | AA12: =IF(OR($N12<>"Yes",$O12=""),0,$Y12*MAX(0,7-$Z12)/12) -> 0 | AB12: =IF(OR($N12<>"Yes",$O12=""),0,$Y12*IF($Z12<=7,12,19-$Z12)/12) -> 0 | AC12: =IF(OR($J12="Yes",$L12="Yes",$N12="Yes"),"Yes","No") -> No | AD12: =MAX($Q12,$U12,$Y12) -> 0 | AE12: =$AD12+ROW()*0.000000001 -> 1.2e-08 | AF12: =IF($J12="Yes","A","")&IF($L12="Yes","B","")&IF($N12="Yes","C","")
B13: R0009 | C13: Program Manager (PEP13-EGI-UKG) | D13: EGI | E13: EGI | F13: AU | G13: Filled | H13: 1 | I13: 0.3432 | J13: No | L13: No | N13: No | P13: 0.3432 | Q13: =IF(AND($J13="Yes",$G13<>"Vendor day rates"),$I13-0.4*$P13,0) -> 0 | R13: =IFERROR(MATCH($K13,MonthList,0),0) -> 0 | S13: =IF(OR($J13<>"Yes",$K13=""),0,$Q13*MAX(0,7-$R13)/12) -> 0 | T13: =IF(OR($J13<>"Yes",$K13=""),0,$Q13*IF($R13<=7,12,19-$R13)/12) -> 0 | U13: =IF(AND($L13="Yes",$G13<>"Vendor day rates"),$I13-0.4*$P13,0) -> 0 | V13: =IFERROR(MATCH($M13,MonthList,0),0) -> 0 | W13: =IF(OR($L13<>"Yes",$M13=""),0,$U13*MAX(0,7-$V13)/12) -> 0 | X13: =IF(OR($L13<>"Yes",$M13=""),0,$U13*IF($V13<=7,12,19-$V13)/12) -> 0 | Y13: =IF(AND($N13="Yes",$G13<>"Vendor day rates"),$I13-0.4*$P13,0) -> 0 | Z13: =IFERROR(MATCH($O13,MonthList,0),0) -> 0 | AA13: =IF(OR($N13<>"Yes",$O13=""),0,$Y13*MAX(0,7-$Z13)/12) -> 0 | AB13: =IF(OR($N13<>"Yes",$O13=""),0,$Y13*IF($Z13<=7,12,19-$Z13)/12) -> 0 | AC13: =IF(OR($J13="Yes",$L13="Yes",$N13="Yes"),"Yes","No") -> No | AD13: =MAX($Q13,$U13,$Y13) -> 0 | AE13: =$AD13+ROW()*0.000000001 -> 1.3e-08 | AF13: =IF($J13="Yes","A","")&IF($L13="Yes","B","")&IF($N13="Yes","C","")
B14: R0010 | C14: Program Manager Tech & P&C | D14: EGI | E14: EGI | F14: AU | G14: Filled | H14: 1 | I14: 0.2664 | J14: No | L14: No | N14: No | P14: 0.2664 | Q14: =IF(AND($J14="Yes",$G14<>"Vendor day rates"),$I14-0.4*$P14,0) -> 0 | R14: =IFERROR(MATCH($K14,MonthList,0),0) -> 0 | S14: =IF(OR($J14<>"Yes",$K14=""),0,$Q14*MAX(0,7-$R14)/12) -> 0 | T14: =IF(OR($J14<>"Yes",$K14=""),0,$Q14*IF($R14<=7,12,19-$R14)/12) -> 0 | U14: =IF(AND($L14="Yes",$G14<>"Vendor day rates"),$I14-0.4*$P14,0) -> 0 | V14: =IFERROR(MATCH($M14,MonthList,0),0) -> 0 | W14: =IF(OR($L14<>"Yes",$M14=""),0,$U14*MAX(0,7-$V14)/12) -> 0 | X14: =IF(OR($L14<>"Yes",$M14=""),0,$U14*IF($V14<=7,12,19-$V14)/12) -> 0 | Y14: =IF(AND($N14="Yes",$G14<>"Vendor day rates"),$I14-0.4*$P14,0) -> 0 | Z14: =IFERROR(MATCH($O14,MonthList,0),0) -> 0 | AA14: =IF(OR($N14<>"Yes",$O14=""),0,$Y14*MAX(0,7-$Z14)/12) -> 0 | AB14: =IF(OR($N14<>"Yes",$O14=""),0,$Y14*IF($Z14<=7,12,19-$Z14)/12) -> 0 | AC14: =IF(OR($J14="Yes",$L14="Yes",$N14="Yes"),"Yes","No") -> No | AD14: =MAX($Q14,$U14,$Y14) -> 0 | AE14: =$AD14+ROW()*0.000000001 -> 1.4e-08 | AF14: =IF($J14="Yes","A","")&IF($L14="Yes","B","")&IF($N14="Yes","C","")
B15: R0011 | C15: Project Manager Retail | D15: EGI | E15: EGI | F15: AU | G15: Filled | H15: 1 | I15: 0.4884 | J15: No | L15: No | N15: No | P15: 0.4884 | Q15: =IF(AND($J15="Yes",$G15<>"Vendor day rates"),$I15-0.4*$P15,0) -> 0 | R15: =IFERROR(MATCH($K15,MonthList,0),0) -> 0 | S15: =IF(OR($J15<>"Yes",$K15=""),0,$Q15*MAX(0,7-$R15)/12) -> 0 | T15: =IF(OR($J15<>"Yes",$K15=""),0,$Q15*IF($R15<=7,12,19-$R15)/12) -> 0 | U15: =IF(AND($L15="Yes",$G15<>"Vendor day rates"),$I15-0.4*$P15,0) -> 0 | V15: =IFERROR(MATCH($M15,MonthList,0),0) -> 0 | W15: =IF(OR($L15<>"Yes",$M15=""),0,$U15*MAX(0,7-$V15)/12) -> 0 | X15: =IF(OR($L15<>"Yes",$M15=""),0,$U15*IF($V15<=7,12,19-$V15)/12) -> 0 | Y15: =IF(AND($N15="Yes",$G15<>"Vendor day rates"),$I15-0.4*$P15,0) -> 0 | Z15: =IFERROR(MATCH($O15,MonthList,0),0) -> 0 | AA15: =IF(OR($N15<>"Yes",$O15=""),0,$Y15*MAX(0,7-$Z15)/12) -> 0 | AB15: =IF(OR($N15<>"Yes",$O15=""),0,$Y15*IF($Z15<=7,12,19-$Z15)/12) -> 0 | AC15: =IF(OR($J15="Yes",$L15="Yes",$N15="Yes"),"Yes","No") -> No | AD15: =MAX($Q15,$U15,$Y15) -> 0 | AE15: =$AD15+ROW()*0.000000001 -> 1.5e-08 | AF15: =IF($J15="Yes","A","")&IF($L15="Yes","B","")&IF($N15="Yes","C","")
B16: R0012 | C16: Strategic Delivery Consultant | D16: EGI | E16: EGI | F16: AU | G16: Filled | H16: 1 | I16: 0.2997 | J16: No | L16: No | N16: No | P16: 0.2997 | Q16: =IF(AND($J16="Yes",$G16<>"Vendor day rates"),$I16-0.4*$P16,0) -> 0 | R16: =IFERROR(MATCH($K16,MonthList,0),0) -> 0 | S16: =IF(OR($J16<>"Yes",$K16=""),0,$Q16*MAX(0,7-$R16)/12) -> 0 | T16: =IF(OR($J16<>"Yes",$K16=""),0,$Q16*IF($R16<=7,12,19-$R16)/12) -> 0 | U16: =IF(AND($L16="Yes",$G16<>"Vendor day rates"),$I16-0.4*$P16,0) -> 0 | V16: =IFERROR(MATCH($M16,MonthList,0),0) -> 0 | W16: =IF(OR($L16<>"Yes",$M16=""),0,$U16*MAX(0,7-$V16)/12) -> 0 | X16: =IF(OR($L16<>"Yes",$M16=""),0,$U16*IF($V16<=7,12,19-$V16)/12) -> 0 | Y16: =IF(AND($N16="Yes",$G16<>"Vendor day rates"),$I16-0.4*$P16,0) -> 0 | Z16: =IFERROR(MATCH($O16,MonthList,0),0) -> 0 | AA16: =IF(OR($N16<>"Yes",$O16=""),0,$Y16*MAX(0,7-$Z16)/12) -> 0 | AB16: =IF(OR($N16<>"Yes",$O16=""),0,$Y16*IF($Z16<=7,12,19-$Z16)/12) -> 0 | AC16: =IF(OR($J16="Yes",$L16="Yes",$N16="Yes"),"Yes","No") -> No | AD16: =MAX($Q16,$U16,$Y16) -> 0 | AE16: =$AD16+ROW()*0.000000001 -> 1.6e-08 | AF16: =IF($J16="Yes","A","")&IF($L16="Yes","B","")&IF($N16="Yes","C","")
B17: R0013 | C17: Strategic Delivery Consultant | D17: EGI | E17: EGI | F17: AU | G17: Filled | H17: 1 | I17: 0.2304 | J17: No | L17: No | N17: No | P17: 0.2304 | Q17: =IF(AND($J17="Yes",$G17<>"Vendor day rates"),$I17-0.4*$P17,0) -> 0 | R17: =IFERROR(MATCH($K17,MonthList,0),0) -> 0 | S17: =IF(OR($J17<>"Yes",$K17=""),0,$Q17*MAX(0,7-$R17)/12) -> 0 | T17: =IF(OR($J17<>"Yes",$K17=""),0,$Q17*IF($R17<=7,12,19-$R17)/12) -> 0 | U17: =IF(AND($L17="Yes",$G17<>"Vendor day rates"),$I17-0.4*$P17,0) -> 0 | V17: =IFERROR(MATCH($M17,MonthList,0),0) -> 0 | W17: =IF(OR($L17<>"Yes",$M17=""),0,$U17*MAX(0,7-$V17)/12) -> 0 | X17: =IF(OR($L17<>"Yes",$M17=""),0,$U17*IF($V17<=7,12,19-$V17)/12) -> 0 | Y17: =IF(AND($N17="Yes",$G17<>"Vendor day rates"),$I17-0.4*$P17,0) -> 0 | Z17: =IFERROR(MATCH($O17,MonthList,0),0) -> 0 | AA17: =IF(OR($N17<>"Yes",$O17=""),0,$Y17*MAX(0,7-$Z17)/12) -> 0 | AB17: =IF(OR($N17<>"Yes",$O17=""),0,$Y17*IF($Z17<=7,12,19-$Z17)/12) -> 0 | AC17: =IF(OR($J17="Yes",$L17="Yes",$N17="Yes"),"Yes","No") -> No | AD17: =MAX($Q17,$U17,$Y17) -> 0 | AE17: =$AD17+ROW()*0.000000001 -> 1.7e-08 | AF17: =IF($J17="Yes","A","")&IF($L17="Yes","B","")&IF($N17="Yes","C","")
B18: R0014 | C18: Project Manager Deployment | E18: EGI | F18: AU | G18: Filled | H18: 1 | I18: 0.2664 | J18: No | L18: No | N18: No | P18: 0.2664 | Q18: =IF(AND($J18="Yes",$G18<>"Vendor day rates"),$I18-0.4*$P18,0) -> 0 | R18: =IFERROR(MATCH($K18,MonthList,0),0) -> 0 | S18: =IF(OR($J18<>"Yes",$K18=""),0,$Q18*MAX(0,7-$R18)/12) -> 0 | T18: =IF(OR($J18<>"Yes",$K18=""),0,$Q18*IF($R18<=7,12,19-$R18)/12) -> 0 | U18: =IF(AND($L18="Yes",$G18<>"Vendor day rates"),$I18-0.4*$P18,0) -> 0 | V18: =IFERROR(MATCH($M18,MonthList,0),0) -> 0 | W18: =IF(OR($L18<>"Yes",$M18=""),0,$U18*MAX(0,7-$V18)/12) -> 0 | X18: =IF(OR($L18<>"Yes",$M18=""),0,$U18*IF($V18<=7,12,19-$V18)/12) -> 0 | Y18: =IF(AND($N18="Yes",$G18<>"Vendor day rates"),$I18-0.4*$P18,0) -> 0 | Z18: =IFERROR(MATCH($O18,MonthList,0),0) -> 0 | AA18: =IF(OR($N18<>"Yes",$O18=""),0,$Y18*MAX(0,7-$Z18)/12) -> 0 | AB18: =IF(OR($N18<>"Yes",$O18=""),0,$Y18*IF($Z18<=7,12,19-$Z18)/12) -> 0 | AC18: =IF(OR($J18="Yes",$L18="Yes",$N18="Yes"),"Yes","No") -> No | AD18: =MAX($Q18,$U18,$Y18) -> 0 | AE18: =$AD18+ROW()*0.000000001 -> 1.8e-08 | AF18: =IF($J18="Yes","A","")&IF($L18="Yes","B","")&IF($N18="Yes","C","")
B19: R0015 | C19: Reporting Analyst | D19: Infrastructure | E19: Data & Insights | F19: AU | G19: Filled | H19: 1 | I19: 0.1976 | J19: No | L19: No | N19: No | P19: 0.1976 | Q19: =IF(AND($J19="Yes",$G19<>"Vendor day rates"),$I19-0.4*$P19,0) -> 0 | R19: =IFERROR(MATCH($K19,MonthList,0),0) -> 0 | S19: =IF(OR($J19<>"Yes",$K19=""),0,$Q19*MAX(0,7-$R19)/12) -> 0 | T19: =IF(OR($J19<>"Yes",$K19=""),0,$Q19*IF($R19<=7,12,19-$R19)/12) -> 0 | U19: =IF(AND($L19="Yes",$G19<>"Vendor day rates"),$I19-0.4*$P19,0) -> 0 | V19: =IFERROR(MATCH($M19,MonthList,0),0) -> 0 | W19: =IF(OR($L19<>"Yes",$M19=""),0,$U19*MAX(0,7-$V19)/12) -> 0 | X19: =IF(OR($L19<>"Yes",$M19=""),0,$U19*IF($V19<=7,12,19-$V19)/12) -> 0 | Y19: =IF(AND($N19="Yes",$G19<>"Vendor day rates"),$I19-0.4*$P19,0) -> 0 | Z19: =IFERROR(MATCH($O19,MonthList,0),0) -> 0 | AA19: =IF(OR($N19<>"Yes",$O19=""),0,$Y19*MAX(0,7-$Z19)/12) -> 0 | AB19: =IF(OR($N19<>"Yes",$O19=""),0,$Y19*IF($Z19<=7,12,19-$Z19)/12) -> 0 | AC19: =IF(OR($J19="Yes",$L19="Yes",$N19="Yes"),"Yes","No") -> No | AD19: =MAX($Q19,$U19,$Y19) -> 0 | AE19: =$AD19+ROW()*0.000000001 -> 1.9e-08 | AF19: =IF($J19="Yes","A","")&IF($L19="Yes","B","")&IF($N19="Yes","C","")
B20: R0016 | C20: QA / Tester / Mid | D20: Ampol Customer | E20: Ampol Loyalty & Martech | F20: AU | G20: Vendor day rates | H20: 1 | I20: 0.0733 | J20: No | L20: No | N20: No | P20: 0.0733 | Q20: =IF(AND($J20="Yes",$G20<>"Vendor day rates"),$I20-0.4*$P20,0) -> 0 | R20: =IFERROR(MATCH($K20,MonthList,0),0) -> 0 | S20: =IF(OR($J20<>"Yes",$K20=""),0,$Q20*MAX(0,7-$R20)/12) -> 0 | T20: =IF(OR($J20<>"Yes",$K20=""),0,$Q20*IF($R20<=7,12,19-$R20)/12) -> 0 | U20: =IF(AND($L20="Yes",$G20<>"Vendor day rates"),$I20-0.4*$P20,0) -> 0 | V20: =IFERROR(MATCH($M20,MonthList,0),0) -> 0 | W20: =IF(OR($L20<>"Yes",$M20=""),0,$U20*MAX(0,7-$V20)/12) -> 0 | X20: =IF(OR($L20<>"Yes",$M20=""),0,$U20*IF($V20<=7,12,19-$V20)/12) -> 0 | Y20: =IF(AND($N20="Yes",$G20<>"Vendor day rates"),$I20-0.4*$P20,0) -> 0 | Z20: =IFERROR(MATCH($O20,MonthList,0),0) -> 0 | AA20: =IF(OR($N20<>"Yes",$O20=""),0,$Y20*MAX(0,7-$Z20)/12) -> 0 | AB20: =IF(OR($N20<>"Yes",$O20=""),0,$Y20*IF($Z20<=7,12,19-$Z20)/12) -> 0 | AC20: =IF(OR($J20="Yes",$L20="Yes",$N20="Yes"),"Yes","No") -> No | AD20: =MAX($Q20,$U20,$Y20) -> 0 | AE20: =$AD20+ROW()*0.000000001 -> 2e-08 | AF20: =IF($J20="Yes","A","")&IF($L20="Yes","B","")&IF($N20="Yes","C","")
B21: R0017 | C21: Systems Analyst / Mid | D21: Ampol Customer | E21: Ampol Loyalty & Martech | F21: AU | G21: Vendor day rates | H21: 1 | I21: 0.0733 | J21: No | L21: No | N21: No | P21: 0.0733 | Q21: =IF(AND($J21="Yes",$G21<>"Vendor day rates"),$I21-0.4*$P21,0) -> 0 | R21: =IFERROR(MATCH($K21,MonthList,0),0) -> 0 | S21: =IF(OR($J21<>"Yes",$K21=""),0,$Q21*MAX(0,7-$R21)/12) -> 0 | T21: =IF(OR($J21<>"Yes",$K21=""),0,$Q21*IF($R21<=7,12,19-$R21)/12) -> 0 | U21: =IF(AND($L21="Yes",$G21<>"Vendor day rates"),$I21-0.4*$P21,0) -> 0 | V21: =IFERROR(MATCH($M21,MonthList,0),0) -> 0 | W21: =IF(OR($L21<>"Yes",$M21=""),0,$U21*MAX(0,7-$V21)/12) -> 0 | X21: =IF(OR($L21<>"Yes",$M21=""),0,$U21*IF($V21<=7,12,19-$V21)/12) -> 0 | Y21: =IF(AND($N21="Yes",$G21<>"Vendor day rates"),$I21-0.4*$P21,0) -> 0 | Z21: =IFERROR(MATCH($O21,MonthList,0),0) -> 0 | AA21: =IF(OR($N21<>"Yes",$O21=""),0,$Y21*MAX(0,7-$Z21)/12) -> 0 | AB21: =IF(OR($N21<>"Yes",$O21=""),0,$Y21*IF($Z21<=7,12,19-$Z21)/12) -> 0 | AC21: =IF(OR($J21="Yes",$L21="Yes",$N21="Yes"),"Yes","No") -> No | AD21: =MAX($Q21,$U21,$Y21) -> 0 | AE21: =$AD21+ROW()*0.000000001 -> 2.1e-08 | AF21: =IF($J21="Yes","A","")&IF($L21="Yes","B","")&IF($N21="Yes","C","")
B22: R0018 | C22: Data Migration Lead | D22: EGI Integration | E22: EGI TDD | F22: AU | G22: Filled | H22: 1 | I22: 0.2997 | J22: No | L22: No | N22: No | P22: 0.2997 | Q22: =IF(AND($J22="Yes",$G22<>"Vendor day rates"),$I22-0.4*$P22,0) -> 0 | R22: =IFERROR(MATCH($K22,MonthList,0),0) -> 0 | S22: =IF(OR($J22<>"Yes",$K22=""),0,$Q22*MAX(0,7-$R22)/12) -> 0 | T22: =IF(OR($J22<>"Yes",$K22=""),0,$Q22*IF($R22<=7,12,19-$R22)/12) -> 0 | U22: =IF(AND($L22="Yes",$G22<>"Vendor day rates"),$I22-0.4*$P22,0) -> 0 | V22: =IFERROR(MATCH($M22,MonthList,0),0) -> 0 | W22: =IF(OR($L22<>"Yes",$M22=""),0,$U22*MAX(0,7-$V22)/12) -> 0 | X22: =IF(OR($L22<>"Yes",$M22=""),0,$U22*IF($V22<=7,12,19-$V22)/12) -> 0 | Y22: =IF(AND($N22="Yes",$G22<>"Vendor day rates"),$I22-0.4*$P22,0) -> 0 | Z22: =IFERROR(MATCH($O22,MonthList,0),0) -> 0 | AA22: =IF(OR($N22<>"Yes",$O22=""),0,$Y22*MAX(0,7-$Z22)/12) -> 0 | AB22: =IF(OR($N22<>"Yes",$O22=""),0,$Y22*IF($Z22<=7,12,19-$Z22)/12) -> 0 | AC22: =IF(OR($J22="Yes",$L22="Yes",$N22="Yes"),"Yes","No") -> No | AD22: =MAX($Q22,$U22,$Y22) -> 0 | AE22: =$AD22+ROW()*0.000000001 -> 2.2e-08 | AF22: =IF($J22="Yes","A","")&IF($L22="Yes","B","")&IF($N22="Yes","C","")
B23: R0019 | C23: .NET Back End Developer / Mid | D23: Ampol Customer | E23: Digital Operations | F23: AU | G23: Vendor day rates | H23: 1 | I23: 0.0733 | J23: No | L23: No | N23: No | P23: 0.0733 | Q23: =IF(AND($J23="Yes",$G23<>"Vendor day rates"),$I23-0.4*$P23,0) -> 0 | R23: =IFERROR(MATCH($K23,MonthList,0),0) -> 0 | S23: =IF(OR($J23<>"Yes",$K23=""),0,$Q23*MAX(0,7-$R23)/12) -> 0 | T23: =IF(OR($J23<>"Yes",$K23=""),0,$Q23*IF($R23<=7,12,19-$R23)/12) -> 0 | U23: =IF(AND($L23="Yes",$G23<>"Vendor day rates"),$I23-0.4*$P23,0) -> 0 | V23: =IFERROR(MATCH($M23,MonthList,0),0) -> 0 | W23: =IF(OR($L23<>"Yes",$M23=""),0,$U23*MAX(0,7-$V23)/12) -> 0 | X23: =IF(OR($L23<>"Yes",$M23=""),0,$U23*IF($V23<=7,12,19-$V23)/12) -> 0 | Y23: =IF(AND($N23="Yes",$G23<>"Vendor day rates"),$I23-0.4*$P23,0) -> 0 | Z23: =IFERROR(MATCH($O23,MonthList,0),0) -> 0 | AA23: =IF(OR($N23<>"Yes",$O23=""),0,$Y23*MAX(0,7-$Z23)/12) -> 0 | AB23: =IF(OR($N23<>"Yes",$O23=""),0,$Y23*IF($Z23<=7,12,19-$Z23)/12) -> 0 | AC23: =IF(OR($J23="Yes",$L23="Yes",$N23="Yes"),"Yes","No") -> No | AD23: =MAX($Q23,$U23,$Y23) -> 0 | AE23: =$AD23+ROW()*0.000000001 -> 2.3e-08 | AF23: =IF($J23="Yes","A","")&IF($L23="Yes","B","")&IF($N23="Yes","C","")
B24: R0020 | C24: .NET Back End Developer / Mid | D24: Ampol Customer | E24: Digital Operations | F24: AU | G24: Vendor day rates | H24: 1 | I24: 0.0733 | J24: No | L24: No | N24: No | P24: 0.0733 | Q24: =IF(AND($J24="Yes",$G24<>"Vendor day rates"),$I24-0.4*$P24,0) -> 0 | R24: =IFERROR(MATCH($K24,MonthList,0),0) -> 0 | S24: =IF(OR($J24<>"Yes",$K24=""),0,$Q24*MAX(0,7-$R24)/12) -> 0 | T24: =IF(OR($J24<>"Yes",$K24=""),0,$Q24*IF($R24<=7,12,19-$R24)/12) -> 0 | U24: =IF(AND($L24="Yes",$G24<>"Vendor day rates"),$I24-0.4*$P24,0) -> 0 | V24: =IFERROR(MATCH($M24,MonthList,0),0) -> 0 | W24: =IF(OR($L24<>"Yes",$M24=""),0,$U24*MAX(0,7-$V24)/12) -> 0 | X24: =IF(OR($L24<>"Yes",$M24=""),0,$U24*IF($V24<=7,12,19-$V24)/12) -> 0 | Y24: =IF(AND($N24="Yes",$G24<>"Vendor day rates"),$I24-0.4*$P24,0) -> 0 | Z24: =IFERROR(MATCH($O24,MonthList,0),0) -> 0 | AA24: =IF(OR($N24<>"Yes",$O24=""),0,$Y24*MAX(0,7-$Z24)/12) -> 0 | AB24: =IF(OR($N24<>"Yes",$O24=""),0,$Y24*IF($Z24<=7,12,19-$Z24)/12) -> 0 | AC24: =IF(OR($J24="Yes",$L24="Yes",$N24="Yes"),"Yes","No") -> No | AD24: =MAX($Q24,$U24,$Y24) -> 0 | AE24: =$AD24+ROW()*0.000000001 -> 2.4e-08 | AF24: =IF($J24="Yes","A","")&IF($L24="Yes","B","")&IF($N24="Yes","C","")
B25: R0021 | C25: .NET Back End Developer / Mid | D25: Ampol Customer | E25: Digital Operations | F25: AU | G25: Vendor day rates | H25: 1 | I25: 0.0733 | J25: No | L25: No | N25: No | P25: 0.0733 | Q25: =IF(AND($J25="Yes",$G25<>"Vendor day rates"),$I25-0.4*$P25,0) -> 0 | R25: =IFERROR(MATCH($K25,MonthList,0),0) -> 0 | S25: =IF(OR($J25<>"Yes",$K25=""),0,$Q25*MAX(0,7-$R25)/12) -> 0 | T25: =IF(OR($J25<>"Yes",$K25=""),0,$Q25*IF($R25<=7,12,19-$R25)/12) -> 0 | U25: =IF(AND($L25="Yes",$G25<>"Vendor day rates"),$I25-0.4*$P25,0) -> 0 | V25: =IFERROR(MATCH($M25,MonthList,0),0) -> 0 | W25: =IF(OR($L25<>"Yes",$M25=""),0,$U25*MAX(0,7-$V25)/12) -> 0 | X25: =IF(OR($L25<>"Yes",$M25=""),0,$U25*IF($V25<=7,12,19-$V25)/12) -> 0 | Y25: =IF(AND($N25="Yes",$G25<>"Vendor day rates"),$I25-0.4*$P25,0) -> 0 | Z25: =IFERROR(MATCH($O25,MonthList,0),0) -> 0 | AA25: =IF(OR($N25<>"Yes",$O25=""),0,$Y25*MAX(0,7-$Z25)/12) -> 0 | AB25: =IF(OR($N25<>"Yes",$O25=""),0,$Y25*IF($Z25<=7,12,19-$Z25)/12) -> 0 | AC25: =IF(OR($J25="Yes",$L25="Yes",$N25="Yes"),"Yes","No") -> No | AD25: =MAX($Q25,$U25,$Y25) -> 0 | AE25: =$AD25+ROW()*0.000000001 -> 2.5e-08 | AF25: =IF($J25="Yes","A","")&IF($L25="Yes","B","")&IF($N25="Yes","C","")
B26: R0022 | C26: QA / Tester / Mid | D26: Ampol Customer | E26: Digital Operations | F26: AU | G26: Vendor day rates | H26: 1 | I26: 0.0733 | J26: No | L26: No | N26: No | P26: 0.0733 | Q26: =IF(AND($J26="Yes",$G26<>"Vendor day rates"),$I26-0.4*$P26,0) -> 0 | R26: =IFERROR(MATCH($K26,MonthList,0),0) -> 0 | S26: =IF(OR($J26<>"Yes",$K26=""),0,$Q26*MAX(0,7-$R26)/12) -> 0 | T26: =IF(OR($J26<>"Yes",$K26=""),0,$Q26*IF($R26<=7,12,19-$R26)/12) -> 0 | U26: =IF(AND($L26="Yes",$G26<>"Vendor day rates"),$I26-0.4*$P26,0) -> 0 | V26: =IFERROR(MATCH($M26,MonthList,0),0) -> 0 | W26: =IF(OR($L26<>"Yes",$M26=""),0,$U26*MAX(0,7-$V26)/12) -> 0 | X26: =IF(OR($L26<>"Yes",$M26=""),0,$U26*IF($V26<=7,12,19-$V26)/12) -> 0 | Y26: =IF(AND($N26="Yes",$G26<>"Vendor day rates"),$I26-0.4*$P26,0) -> 0 | Z26: =IFERROR(MATCH($O26,MonthList,0),0) -> 0 | AA26: =IF(OR($N26<>"Yes",$O26=""),0,$Y26*MAX(0,7-$Z26)/12) -> 0 | AB26: =IF(OR($N26<>"Yes",$O26=""),0,$Y26*IF($Z26<=7,12,19-$Z26)/12) -> 0 | AC26: =IF(OR($J26="Yes",$L26="Yes",$N26="Yes"),"Yes","No") -> No | AD26: =MAX($Q26,$U26,$Y26) -> 0 | AE26: =$AD26+ROW()*0.000000001 -> 2.6e-08 | AF26: =IF($J26="Yes","A","")&IF($L26="Yes","B","")&IF($N26="Yes","C","")
B27: R0023 | C27: Integration Architect (C) - Boomi | D27: EGI | E27: EGI TDD | F27: AU | G27: Filled | H27: 1 | I27: 0.3481 | J27: No | L27: No | N27: No | P27: 0.3481 | Q27: =IF(AND($J27="Yes",$G27<>"Vendor day rates"),$I27-0.4*$P27,0) -> 0 | R27: =IFERROR(MATCH($K27,MonthList,0),0) -> 0 | S27: =IF(OR($J27<>"Yes",$K27=""),0,$Q27*MAX(0,7-$R27)/12) -> 0 | T27: =IF(OR($J27<>"Yes",$K27=""),0,$Q27*IF($R27<=7,12,19-$R27)/12) -> 0 | U27: =IF(AND($L27="Yes",$G27<>"Vendor day rates"),$I27-0.4*$P27,0) -> 0 | V27: =IFERROR(MATCH($M27,MonthList,0),0) -> 0 | W27: =IF(OR($L27<>"Yes",$M27=""),0,$U27*MAX(0,7-$V27)/12) -> 0 | X27: =IF(OR($L27<>"Yes",$M27=""),0,$U27*IF($V27<=7,12,19-$V27)/12) -> 0 | Y27: =IF(AND($N27="Yes",$G27<>"Vendor day rates"),$I27-0.4*$P27,0) -> 0 | Z27: =IFERROR(MATCH($O27,MonthList,0),0) -> 0 | AA27: =IF(OR($N27<>"Yes",$O27=""),0,$Y27*MAX(0,7-$Z27)/12) -> 0 | AB27: =IF(OR($N27<>"Yes",$O27=""),0,$Y27*IF($Z27<=7,12,19-$Z27)/12) -> 0 | AC27: =IF(OR($J27="Yes",$L27="Yes",$N27="Yes"),"Yes","No") -> No | AD27: =MAX($Q27,$U27,$Y27) -> 0 | AE27: =$AD27+ROW()*0.000000001 -> 2.7e-08 | AF27: =IF($J27="Yes","A","")&IF($L27="Yes","B","")&IF($N27="Yes","C","")
B28: R0024 | C28: Integration Architect (C) | D28: EGI | E28: EGI TDD | F28: NZ | G28: Filled | H28: 1 | I28: 0.2664 | J28: No | L28: No | N28: No | P28: 0.2664 | Q28: =IF(AND($J28="Yes",$G28<>"Vendor day rates"),$I28-0.4*$P28,0) -> 0 | R28: =IFERROR(MATCH($K28,MonthList,0),0) -> 0 | S28: =IF(OR($J28<>"Yes",$K28=""),0,$Q28*MAX(0,7-$R28)/12) -> 0 | T28: =IF(OR($J28<>"Yes",$K28=""),0,$Q28*IF($R28<=7,12,19-$R28)/12) -> 0 | U28: =IF(AND($L28="Yes",$G28<>"Vendor day rates"),$I28-0.4*$P28,0) -> 0 | V28: =IFERROR(MATCH($M28,MonthList,0),0) -> 0 | W28: =IF(OR($L28<>"Yes",$M28=""),0,$U28*MAX(0,7-$V28)/12) -> 0 | X28: =IF(OR($L28<>"Yes",$M28=""),0,$U28*IF($V28<=7,12,19-$V28)/12) -> 0 | Y28: =IF(AND($N28="Yes",$G28<>"Vendor day rates"),$I28-0.4*$P28,0) -> 0 | Z28: =IFERROR(MATCH($O28,MonthList,0),0) -> 0 | AA28: =IF(OR($N28<>"Yes",$O28=""),0,$Y28*MAX(0,7-$Z28)/12) -> 0 | AB28: =IF(OR($N28<>"Yes",$O28=""),0,$Y28*IF($Z28<=7,12,19-$Z28)/12) -> 0 | AC28: =IF(OR($J28="Yes",$L28="Yes",$N28="Yes"),"Yes","No") -> No | AD28: =MAX($Q28,$U28,$Y28) -> 0 | AE28: =$AD28+ROW()*0.000000001 -> 2.8e-08 | AF28: =IF($J28="Yes","A","")&IF($L28="Yes","B","")&IF($N28="Yes","C","")
B29: R0025 | C29: Engineer - Mobile | D29: Ampol Customer | E29: Ampol App | F29: AU | G29: Filled | H29: 1 | I29: 0.1909 | J29: No | L29: No | N29: No | P29: 0.1909 | Q29: =IF(AND($J29="Yes",$G29<>"Vendor day rates"),$I29-0.4*$P29,0) -> 0 | R29: =IFERROR(MATCH($K29,MonthList,0),0) -> 0 | S29: =IF(OR($J29<>"Yes",$K29=""),0,$Q29*MAX(0,7-$R29)/12) -> 0 | T29: =IF(OR($J29<>"Yes",$K29=""),0,$Q29*IF($R29<=7,12,19-$R29)/12) -> 0 | U29: =IF(AND($L29="Yes",$G29<>"Vendor day rates"),$I29-0.4*$P29,0) -> 0 | V29: =IFERROR(MATCH($M29,MonthList,0),0) -> 0 | W29: =IF(OR($L29<>"Yes",$M29=""),0,$U29*MAX(0,7-$V29)/12) -> 0 | X29: =IF(OR($L29<>"Yes",$M29=""),0,$U29*IF($V29<=7,12,19-$V29)/12) -> 0 | Y29: =IF(AND($N29="Yes",$G29<>"Vendor day rates"),$I29-0.4*$P29,0) -> 0 | Z29: =IFERROR(MATCH($O29,MonthList,0),0) -> 0 | AA29: =IF(OR($N29<>"Yes",$O29=""),0,$Y29*MAX(0,7-$Z29)/12) -> 0 | AB29: =IF(OR($N29<>"Yes",$O29=""),0,$Y29*IF($Z29<=7,12,19-$Z29)/12) -> 0 | AC29: =IF(OR($J29="Yes",$L29="Yes",$N29="Yes"),"Yes","No") -> No | AD29: =MAX($Q29,$U29,$Y29) -> 0 | AE29: =$AD29+ROW()*0.000000001 -> 2.9e-08 | AF29: =IF($J29="Yes","A","")&IF($L29="Yes","B","")&IF($N29="Yes","C","")
B30: R0026 | C30: Solution Architect | D30: Ampol Customer | E30: Ampol Web | F30: AU | G30: Filled | H30: 1 | I30: 0.3219 | J30: No | L30: No | N30: No | P30: 0.3219 | Q30: =IF(AND($J30="Yes",$G30<>"Vendor day rates"),$I30-0.4*$P30,0) -> 0 | R30: =IFERROR(MATCH($K30,MonthList,0),0) -> 0 | S30: =IF(OR($J30<>"Yes",$K30=""),0,$Q30*MAX(0,7-$R30)/12) -> 0 | T30: =IF(OR($J30<>"Yes",$K30=""),0,$Q30*IF($R30<=7,12,19-$R30)/12) -> 0 | U30: =IF(AND($L30="Yes",$G30<>"Vendor day rates"),$I30-0.4*$P30,0) -> 0 | V30: =IFERROR(MATCH($M30,MonthList,0),0) -> 0 | W30: =IF(OR($L30<>"Yes",$M30=""),0,$U30*MAX(0,7-$V30)/12) -> 0 | X30: =IF(OR($L30<>"Yes",$M30=""),0,$U30*IF($V30<=7,12,19-$V30)/12) -> 0 | Y30: =IF(AND($N30="Yes",$G30<>"Vendor day rates"),$I30-0.4*$P30,0) -> 0 | Z30: =IFERROR(MATCH($O30,MonthList,0),0) -> 0 | AA30: =IF(OR($N30<>"Yes",$O30=""),0,$Y30*MAX(0,7-$Z30)/12) -> 0 | AB30: =IF(OR($N30<>"Yes",$O30=""),0,$Y30*IF($Z30<=7,12,19-$Z30)/12) -> 0 | AC30: =IF(OR($J30="Yes",$L30="Yes",$N30="Yes"),"Yes","No") -> No | AD30: =MAX($Q30,$U30,$Y30) -> 0 | AE30: =$AD30+ROW()*0.000000001 -> 3e-08 | AF30: =IF($J30="Yes","A","")&IF($L30="Yes","B","")&IF($N30="Yes","C","")
... B32: R0028 | C32: Quality Assurance | D32: Ampol Customer | E32: Ampol App | F32: AU | G32: Already at the offshore rate | H32: 1 | I32: 0.0717 | J32: No | L32: No | N32: No | P32: 0.1792 | Q32: =IF(AND($J32="Yes",$G32<>"Vendor day rates"),$I32-0.4*$P32,0) -> 0 | R32: =IFERROR(MATCH($K32,MonthList,0),0) -> 0 | S32: =IF(OR($J32<>"Yes",$K32=""),0,$Q32*MAX(0,7-$R32)/12) -> 0 | T32: =IF(OR($J32<>"Yes",$K32=""),0,$Q32*IF($R32<=7,12,19-$R32)/12) -> 0 | U32: =IF(AND($L32="Yes",$G32<>"Vendor day rates"),$I32-0.4*$P32,0) -> 0 | V32: =IFERROR(MATCH($M32,MonthList,0),0) -> 0 | W32: =IF(OR($L32<>"Yes",$M32=""),0,$U32*MAX(0,7-$V32)/12) -> 0 | X32: =IF(OR($L32<>"Yes",$M32=""),0,$U32*IF($V32<=7,12,19-$V32)/12) -> 0 | Y32: =IF(AND($N32="Yes",$G32<>"Vendor day rates"),$I32-0.4*$P32,0) -> 0 | Z32: =IFERROR(MATCH($O32,MonthList,0),0) -> 0 | AA32: =IF(OR($N32<>"Yes",$O32=""),0,$Y32*MAX(0,7-$Z32)/12) -> 0 | AB32: =IF(OR($N32<>"Yes",$O32=""),0,$Y32*IF($Z32<=7,12,19-$Z32)/12) -> 0 | AC32: =IF(OR($J32="Yes",$L32="Yes",$N32="Yes"),"Yes","No") -> No | AD32: =MAX($Q32,$U32,$Y32) -> 0 | AE32: =$AD32+ROW()*0.000000001 -> 3.2e-08 | AF32: =IF($J32="Yes","A","")&IF($L32="Yes","B","")&IF($N32="Yes","C","")
B33: R0029 | C33: Lead Engineer - Mobile | D33: Ampol Customer | E33: Ampol App | F33: AU | G33: Already at the offshore rate | H33: 1 | I33: 0.1113 | J33: Yes | K33: Oct-2026 | L33: No | N33: No | P33: 0.2782 | Q33: =IF(AND($J33="Yes",$G33<>"Vendor day rates"),$I33-0.4*$P33,0) -> 2e-05 | R33: =IFERROR(MATCH($K33,MonthList,0),0) -> 4 | S33: =IF(OR($J33<>"Yes",$K33=""),0,$Q33*MAX(0,7-$R33)/12) -> 5e-06 | T33: =IF(OR($J33<>"Yes",$K33=""),0,$Q33*IF($R33<=7,12,19-$R33)/12) -> 2e-05 | U33: =IF(AND($L33="Yes",$G33<>"Vendor day rates"),$I33-0.4*$P33,0) -> 0 | V33: =IFERROR(MATCH($M33,MonthList,0),0) -> 0 | W33: =IF(OR($L33<>"Yes",$M33=""),0,$U33*MAX(0,7-$V33)/12) -> 0 | X33: =IF(OR($L33<>"Yes",$M33=""),0,$U33*IF($V33<=7,12,19-$V33)/12) -> 0 | Y33: =IF(AND($N33="Yes",$G33<>"Vendor day rates"),$I33-0.4*$P33,0) -> 0 | Z33: =IFERROR(MATCH($O33,MonthList,0),0) -> 0 | AA33: =IF(OR($N33<>"Yes",$O33=""),0,$Y33*MAX(0,7-$Z33)/12) -> 0 | AB33: =IF(OR($N33<>"Yes",$O33=""),0,$Y33*IF($Z33<=7,12,19-$Z33)/12) -> 0 | AC33: =IF(OR($J33="Yes",$L33="Yes",$N33="Yes"),"Yes","No") -> Yes | AD33: =MAX($Q33,$U33,$Y33) -> 2e-05 | AE33: =$AD33+ROW()*0.000000001 -> 2.0033e-05 | AF33: =IF($J33="Yes","A","")&IF($L33="Yes","B","")&IF($N33="Yes","C","") -> A
B34: R0030 | C34: Solution Architect | D34: Ampol Customer | E34: Ampol Web | F34: AU | G34: Filled | H34: 1 | I34: 0.2431 | J34: No | L34: No | N34: No | P34: 0.2431 | Q34: =IF(AND($J34="Yes",$G34<>"Vendor day rates"),$I34-0.4*$P34,0) -> 0 | R34: =IFERROR(MATCH($K34,MonthList,0),0) -> 0 | S34: =IF(OR($J34<>"Yes",$K34=""),0,$Q34*MAX(0,7-$R34)/12) -> 0 | T34: =IF(OR($J34<>"Yes",$K34=""),0,$Q34*IF($R34<=7,12,19-$R34)/12) -> 0 | U34: =IF(AND($L34="Yes",$G34<>"Vendor day rates"),$I34-0.4*$P34,0) -> 0 | V34: =IFERROR(MATCH($M34,MonthList,0),0) -> 0 | W34: =IF(OR($L34<>"Yes",$M34=""),0,$U34*MAX(0,7-$V34)/12) -> 0 | X34: =IF(OR($L34<>"Yes",$M34=""),0,$U34*IF($V34<=7,12,19-$V34)/12) -> 0 | Y34: =IF(AND($N34="Yes",$G34<>"Vendor day rates"),$I34-0.4*$P34,0) -> 0 | Z34: =IFERROR(MATCH($O34,MonthList,0),0) -> 0 | AA34: =IF(OR($N34<>"Yes",$O34=""),0,$Y34*MAX(0,7-$Z34)/12) -> 0 | AB34: =IF(OR($N34<>"Yes",$O34=""),0,$Y34*IF($Z34<=7,12,19-$Z34)/12) -> 0 | AC34: =IF(OR($J34="Yes",$L34="Yes",$N34="Yes"),"Yes","No") -> No | AD34: =MAX($Q34,$U34,$Y34) -> 0 | AE34: =$AD34+ROW()*0.000000001 -> 3.4e-08 | AF34: =IF($J34="Yes","A","")&IF($L34="Yes","B","")&IF($N34="Yes","C","")
B35: R0031 | C35: Quality Assurance | D35: EGI Integration | E35: EGI Customer | F35: AU | G35: Filled | H35: 1 | I35: 0.2697 | J35: No | L35: No | N35: No | P35: 0.2697 | Q35: =IF(AND($J35="Yes",$G35<>"Vendor day rates"),$I35-0.4*$P35,0) -> 0 | R35: =IFERROR(MATCH($K35,MonthList,0),0) -> 0 | S35: =IF(OR($J35<>"Yes",$K35=""),0,$Q35*MAX(0,7-$R35)/12) -> 0 | T35: =IF(OR($J35<>"Yes",$K35=""),0,$Q35*IF($R35<=7,12,19-$R35)/12) -> 0 | U35: =IF(AND($L35="Yes",$G35<>"Vendor day rates"),$I35-0.4*$P35,0) -> 0 | V35: =IFERROR(MATCH($M35,MonthList,0),0) -> 0 | W35: =IF(OR($L35<>"Yes",$M35=""),0,$U35*MAX(0,7-$V35)/12) -> 0 | X35: =IF(OR($L35<>"Yes",$M35=""),0,$U35*IF($V35<=7,12,19-$V35)/12) -> 0 | Y35: =IF(AND($N35="Yes",$G35<>"Vendor day rates"),$I35-0.4*$P35,0) -> 0 | Z35: =IFERROR(MATCH($O35,MonthList,0),0) -> 0 | AA35: =IF(OR($N35<>"Yes",$O35=""),0,$Y35*MAX(0,7-$Z35)/12) -> 0 | AB35: =IF(OR($N35<>"Yes",$O35=""),0,$Y35*IF($Z35<=7,12,19-$Z35)/12) -> 0 | AC35: =IF(OR($J35="Yes",$L35="Yes",$N35="Yes"),"Yes","No") -> No | AD35: =MAX($Q35,$U35,$Y35) -> 0 | AE35: =$AD35+ROW()*0.000000001 -> 3.5e-08 | AF35: =IF($J35="Yes","A","")&IF($L35="Yes","B","")&IF($N35="Yes","C","")
B36: R0032 | C36: Delivery Lead - Integration | D36: EGI | E36: EGI | F36: AU | G36: Filled | H36: 1 | I36: 0.2735 | J36: No | L36: No | N36: No | P36: 0.2735 | Q36: =IF(AND($J36="Yes",$G36<>"Vendor day rates"),$I36-0.4*$P36,0) -> 0 | R36: =IFERROR(MATCH($K36,MonthList,0),0) -> 0 | S36: =IF(OR($J36<>"Yes",$K36=""),0,$Q36*MAX(0,7-$R36)/12) -> 0 | T36: =IF(OR($J36<>"Yes",$K36=""),0,$Q36*IF($R36<=7,12,19-$R36)/12) -> 0 | U36: =IF(AND($L36="Yes",$G36<>"Vendor day rates"),$I36-0.4*$P36,0) -> 0 | V36: =IFERROR(MATCH($M36,MonthList,0),0) -> 0 | W36: =IF(OR($L36<>"Yes",$M36=""),0,$U36*MAX(0,7-$V36)/12) -> 0 | X36: =IF(OR($L36<>"Yes",$M36=""),0,$U36*IF($V36<=7,12,19-$V36)/12) -> 0 | Y36: =IF(AND($N36="Yes",$G36<>"Vendor day rates"),$I36-0.4*$P36,0) -> 0 | Z36: =IFERROR(MATCH($O36,MonthList,0),0) -> 0 | AA36: =IF(OR($N36<>"Yes",$O36=""),0,$Y36*MAX(0,7-$Z36)/12) -> 0 | AB36: =IF(OR($N36<>"Yes",$O36=""),0,$Y36*IF($Z36<=7,12,19-$Z36)/12) -> 0 | AC36: =IF(OR($J36="Yes",$L36="Yes",$N36="Yes"),"Yes","No") -> No | AD36: =MAX($Q36,$U36,$Y36) -> 0 | AE36: =$AD36+ROW()*0.000000001 -> 3.6e-08 | AF36: =IF($J36="Yes","A","")&IF($L36="Yes","B","")&IF($N36="Yes","C","")
B37: R0033 | C37: SAP Solution Architect | E37: SAP ERP | F37: AU | G37: Filled | H37: 1 | I37: 0.3552 | J37: No | L37: No | N37: No | P37: 0.3552 | Q37: =IF(AND($J37="Yes",$G37<>"Vendor day rates"),$I37-0.4*$P37,0) -> 0 | R37: =IFERROR(MATCH($K37,MonthList,0),0) -> 0 | S37: =IF(OR($J37<>"Yes",$K37=""),0,$Q37*MAX(0,7-$R37)/12) -> 0 | T37: =IF(OR($J37<>"Yes",$K37=""),0,$Q37*IF($R37<=7,12,19-$R37)/12) -> 0 | U37: =IF(AND($L37="Yes",$G37<>"Vendor day rates"),$I37-0.4*$P37,0) -> 0 | V37: =IFERROR(MATCH($M37,MonthList,0),0) -> 0 | W37: =IF(OR($L37<>"Yes",$M37=""),0,$U37*MAX(0,7-$V37)/12) -> 0 | X37: =IF(OR($L37<>"Yes",$M37=""),0,$U37*IF($V37<=7,12,19-$V37)/12) -> 0 | Y37: =IF(AND($N37="Yes",$G37<>"Vendor day rates"),$I37-0.4*$P37,0) -> 0 | Z37: =IFERROR(MATCH($O37,MonthList,0),0) -> 0 | AA37: =IF(OR($N37<>"Yes",$O37=""),0,$Y37*MAX(0,7-$Z37)/12) -> 0 | AB37: =IF(OR($N37<>"Yes",$O37=""),0,$Y37*IF($Z37<=7,12,19-$Z37)/12) -> 0 | AC37: =IF(OR($J37="Yes",$L37="Yes",$N37="Yes"),"Yes","No") -> No | AD37: =MAX($Q37,$U37,$Y37) -> 0 | AE37: =$AD37+ROW()*0.000000001 -> 3.7e-08 | AF37: =IF($J37="Yes","A","")&IF($L37="Yes","B","")&IF($N37="Yes","C","")
B38: R0034 | C38: Project Manger | D38: EGI | E38: EGI | F38: AU | G38: Filled | H38: 1 | I38: 0.222 | J38: No | L38: No | N38: No | P38: 0.222 | Q38: =IF(AND($J38="Yes",$G38<>"Vendor day rates"),$I38-0.4*$P38,0) -> 0 | R38: =IFERROR(MATCH($K38,MonthList,0),0) -> 0 | S38: =IF(OR($J38<>"Yes",$K38=""),0,$Q38*MAX(0,7-$R38)/12) -> 0 | T38: =IF(OR($J38<>"Yes",$K38=""),0,$Q38*IF($R38<=7,12,19-$R38)/12) -> 0 | U38: =IF(AND($L38="Yes",$G38<>"Vendor day rates"),$I38-0.4*$P38,0) -> 0 | V38: =IFERROR(MATCH($M38,MonthList,0),0) -> 0 | W38: =IF(OR($L38<>"Yes",$M38=""),0,$U38*MAX(0,7-$V38)/12) -> 0 | X38: =IF(OR($L38<>"Yes",$M38=""),0,$U38*IF($V38<=7,12,19-$V38)/12) -> 0 | Y38: =IF(AND($N38="Yes",$G38<>"Vendor day rates"),$I38-0.4*$P38,0) -> 0 | Z38: =IFERROR(MATCH($O38,MonthList,0),0) -> 0 | AA38: =IF(OR($N38<>"Yes",$O38=""),0,$Y38*MAX(0,7-$Z38)/12) -> 0 | AB38: =IF(OR($N38<>"Yes",$O38=""),0,$Y38*IF($Z38<=7,12,19-$Z38)/12) -> 0 | AC38: =IF(OR($J38="Yes",$L38="Yes",$N38="Yes"),"Yes","No") -> No | AD38: =MAX($Q38,$U38,$Y38) -> 0 | AE38: =$AD38+ROW()*0.000000001 -> 3.8e-08 | AF38: =IF($J38="Yes","A","")&IF($L38="Yes","B","")&IF($N38="Yes","C","")
B39: R0035 | C39: strategic program architect | D39: EGI | E39: EGI | F39: AU | G39: Filled | H39: 1 | I39: 0.333 | J39: No | L39: No | N39: No | P39: 0.333 | Q39: =IF(AND($J39="Yes",$G39<>"Vendor day rates"),$I39-0.4*$P39,0) -> 0 | R39: =IFERROR(MATCH($K39,MonthList,0),0) -> 0 | S39: =IF(OR($J39<>"Yes",$K39=""),0,$Q39*MAX(0,7-$R39)/12) -> 0 | T39: =IF(OR($J39<>"Yes",$K39=""),0,$Q39*IF($R39<=7,12,19-$R39)/12) -> 0 | U39: =IF(AND($L39="Yes",$G39<>"Vendor day rates"),$I39-0.4*$P39,0) -> 0 | V39: =IFERROR(MATCH($M39,MonthList,0),0) -> 0 | W39: =IF(OR($L39<>"Yes",$M39=""),0,$U39*MAX(0,7-$V39)/12) -> 0 | X39: =IF(OR($L39<>"Yes",$M39=""),0,$U39*IF($V39<=7,12,19-$V39)/12) -> 0 | Y39: =IF(AND($N39="Yes",$G39<>"Vendor day rates"),$I39-0.4*$P39,0) -> 0 | Z39: =IFERROR(MATCH($O39,MonthList,0),0) -> 0 | AA39: =IF(OR($N39<>"Yes",$O39=""),0,$Y39*MAX(0,7-$Z39)/12) -> 0 | AB39: =IF(OR($N39<>"Yes",$O39=""),0,$Y39*IF($Z39<=7,12,19-$Z39)/12) -> 0 | AC39: =IF(OR($J39="Yes",$L39="Yes",$N39="Yes"),"Yes","No") -> No | AD39: =MAX($Q39,$U39,$Y39) -> 0 | AE39: =$AD39+ROW()*0.000000001 -> 3.9e-08 | AF39: =IF($J39="Yes","A","")&IF($L39="Yes","B","")&IF($N39="Yes","C","")
B40: R0036 | C40: Engineer - BE | D40: Ampol Customer | E40: Ampol Web | F40: AU | G40: Already at the offshore rate | H40: 1 | I40: 0.111 | J40: No | L40: No | N40: No | P40: 0.2775 | Q40: =IF(AND($J40="Yes",$G40<>"Vendor day rates"),$I40-0.4*$P40,0) -> 0 | R40: =IFERROR(MATCH($K40,MonthList,0),0) -> 0 | S40: =IF(OR($J40<>"Yes",$K40=""),0,$Q40*MAX(0,7-$R40)/12) -> 0 | T40: =IF(OR($J40<>"Yes",$K40=""),0,$Q40*IF($R40<=7,12,19-$R40)/12) -> 0 | U40: =IF(AND($L40="Yes",$G40<>"Vendor day rates"),$I40-0.4*$P40,0) -> 0 | V40: =IFERROR(MATCH($M40,MonthList,0),0) -> 0 | W40: =IF(OR($L40<>"Yes",$M40=""),0,$U40*MAX(0,7-$V40)/12) -> 0 | X40: =IF(OR($L40<>"Yes",$M40=""),0,$U40*IF($V40<=7,12,19-$V40)/12) -> 0 | Y40: =IF(AND($N40="Yes",$G40<>"Vendor day rates"),$I40-0.4*$P40,0) -> 0 | Z40: =IFERROR(MATCH($O40,MonthList,0),0) -> 0 | AA40: =IF(OR($N40<>"Yes",$O40=""),0,$Y40*MAX(0,7-$Z40)/12) -> 0 | AB40: =IF(OR($N40<>"Yes",$O40=""),0,$Y40*IF($Z40<=7,12,19-$Z40)/12) -> 0 | AC40: =IF(OR($J40="Yes",$L40="Yes",$N40="Yes"),"Yes","No") -> No | AD40: =MAX($Q40,$U40,$Y40) -> 0 | AE40: =$AD40+ROW()*0.000000001 -> 4e-08 | AF40: =IF($J40="Yes","A","")&IF($L40="Yes","B","")&IF($N40="Yes","C","")
B41: R0037 | C41: Engineer - BE | D41: Ampol Customer | E41: Ampol App | F41: AU | G41: Already at the offshore rate | H41: 1 | I41: 0.1082 | J41: No | L41: No | N41: No | P41: 0.2705 | Q41: =IF(AND($J41="Yes",$G41<>"Vendor day rates"),$I41-0.4*$P41,0) -> 0 | R41: =IFERROR(MATCH($K41,MonthList,0),0) -> 0 | S41: =IF(OR($J41<>"Yes",$K41=""),0,$Q41*MAX(0,7-$R41)/12) -> 0 | T41: =IF(OR($J41<>"Yes",$K41=""),0,$Q41*IF($R41<=7,12,19-$R41)/12) -> 0 | U41: =IF(AND($L41="Yes",$G41<>"Vendor day rates"),$I41-0.4*$P41,0) -> 0 | V41: =IFERROR(MATCH($M41,MonthList,0),0) -> 0 | W41: =IF(OR($L41<>"Yes",$M41=""),0,$U41*MAX(0,7-$V41)/12) -> 0 | X41: =IF(OR($L41<>"Yes",$M41=""),0,$U41*IF($V41<=7,12,19-$V41)/12) -> 0 | Y41: =IF(AND($N41="Yes",$G41<>"Vendor day rates"),$I41-0.4*$P41,0) -> 0 | Z41: =IFERROR(MATCH($O41,MonthList,0),0) -> 0 | AA41: =IF(OR($N41<>"Yes",$O41=""),0,$Y41*MAX(0,7-$Z41)/12) -> 0 | AB41: =IF(OR($N41<>"Yes",$O41=""),0,$Y41*IF($Z41<=7,12,19-$Z41)/12) -> 0 | AC41: =IF(OR($J41="Yes",$L41="Yes",$N41="Yes"),"Yes","No") -> No | AD41: =MAX($Q41,$U41,$Y41) -> 0 | AE41: =$AD41+ROW()*0.000000001 -> 4.1e-08 | AF41: =IF($J41="Yes","A","")&IF($L41="Yes","B","")&IF($N41="Yes","C","")
B42: R0038 | C42: Engineer - BE | D42: EGI Integration | E42: EGI Customer | F42: AU | G42: Filled | H42: 1 | I42: 0 | J42: No | L42: No | N42: No | P42: 0 | Q42: =IF(AND($J42="Yes",$G42<>"Vendor day rates"),$I42-0.4*$P42,0) -> 0 | R42: =IFERROR(MATCH($K42,MonthList,0),0) -> 0 | S42: =IF(OR($J42<>"Yes",$K42=""),0,$Q42*MAX(0,7-$R42)/12) -> 0 | T42: =IF(OR($J42<>"Yes",$K42=""),0,$Q42*IF($R42<=7,12,19-$R42)/12) -> 0 | U42: =IF(AND($L42="Yes",$G42<>"Vendor day rates"),$I42-0.4*$P42,0) -> 0 | V42: =IFERROR(MATCH($M42,MonthList,0),0) -> 0 | W42: =IF(OR($L42<>"Yes",$M42=""),0,$U42*MAX(0,7-$V42)/12) -> 0 | X42: =IF(OR($L42<>"Yes",$M42=""),0,$U42*IF($V42<=7,12,19-$V42)/12) -> 0 | Y42: =IF(AND($N42="Yes",$G42<>"Vendor day rates"),$I42-0.4*$P42,0) -> 0 | Z42: =IFERROR(MATCH($O42,MonthList,0),0) -> 0 | AA42: =IF(OR($N42<>"Yes",$O42=""),0,$Y42*MAX(0,7-$Z42)/12) -> 0 | AB42: =IF(OR($N42<>"Yes",$O42=""),0,$Y42*IF($Z42<=7,12,19-$Z42)/12) -> 0 | AC42: =IF(OR($J42="Yes",$L42="Yes",$N42="Yes"),"Yes","No") -> No | AD42: =MAX($Q42,$U42,$Y42) -> 0 | AE42: =$AD42+ROW()*0.000000001 -> 4.2e-08 | AF42: =IF($J42="Yes","A","")&IF($L42="Yes","B","")&IF($N42="Yes","C","")
...

Sheet 3 Compare
B1: Compare your three lists
B2: Everything here moves the moment you set a role to Yes on the Pick roles tab. All figures are A$ millions.
B4: Measure | C4: ='1 Start here'!$B$8 -> Example | D4: ='1 Start here'!$E$8 -> List B | E4: ='1 Start here'!$H$8 -> List C | H4: Month | I4: ='1 Start here'!$B$8 -> Example | J4: ='1 Start here'!$E$8 -> List B | K4: ='1 Start here'!$H$8 -> List C
B5: Roles moved | C5: =COUNTIF('2 Pick roles'!$J$5:$J$544,"Yes") -> 4 | D5: =COUNTIF('2 Pick roles'!$L$5:$L$544,"Yes") -> 0 | E5: =COUNTIF('2 Pick roles'!$N$5:$N$544,"Yes") -> 0 | H5: ='4 Lists'!$B$2 -> Jul-2026 | I5: =SUMPRODUCT(('2 Pick roles'!$R$5:$R$544>=1)*('2 Pick roles'!$R$5:$R$544<=1)*'2 Pick roles'!$Q$5:$Q$544) -> 0 | J5: =SUMPRODUCT(('2 Pick roles'!$V$5:$V$544>=1)*('2 Pick roles'!$V$5:$V$544<=1)*'2 Pick roles'!$U$5:$U$544) -> 0 | K5: =SUMPRODUCT(('2 Pick roles'!$Z$5:$Z$544>=1)*('2 Pick roles'!$Z$5:$Z$544<=1)*'2 Pick roles'!$Y$5:$Y$544) -> 0
B6: People (FTE) | C6: =SUMIF('2 Pick roles'!$J$5:$J$544,"Yes",'2 Pick roles'!$H$5:$H$544) -> 4 | D6: =SUMIF('2 Pick roles'!$L$5:$L$544,"Yes",'2 Pick roles'!$H$5:$H$544) -> 0 | E6: =SUMIF('2 Pick roles'!$N$5:$N$544,"Yes",'2 Pick roles'!$H$5:$H$544) -> 0 | H6: ='4 Lists'!$B$3 -> Aug-2026 | I6: =SUMPRODUCT(('2 Pick roles'!$R$5:$R$544>=1)*('2 Pick roles'!$R$5:$R$544<=2)*'2 Pick roles'!$Q$5:$Q$544) -> 0 | J6: =SUMPRODUCT(('2 Pick roles'!$V$5:$V$544>=1)*('2 Pick roles'!$V$5:$V$544<=2)*'2 Pick roles'!$U$5:$U$544) -> 0 | K6: =SUMPRODUCT(('2 Pick roles'!$Z$5:$Z$544>=1)*('2 Pick roles'!$Z$5:$Z$544<=2)*'2 Pick roles'!$Y$5:$Y$544) -> 0
B7: Cost today | C7: =SUMIF('2 Pick roles'!$J$5:$J$544,"Yes",'2 Pick roles'!$I$5:$I$544) -> 0.7607 | D7: =SUMIF('2 Pick roles'!$L$5:$L$544,"Yes",'2 Pick roles'!$I$5:$I$544) -> 0 | E7: =SUMIF('2 Pick roles'!$N$5:$N$544,"Yes",'2 Pick roles'!$I$5:$I$544) -> 0 | H7: ='4 Lists'!$B$4 -> Sep-2026 | I7: =SUMPRODUCT(('2 Pick roles'!$R$5:$R$544>=1)*('2 Pick roles'!$R$5:$R$544<=3)*'2 Pick roles'!$Q$5:$Q$544) -> 0 | J7: =SUMPRODUCT(('2 Pick roles'!$V$5:$V$544>=1)*('2 Pick roles'!$V$5:$V$544<=3)*'2 Pick roles'!$U$5:$U$544) -> 0 | K7: =SUMPRODUCT(('2 Pick roles'!$Z$5:$Z$544>=1)*('2 Pick roles'!$Z$5:$Z$544<=3)*'2 Pick roles'!$Y$5:$Y$544) -> 0
B8: Cost at the offshore rate | C8: =C7-C9 -> 0.37104 | D8: =D7-D9 -> 0 | E8: =E7-E9 -> 0 | H8: ='4 Lists'!$B$5 -> Oct-2026 | I8: =SUMPRODUCT(('2 Pick roles'!$R$5:$R$544>=1)*('2 Pick roles'!$R$5:$R$544<=4)*'2 Pick roles'!$Q$5:$Q$544) -> 0.28472 | J8: =SUMPRODUCT(('2 Pick roles'!$V$5:$V$544>=1)*('2 Pick roles'!$V$5:$V$544<=4)*'2 Pick roles'!$U$5:$U$544) -> 0 | K8: =SUMPRODUCT(('2 Pick roles'!$Z$5:$Z$544>=1)*('2 Pick roles'!$Z$5:$Z$544<=4)*'2 Pick roles'!$Y$5:$Y$544) -> 0
B9: Cost taken out, full year | C9: =SUM('2 Pick roles'!$Q$5:$Q$544) -> 0.38966 | D9: =SUM('2 Pick roles'!$U$5:$U$544) -> 0 | E9: =SUM('2 Pick roles'!$Y$5:$Y$544) -> 0 | H9: ='4 Lists'!$B$6 -> Nov-2026 | I9: =SUMPRODUCT(('2 Pick roles'!$R$5:$R$544>=1)*('2 Pick roles'!$R$5:$R$544<=5)*'2 Pick roles'!$Q$5:$Q$544) -> 0.28472 | J9: =SUMPRODUCT(('2 Pick roles'!$V$5:$V$544>=1)*('2 Pick roles'!$V$5:$V$544<=5)*'2 Pick roles'!$U$5:$U$544) -> 0 | K9: =SUMPRODUCT(('2 Pick roles'!$Z$5:$Z$544>=1)*('2 Pick roles'!$Z$5:$Z$544<=5)*'2 Pick roles'!$Y$5:$Y$544) -> 0
B10: Taken out in 2026 | C10: =SUM('2 Pick roles'!$S$5:$S$544) -> 0.07118 | D10: =SUM('2 Pick roles'!$W$5:$W$544) -> 0 | E10: =SUM('2 Pick roles'!$AA$5:$AA$544) -> 0 | H10: ='4 Lists'!$B$7 -> Dec-2026 | I10: =SUMPRODUCT(('2 Pick roles'!$R$5:$R$544>=1)*('2 Pick roles'!$R$5:$R$544<=6)*'2 Pick roles'!$Q$5:$Q$544) -> 0.28472 | J10: =SUMPRODUCT(('2 Pick roles'!$V$5:$V$544>=1)*('2 Pick roles'!$V$5:$V$544<=6)*'2 Pick roles'!$U$5:$U$544) -> 0 | K10: =SUMPRODUCT(('2 Pick roles'!$Z$5:$Z$544>=1)*('2 Pick roles'!$Z$5:$Z$544<=6)*'2 Pick roles'!$Y$5:$Y$544) -> 0
B11: Taken out in 2027 | C11: =SUM('2 Pick roles'!$T$5:$T$544) -> 0.38966 | D11: =SUM('2 Pick roles'!$X$5:$X$544) -> 0 | E11: =SUM('2 Pick roles'!$AB$5:$AB$544) -> 0 | H11: ='4 Lists'!$B$8 -> Jan-2027 | I11: =SUMPRODUCT(('2 Pick roles'!$R$5:$R$544>=1)*('2 Pick roles'!$R$5:$R$544<=7)*'2 Pick roles'!$Q$5:$Q$544) -> 0.38966 | J11: =SUMPRODUCT(('2 Pick roles'!$V$5:$V$544>=1)*('2 Pick roles'!$V$5:$V$544<=7)*'2 Pick roles'!$U$5:$U$544) -> 0 | K11: =SUMPRODUCT(('2 Pick roles'!$Z$5:$Z$544>=1)*('2 Pick roles'!$Z$5:$Z$544<=7)*'2 Pick roles'!$Y$5:$Y$544) -> 0
H12: ='4 Lists'!$B$9 -> Feb-2027 | I12: =SUMPRODUCT(('2 Pick roles'!$R$5:$R$544>=1)*('2 Pick roles'!$R$5:$R$544<=8)*'2 Pick roles'!$Q$5:$Q$544) -> 0.38966 | J12: =SUMPRODUCT(('2 Pick roles'!$V$5:$V$544>=1)*('2 Pick roles'!$V$5:$V$544<=8)*'2 Pick roles'!$U$5:$U$544) -> 0 | K12: =SUMPRODUCT(('2 Pick roles'!$Z$5:$Z$544>=1)*('2 Pick roles'!$Z$5:$Z$544<=8)*'2 Pick roles'!$Y$5:$Y$544) -> 0
H13: ='4 Lists'!$B$10 -> Mar-2027 | I13: =SUMPRODUCT(('2 Pick roles'!$R$5:$R$544>=1)*('2 Pick roles'!$R$5:$R$544<=9)*'2 Pick roles'!$Q$5:$Q$544) -> 0.38966 | J13: =SUMPRODUCT(('2 Pick roles'!$V$5:$V$544>=1)*('2 Pick roles'!$V$5:$V$544<=9)*'2 Pick roles'!$U$5:$U$544) -> 0 | K13: =SUMPRODUCT(('2 Pick roles'!$Z$5:$Z$544>=1)*('2 Pick roles'!$Z$5:$Z$544<=9)*'2 Pick roles'!$Y$5:$Y$544) -> 0
B14: Cost taken out by portfolio, full year | H14: ='4 Lists'!$B$11 -> Apr-2027 | I14: =SUMPRODUCT(('2 Pick roles'!$R$5:$R$544>=1)*('2 Pick roles'!$R$5:$R$544<=10)*'2 Pick roles'!$Q$5:$Q$544) -> 0.38966 | J14: =SUMPRODUCT(('2 Pick roles'!$V$5:$V$544>=1)*('2 Pick roles'!$V$5:$V$544<=10)*'2 Pick roles'!$U$5:$U$544) -> 0 | K14: =SUMPRODUCT(('2 Pick roles'!$Z$5:$Z$544>=1)*('2 Pick roles'!$Z$5:$Z$544<=10)*'2 Pick roles'!$Y$5:$Y$544) -> 0
B15: Portfolio | C15: ='1 Start here'!$B$8 -> Example | D15: ='1 Start here'!$E$8 -> List B | E15: ='1 Start here'!$H$8 -> List C | H15: ='4 Lists'!$B$12 -> May-2027 | I15: =SUMPRODUCT(('2 Pick roles'!$R$5:$R$544>=1)*('2 Pick roles'!$R$5:$R$544<=11)*'2 Pick roles'!$Q$5:$Q$544) -> 0.38966 | J15: =SUMPRODUCT(('2 Pick roles'!$V$5:$V$544>=1)*('2 Pick roles'!$V$5:$V$544<=11)*'2 Pick roles'!$U$5:$U$544) -> 0 | K15: =SUMPRODUCT(('2 Pick roles'!$Z$5:$Z$544>=1)*('2 Pick roles'!$Z$5:$Z$544<=11)*'2 Pick roles'!$Y$5:$Y$544) -> 0
B16: EGI Integration | C16: =SUMIFS('2 Pick roles'!$Q$5:$Q$544,'2 Pick roles'!$D$5:$D$544,"EGI Integration") -> 0 | D16: =SUMIFS('2 Pick roles'!$U$5:$U$544,'2 Pick roles'!$D$5:$D$544,"EGI Integration") -> 0 | E16: =SUMIFS('2 Pick roles'!$Y$5:$Y$544,'2 Pick roles'!$D$5:$D$544,"EGI Integration") -> 0 | H16: ='4 Lists'!$B$13 -> Jun-2027 | I16: =SUMPRODUCT(('2 Pick roles'!$R$5:$R$544>=1)*('2 Pick roles'!$R$5:$R$544<=12)*'2 Pick roles'!$Q$5:$Q$544) -> 0.38966 | J16: =SUMPRODUCT(('2 Pick roles'!$V$5:$V$544>=1)*('2 Pick roles'!$V$5:$V$544<=12)*'2 Pick roles'!$U$5:$U$544) -> 0 | K16: =SUMPRODUCT(('2 Pick roles'!$Z$5:$Z$544>=1)*('2 Pick roles'!$Z$5:$Z$544<=12)*'2 Pick roles'!$Y$5:$Y$544) -> 0
B17: Ampol Customer | C17: =SUMIFS('2 Pick roles'!$Q$5:$Q$544,'2 Pick roles'!$D$5:$D$544,"Ampol Customer") -> 0.16376 | D17: =SUMIFS('2 Pick roles'!$U$5:$U$544,'2 Pick roles'!$D$5:$D$544,"Ampol Customer") -> 0 | E17: =SUMIFS('2 Pick roles'!$Y$5:$Y$544,'2 Pick roles'!$D$5:$D$544,"Ampol Customer") -> 0 | H17: ='4 Lists'!$B$14 -> Jul-2027 | I17: =SUMPRODUCT(('2 Pick roles'!$R$5:$R$544>=1)*('2 Pick roles'!$R$5:$R$544<=13)*'2 Pick roles'!$Q$5:$Q$544) -> 0.38966 | J17: =SUMPRODUCT(('2 Pick roles'!$V$5:$V$544>=1)*('2 Pick roles'!$V$5:$V$544<=13)*'2 Pick roles'!$U$5:$U$544) -> 0 | K17: =SUMPRODUCT(('2 Pick roles'!$Z$5:$Z$544>=1)*('2 Pick roles'!$Z$5:$Z$544<=13)*'2 Pick roles'!$Y$5:$Y$544) -> 0
B18: EGI | C18: =SUMIFS('2 Pick roles'!$Q$5:$Q$544,'2 Pick roles'!$D$5:$D$544,"EGI") -> 0 | D18: =SUMIFS('2 Pick roles'!$U$5:$U$544,'2 Pick roles'!$D$5:$D$544,"EGI") -> 0 | E18: =SUMIFS('2 Pick roles'!$Y$5:$Y$544,'2 Pick roles'!$D$5:$D$544,"EGI") -> 0 | H18: ='4 Lists'!$B$15 -> Aug-2027 | I18: =SUMPRODUCT(('2 Pick roles'!$R$5:$R$544>=1)*('2 Pick roles'!$R$5:$R$544<=14)*'2 Pick roles'!$Q$5:$Q$544) -> 0.38966 | J18: =SUMPRODUCT(('2 Pick roles'!$V$5:$V$544>=1)*('2 Pick roles'!$V$5:$V$544<=14)*'2 Pick roles'!$U$5:$U$544) -> 0 | K18: =SUMPRODUCT(('2 Pick roles'!$Z$5:$Z$544>=1)*('2 Pick roles'!$Z$5:$Z$544<=14)*'2 Pick roles'!$Y$5:$Y$544) -> 0
B19: Infrastructure | C19: =SUMIFS('2 Pick roles'!$Q$5:$Q$544,'2 Pick roles'!$D$5:$D$544,"Infrastructure") -> 0 | D19: =SUMIFS('2 Pick roles'!$U$5:$U$544,'2 Pick roles'!$D$5:$D$544,"Infrastructure") -> 0 | E19: =SUMIFS('2 Pick roles'!$Y$5:$Y$544,'2 Pick roles'!$D$5:$D$544,"Infrastructure") -> 0 | H19: ='4 Lists'!$B$16 -> Sep-2027 | I19: =SUMPRODUCT(('2 Pick roles'!$R$5:$R$544>=1)*('2 Pick roles'!$R$5:$R$544<=15)*'2 Pick roles'!$Q$5:$Q$544) -> 0.38966 | J19: =SUMPRODUCT(('2 Pick roles'!$V$5:$V$544>=1)*('2 Pick roles'!$V$5:$V$544<=15)*'2 Pick roles'!$U$5:$U$544) -> 0 | K19: =SUMPRODUCT(('2 Pick roles'!$Z$5:$Z$544>=1)*('2 Pick roles'!$Z$5:$Z$544<=15)*'2 Pick roles'!$Y$5:$Y$544) -> 0
B20: NA | C20: =SUMIFS('2 Pick roles'!$Q$5:$Q$544,'2 Pick roles'!$D$5:$D$544,"NA") -> 0 | D20: =SUMIFS('2 Pick roles'!$U$5:$U$544,'2 Pick roles'!$D$5:$D$544,"NA") -> 0 | E20: =SUMIFS('2 Pick roles'!$Y$5:$Y$544,'2 Pick roles'!$D$5:$D$544,"NA") -> 0 | H20: ='4 Lists'!$B$17 -> Oct-2027 | I20: =SUMPRODUCT(('2 Pick roles'!$R$5:$R$544>=1)*('2 Pick roles'!$R$5:$R$544<=16)*'2 Pick roles'!$Q$5:$Q$544) -> 0.38966 | J20: =SUMPRODUCT(('2 Pick roles'!$V$5:$V$544>=1)*('2 Pick roles'!$V$5:$V$544<=16)*'2 Pick roles'!$U$5:$U$544) -> 0 | K20: =SUMPRODUCT(('2 Pick roles'!$Z$5:$Z$544>=1)*('2 Pick roles'!$Z$5:$Z$544<=16)*'2 Pick roles'!$Y$5:$Y$544) -> 0
