Workbook

Sheet 1 FY26 Forecast
B2: FY26 people cost
B3: The model with the vacancy hire months. All in AUD; New Zealand at the live rate.
B5: Input | C5: Value | D5: What it does
B6: Live NZD to AUD rate | C6: 0.83 | D6: Converts NZ to AUD
B7: Operating model adjustment to contingent and personnel ($m) | C7: 0 | D7: Spread one twelfth per month
B9: Gross | C9: Actuals to June | D9: July | E9: August | F9: September | G9: October | H9: November | I9: December | J9: FY26 landing | K9: Budget | L9: Over/(under) allocation
B10: NZ | C10: =$C$6*'2 Data - Finance (June)'!D11 -> 8.4807478 | D10: ='3 Data - model'!$C$52/12-SUMPRODUCT(('4 Vacancy timing'!$D$6:$D$107="NZ")*('4 Vacancy timing'!$C$6:$C$107>"2026-07")*'4 Vacancy timing'!$F$6:$F$107)/12 -> 1.6537014 | E10: ='3 Data - model'!$C$52/12-SUMPRODUCT(('4 Vacancy timing'!$D$6:$D$107="NZ")*('4 Vacancy timing'!$C$6:$C$107>"2026-08")*'4 Vacancy timing'!$F$6:$F$107)/12 -> 1.6537014 | F10: ='3 Data - model'!$C$52/12-SUMPRODUCT(('4 Vacancy timing'!$D$6:$D$107="NZ")*('4 Vacancy timing'!$C$6:$C$107>"2026-09")*'4 Vacancy timing'!$F$6:$F$107)/12 -> 1.6657987 | G10: ='3 Data - model'!$C$52/12-SUMPRODUCT(('4 Vacancy timing'!$D$6:$D$107="NZ")*('4 Vacancy timing'!$C$6:$C$107>"2026-10")*'4 Vacancy timing'!$F$6:$F$107)/12 -> 1.6657987 | H10: ='3 Data - model'!$C$52/12-SUMPRODUCT(('4 Vacancy timing'!$D$6:$D$107="NZ")*('4 Vacancy timing'!$C$6:$C$107>"2026-11")*'4 Vacancy timing'!$F$6:$F$107)/12 -> 1.6762982 | I10: ='3 Data - model'!$C$52/12-SUMPRODUCT(('4 Vacancy timing'!$D$6:$D$107="NZ")*('4 Vacancy timing'!$C$6:$C$107>"2026-12")*'4 Vacancy timing'!$F$6:$F$107)/12 -> 1.6762982 | J10: =C10+SUM(D10:I10) -> 18.472344 | K10: =21.5*$C$6 -> 17.845 | L10: =J10-K10 -> 0.62734426
B11: AU | C11: ='2 Data - Finance (June)'!D6 -> 30.261728 | D11: ='3 Data - model'!$C$51/12-SUMPRODUCT(('4 Vacancy timing'!$D$6:$D$107="AU")*('4 Vacancy timing'!$C$6:$C$107>"2026-07")*'4 Vacancy timing'!$F$6:$F$107)/12 -> 5.0999592 | E11: ='3 Data - model'!$C$51/12-SUMPRODUCT(('4 Vacancy timing'!$D$6:$D$107="AU")*('4 Vacancy timing'!$C$6:$C$107>"2026-08")*'4 Vacancy timing'!$F$6:$F$107)/12 -> 5.3600342 | F11: ='3 Data - model'!$C$51/12-SUMPRODUCT(('4 Vacancy timing'!$D$6:$D$107="AU")*('4 Vacancy timing'!$C$6:$C$107>"2026-09")*'4 Vacancy timing'!$F$6:$F$107)/12 -> 5.8863342 | G11: ='3 Data - model'!$C$51/12-SUMPRODUCT(('4 Vacancy timing'!$D$6:$D$107="AU")*('4 Vacancy timing'!$C$6:$C$107>"2026-10")*'4 Vacancy timing'!$F$6:$F$107)/12 -> 6.0787758 | H11: ='3 Data - model'!$C$51/12-SUMPRODUCT(('4 Vacancy timing'!$D$6:$D$107="AU")*('4 Vacancy timing'!$C$6:$C$107>"2026-11")*'4 Vacancy timing'!$F$6:$F$107)/12 -> 6.1524258 | I11: ='3 Data - model'!$C$51/12-SUMPRODUCT(('4 Vacancy timing'!$D$6:$D$107="AU")*('4 Vacancy timing'!$C$6:$C$107>"2026-12")*'4 Vacancy timing'!$F$6:$F$107)/12 -> 6.1524258 | J11: =C11+SUM(D11:I11) -> 64.991683 | K11: 62.59 | L11: =J11-K11 -> 2.4016832
B12: Total | C12: =C10+C11 -> 38.742476 | D12: =D10+D11 -> 6.7536606 | E12: =E10+E11 -> 7.0137356 | F12: =F10+F11 -> 7.5521328 | G12: =G10+G11 -> 7.7445745 | H12: =H10+H11 -> 7.828724 | I12: =I10+I11 -> 7.828724 | J12: =J10+J11 -> 83.464027 | K12: =K10+K11 -> 80.435 | L12: =J12-K12 -> 3.0290275
B13: Gross is the model price of everyone on board. Gross budgets: Australia 62.59 AUD; New Zealand 21.5 NZD at the live rate. NZ actuals are its people cost line.
B15: TDD Lights on | C15: Actuals to June | D15: July | E15: August | F15: September | G15: October | H15: November | I15: December | J15: FY26 landing | K15: Budget | L15: Over/(under) allocation
B16: NZ | C16: =$C$6*'2 Data - Finance (June)'!D11 -> 8.4807478 | D16: ='6 Monthly view'!I8 -> 1.2300197 | E16: ='6 Monthly view'!J8 -> 1.2300197 | F16: ='6 Monthly view'!K8 -> 1.2324391 | G16: ='6 Monthly view'!L8 -> 1.2324391 | H16: ='6 Monthly view'!M8 -> 1.2429386 | I16: ='6 Monthly view'!N8 -> 1.2429386 | J16: =C16+SUM(D16:I16) -> 15.891542 | K16: 17.5 | L16: =J16-K16 -> -1.6084575
B17: AU | C17: ='2 Data - Finance (June)'!D10 -> 20.010006 | D17: ='6 Monthly view'!I7 -> 2.3907774 | E17: ='6 Monthly view'!J7 -> 2.5033616 | F17: ='6 Monthly view'!K7 -> 2.7827386 | G17: ='6 Monthly view'!L7 -> 2.9215949 | H17: ='6 Monthly view'!M7 -> 2.9906982 | I17: ='6 Monthly view'!N7 -> 2.9906982 | J17: =C17+SUM(D17:I17) -> 36.589875 | K17: 33 | L17: =J17-K17 -> 3.589875
B18: Total | C18: =C16+C17 -> 28.490754 | D18: =D16+D17 -> 3.6207971 | E18: =E16+E17 -> 3.7333812 | F18: =F16+F17 -> 4.0151778 | G18: =G16+G17 -> 4.154034 | H18: =H16+H17 -> 4.2336368 | I18: =I16+I17 -> 4.2336368 | J18: =J16+J17 -> 52.481417 | K18: 50.5 | L18: =J18-K18 -> 1.9814175
B19: New Zealand actuals run in NZD and convert at the live rate; the forecast months are the model AUD figures. Budget columns carry each side share of the 50.5 allocation, 17.5 and 33.0.
B21: December exit run rate, annualised | J21: ='6 Monthly view'!N11 -> 50.803642
B22: The FY27 model plans | J22: 54.12 | K22: 50.5 | L22: =J22-K22 -> 3.62
B24: ="All checks pass: "&IF(AND(ABS(J18-'6 Monthly view'!N10)<0.01,ABS(J18-(J16+J17))<0.005,ABS(J12-(J10+J11))<0.005,ABS(('3 Data - model'!C51+'3 Data - model'!C52)-99.3562)<0.001),"Yes","No") -> All checks pass: Yes
B26: How the forecast is built
B27: 1 January to June are Finance's closed months: Staff Cost for Australia, People Costs for New Zealand.
B28: 2 July to December price everyone on board each month: the model with everyone at a full year, less the roles not yet hired. Each vacancy joins in its planned hire month on tab 4.
B29: 3 A vacancy counts at its cost times its squad support percentage; EGI-funded roles count zero.
B30: 4 New Zealand actuals to June convert at the live rate in the cream cell; the forecast months are the model AUD figures. The NZ gross budget of 21.5 NZD converts at the live rate.
B31: 5 Gross is the model price of everyone on board. The operating model adjustment spreads one twelfth a month.

Sheet 2 Data - Finance (June)
B2: Finance figures from the June report
B3: Every number below is the value read from the June Finance report file named in the source column. Nothing on this tab is typed by hand and nothing on this tab is a forecast of our own - Finance supplies actuals.
B5: Line | C5: Source | D5: Actual to June | E5: Budget to June | F5: Jan actual | G5: Feb actual | H5: Mar actual | I5: Apr actual | J5: May actual | K5: Jun actual | L5: Jul forecast | M5: Aug forecast | N5: Sep forecast | O5: Oct forecast | P5: Nov forecast | Q5: Dec forecast | R5: Full year forecast | S5: Full year budget
B6: Internal Labor (AUD) | C6: TDD Pack (2) row 31 | D6: 30.261728 | E6: 31.434341 | F6: 4.0504688 | G6: 4.6973693 | H6: 4.6992191 | I6: 5.7596441 | J6: 5.0874698 | K6: 5.9675571 | L6: 4.7041959 | M6: 4.7297354 | N6: 4.763949 | O6: 4.6739987 | P6: 4.5856917 | Q6: 4.5856917 | R6: 57.049195 | S6: 62.593258
B7: Contingent Labour (AUD) | C7: TDD Pack (2) row 32 | D7: 0.5248523 | E7: 0.98497128 | F7: -0.13004342 | G7: -0.00368095 | H7: 0.30849969 | I7: 0.10437343 | J7: 0.06358262 | K7: 0.18212093 | L7: 0.21193 | M7: 0.21193 | N7: 0.21193 | O7: 0.21193 | P7: 0.01193 | Q7: 0.01193 | R7: 1.4262414 | S7: 1.8132759
B8: Personnel Costs (AUD) | C8: TDD Pack (2) row 33 | D8: 0.21470203 | E8: 0.408952 | F8: 0.03175936 | G8: 0.03755478 | H8: 0.04625839 | I8: 0.02322646 | J8: 0.03546735 | K8: 0.04043569 | L8: 0.079462 | M8: 0.077262 | N8: 0.079462 | O8: 0.076462 | P8: 0.077262 | Q8: 0.034362 | R8: 0.67500034 | S8: 0.822279
B9: Labour Recharge (AUD) | C9: TDD Pack (2) row 34 | D9: -10.991277 | E9: -14.78914 | F9: -0.93222691 | G9: -1.6342265 | H9: -2.1266457 | I9: -1.7623245 | J9: -2.1822301 | K9: -2.3536228 | L9: -2.1213352 | M9: -2.1291052 | N9: -2.1239252 | O9: -2.1265152 | P9: -2.1265152 | Q9: -2.1368752 | R9: -23.540107 | S9: -29.997424
B10: Staff Cost (AUD) | C10: TDD Pack (2) row 35 | D10: 20.010006 | E10: 18.039125 | F10: 3.0199578 | G10: 3.0970167 | H10: 2.9273314 | I10: 4.1249195 | J10: 3.0042897 | K10: 3.8364909 | L10: 2.8742527 | M10: 2.8898222 | N10: 2.9314158 | O10: 2.8358756 | P10: 2.5483685 | Q10: 2.4951085 | R10: 35.61033 | S10: 35.23139
B11: People Costs, New Zealand (NZD) | C11: TDD Pack (2) row 49 | D11: 10.217768 | E11: 10.320252 | F11: 1.4201672 | G11: 1.6934564 | H11: 1.5285588 | I11: 1.3680817 | J11: 1.8352543 | K11: 2.37225 | L11: 1.780915 | M11: 1.780915 | N11: 1.780915 | O11: 1.780915 | P11: 1.780915 | Q11: 1.780915 | R11: 20.903258 | S11: 21.530787
B13: Actual to June is column O, budget to June column P, the closed months are columns AG to AL, the July to December forecast is columns BE to BJ, the full year forecast is column BK and the full year budget is column X. The six closed months add to the actual to June on every line.
B15: Lights on for the whole of TDD, AUD | C15: Source | D15: Full year budget | E15: Actual to June | F15: Full year forecast
B16: Australia (TDD Corporate) | C16: Presentation Pack (2) O21, N5, N21 | D16: 78.894863 | E16: 40.972956 | F16: 79.310436
B17: New Zealand (Z-Energy) | C17: Presentation Pack (2) O22, N6, N22 | D17: 52.22526 | E17: 26.455513 | F17: 53.465434
B18: Total TDD lights on | D18: =SUM(D16:D17) -> 131.12012 | E18: =SUM(E16:E17) -> 67.428469 | F18: =SUM(F16:F17) -> 132.77587
B19: The Presentation Pack figures are the lights on run for the whole of TDD and are stated in AUD on both lines. The people cost tracked on tab 1 is the slice of this run that the cost model prices.

Sheet 3 Data - model
B2: Model figures used by this forecast
B3: Block A holds the figures read from the FY27 cost model file. When an updated model arrives, retype the block A values against the source cells named beside them and the whole workbook moves. Blocks B, C and D are worked out from block A and tab 4 by formula.
B5: Block A - current model (refresh these when the updated model arrives) | C5: Value ($m) | D5: Source cell
B6: Total people cost after levers | C6: ='7 Model 3.5'!C24 -> 98.83025 | D6: Tab 7, the pasted 3.5 total people cost
B7: Cost to TDD lights on | C7: ='7 Model 3.5'!L24 -> 54.117722 | D7: Tab 7, the pasted 3.5 cost to TDD lights on
B8: What TDD pays, Australia | C8: ='8 Model 3.6'!M24 -> 38.911036 | D8: Tab 8, the pasted 3.6 Australian spend
B9: What TDD pays, New Zealand, AUD | C9: ='8 Model 3.6'!N24 -> 15.206685 | D9: Tab 8, the pasted 3.6 New Zealand spend, AUD as the model holds it
B10: Allocation, total | C10: 50.5 | D10: 0.2 Data Config E27
B11: Allocation, Australia | C11: 33 | D11: 0.2 Data Config C27
B12: Allocation, New Zealand | C12: 17.5 | D12: 0.2 Data Config D27
B13: Full budget, total | C13: 53.8 | D13: 0.2 Data Config E28
B14: Full budget, Australia | C14: 36.2 | D14: 0.2 Data Config C28
B15: Full budget, New Zealand | C15: 17.6 | D15: 0.2 Data Config D28
B16: Funded outside | C16: 19.8327 | D16: 3.5 TDD Lights On D24
B17: Support cost | C17: 31.2205 | D17: 3.5 TDD Lights On E24
B18: Overheads inside what TDD pays | C18: 22.8972 | D18: 3.5 TDD Lights On K24
B19: Add back to price the twelve start quarter roles at a full year | C19: 0.3113 | D19: 2.1 F84, F86, F87, F88, F89; 2.2 F56, F57; 2.6 F41; 2.7 F30; 2.8 F51; 2.9 F58; 2.13 F45; factors Lists AC14:AD17
B20: What TDD pays with everyone at a full year, Australia | C20: =C8+C19 -> 39.222336 | D20: Block A what TDD pays for Australia, plus the add back. All twelve roles sit on the Australian side.
B21: What TDD pays with everyone at a full year, New Zealand, AUD | C21: =C9 -> 15.206685 | D21: Block A what TDD pays for New Zealand, unchanged. No New Zealand role is priced from a start quarter.
B22: What TDD pays with everyone at a full year, total | C22: =C20+C21 -> 54.429022 | D22: The Australian and New Zealand figures together. Equals 54.1177 plus 0.3113.
B23: The model prices twelve roles from an FY27 start quarter: 2.1 F84, F86, F87, F88 and F89, 2.2 F56 and F57, 2.6 F41, 2.7 F30, 2.8 F51, 2.9 F58 and 2.13 F45, with the quarter factors on Lists AC14 to AD17. A start quarter is an FY27 idea, so FY26 prices everyone at a full year: each of the twelve comes back at its after lever cost times its support percentage times one less its quarter factor, 0.3113 in all. Checked role by role in the model: all twelve sit on the Australian side, so the whole add back is Australian and the New Zealand figure is unchanged. The two New Zealand priced vacancies both start inside the 2026 half, so no New Zealand role is priced from a start quarter.
B25: Block B - the Australian second half | C25: Value ($m) | D25: How it is worked out
B26: What TDD pays for Australia for the year, everyone at a full year | C26: =C20 -> 39.222336 | D26: Block A, the full year Australian figure
B27: Half a year of that | C27: =C26/2 -> 19.611168 | D27: The year figure divided by two
B28: July start halves on the Australian roles | C28: ='4 Vacancy timing'!I108 -> 5.4044038 | D28: Tab 4, the Australian July start halves
B29: Planned months cost on the Australian roles | C29: ='4 Vacancy timing'!J108 -> 2.3731046 | D29: Tab 4, the Australian planned months cost
B30: Second half Staff Cost before the operating model adjustment | C30: =C27-C28+C29 -> 16.579869 | D30: Half a year, less the July start halves, plus the planned months cost
B31: Staff Cost monthly target before the operating model adjustment | C31: =C30/6 -> 2.7633115 | D31: The second half spread over the six months
B32: Contingent Labour monthly rate from actuals to June | C32: ='2 Data - Finance (June)'!D7/6 -> 0.087475383 | D32: Tab 2, actual to June divided by six
B33: Personnel Costs monthly rate from actuals to June | C33: ='2 Data - Finance (June)'!D8/6 -> 0.035783672 | D33: Tab 2, actual to June divided by six
B34: Labour Recharge monthly rate from actuals to June | C34: ='2 Data - Finance (June)'!D9/6 -> -1.8318794 | D34: Tab 2, actual to June divided by six
B35: Internal Labor monthly, the line the operating model drives | C35: =C31-C32-C33-C34 -> 4.4719319 | D35: The target less the three lines that run on at the rate they ran to June
B36: Contingent Labour, Personnel Costs and Labour Recharge run on at the rate they ran to June. Internal Labor carries the operating model: it is set so that, before any operating model adjustment, Staff Cost across the six months equals half a year of what TDD pays for Australia with everyone at a full year, less the July start halves on the Australian vacancies, plus the planned months cost of the same vacancies.
B38: Block C - the New Zealand second half | C38: Value ($m) | D38: How it is worked out
B39: What TDD pays for New Zealand for the year, AUD, at a full year | C39: =C21 -> 15.206685 | D39: Block A, the full year New Zealand figure
B40: Half a year of that | C40: =C39/2 -> 7.6033426 | D40: The year figure divided by two
B41: July start halves on the New Zealand roles | C41: ='4 Vacancy timing'!I109 -> 0.2232247 | D41: Tab 4, the New Zealand July start halves
B42: Planned months cost on the New Zealand roles | C42: ='4 Vacancy timing'!J109 -> 0.0306768 | D42: Tab 4, the New Zealand planned months cost
B43: New Zealand second half, AUD | C43: =C40-C41+C42 -> 7.4107947 | D43: Half a year, less the July start halves, plus the planned months cost
B44: New Zealand monthly figure, AUD | C44: =C43/6 -> 1.2351325 | D44: The second half spread over the six months
...

Sheet 4 Vacancy timing
B2: Vacancy timing
B3: The priced vacancies with their hire months, plus the 17 priced roles with no date, assumed to start January 2027 per the ruling. Holds are holds: they carry zero whatever their dates. NZ roles in NZD; the live rate converts them.
B5: Role ID | C5: Hire month | D5: Country | E5: Squad | F5: Annual after lever cost ($m) | G5: Support percentage | H5: What TDD pays a year ($m) | I5: July start half ($m) | J5: Planned months cost ($m)
B6: R0360 | C6: 2026-09 | D6: AU | E6: Above Store | F6: 0.0682 | G6: 0.2 | H6: 0.01364 | I6: =H6/2 -> 0.00682 | J6: =H6*IF(VALUE(LEFT(C6,4))=2026,MAX(0,MIN(6,13-VALUE(RIGHT(C6,2)))),0)/12 -> 0.0045466667
B7: R0467 | C7: 2026-11 | D7: AU | E7: Above Store | F7: 0.0682 | G7: 0.2 | H7: 0.01364 | I7: =H7/2 -> 0.00682 | J7: =H7*IF(VALUE(LEFT(C7,4))=2026,MAX(0,MIN(6,13-VALUE(RIGHT(C7,2)))),0)/12 -> 0.0022733333
B8: R0468 | C8: 2026-09 | D8: AU | E8: Above Store | F8: 0.2016 | G8: 0.2 | H8: 0.04032 | I8: =H8/2 -> 0.02016 | J8: =H8*IF(VALUE(LEFT(C8,4))=2026,MAX(0,MIN(6,13-VALUE(RIGHT(C8,2)))),0)/12 -> 0.01344
B9: R0235 | C9: 2026-10 | D9: AU | E9: Data AU | F9: 0.0811 | G9: 0.9 | H9: 0.07299 | I9: =H9/2 -> 0.036495 | J9: =H9*IF(VALUE(LEFT(C9,4))=2026,MAX(0,MIN(6,13-VALUE(RIGHT(C9,2)))),0)/12 -> 0.0182475
B10: R0320 | C10: 2026-10 | D10: AU | E10: Data AU | F10: 0.0806 | G10: 0.9 | H10: 0.07254 | I10: =H10/2 -> 0.03627 | J10: =H10*IF(VALUE(LEFT(C10,4))=2026,MAX(0,MIN(6,13-VALUE(RIGHT(C10,2)))),0)/12 -> 0.018135
B11: R0321 | C11: 2026-10 | D11: AU | E11: Data AU | F11: 0.0927 | G11: 0.9 | H11: 0.08343 | I11: =H11/2 -> 0.041715 | J11: =H11*IF(VALUE(LEFT(C11,4))=2026,MAX(0,MIN(6,13-VALUE(RIGHT(C11,2)))),0)/12 -> 0.0208575
B12: R0322 | C12: 2026-10 | D12: AU | E12: Data AU | F12: 0.0811 | G12: 0.9 | H12: 0.07299 | I12: =H12/2 -> 0.036495 | J12: =H12*IF(VALUE(LEFT(C12,4))=2026,MAX(0,MIN(6,13-VALUE(RIGHT(C12,2)))),0)/12 -> 0.0182475
B13: R0323 | C13: 2026-10 | D13: AU | E13: Data AU | F13: 0.0811 | G13: 0.9 | H13: 0.07299 | I13: =H13/2 -> 0.036495 | J13: =H13*IF(VALUE(LEFT(C13,4))=2026,MAX(0,MIN(6,13-VALUE(RIGHT(C13,2)))),0)/12 -> 0.0182475
B14: R0324 | C14: 2026-10 | D14: AU | E14: Data AU | F14: 0.0682 | G14: 0.9 | H14: 0.06138 | I14: =H14/2 -> 0.03069 | J14: =H14*IF(VALUE(LEFT(C14,4))=2026,MAX(0,MIN(6,13-VALUE(RIGHT(C14,2)))),0)/12 -> 0.015345
B15: R0396 | C15: 2026-09 | D15: AU | E15: Network & QSR | F15: 0.2029 | G15: 0.2 | H15: 0.04058 | I15: =H15/2 -> 0.02029 | J15: =H15*IF(VALUE(LEFT(C15,4))=2026,MAX(0,MIN(6,13-VALUE(RIGHT(C15,2)))),0)/12 -> 0.013526667
B16: R0489 | C16: 2026-09 | D16: AU | E16: Network & QSR | F16: 0.2317 | G16: 0.2 | H16: 0.04634 | I16: =H16/2 -> 0.02317 | J16: =H16*IF(VALUE(LEFT(C16,4))=2026,MAX(0,MIN(6,13-VALUE(RIGHT(C16,2)))),0)/12 -> 0.015446667
B17: R0255 | C17: 2026-09 | D17: AU | E17: POS | F17: 0.2245 | G17: 0.65 | H17: 0.145925 | I17: =H17/2 -> 0.0729625 | J17: =H17*IF(VALUE(LEFT(C17,4))=2026,MAX(0,MIN(6,13-VALUE(RIGHT(C17,2)))),0)/12 -> 0.048641667
... B60: R0229 | C60: 2026-08 | D60: AU | E60: SAP ERP | F60: 0.2317 | G60: 0.2 | H60: 0.04634 | I60: =H60/2 -> 0.02317 | J60: =H60*IF(VALUE(LEFT(C60,4))=2026,MAX(0,MIN(6,13-VALUE(RIGHT(C60,2)))),0)/12 -> 0.019308333
B61: R0351 | C61: 2026-09 | D61: NZ | E61: SAP ERP | F61: 0.145167 | G61: 0.2 | H61: =F61*G61 -> 0.0290334 | I61: =H61/2 -> 0.0145167 | J61: =H61*IF(VALUE(LEFT(C61,4))=2026,MAX(0,MIN(6,13-VALUE(RIGHT(C61,2)))),0)/12 -> 0.0096778
B62: R0253 | C62: 2027-04 | D62: AU | E62: Data & Insights | F62: 0.0927 | G62: 0.2 | H62: 0.01854 | I62: =H62/2 -> 0.00927 | J62: =H62*IF(VALUE(LEFT(C62,4))=2026,MAX(0,MIN(6,13-VALUE(RIGHT(C62,2)))),0)/12 -> 0
B63: R0388 | C63: 2026-10 | D63: AU | E63: Data & Insights | F63: 0.0811 | G63: 0.2 | H63: 0.01622 | I63: =H63/2 -> 0.00811 | J63: =H63*IF(VALUE(LEFT(C63,4))=2026,MAX(0,MIN(6,13-VALUE(RIGHT(C63,2)))),0)/12 -> 0.004055
B64: R0160 | C64: 2026-09 | D64: AU | E64: B2B | F64: 0.2317 | G64: 0.1 | H64: 0.02317 | I64: =H64/2 -> 0.011585 | J64: =H64*IF(VALUE(LEFT(C64,4))=2026,MAX(0,MIN(6,13-VALUE(RIGHT(C64,2)))),0)/12 -> 0.0077233333
B65: R0303 | C65: 2027-04 | D65: AU | E65: Energy | F65: 0.2029 | G65: 0.15 | H65: 0.030435 | I65: =H65/2 -> 0.0152175 | J65: =H65*IF(VALUE(LEFT(C65,4))=2026,MAX(0,MIN(6,13-VALUE(RIGHT(C65,2)))),0)/12 -> 0
B66: R0304 | C66: 2026-10 | D66: AU | E66: Energy | F66: 0.2029 | G66: 0.15 | H66: 0.030435 | I66: =H66/2 -> 0.0152175 | J66: =H66*IF(VALUE(LEFT(C66,4))=2026,MAX(0,MIN(6,13-VALUE(RIGHT(C66,2)))),0)/12 -> 0.00760875
B67: R0375 | C67: 2026-09 | D67: AU | E67: Energy | F67: 0.2029 | G67: 0.15 | H67: 0.030435 | I67: =H67/2 -> 0.0152175 | J67: =H67*IF(VALUE(LEFT(C67,4))=2026,MAX(0,MIN(6,13-VALUE(RIGHT(C67,2)))),0)/12 -> 0.010145
B68: R0092 | C68: 2026-09 | D68: AU | E68: Leadership | F68: 0.2758 | G68: 1 | H68: 0.2758 | I68: =H68/2 -> 0.1379 | J68: =H68*IF(VALUE(LEFT(C68,4))=2026,MAX(0,MIN(6,13-VALUE(RIGHT(C68,2)))),0)/12 -> 0.091933333
B69: R0222 | C69: 2026-08 | D69: AU | E69: Supply | F69: 0.2317 | G69: 0 | H69: 0 | I69: =H69/2 -> 0 | J69: =H69*IF(VALUE(LEFT(C69,4))=2026,MAX(0,MIN(6,13-VALUE(RIGHT(C69,2)))),0)/12 -> 0
B70: R0284 | C70: 2026-09 | D70: AU | E70: Supply | F70: 0.2029 | G70: 0 | H70: 0 | I70: =H70/2 -> 0 | J70: =H70*IF(VALUE(LEFT(C70,4))=2026,MAX(0,MIN(6,13-VALUE(RIGHT(C70,2)))),0)/12 -> 0
B71: R0387 | C71: 2026-09 | D71: AU | E71: Supply | F71: 0.2029 | G71: 0 | H71: 0 | I71: =H71/2 -> 0 | J71: =H71*IF(VALUE(LEFT(C71,4))=2026,MAX(0,MIN(6,13-VALUE(RIGHT(C71,2)))),0)/12 -> 0
B72: R0223 | C72: 2026-10 | D72: AU | E72: Trading & Shipping | F72: 0.2317 | G72: 0.2 | H72: 0.04634 | I72: =H72/2 -> 0.02317 | J72: =H72*IF(VALUE(LEFT(C72,4))=2026,MAX(0,MIN(6,13-VALUE(RIGHT(C72,2)))),0)/12 -> 0.011585
B73: R0484 | C73: 2027-04 | D73: AU | E73: Trading & Shipping | F73: 0.1705 | G73: 0.2 | H73: 0.0341 | I73: =H73/2 -> 0.01705 | J73: =H73*IF(VALUE(LEFT(C73,4))=2026,MAX(0,MIN(6,13-VALUE(RIGHT(C73,2)))),0)/12 -> 0
... B83: R0463 | C83: 2026-11 | D83: AU | E83: Transformation | F83: 0.0682 | G83: 1 | H83: 0.0682 | I83: =H83/2 -> 0.0341 | J83: =H83*IF(VALUE(LEFT(C83,4))=2026,MAX(0,MIN(6,13-VALUE(RIGHT(C83,2)))),0)/12 -> 0.011366667
B84: R0481 | C84: 2026-11 | D84: NZ | E84: Transformation | F84: 0.125994 | G84: 1 | H84: =F84*G84 -> 0.125994 | I84: =H84/2 -> 0.062997 | J84: =H84*IF(VALUE(LEFT(C84,4))=2026,MAX(0,MIN(6,13-VALUE(RIGHT(C84,2)))),0)/12 -> 0.020999
B85: R0237 | C85: 2026-09 | D85: AU | E85: Architecture | F85: 0.2317 | G85: 1 | H85: 0.2317 | I85: =H85/2 -> 0.11585 | J85: =H85*IF(VALUE(LEFT(C85,4))=2026,MAX(0,MIN(6,13-VALUE(RIGHT(C85,2)))),0)/12 -> 0.077233333
B86: R0238 | C86: 2026-09 | D86: AU | E86: Architecture | F86: 0.2317 | G86: 1 | H86: 0.2317 | I86: =H86/2 -> 0.11585 | J86: =H86*IF(VALUE(LEFT(C86,4))=2026,MAX(0,MIN(6,13-VALUE(RIGHT(C86,2)))),0)/12 -> 0.077233333
B87: R0239 | C87: 2026-10 | D87: AU | E87: Architecture | F87: 0.2317 | G87: 1 | H87: 0.2317 | I87: =H87/2 -> 0.11585 | J87: =H87*IF(VALUE(LEFT(C87,4))=2026,MAX(0,MIN(6,13-VALUE(RIGHT(C87,2)))),0)/12 -> 0.057925
B88: R0065 | C88: 2027-07 | D88: AU | E88: Group Data | F88: 0.3896 | G88: 1 | H88: 0.3896 | I88: =H88/2 -> 0.1948 | J88: =H88*IF(VALUE(LEFT(C88,4))=2026,MAX(0,MIN(6,13-VALUE(RIGHT(C88,2)))),0)/12 -> 0
B89: R0054 | C89: 2026-09 | D89: AU | E89: Leadership | F89: 0.335 | G89: 1 | H89: 0.335 | I89: =H89/2 -> 0.1675 | J89: =H89*IF(VALUE(LEFT(C89,4))=2026,MAX(0,MIN(6,13-VALUE(RIGHT(C89,2)))),0)/12 -> 0.11166667
B90: R0380 | C90: 2026-11 | D90: AU | E90: Technology Strategy & AI Capability | F90: 0.2029 | G90: 1 | H90: 0.2029 | I90: =H90/2 -> 0.10145 | J90: =H90*IF(VALUE(LEFT(C90,4))=2026,MAX(0,MIN(6,13-VALUE(RIGHT(C90,2)))),0)/12 -> 0.033816667
B91: R0273 | C91: 2027-01 | D91: AU | E91: Customer, AI | F91: 0.19479 | G91: 0 | H91: =F91*G91 -> 0 | I91: =H91/2 -> 0 | J91: =H91*IF(VALUE(LEFT(C91,4))=2026,MAX(0,MIN(6,13-VALUE(RIGHT(C91,2)))),0)/12 -> 0
B92: R0309 | C92: 2027-01 | D92: AU | E92: Reporting & Analytics | F92: 0.202853 | G92: 0.7 | H92: =F92*G92 -> 0.1419971 | I92: =H92/2 -> 0.07099855 | J92: =H92*IF(VALUE(LEFT(C92,4))=2026,MAX(0,MIN(6,13-VALUE(RIGHT(C92,2)))),0)/12 -> 0
B93: R0378 | C93: 2027-01 | D93: AU | E93: Workplace & Enterprise Tooling | F93: 0.201585 | G93: 1 | H93: =F93*G93 -> 0.201585 | I93: =H93/2 -> 0.1007925 | J93: =H93*IF(VALUE(LEFT(C93,4))=2026,MAX(0,MIN(6,13-VALUE(RIGHT(C93,2)))),0)/12 -> 0
...

Sheet 5 Sources
B2: Sources
B3: Every figure that came from outside this workbook, where it came from, and what brings it up to date.
B5: Figure | C5: Where it came from (file, tab, cell) | D5: What refreshes it
B6: Internal Labor: actual to June, budget to June, six closed months, six forecast months, full year forecast, full year budget | C6: TDD_Finance_Report__Jun2026V1__Short_Version.xlsx, TDD Pack (2), row 31, columns O, P, AG:AL, BE:BJ, BK, X | D6: The next Finance report
B7: Contingent Labour: the same seven fields | C7: TDD_Finance_Report__Jun2026V1__Short_Version.xlsx, TDD Pack (2), row 32, same columns | D7: The next Finance report
B8: Personnel Costs: the same seven fields | C8: TDD_Finance_Report__Jun2026V1__Short_Version.xlsx, TDD Pack (2), row 33, same columns | D8: The next Finance report
B9: Labour Recharge: the same seven fields | C9: TDD_Finance_Report__Jun2026V1__Short_Version.xlsx, TDD Pack (2), row 34, same columns | D9: The next Finance report
B10: Staff Cost: the same seven fields | C10: TDD_Finance_Report__Jun2026V1__Short_Version.xlsx, TDD Pack (2), row 35, same columns | D10: The next Finance report
B11: People Costs, New Zealand (NZD): the same seven fields | C11: TDD_Finance_Report__Jun2026V1__Short_Version.xlsx, TDD Pack (2), row 49, same columns | D11: The next Finance report
B12: Australia lights on: full year budget, actual to June, full year forecast | C12: TDD_Finance_Report__Jun2026V1__Short_Version.xlsx, For Presentation Pack (2), O21, N5, N21 | D12: The next Finance report
B13: New Zealand lights on: full year budget, actual to June, full year forecast | C13: TDD_Finance_Report__Jun2026V1__Short_Version.xlsx, For Presentation Pack (2), O22, N6, N22 | D13: The next Finance report
B14: Total people cost after levers | C14: TDD_FY27_Cost_Calc_0608.xlsx (1347cab8), 3.5 TDD Lights On C24 | D14: The updated model, retyped into tab 3 block A
B15: Cost to TDD lights on | C15: TDD_FY27_Cost_Calc_0608.xlsx (1347cab8), 3.5 TDD Lights On L24 | D15: The updated model, retyped into tab 3 block A
B16: What TDD pays, Australia | C16: TDD_FY27_Cost_Calc_0608.xlsx (1347cab8), 3.6 TDD Lights On AU NZ M24 | D16: The updated model, retyped into tab 3 block A
... B30: EGI funded flag on each vacancy role | C30: TDD_FY27_Cost_Calc_0608.xlsx (1347cab8), REVIEW - Complete Role Mapping, column AM | D30: The updated model

Sheet 6 Monthly view
B2: FY26 month by month
B3: Both countries in AUD. July to December move with the hire months.
B5: Month | C5: 46023 | D5: 46054 | E5: 46082 | F5: 46113 | G5: 46143 | H5: 46174 | I5: 46204 | J5: 46235 | K5: 46266 | L5: 46296 | M5: 46327 | N5: 46357
B6: Actual or forecast | C6: =IF(MONTH(C$5)<=6,"Actual","Forecast") -> Actual | D6: =IF(MONTH(D$5)<=6,"Actual","Forecast") -> Actual | E6: =IF(MONTH(E$5)<=6,"Actual","Forecast") -> Actual | F6: =IF(MONTH(F$5)<=6,"Actual","Forecast") -> Actual | G6: =IF(MONTH(G$5)<=6,"Actual","Forecast") -> Actual | H6: =IF(MONTH(H$5)<=6,"Actual","Forecast") -> Actual | I6: =IF(MONTH(I$5)<=6,"Actual","Forecast") -> Forecast | J6: =IF(MONTH(J$5)<=6,"Actual","Forecast") -> Forecast | ... N6: =IF(MONTH(N$5)<=6,"Actual","Forecast") -> Forecast
B7: Australia, $m AUD | C7: ='2 Data - Finance (June)'!F10 -> 3.0199578 | D7: ='2 Data - Finance (June)'!G10 -> 3.0970167 | E7: ='2 Data - Finance (June)'!H10 -> 2.9273314 | F7: ='2 Data - Finance (June)'!I10 -> 4.1249195 | G7: ='2 Data - Finance (June)'!J10 -> 3.0042897 | H7: ='2 Data - Finance (June)'!K10 -> 3.8364909 | I7: ='3 Data - model'!$C$26/12-SUMPRODUCT(('4 Vacancy timing'!$D$6:$D$107="AU")*('4 Vacancy timing'!$C$6:$C$107>TEXT(I$5,"YYYY-MM"))*'4 Vacancy timing'!$H$6:$H$107)/12+'1 FY26 Forecast'!$C$7/6 -> 2.3907774 | J7: ='3 Data - model'!$C$26/12-SUMPRODUCT(('4 Vacancy timing'!$D$6:$D$107="AU")*('4 Vacancy timing'!$C$6:$C$107>TEXT(J$5,"YYYY-MM"))*'4 Vacancy timing'!$H$6:$H$107)/12+'1 FY26 Forecast'!$C$7/6 -> 2.5033616 | K7: ='3 Data - model'!$C$26/12-SUMPRODUCT(('4 Vacancy timing'!$D$6:$D$107="AU")*('4 Vacancy timing'!$C$6:$C$107>TEXT(K$5,"YYYY-MM"))*'4 Vacancy timing'!$H$6:$H$107)/12+'1 FY26 Forecast'!$C$7/6 -> 2.7827386 | L7: ='3 Data - model'!$C$26/12-SUMPRODUCT(('4 Vacancy timing'!$D$6:$D$107="AU")*('4 Vacancy timing'!$C$6:$C$107>TEXT(L$5,"YYYY-MM"))*'4 Vacancy timing'!$H$6:$H$107)/12+'1 FY26 Forecast'!$C$7/6 -> 2.9215949 | M7: ='3 Data - model'!$C$26/12-SUMPRODUCT(('4 Vacancy timing'!$D$6:$D$107="AU")*('4 Vacancy timing'!$C$6:$C$107>TEXT(M$5,"YYYY-MM"))*'4 Vacancy timing'!$H$6:$H$107)/12+'1 FY26 Forecast'!$C$7/6 -> 2.9906982 | N7: ='3 Data - model'!$C$26/12-SUMPRODUCT(('4 Vacancy timing'!$D$6:$D$107="AU")*('4 Vacancy timing'!$C$6:$C$107>TEXT(N$5,"YYYY-MM"))*'4 Vacancy timing'!$H$6:$H$107)/12+'1 FY26 Forecast'!$C$7/6 -> 2.9906982
B8: New Zealand, $m AUD | C8: ='2 Data - Finance (June)'!F11*'1 FY26 Forecast'!$C$6 -> 1.1787387 | D8: ='2 Data - Finance (June)'!G11*'1 FY26 Forecast'!$C$6 -> 1.4055688 | E8: ='2 Data - Finance (June)'!H11*'1 FY26 Forecast'!$C$6 -> 1.2687038 | F8: ='2 Data - Finance (June)'!I11*'1 FY26 Forecast'!$C$6 -> 1.1355078 | G8: ='2 Data - Finance (June)'!J11*'1 FY26 Forecast'!$C$6 -> 1.5232611 | H8: ='2 Data - Finance (June)'!K11*'1 FY26 Forecast'!$C$6 -> 1.9689675 | I8: ='3 Data - model'!$C$39/12-SUMPRODUCT(('4 Vacancy timing'!$D$6:$D$107="NZ")*('4 Vacancy timing'!$C$6:$C$107>TEXT(I$5,"YYYY-MM"))*'4 Vacancy timing'!$H$6:$H$107)/12 -> 1.2300197 | J8: ='3 Data - model'!$C$39/12-SUMPRODUCT(('4 Vacancy timing'!$D$6:$D$107="NZ")*('4 Vacancy timing'!$C$6:$C$107>TEXT(J$5,"YYYY-MM"))*'4 Vacancy timing'!$H$6:$H$107)/12 -> 1.2300197 | K8: ='3 Data - model'!$C$39/12-SUMPRODUCT(('4 Vacancy timing'!$D$6:$D$107="NZ")*('4 Vacancy timing'!$C$6:$C$107>TEXT(K$5,"YYYY-MM"))*'4 Vacancy timing'!$H$6:$H$107)/12 -> 1.2324391 | L8: ='3 Data - model'!$C$39/12-SUMPRODUCT(('4 Vacancy timing'!$D$6:$D$107="NZ")*('4 Vacancy timing'!$C$6:$C$107>TEXT(L$5,"YYYY-MM"))*'4 Vacancy timing'!$H$6:$H$107)/12 -> 1.2324391 | M8: ='3 Data - model'!$C$39/12-SUMPRODUCT(('4 Vacancy timing'!$D$6:$D$107="NZ")*('4 Vacancy timing'!$C$6:$C$107>TEXT(M$5,"YYYY-MM"))*'4 Vacancy timing'!$H$6:$H$107)/12 -> 1.2429386 | N8: ='3 Data - model'!$C$39/12-SUMPRODUCT(('4 Vacancy timing'!$D$6:$D$107="NZ")*('4 Vacancy timing'!$C$6:$C$107>TEXT(N$5,"YYYY-MM"))*'4 Vacancy timing'!$H$6:$H$107)/12 -> 1.2429386
B9: Total, $m AUD | C9: =C7+C8 -> 4.1986966 | D9: =D7+D8 -> 4.5025856 | E9: =E7+E8 -> 4.1960352 | F9: =F7+F8 -> 5.2604272 | G9: =G7+G8 -> 4.5275508 | H9: =H7+H8 -> 5.8054584 | I9: =I7+I8 -> 3.6207971 | J9: =J7+J8 -> 3.7333812 | ... N9: =N7+N8 -> 4.2336368
B10: Running total, $m AUD | C10: =C9 -> 4.1986966 | D10: =C10+D9 -> 8.7012821 | E10: =D10+E9 -> 12.897317 | F10: =E10+F9 -> 18.157745 | G10: =F10+G9 -> 22.685295 | H10: =G10+H9 -> 28.490754 | I10: =H10+I9 -> 32.111551 | J10: =I10+J9 -> 35.844932 | K10: =J10+K9 -> 39.86011 | ... N10: =M10+N9 -> 52.481417
B11: December times twelve, the exit run rate, $m AUD | N11: =N9*12 -> 50.803642
B13: Roles joining in the month, from the tab 4 hire months | I13: =COUNTIF('4 Vacancy timing'!$C$6:$C$107,"2026-07") -> 1 | J13: =COUNTIF('4 Vacancy timing'!$C$6:$C$107,"2026-08") -> 14 | K13: =COUNTIF('4 Vacancy timing'!$C$6:$C$107,"2026-09") -> 30 | L13: =COUNTIF('4 Vacancy timing'!$C$6:$C$107,"2026-10") -> 18 | M13: =COUNTIF('4 Vacancy timing'!$C$6:$C$107,"2026-11") -> 7 | N13: =COUNTIF('4 Vacancy timing'!$C$6:$C$107,"2026-12") -> 0
B14: Priced roles still to start | I14: =COUNTIF('4 Vacancy timing'!$C$6:$C$107,">"&"2026-07") -> 101 | J14: =COUNTIF('4 Vacancy timing'!$C$6:$C$107,">"&"2026-08") -> 87 | K14: =COUNTIF('4 Vacancy timing'!$C$6:$C$107,">"&"2026-09") -> 57 | L14: =COUNTIF('4 Vacancy timing'!$C$6:$C$107,">"&"2026-10") -> 39 | M14: =COUNTIF('4 Vacancy timing'!$C$6:$C$107,">"&"2026-11") -> 32 | N14: =COUNTIF('4 Vacancy timing'!$C$6:$C$107,">"&"2026-12") -> 32
B16: Sources: tab 2 closed months to June; tabs 7, 8 and 9 hold the model data; tabs 3 and 4 build the forecast from them.

Sheet 7 Model 3.5
B2: The model, 3.5 TDD Lights On, pasted as values
B4: Portfolios & COEs & EGI | C4: Total People cost | D4: Sig items funded | E4: Support Cost (this is the % in the 1.x tabs) | F4: BP allocation | G4: Domain architect allocation | H4: GM allocation | I4: Other overheads (Tech Managers, Delivery Managers, HoT) | J4: Other overheads toggle | K4: Amount of overheads charged to TDD | L4: Total portfolio cost charged to TDD | M4: TDD Lights On budget | O4: Over/ (Under) TDD budget
B5: COE Strategy Architecture | C5: 3.3418273 | D5: 0 | E5: 0.91580925 | F5: 0 | G5: 0 | I5: 1.0370818 | J5: 1 | K5: 1.0370818 | L5: 1.9528911 | M5: 2 | O5: -0.04710895
B6: COE Cyber | C6: 3.15606 | D6: 0.49481945 | E6: 2.4699467 | F6: 0 | G6: 0 | I6: 0.19129385 | J6: 1 | K6: 0.19129385 | L6: 2.6612405 | M6: 1.5 | O6: 1.1612405
B7: COE Service Ops | C7: 2.8319503 | D7: 0 | E7: 2.4312789 | F7: 0 | G7: 0 | I7: 0.4006714 | J7: 1 | K7: 0.4006714 | L7: 2.8319503 | M7: 0.5 | O7: 2.3319503
B8: COE Transformation | C8: 2.8839934 | D8: 0 | E8: 1.9644729 | F8: 0 | G8: 0 | I8: 0.9195205 | J8: 1 | K8: 0.9195205 | L8: 2.8839934 | M8: 2 | O8: 0.88399343
B9: COE Business Partnering | C9: 3.2925626 | D9: 0 | E9: 0.97901419 | F9: 0 | G9: 0 | I9: 0 | K9: 0 | L9: 0.97901419 | M9: 2 | O9: -1.0209858
B10: COE Data | C10: 1.6281779 | D10: 0 | E10: 1.6281779 | F10: 0 | G10: 0 | I10: 0 | K10: 0 | L10: 1.6281779 | M10: 2 | O10: -0.37182213
B11: Ampol Retail | C11: 11.736363 | D11: 2.5862356 | E11: 3.2910164 | F11: 0.21032258 | G11: 0.12626694 | H11: 0.46363636 | I11: 1.1647348 | J11: 1 | K11: 1.9649606 | L11: 5.255977 | M11: 5.5 | O11: -0.24402299
B12: Z Retail | C12: 6.6662902 | D12: 0 | E12: 4.4511559 | F12: 0.21032258 | G12: 0.12626694 | H12: 0.46363636 | I12: 1.1954928 | J12: 1 | K12: 1.9957187 | L12: 6.4468746 | M12: 6.5 | O12: -0.053125412
B13: Ampol Customer | C13: 9.1050702 | D13: 2.859859 | E13: 1.400639 | F13: 0.07999247 | G13: 0.048023393 | H13: 0.23181818 | I13: 0.81362941 | J13: 1 | K13: 1.1734635 | L13: 2.5741024 | M13: 2.5 | O13: 0.074102406
B14: Z Customer | C14: 4.619575 | D14: 0 | E14: 2.2820327 | F14: 0.13033011 | G14: 0.078243542 | H14: 0.23181818 | I14: 1.3256299 | J14: 1 | K14: 1.7660218 | L14: 4.0480545 | M14: 4 | O14: 0.048054483
B15: Commercial Fuels | C15: 8.9409346 | D15: 3.8 | E15: 0.50278987 | F15: 0.21032258 | G15: 0.12626694 | H15: 0.46363636 | I15: 1.1313423 | J15: 1 | K15: 1.9315682 | L15: 2.4343581 | M15: 2.5 | O15: -0.065641909
B16: Energy Solutions & B2B | C16: 5.8851998 | D16: 0 | E16: 0.61533218 | F16: 0.21032258 | G16: 0.12626694 | H16: 0.46363636 | I16: 1.0537171 | J16: 1 | K16: 1.853943 | L16: 2.4692752 | M16: 2.5 | O16: -0.030724815
B17: Infrastructure | C17: 6.3462486 | D17: 0 | E17: 1.1706431 | F17: 0.21032258 | G17: 0.12626694 | H17: 0.46363636 | I17: 1.2052578 | J17: 1 | K17: 2.0054837 | L17: 3.1761269 | M17: 2.5 | O17: 0.67612686
B18: P&C | C18: 3.2810903 | D18: 0.238965 | E18: 0.33264482 | F18: 0.21032258 | G18: 0.12626694 | H18: 0.46363636 | I18: 0.93642515 | J18: 1 | K18: 1.736651 | L18: 2.0692958 | M18: 2 | O18: 0.069295847
B19: Finance | C19: 3.0215338 | D19: 0.24172845 | E19: 1.0316317 | F19: 0.21032258 | G19: 0.12626694 | H19: 0.46363636 | I19: 0.32356045 | J19: 1 | K19: 1.1237863 | L19: 2.155418 | M19: 2 | O19: 0.15541805
B20: TDD Group Functions | C20: 8.1106509 | D20: 1.3245485 | E20: 3.452595 | F20: 0.21032258 | G20: 0.12626694 | H20: 0.46363636 | I20: 1.3353493 | J20: 1 | K20: 2.1355752 | L20: 5.5881702 | M20: 5.5 | O20: 0.088170215
B21: Enterprise Data | C21: 6.6937062 | D21: 1.8359557 | E21: 1.6307553 | F21: 0.21032258 | G21: 0.12626694 | H21: 0.46363636 | I21: 1.0610344 | J21: 1 | K21: 1.8612603 | L21: 3.4920156 | M21: 3.5 | O21: -0.0079844022
B22: TDD Cyber | C22: 2.1381967 | D22: 1.2998 | E22: 0.67056012 | F22: 0.21032258 | G22: 0.12626694 | H22: 0.46363636 | I22: 0 | K22: 0.80022588 | L22: 1.470786 | M22: 1.5 | O22: -0.029213999
B23: EGI | C23: 5.1508193 | D23: 5.1508193 | E23: 0 | F23: 0 | G23: 0 | H23: 0 | I23: 0 | K23: 0 | L23: 0 | M23: 0 | O23: 0
B24: Total, over or under the allocations for these rows | C24: 98.83025 | D24: 19.832731 | E24: 31.220496 | F24: 2.3135484 | G24: 1.3889363 | H24: 5.1 | I24: 14.094741 | K24: 22.897226 | L24: 54.117722 | M24: 50.5 | O24: 3.6177217
B25: Budget, over or under the full TDD budget | M25: 53.8 | O25: 0.31772169

Sheet 8 Model 3.6
B2: The model, 3.6 AU and NZ, pasted as values
B4: Portfolios & COEs & EGI | C4: Total People cost | D4: Sig items funded | E4: Support Cost (this is the % in the 1.x tabs) | F4: BP allocation | G4: Domain architect allocation | H4: GM allocation | I4: Other overheads | J4: Other overheads toggle | K4: Amount of overheads charged to TDD | L4: Total portfolio cost charged to TDD | M4: AU spend | N4: NZ spend | O4: Total
B5: COE Strategy Architecture | C5: 3.3418273 | D5: 0 | E5: 0.91580925 | F5: 0 | G5: 0 | I5: 1.0370818 | J5: 1 | K5: 1.0370818 | L5: 1.9528911 | M5: 1.9528911 | N5: 0 | O5: 1.9528911
B6: COE Cyber | C6: 3.15606 | D6: 0.49481945 | E6: 2.4699467 | F6: 0 | G6: 0 | I6: 0.19129385 | J6: 1 | K6: 0.19129385 | L6: 2.6612405 | M6: 2.2729268 | N6: 0.38831369 | O6: 2.6612405
B7: COE Service Ops | C7: 2.8319503 | D7: 0 | E7: 2.4312789 | F7: 0 | G7: 0 | I7: 0.4006714 | J7: 1 | K7: 0.4006714 | L7: 2.8319503 | M7: 2.5689646 | N7: 0.2629857 | O7: 2.8319503
B8: COE Transformation | C8: 2.8839934 | D8: 0 | E8: 1.9644729 | F8: 0 | G8: 0 | I8: 0.9195205 | J8: 1 | K8: 0.9195205 | L8: 2.8839934 | M8: 2.5844666 | N8: 0.29952678 | O8: 2.8839934
B9: COE Business Partnering | C9: 3.2925626 | D9: 0 | E9: 0.97901419 | F9: 0 | G9: 0 | I9: 0 | K9: 0 | L9: 0.97901419 | M9: 0.8280117 | N9: 0.15100249 | O9: 0.97901419
B10: COE Data | C10: 1.6281779 | D10: 0 | E10: 1.6281779 | F10: 0 | G10: 0 | I10: 0 | K10: 0 | L10: 1.6281779 | M10: 1.4784314 | N10: 0.14974642 | O10: 1.6281779
B11: Ampol Retail | C11: 11.736363 | D11: 2.5862356 | E11: 3.2910164 | F11: 0.21032258 | G11: 0.12626694 | H11: 0.46363636 | I11: 1.1647348 | J11: 1 | K11: 1.9649606 | L11: 5.255977 | M11: 5.0712457 | N11: 0.18473129 | O11: 5.255977
B12: Z Retail | C12: 6.6662902 | D12: 0 | E12: 4.4511559 | F12: 0.21032258 | G12: 0.12626694 | H12: 0.46363636 | I12: 1.1954928 | J12: 1 | K12: 1.9957187 | L12: 6.4468746 | M12: 1.4785454 | N12: 4.9683291 | O12: 6.4468746
B13: Ampol Customer | C13: 9.1050702 | D13: 2.859859 | E13: 1.400639 | F13: 0.07999247 | G13: 0.048023393 | H13: 0.23181818 | I13: 0.81362941 | J13: 1 | K13: 1.1734635 | L13: 2.5741024 | M13: 1.9941906 | N13: 0.57991179 | O13: 2.5741024
B14: Z Customer | C14: 4.619575 | D14: 0 | E14: 2.2820327 | F14: 0.13033011 | G14: 0.078243542 | H14: 0.23181818 | I14: 1.3256299 | J14: 1 | K14: 1.7660218 | L14: 4.0480545 | M14: 1.0664787 | N14: 2.9815757 | O14: 4.0480545
B15: Commercial Fuels | C15: 8.9409346 | D15: 3.8 | E15: 0.50278987 | F15: 0.21032258 | G15: 0.12626694 | H15: 0.46363636 | I15: 1.1313423 | J15: 1 | K15: 1.9315682 | L15: 2.4343581 | M15: 1.9571921 | N15: 0.47716602 | O15: 2.4343581
B16: Energy Solutions & B2B | C16: 5.8851998 | D16: 0 | E16: 0.61533218 | F16: 0.21032258 | G16: 0.12626694 | H16: 0.46363636 | I16: 1.0537171 | J16: 1 | K16: 1.853943 | L16: 2.4692752 | M16: 1.594621 | N16: 0.8746542 | O16: 2.4692752
B17: Infrastructure | C17: 6.3462486 | D17: 0 | E17: 1.1706431 | F17: 0.21032258 | G17: 0.12626694 | H17: 0.46363636 | I17: 1.2052578 | J17: 1 | K17: 2.0054837 | L17: 3.1761269 | M17: 2.9913956 | N17: 0.18473129 | O17: 3.1761269
B18: P&C | C18: 3.2810903 | D18: 0.238965 | E18: 0.33264482 | F18: 0.21032258 | G18: 0.12626694 | H18: 0.46363636 | I18: 0.93642515 | J18: 1 | K18: 1.736651 | L18: 2.0692958 | M18: 1.8458929 | N18: 0.22340294 | O18: 2.0692958
B19: Finance | C19: 3.0215338 | D19: 0.24172845 | E19: 1.0316317 | F19: 0.21032258 | G19: 0.12626694 | H19: 0.46363636 | I19: 0.32356045 | J19: 1 | K19: 1.1237863 | L19: 2.155418 | M19: 1.4005565 | N19: 0.75486151 | O19: 2.155418
B20: TDD Group Functions | C20: 8.1106509 | D20: 1.3245485 | E20: 3.452595 | F20: 0.21032258 | G20: 0.12626694 | H20: 0.46363636 | I20: 1.3353493 | J20: 1 | K20: 2.1355752 | L20: 5.5881702 | M20: 3.8923058 | N20: 1.6958644 | O20: 5.5881702
B21: Enterprise Data | C21: 6.6937062 | D21: 1.8359557 | E21: 1.6307553 | F21: 0.21032258 | G21: 0.12626694 | H21: 0.46363636 | I21: 1.0610344 | J21: 1 | K21: 1.8612603 | L21: 3.4920156 | M21: 2.6468651 | N21: 0.84515054 | O21: 3.4920156
B22: TDD Cyber | C22: 2.1381967 | D22: 1.2998 | E22: 0.67056012 | F22: 0.21032258 | G22: 0.12626694 | H22: 0.46363636 | I22: 0 | K22: 0.80022588 | L22: 1.470786 | M22: 1.2860547 | N22: 0.18473129 | O22: 1.470786
B23: EGI | C23: 5.1508193 | D23: 5.1508193 | E23: 0 | F23: 0 | G23: 0 | H23: 0 | I23: 0 | K23: 0 | L23: 0 | M23: 0 | N23: 0 | O23: 0
B24: Total, over or under the allocations for these rows | C24: 98.83025 | D24: 19.832731 | E24: 31.220496 | F24: 2.3135484 | G24: 1.3889363 | H24: 5.1 | I24: 14.094741 | K24: 22.897226 | L24: 54.117722 | M24: 38.911036 | N24: 15.206685 | O24: 54.117722

Sheet 9 Model 3.7 vacancies
B2: The model, 3.7 vacancy register, all 132 roles, pasted as values
B4: Role ID | C4: Title | D4: Portfolio | E4: Squad or overhead line | F4: Overhead role? | G4: Country | H4: FTE | I4: Decision (live from 2.x tab) | J4: Full cost ($m) | K4: We plan to spend ($m)
B5: R0360 | C5: Engineer - Integration | D5: Ampol Retail | E5: Above Store | F5: No | G5: Australia | H5: 1 | I5: Offshore | J5: 0.17048975 | K5: 0.0681959
B6: R0395 | C6: Business Analyst | D6: Ampol Retail | E6: Above Store | F6: No | G6: Australia | H6: 1 | I6: Hold | J6: 0.20285325 | K6: 0
B7: R0467 | C7: Quality Assurance | D7: Ampol Retail | E7: Above Store | F7: No | G7: Australia | H7: 1 | I7: Offshore | J7: 0.17050159 | K7: 0.068200634
B8: R0468 | C8: Systems Analyst | D8: Ampol Retail | E8: Above Store | F8: No | G8: Australia | H8: 1 | I8: Hire | J8: 0.201585 | K8: 0.201585
B9: R0235 | C9: Delivery Lead | D9: Ampol Retail | E9: Data AU | F9: No | G9: Australia | H9: 1 | I9: Offshore | J9: 0.20285325 | K9: 0.0811413
B10: R0320 | C10: Data Analyst | D10: Ampol Retail | E10: Data AU | F10: No | G10: Australia | H10: 1 | I10: Offshore | J10: 0.201585 | K10: 0.080634
B11: R0321 | C11: Data Analyst | D11: Ampol Retail | E11: Data AU | F11: No | G11: Australia | H11: 1 | I11: Offshore | J11: 0.23168925 | K11: 0.0926757
B12: R0322 | C12: Engineer - Data | D12: Ampol Retail | E12: Data AU | F12: No | G12: Australia | H12: 1 | I12: Offshore | J12: 0.20285325 | K12: 0.0811413
B13: R0323 | C13: Engineer - Data | D13: Ampol Retail | E13: Data AU | F13: No | G13: Australia | H13: 1 | I13: Offshore | J13: 0.20285325 | K13: 0.0811413
B14: R0324 | C14: Engineer - Data | D14: Ampol Retail | E14: Data AU | F14: No | G14: Australia | H14: 1 | I14: Offshore | J14: 0.17048975 | K14: 0.0681959
B15: R0396 | C15: Business Analyst | D15: Ampol Retail | E15: Network & QSR | F15: No | G15: Australia | H15: 1 | I15: Hire | J15: 0.20285325 | K15: 0.20285325
B16: R0489 | C16: Systems Analyst | D16: Ampol Retail | E16: Network & QSR | F16: No | G16: Australia | H16: 1 | I16: Hire | J16: 0.23168925 | K16: 0.23168925
... B136: R0474 | C136: Strategy Analyst | D136: COE SA&D | E136: Technology Strategy & AI Capability | F136: No | G136: Australia | H136: 1 | I136: Hold | J136: 0.17048975 | K136: 0
